Workbook
Name ActitudinalBAK: 'Taxonomias para RA'!$AC$3:$AG$3
Name Bloom: 'Taxonomias para RA'!$G$3:$I$3
Name Circutos: 'Paso 2 Redacción competen'!$F$4
Name CognitivoBAK: 'Taxonomias para RA'!$S$3:$X$3
Name CompetenciaEspecifica1: 'Paso 2 Redacción competen'!$F$4
Name ComponentesCompetencias: 'Paso1 Analisis perfil egreso'!$E$2:$G$2
Name FACULTADES: #REF!
Name ProcedimentalBAK: 'Taxonomias para RA'!$Y$3:$AB$3
Name RA: 'Paso 5 Estrategias micro'!$B$8
Name resultadoaprendizaje: #REF!
Name Saber: 'Paso1 Analisis perfil egreso'!$E$3:$E$5
Name SaberHacer: 'Paso1 Analisis perfil egreso'!$F$3:$F$5
Name SaberSer: 'Paso1 Analisis perfil egreso'!$G$3:$G$5
Name TIC: 'Paso 2 Redacción competen'!$F$6

Sheet Paso1 Analisis perfil egreso
A1: [Escribir el nombre del programa] | B1: [Escribir la modalidad: presencial o virtual] | C1: [Escribir el perfil profesional del egresado.] | D1: [Escribir el perfil ocupacional del egresado.] | E1: Componentes fundamentales aplicables a la solución de problemas en la vida profesional [Listar, según lo escrito en el perfil profesional, qué debe saber el egresado en las categorías de Saber -conocimientos, hechos, teorías-, Saber hacer -técnicas, procedimientos, metodologías-, y Saber ser -valores, condiciones, etc.] | H1: Componentes fundamentales de la ocupación laboral del profesional [Listar, según lo escrito en el perfil ocupacional, en qué áreas, qué tareas potenciales y en qué poblaciones o contextos podrá laborar el profesional.] | K1: Diferencial (valor agregado) del profesional [Listar, según lo escrito en los perfiles, los elementos que son diferenciales y generan un valor agregado al egresado.]
A2: Programa | B2: Modalidad | C2: Perfil profesional | D2: Perfil ocupacional | E2: Saber | F2: SaberHacer | G2: SaberSer | H2: Áreas profesionales | I2: Tareas profesionales | J2: Poblaciones actuación | K2: Valor agregado
A3: Ingeniería de Sistemas | B3: Presencial | C3: El ingeniero de sistemas de la Institución Universitaria Politécnico Grancolombiano posee una formación integral que le permite intervenir en distintas fases de proyectos de tecnologías de la información, generando valor a los procesos organizacionales. Asimismo, diseña e implementa soluciones de software orientadas al desarrollo tecnológico y a la construcción de sistemas computacionales alineados con los objetivos del país. Su desempeño se caracteriza por el uso responsable del conocimiento, la autonomía, el pensamiento crítico y una actitud ética y honesta en el ámbito de los sistemas informáticos y la computación. | D3: El egresado de Ingeniería de Sistemas posee competencias técnicas que le permiten aportar en diversas etapas del ciclo de vida del software y de los sistemas de información. Está preparado para desempeñarse en funciones de desarrollo de aplicaciones, análisis de requerimientos, consultoría, dirección de proyectos, infraestructura tecnológica, arquitectura de la información y gestión de bases de datos, contribuyendo con soluciones innovadoras y eficientes a las demandas del sector productivo nacional. | E3: Ingeniería de software e infraestructura TIC | F3: diseñar soluciones de software | G3: alineadas con prácticas basadas en estándares y marcos de referencia aplicados en los sistemas empresariales u organizacionales. | H3: Análisis de sistemas Desarrollo de software Administración de sistemas Diseño y administración de bases de datos Consultoría de sistemas | I3: Analizar software y sistemas de información Diseñar sistemas TI Diseñar sistemas informáticos Analizar y diseñar sistemas Implemetar procesos de negocio de tecnología de la información proponer arquitecturas de información para análisis de negocio Diseño de software. Aplicar metodologías de desarrollo de software. | J3: Sistemas informáticos Sistemas de producción de software Sistemas informáticos Datos e información de la organización | K3: El graduado en Ingeniería de Sistemas del Politécnico Grancolombiano se distingue por su capacidad de abordar problemas complejos con un enfoque estructurado y analítico, optimizando recursos y diseñando soluciones eficientes. Su formación le permite desarrollar un pensamiento lógico riguroso, descomponer problemas en componentes fundamentales y construir modelos precisos que mejoran el desempeño de los sistemas computacionales. Esta habilidad para razonar con claridad, abstraer conceptos y aplicar principios formales en el desarrollo de tecnología lo convierte en un profesional altamente competitivo, preparado para enfrentar desafíos en diversos campos de la industria, desde la implementación de algoritmos hasta la innovación en software y la toma de decisiones basada en datos.
E4: Esquemas de representación de información | F4: manipular la información adecuadamente | G4: considerando principios de integridad, de acuerdo con los retos propios del sector.
E5: Algoritmia y programación | F5: construir soluciones computacionales | G5: integrando criterios de eficiencia, según las necesidades tecnológicas de las empresas u organizaciones.
E6: Fenómenos contemporáneos | F6: reconocer sus afectaciones o contribuciones en el marco de las ciudadanías globales y de una sociedad responsable y sostenible. | G6: desde una perspectiva global, soportada en datos, con una mirada ética y crítica.

Sheet Paso 2 Redacción competen
A1: Elementos para redactar las competencias que desarrollará el programa
A2: [Enumerar las competencias que se van a declarar.] | B2: [A partir de la celda B2 dar clic sobre el ícono de lista desplegable y elegir el verbo que considere adecuado.] | C2: [A partir de la celda C2 dar clic sobre la lista desplegable y elegir el saber extraído del perfil de egreso.] | D2: [Escribir para qué se abordará el saber elegido. Se sugiere apoyarse en el saber hacer.] | E2: [Escribir la condición describiendo los referentes, parámetros, principios, requerimientos o retos que se necesitan para alcanzar las características del perfil en el contexto donde el egresado se desenvolverá.] | F2: [Articular los componentes. Iniciar con el verbo, continuar con el objeto conceptual, luego la finalidad y condición de contexto o referencia; estos últimos no requieren un orden particular.] | G2: [Escribir el tipo de competencia del perfil: Específica (si es del bloque Disciplinar para pregrado o de los componentes para el caso de posgrado) o Genérica (si aplica bloque institucional pregrado)]
A3: No. | B3: Verbo competencia | C3: Objeto conceptual | D3: Finalidad | E3: Condición de contexto o referencia | F3: Redacción competencia | G3: Tipo de competencia
A4: 1 | B4: Dominar | C4: Ingeniería de software e infraestructura TIC | D4: diseñar soluciones de software | E4: alineadas con prácticas basadas en estándares y marcos de referencia aplicados en los sistemas empresariales u organizacionales. | F4: Dominar los conceptos propios de la ingeniería de software y la infraestructura TIC para diseñar soluciones de software, alineadas con prácticas basadas en estándares y marcos de referencia aplicados en sistemas empresariales u organizacionales. | G4: Específica
A5: 2 | B5: Diseñar | C5: Esquemas de representación de información | D5: manipular la información adecuadamente | E5: considerando principios de integridad, de acuerdo con los retos propios del sector. | F5: Diseñar esquemas de representación para manipular apropiadamente la información, considerando principios de integridad, de acuerdo con los retos propios del sector. | G5: Específica
A6: 3 | B6: Dominar | C6: Algoritmia y programación | D6: construir soluciones computacionales | E6: integrando criterios de eficiencia, según las necesidades tecnológicas de las empresas u organizaciones. | F6: Dominar conceptos de algoritmia y programación para construir soluciones computacionales, integrando criterios de eficiencia, según las necesidades tecnológicas de las empresas u organizaciones. | G6: Específica
A7: 4 | B7: Analizar | C7: Fenómenos contemporáneos | D7: reconocer sus afectaciones o contribuciones en el marco de las ciudadanías globales y de una sociedad responsable y sostenible. | E7: desde una perspectiva global, soportada en datos, con una mirada ética y crítica | F7: Analizar los fenómenos contemporáneos desde una perspectiva glocal, soportada en datos, con una mirada ética y crítica, para reconocer sus afectaciones o contribuciones en el marco de las ciudadanías globales y de una sociedad responsable y sostenible. | G7: Genérica

Sheet Paso 3 Redacción RA
A1: [A partir de la celda A2 dar clic en la lista desplegable y seleccionar la competencia redactada en el paso 2.] | B1: [Enumerar los resultados de aprendizaje que se van a declarar.] | C1: [A partir de la celda C2, dar clic en la lista desplegable y elegir el tipo de dominio a tratar en el resultado de aprendizaje.] | D1: [A partir de la cela D2, dar clic en la lista desplegable y elegir el saber correspondiente al dominio.] | E1: [A partir de la celda E2, dar clic en la lista desplegable y elegir la taxonomía que se considere adecuada, solo se elige una para todos los saberes.] | F1: [A partir de la celda F2, dar clic en la lista desplegable y elegir el dominio que se considera adecuado.] | G1: [A partir de la celda G2, dar clic en la lista desplegable y elegir el nivel del dominio que se considera adecuado.] | H1: [A partir de la celda H2, dar clic en la lista desplegable y elegir el verbo que se considera adecuado.] | I1: [Iniciar con el verbo elegido (columna H), en infinitivo, luego el objeto sobre el cual recae la acción (columna D) y finalmente la condición de contexto (académico, disciplinar, social u otro).]
A2: Competencia por desarrollar | B2: Número de resultado | C2: TipoSaber | D2: SaberAsociado | E2: Taxonomía | F2: Dominio Asociado | G2: Nivel Dominio | H2: Verbo RA | I2: Resultados Aprendizaje
A3: Dominar los conceptos propios de la ingeniería de software y la infraestructura TIC para diseñar soluciones de software, alineadas con prácticas basadas en estándares y marcos de referencia aplicados en sistemas empresariales u organizacionales. | B3: 1 | C3: Saber | D3: Ingeniería de software e infraestructura TIC | E3: BAK | F3: CognitivoBAK | G3: SíntesisBAK | H3: Interpretar | I3: Interpreta patrones de arquitectura y diseño de software, así como de infraestructura TIC, para determinar las necesidades técnicas y tecnológicas de los sistemas de información, según las condiciones que emergen en los proyectos de software.
A4: Dominar los conceptos propios de la ingeniería de software y la infraestructura TIC para diseñar soluciones de software, alineadas con prácticas basadas en estándares y marcos de referencia aplicados en sistemas empresariales u organizacionales. | B4: 3 | C4: SaberHacer | D4: diseñar soluciones de software | E4: BAK | F4: ProcedimentalBAK | G4: PrecisiónBAK | H4: Producir | I4: Produce artefactos de software para estructurar soluciones correspondientes, según las condiciones y restricciones del contexto.
A5: Dominar los conceptos propios de la ingeniería de software y la infraestructura TIC para diseñar soluciones de software, alineadas con prácticas basadas en estándares y marcos de referencia aplicados en sistemas empresariales u organizacionales. | B5: 4 | C5: SaberSer | D5: alineadas con prácticas basadas en estándares y marcos de referencia aplicados en los sistemas empresariales u organizacionales. | E5: BAK | F5: ActitudinalBAK | G5: OrganizarBAK | H5: Identificar | I5: Identifica los requisitos de sistemas que emergen en contextos de desarrollo tecnológico, teniendo en cuenta los referentes técnicos y normativos, para formular propuestas y proyectos, incorporando criterios de eficiencia e integridad en entornos empresariales u organizacionales.
A6: Diseñar esquemas de representación para manipular apropiadamente la información, considerando principios de integridad, de acuerdo con los retos propios del sector. | B6: 5 | C6: Saber | D6: Esquemas de representación de información | E6: BAK | F6: CognitivoBAK | G6: AnálisisBAK | H6: Analizar | I6: Analiza estructuras de representación de datos para determinar su idoneidad en la resolución de problemas computacionales, teniendo en cuenta los requerimientos tecnológicos del contexto.
A7: Diseñar esquemas de representación para manipular apropiadamente la información, considerando principios de integridad, de acuerdo con los retos propios del sector. | B7: 6 | C7: SaberHacer | D7: manipular la información adecuadamente | E7: BAK | F7: ProcedimentalBAK | G7: ControlBAK | H7: Utilizar | I7: Utiliza herramientas y tecnologías de almacenamiento, gestión y transformación de los datos para obtener información, según las condiciones y restricciones que se observen en el contexto.
A8: Diseñar esquemas de representación para manipular apropiadamente la información, considerando principios de integridad, de acuerdo con los retos propios del sector. | B8: 4 | C8: SaberSer | D8: considerando principios de integridad, de acuerdo con los retos propios del sector. | E8: BAK | F8: ActitudinalBAK | G8: OrganizarBAK | H8: Identificar | I8: Identifica los requisitos de sistemas que emergen en contextos de desarrollo tecnológico, teniendo en cuenta los referentes técnicos y normativos, para formular propuestas y proyectos, incorporando criterios de eficiencia e integridad en entornos empresariales u organizacionales.
A9: Dominar conceptos de algoritmia y programación para construir soluciones computacionales, integrando criterios de eficiencia, según las necesidades tecnológicas de las empresas u organizaciones. | B9: 7 | C9: Saber | D9: Algoritmia y programación | E9: BAK | F9: CognitivoBAK | G9: SíntesisBAK | H9: Articular | I9: Articula principios de algoritmia y programación para establecer la viabilidad técnica de soluciones computacionales, según el tipo de usuario y las condiciones del entorno tecnológico.
A10: Dominar conceptos de algoritmia y programación para construir soluciones computacionales, integrando criterios de eficiencia, según las necesidades tecnológicas de las empresas u organizaciones. | B10: 8 | C10: SaberHacer | D10: construir soluciones computacionales | E10: BAK | F10: ProcedimentalBAK | G10: ControlBAK | H10: Implementar | I10: Implementa algoritmos para generar soluciones computacionales, siguiendo métodos, técnicas y estructuras propios de los paradigmas de programación.
A11: Dominar conceptos de algoritmia y programación para construir soluciones computacionales, integrando criterios de eficiencia, según las necesidades tecnológicas de las empresas u organizaciones. | B11: 4 | C11: SaberSer | D11: integrando criterios de eficiencia, según las necesidades tecnológicas de las empresas u organizaciones. | E11: BAK | F11: ActitudinalBAK | G11: OrganizarBAK | H11: Identificar | I11: Identifica los requisitos de sistemas que emergen en contextos de desarrollo tecnológico, teniendo en cuenta los referentes técnicos y normativos, para formular propuestas y proyectos, incorporando criterios de eficiencia e integridad en entornos empresariales u organizacionales.
A12: Analizar los fenómenos contemporáneos desde una perspectiva glocal, soportada en datos, con una mirada ética y crítica, para reconocer sus afectaciones o contribuciones en el marco de las ciudadanías globales y de una sociedad responsable y sostenible. | B12: 2 | C12: Saber | D12: Fenómenos contemporáneos | E12: Bloom | F12: CognitivoB | G12: ComprensiónB | H12: Identificar | I12: Identifica fenómenos contemporáneos y su relación con la profesión, para determinar sus impactos e influencia en la sociedad, de forma responsable y crítica.

Sheet Paso 4 Estrategias mesocurricu
A1: [A partir de la celda A3 despliegue el(los) resultado(s) de aprendizaje y elegir aquel (aquellos) al(a los) que se contribuye desde la estrategia.] | B1: [Escribir el nombre de la estrategia a desarrollar. Participación de los estudiantes en cursos, talleres, seminarios, conferencias, pruebas estandarizadas, investigaciones, actividades o experiencias, cuerpos académicos, redes, comunidades, la elaboración de textos y materiales, así como las publicaciones, entre otros.] | C1: [Describir la(s) estrategia(s) definidas por el programa.] | D1: [Escribir los indicadores de impacto de la estrategia. Se sugieren indicadores como: Valora el nivel de contribución de la estrategia a los resultados de aprendizaje; Número de estudiantes que participan en la estrategia; Número de veces que se realiza la estrategia, entre otros.] | E1: [Escribir las acciones de retroalimentación que usará el programa para comunicar a los estudiantes sobre el alcance de sus resultados de aprendizaje.] | F1: [Escribir, para cada indicador con qué instrumento se recogerá información para evidenciar el (los) impacto (s) declarados. Encuesta, lista de asistencia, informe, entre otros.]
A2: Resultado de aprendizaje | B2: Estrategia del programa | C2: Descripción | D2: Indicador de Impacto de la Estrategia | E2: Acciones de retroalimentación para los estudiantes | F2: Instrumentos de medición
A3: Identifica los requisitos de sistemas que emergen en contextos de desarrollo tecnológico, teniendo en cuenta los referentes técnicos y normativos, para formular propuestas y proyectos, incorporando criterios de eficiencia e integridad en entornos empresariales u organizacionales. | B3: Visitas técnicas | C3: Realización de visitas técnicas presenciales y virtuales a empresas públicas y privadas afines a las asignaturas del programa con el fin de reconocer los elementos conceptuales vistos en el aula en espacios de aplicación real en empresas del sector e identificar los entornos empresariales de aplicación de los conocimientos adquiridos, así como las tendencias de la industria. | D3: Número de estudiantes que participan en la estrategia por año. | E3: Informar a estudiantes y docentes, mediante un informe anual, el grado de alineación entre lo observado en las visitas técnicas y los resultados de aprendizaje del programa. Formar a los estudiantes, a través de talleres posteriores a las visitas, en la aplicación práctica de los conceptos observados en empresas reales. | F3: Listados de participación.
A4: Analiza estructuras de representación de datos para determinar su idoneidad en la resolución de problemas computacionales, teniendo en cuenta los requerimientos tecnológicos del contexto. | D4: Número de veces que se realiza la estrategia por año. | F4: Informe o Reporte.
A5: Articula principios de algoritmia y programación para establecer la viabilidad técnica de soluciones computacionales, según el tipo de usuario y las condiciones del entorno tecnológico. | D5: Valoración del nivel de aporte de la estrategia a los resultados de aprendizaje del programa. | F5: Encuesta de valoración.
A6: Interpreta patrones de arquitectura y diseño de software, así como de infraestructura TIC, para determinar las necesidades técnicas y tecnológicas de los sistemas de información, según las condiciones que emergen en los proyectos de software. | B6: Monitorias académicas | C6: Se proveen los recursos y habilitan los espacios en modalidad presencial, remota o combinada para que estudiantes con excelente desempeño académico, conocimientos y habilidades en asignaturas específicas y cualidades humanas orienten y apoyen a sus compañeros que tienen dificultades en determinados campos del saber con el objetivo de fortalecer las prácticas pedagógicas y el mejoramiento del desempeño académico, en un marco de solidaridad entre estudiantes. | D6: Número de estudiantes que participan en la estrategia por periodo académico. | E6: Prevenir dificultades recurrentes en el aprendizaje al identificar, durante las monitorías, los temas en los que los estudiantes muestran mayores vacíos conceptuales. Ayudar a tomar decisiones sobre ajustes pedagógicos en las asignaturas al sistematizar la información recogida en las monitorías. | F6: Listados de participación.
A7: Analiza estructuras de representación de datos para determinar su idoneidad en la resolución de problemas computacionales, teniendo en cuenta los requerimientos tecnológicos del contexto. | D7: Número de veces que se realiza la estrategia por periodo académico. | F7: Informe o Reporte.
A8: Articula principios de algoritmia y programación para establecer la viabilidad técnica de soluciones computacionales, según el tipo de usuario y las condiciones del entorno tecnológico. | D8: Valoración del nivel de aporte de la estrategia a los resultados de aprendizaje del programa. | F8: Encuesta de valoración.
A9: Interpreta patrones de arquitectura y diseño de software, así como de infraestructura TIC, para determinar las necesidades técnicas y tecnológicas de los sistemas de información, según las condiciones que emergen en los proyectos de software. | B9: Líderes académicos en el aula | C9: Incentivar a los estudiantes que participan de los espacios académicos, desarrollar habilidades blandas como liderazgo, trabajo en equipo, comunicación asertiva, ejerciendo un papel como líder académico al interior del aula. De tal forma que pueda ser un enlace entre el docente y el grupo de estudiantes. | D9: Número de estudiantes que participan en la estrategia. | E9: Formar a los estudiantes líderes en habilidades de comunicación y gestión académica que potencien su papel como enlace entre el docente y el grupo. | F9: Listados de participación.
A10: Analiza estructuras de representación de datos para determinar su idoneidad en la resolución de problemas computacionales, teniendo en cuenta los requerimientos tecnológicos del contexto. | D10: Número de veces que se realiza la estrategia por año. | F10: Informe o Reporte.
A11: Articula principios de algoritmia y programación para establecer la viabilidad técnica de soluciones computacionales, según el tipo de usuario y las condiciones del entorno tecnológico. | D11: Valoración del nivel de aporte de la estrategia a los resultados de aprendizaje del programa. | F11: Encuesta de valoración.
A12: Identifica los requisitos de sistemas que emergen en contextos de desarrollo tecnológico, teniendo en cuenta los referentes técnicos y normativos, para formular propuestas y proyectos, incorporando criterios de eficiencia e integridad en entornos empresariales u organizacionales. | B12: Consultorías, auditorías e interventorias | C12: Designación de expertos en temáticas específicas de las TIC, encargados de definir de forma dinámica los campos de desarrollo de procesos de consultorías, auditorías e interventorías. Creación de espacios conformados por estudiantes, egresados, docentes y expertos capacitados para desarrollar procesos de consultoría y/o auditoría en temáticas asociadas a la ingeniería de telecomunicaciones. | D12: Número de estudiantes que participan en la estrategia por año. | E12: Informar a la comunidad académica sobre los resultados, hallazgos y aprendizajes derivados de los procesos de consultoría, auditoría e interventoría desarrollados con participación estudiantil. Ayudar a tomar decisiones sobre la actualización curricular y las líneas de proyección del programa a partir de la sistematización de los aportes y necesidades identificadas en dichos procesos. | F12: Listados de participación.
A13: Produce artefactos de software para estructurar soluciones correspondientes, según las condiciones y restricciones del contexto. | D13: Número de oportunidades de consultoría, auditoría e interventoría desarrolladas con medición anual. | F13: Informe o Reporte.
A14: Utiliza herramientas y tecnologías de almacenamiento, gestión y transformación de los datos para obtener información, según las condiciones y restricciones que se observen en el contexto. | D14: Valoración del nivel de aporte de la estrategia a los resultados de aprendizaje del programa. | F14: Encuesta de valoración.
A15: Implementa algoritmos para generar soluciones computacionales, siguiendo métodos, técnicas y estructuras propios de los paradigmas de programación. | B15: Grupos de interés (Asociaciones, grupos de estudio) | C15: Grupos estudiantiles adscritos a una agremiación nacional o internacional (ejemplo IEEE) o para el desarrollo de una temática propia del programa (ejemplo grupo de estudio en matemáticas), con el fin de profundizar en los contenidos desarrollados en los espacios académicos, participar en eventos, desarrollar proyectos de formación en investigación, entre otros. | D15: Número de estudiantes que participan en la estrategia por año. | E15: Prevenir la desconexión entre las actividades de los grupos y los objetivos curriculares mediante un seguimiento de sus proyectos y logros. | F15: Listados de participación.
A16: Interpreta patrones de arquitectura y diseño de software, así como de infraestructura TIC, para determinar las necesidades técnicas y tecnológicas de los sistemas de información, según las condiciones que emergen en los proyectos de software. | D16: Relación de actividades desarrolladas en el grupo de interés con actividades del perfil ocupacional del programa. | F16: Informe o Reporte.
A17: Analiza estructuras de representación de datos para determinar su idoneidad en la resolución de problemas computacionales, teniendo en cuenta los requerimientos tecnológicos del contexto. | D17: Valoración del nivel de aporte de la estrategia a los resultados de aprendizaje del programa. | F17: Encuesta de valoración.
A18: Produce artefactos de software para estructurar soluciones correspondientes, según las condiciones y restricciones del contexto. | B18: Semilleros | C18: Grupos de trabajo orientados a la discusión y apropiación en diferentes áreas temáticas propuestas por la facultad, adquiriendo en esta dinámica habilidades investigativas. Se generan a partir del desarrollo de las líneas de investigación del grupo CITIC y estan liderados por docentes con asignación de investigación de la escuela TIC | D18: Número de estudiantes que participan en la estrategia por periodo académico. | E18: Informar periódicamente a estudiantes y docentes sobre los avances, productos y logros obtenidos en los semilleros, destacando su aporte a los resultados de aprendizaje del programa. Formar a los participantes en metodologías de investigación aplicada que fortalezcan su capacidad para producir software, gestionar datos e implementar algoritmos en proyectos académicos. | F18: Listas de participación.
A19: Utiliza herramientas y tecnologías de almacenamiento, gestión y transformación de los datos para obtener información, según las condiciones y restricciones que se observen en el contexto. | D19: Número de veces que se realiza la estrategia por periodo académico. | F19: Informe o Reporte.
A20: Implementa algoritmos para generar soluciones computacionales, siguiendo métodos, técnicas y estructuras propios de los paradigmas de programación. | D20: Valoración del nivel de aporte de la estrategia a los resultados de aprendizaje del programa. | F20: Encuesta de valoración.
A21: Interpreta patrones de arquitectura y diseño de software, así como de infraestructura TIC, para determinar las necesidades técnicas y tecnológicas de los sistemas de información, según las condiciones que emergen en los proyectos de software. | B21: Tutorías | C21: Espacios en los que se recibe ayuda y realimentación por parte de profesores, de manera presencial o en línea, respecto a temas o actividades del diario vivir del estudiante, haciendo uso de las herramientas tecnológicas apropiadas para los fines. | D21: Número de estudiantes que participan en la estrategia por periodo académico. | E21: Prevenir la repetición de dificultades de aprendizaje al registrar y analizar los temas más consultados en las tutorías para orientar mejoras pedagógicas. Ayudar a tomar decisiones sobre la pertinencia de reforzar ciertos contenidos o metodologías en las asignaturas a partir de la evidencia recogida en las tutorías. | F21: Listas de participación.
A23: Analiza estructuras de representación de datos para determinar su idoneidad en la resolución de problemas computacionales, teniendo en cuenta los requerimientos tecnológicos del contexto. | D23: Número de veces que se realiza la estrategia por periodo académico. | F23: Informe o Reporte.
A24: Articula principios de algoritmia y programación para establecer la viabilidad técnica de soluciones computacionales, según el tipo de usuario y las condiciones del entorno tecnológico. | D24: Valoración del nivel de aporte de la estrategia a los resultados de aprendizaje del programa. | F24: Encuesta de valoración.

Sheet Paso 3 Redacción RA - Backup 
A1: [A partir de la celda A2 dar clic en la lista desplegable y seleccionar la competencia redactada en el paso 2.] | B1: [Enumerar los resultados de aprendizaje que se van a declarar.] | C1: [A partir de la celda C2, dar clic en la lista desplegable y elegir el tipo de dominio a tratar en el resultado de aprendizaje.] | D1: [A partir de la cela D2, dar clic en la lista desplegable y elegir el saber correspondiente al dominio.] | E1: [A partir de la celda E2, dar clic en la lista desplegable y elegir la taxonomía que se considere adecuada, solo se elige una para todos los saberes.] | F1: [A partir de la celda F2, dar clic en la lista desplegable y elegir el dominio que se considera adecuado.] | G1: [A partir de la celda G2, dar clic en la lista desplegable y elegir el nivel del dominio que se considera adecuado.] | H1: [A partir de la celda H2, dar clic en la lista desplegable y elegir el verbo que se considera adecuado.] | I1: [Iniciar con el verbo elegido (columna H), en infinitivo, luego el objeto sobre el cual recae la acción (columna D) y finalmente la condición de contexto (académico, disciplinar, social u otro).]
A2: Competencia por desarrollar | B2: Número de resultado | C2: TipoSaber | D2: SaberAsociado | E2: Taxonomía | F2: Dominio Asociado | G2: Nivel Dominio | H2: Verbo RA | I2: Resultados Aprendizaje
A3: Dominar los elementos de teoría de circuitos y transmisión de información para diseñar, implementar o administrar la infraestructura eléctrica y los dispositivos electrónicos que dan soporte a los sistemas de telecomunicaciones alineado con prácticas basadas en estándares del sector y la normatividad vigente, teniendo en cuenta las condiciones, restricciones y requerimientos técnicos del entorno. | B3: 1 | C3: Saber | D3: los elementos de teoría de circuitos y transmisión de información | E3: BAK | F3: CognitivoBAK | G3: ComprensiónBAK | H3: Identificar | I3: Identifica los elementos de teoría de circuitos, de transmisión de información, de seguridad de la información, de redes de comunicaciones, de sistemas de cómputo, de estandares y marcos de referencia que hacen parte de la gestión de proyectos como del desarrollo de actividades relacionadas a las infraestructuras de TIC, para explicar soluciones de diseño, administración o implementación a problemáticas del sector, desde un abordaje teórico-práctico, a través de herramientas de simulación, análisis de casos prácticos y uso de equipos de laboratorio.
A4: Dominar los elementos de teoría de circuitos y transmisión de información para diseñar, implementar o administrar la infraestructura eléctrica y los dispositivos electrónicos que dan soporte a los sistemas de telecomunicaciones alineado con prácticas basadas en estándares del sector y la normatividad vigente, teniendo en cuenta las condiciones, restricciones y requerimientos técnicos del entorno. | B4: 4 | C4: SaberHacer | D4: para diseñar, implementar o administrar la infraestructura eléctrica y los dispositivos electrónicos que dan soporte a los sistemas de telecomunicaciones | E4: BAK | F4: ProcedimentalBAK | G4: ManipulaciónBAK | H4: Aplicar | I4: Aplica los elementos de teoría de circuitos, de transmisión de información, de seguridad de la información, de redes de comunicaciones, de sistemas de cómputo, de estandares tecnológicos y marcos de referencia que hacen parte de la gestión de proyectos como del desarrollo de actividades relacionadas a las infraestructuras de TIC, para construir propuestas de diseño, implementación o administración de infraestructura eléctrica, dispositivos electrónicos, servicios de comunicaciones en nube o en sitio, sistemas de telecomunicaciones, a través de herramientas de simulación, análisis de casos prácticos y uso de equipos de laboratorio.
A5: Dominar los elementos de teoría de circuitos y transmisión de información para diseñar, implementar o administrar la infraestructura eléctrica y los dispositivos electrónicos que dan soporte a los sistemas de telecomunicaciones alineado con prácticas basadas en estándares del sector y la normatividad vigente, teniendo en cuenta las condiciones, restricciones y requerimientos técnicos del entorno. | B5: 7 | C5: SaberSer | D5: alineado con prácticas basadas en estándares del sector y la normatividad vigente, teniendo en cuenta las condiciones, restricciones y requerimientos técnicos del entorno. | E5: BAK | F5: ActitudinalBAK | G5: ValorarBAK | H5: Emplear | I5: Emplea las buenas prácticas de teoría de circuitos y transmisión, y de seguridad de la información, redes y sistemas de cómputo basadas en estándares del sector y la normatividad vigente, teniendo en cuenta las condiciones, restricciones y requerimientos técnicos de un proyecto, para formular soluciones en infraestructuras TIC o del área de las telecomunicaciones.
A6: Dominar los elementos de seguridad de la información, redes de comunicaciones y sistemas de cómputo que hacen parte de infraestructuras TIC para diseñar, implementar o administrar infraestructuras y servicios de comunicaciones en sitio o en nube alineado con prácticas basadas en estándares del sector y la normatividad vigente, teniendo en cuenta las condiciones, restricciones y requerimientos técnicos del entorno. | B6: 1 | C6: Saber | D6: los elementos de seguridad de la información, redes de comunicaciones y sistemas de cómputo que hacen parte de infraestructuras TIC | E6: BAK | F6: CognitivoBAK | G6: ComprensiónBAK | H6: Identificar | I6: Identifica los elementos de teoría de circuitos, de transmisión de información, de seguridad de la información, de redes de comunicaciones, de sistemas de cómputo, de estandares y marcos de referencia que hacen parte de la gestión de proyectos como del desarrollo de actividades relacionadas a las infraestructuras de TIC, para evaluar soluciones a problemáticas del sector, desde un abordaje teórico-práctico, a través de herramientas de simulación, análisis de casos prácticos y uso de equipos de laboratorio.
A7: Dominar los elementos de seguridad de la información, redes de comunicaciones y sistemas de cómputo que hacen parte de infraestructuras TIC para diseñar, implementar o administrar infraestructuras y servicios de comunicaciones en sitio o en nube alineado con prácticas basadas en estándares del sector y la normatividad vigente, teniendo en cuenta las condiciones, restricciones y requerimientos técnicos del entorno. | B7: 5 | C7: SaberHacer | D7: para diseñar, implementar o administrar infraestructuras y servicios de comunicaciones en sitio o en nube | E7: BAK | F7: ProcedimentalBAK | G7: ManipulaciónBAK | H7: Aplicar | I7: Aplica los elementos de teoría de circuitos, de transmisión de información, de seguridad de la información, de redes de comunicaciones, de sistemas de cómputo, de estandares tecnológicos y marcos de referencia que hacen parte de la gestión de proyectos como del desarrollo de actividades relacionadas a las infraestructuras de TIC, para construir propuestas de diseño, implementación o administración de infraestructura eléctrica, dispositivos electrónicos, servicios de comunicaciones en nube o en sitio, sistemas de telecomunicaciones, a través de herramientas de simulación, análisis de casos prácticos y uso de equipos de laboratorio.
A8: Dominar los elementos de seguridad de la información, redes de comunicaciones y sistemas de cómputo que hacen parte de infraestructuras TIC para diseñar, implementar o administrar infraestructuras y servicios de comunicaciones en sitio o en nube alineado con prácticas basadas en estándares del sector y la normatividad vigente, teniendo en cuenta las condiciones, restricciones y requerimientos técnicos del entorno. | B8: 7 | C8: SaberSer | D8: alineado con prácticas basadas en estándares del sector y la normatividad vigente, teniendo en cuenta las condiciones, restricciones y requerimientos técnicos del entorno. | E8: BAK | F8: ActitudinalBAK | G8: ValorarBAK | H8: Emplear | I8: Emplea las buenas prácticas de teoría de circuitos y transmisión, y de seguridad de la información, redes y sistemas de cómputo basadas en estándares del sector y la normatividad vigente, teniendo en cuenta las condiciones, restricciones y requerimientos técnicos de un proyecto, para formular soluciones en infraestructuras TIC o del área de las telecomunicaciones.
A9: Conocer los estándares y marcos de referencia asociados tanto a la gestión de proyectos como al desarrollo de actividades relacionadas a las tecnologías de la información para diseñar, implementar o administrar soluciones del área de las telecomunicaciones, la seguridad de la información y la infraestructura TIC manteniendo una postura socialmente responsable, autónoma, teniendo en cuenta las condiciones, restricciones y requerimientos técnicos del entorno. | B9: 2 | C9: Saber | D9: los estándares y marcos de referencia asociados tanto a la gestión de proyectos como al desarrollo de actividades relacionadas a las tecnologías de la información | E9: BAK | F9: CognitivoBAK | G9: ComprensiónBAK | H9: Identificar | I9: Identifica los elementos de teoría de circuitos, de transmisión de información, de seguridad de la información, de redes de comunicaciones, de sistemas de cómputo, de estandares y marcos de referencia que hacen parte de la gestión de proyectos como del desarrollo de actividades relacionadas a las infraestructuras de TIC, para evaluar soluciones a problemáticas del sector, desde un abordaje teórico-práctico, a través de herramientas de simulación, análisis de casos prácticos y uso de equipos de laboratorio.
A10: Conocer los estándares y marcos de referencia asociados tanto a la gestión de proyectos como al desarrollo de actividades relacionadas a las tecnologías de la información para diseñar, implementar o administrar soluciones del área de las telecomunicaciones, la seguridad de la información y la infraestructura TIC manteniendo una postura socialmente responsable, autónoma, teniendo en cuenta las condiciones, restricciones y requerimientos técnicos del entorno. | B10: 6 | C10: SaberHacer | D10: para diseñar, implementar o administrar soluciones del área de las telecomunicaciones, la seguridad de la información y la infraestructura TIC | E10: BAK | F10: ProcedimentalBAK | G10: ManipulaciónBAK | H10: Aplicar | I10: Aplica los elementos de teoría de circuitos, de transmisión de información, de seguridad de la información, de redes de comunicaciones, de sistemas de cómputo, de estandares tecnológicos y marcos de referencia que hacen parte de la gestión de proyectos como del desarrollo de actividades relacionadas a las infraestructuras de TIC, para construir propuestas de diseño, implementación o administración de infraestructura eléctrica, dispositivos electrónicos, servicios de comunicaciones en nube o en sitio, sistemas de telecomunicaciones, a través de herramientas de simulación, análisis de casos prácticos y uso de equipos de laboratorio.
A11: Conocer los estándares y marcos de referencia asociados tanto a la gestión de proyectos como al desarrollo de actividades relacionadas a las tecnologías de la información para diseñar, implementar o administrar soluciones del área de las telecomunicaciones, la seguridad de la información y la infraestructura TIC manteniendo una postura socialmente responsable, autónoma, teniendo en cuenta las condiciones, restricciones y requerimientos técnicos del entorno. | B11: 7 | C11: SaberSer | D11: manteniendo una postura socialmente responsable, autónoma, teniendo en cuenta las condiciones, restricciones y requerimientos técnicos del entorno. | E11: BAK | F11: ActitudinalBAK | G11: ValorarBAK | H11: Emplear | I11: Emplea las buenas prácticas de teoría de circuitos y transmisión, y de seguridad de la información, redes y sistemas de cómputo basadas en estándares del sector y la normatividad vigente, teniendo en cuenta las condiciones, restricciones y requerimientos técnicos de un proyecto, para formular soluciones en infraestructuras TIC o del área de las telecomunicaciones.
A12: Analizar los fenómenos contemporáneos desde una perspectiva glocal, soportada en datos, con una mirada ética y crítica, para reconocer sus afectaciones o contribuciones en el marco de las ciudadanías globales y de una sociedad responsable y sostenible. | B12: 3 | C12: Saber | D12: Fenómenos contemporáneos | E12: Bloom | F12: CognitivoB | G12: ComprensiónB | H12: Identificar | I12: Identifica fenómenos contemporáneos y su relación con la profesión, para determinar sus impactos e influencia en la sociedad, de forma responsable y crítica.

Sheet Paso 5 Estrategias micro
A1: [Estas celdas se diligencian automáticamente. No ajustar.] | B1: [A partir de la celda A3 despliegue el(los) resultado(s) de aprendizaje y elija aquel (aquellos) al(a los) que se contribuye desde la asignatura o módulo).] | C1: [Escribir el semestre en el que se cursa la asignatura o módulo.] | D1: [Escribir el nombre de la asignatura o módulo que contribuye al logro del resultado de aprendizaje.] | E1: [Redactar los indicadores iniciando con el verbo en presente indicativo, luego el objeto conceptual y finalmente el complemento de oración (que indique una condición o finalidad, con, para, de, entre otros conectores).] | F1: [Escribir la tipología: T (teórico), P (Práctico), TP (Teórico Práctico)] | G1: [Marcar con X el bloque o componente al que pertenece la asignatura o módulo. Por favor ajustar para posgrado, eliminar una columna y ubicar los títulos C.Fundamentación y C.Profundización.] | J1: [Escribir el número de créditos de la asignatura o módulo] | K1: [Escribir el número de horas de trabajo directo: 16*# o 12*#, para presencial o virtual, según sea el caso.] | L1: [Escribir el número de horas de trabajo independiente: 32*# columna J o 36*# columna J, para presencial o virtual, respectivamente.] | M1: [Escribir la suma de los números de horas de las dos celdas anteriores.] | N1: [Escribir el nombre de los cuatro núcleos temáticos que abordará la asignatura o el módulo.] | O1: [Escribir las lecturas, talleres, análisis, referentes, etc., que realiza el estudiante, clasificadas en trabajo directo e independiente.] | P1: [Escribir las actividades de evaluación que se emplean para identificar el alcance del (de los) indicador(es) de logro(s).] | Q1: [Escribir las acciones de retroalimentación que se emplearán en la asignatura o módulo, para retroalimentar a los estudiantes respecto al alcance de los indicadores de logro. Recordar que son cuatro acciones: informar, formar, prevenir y ayudar a tomar decisiones e indique cómo.]
A2: Tipo de Saber | B2: Resultado de aprendizaje | C2: Semestre | D2: Nombre asignatura o módulo | E2: Indicadores de logro asignatura o módulo | F2: Tipología | G2: B.Institucional | H2: B.Disciplinar | I2: B.Electivo | J2: Créditos | K2: Número de horas trabajo directo | L2: Número de horas trabajo independiente | M2: Total de horas | N2: Núcleos temáticos | O2: Actividades de aprendizaje | P2: Actividades de evaluación | Q2: Acciones de retroalimentación
A3: =_xlfn.XLOOKUP(B3,'Paso 3 Redacción RA'!I$3:I$12,'Paso 3 Redacción RA'!C$3:C$12,,0,1) -> Saber | B3: Identifica fenómenos contemporáneos y su relación con la profesión, para determinar sus impactos e influencia en la sociedad, de forma responsable y crítica. | C3: 1 | D3: Razonamiento Cuantitativo | E3: Analiza datos numéricos presentados en tablas, gráficos o textos para proponer soluciones informadas a situaciones problema del contexto. | F3: TP | G3: X | J3: 3 | K3: =16*J3 -> 48 | L3: =32*J3 -> 96 | M3: =SUM(K3:L3) -> 144 | N3: 1. Pensamiento numérico. Interpretación y representación de información numérica 2. Pensamiento algebraico. Desde la representación de regularidades y patrones 3. Pensamiento algebraico. Desde las relaciones de comparación entre cantidades o expresiones numéricas 4. Pensamiento geométrico. Propiedades, formas y relaciones espaciales | O3: Trabajo directo: Clase magistral activa Trabajo independiente: Lecturas Laboratorios, talleres, resolución de problemas | P3: Se sugiere emplear estrategias como las siguientes. Evaluación formativa: Preguntas intercaladas, presentaciones de situaciones problema. Evaluación sumativa: Valoración de laboratorios, talleres, estudios de casos y una evaluación final. | Q3: Las acciones de retroalimentación giran en torno a las siguientes. Formar: donde se crean las condiciones para que los estudiantes adquieran conocimientos, habilidades, actitudes, aptitudes y destrezas. Además, debe promover su desarrollo integral y debe acompañarlos en las situaciones académicas que enfrenten durante el desarrollo de un módulo o una asignatura. Informar: para que los estudiantes identifiquen los cambios que pueden afectarlos directa o indirectamente tanto en el aula de clase como en otros espacios. Prevenir: con el fin de anticiparse a las situaciones académicas que pueden representar dificultad para los estudiantes. Esto se logra a través de la interacción individual con los estudiantes y del completo conocimiento del contexto educativo en que el tutor se desenvuelve. Ayudar a decidir: donde se orienta a los estudiantes para que tomen la mejor decisión ante una situación concreta. El objetivo es que el estudiante fortalezca su autonomía y la toma de decisiones responsable.
A4: =_xlfn.XLOOKUP(B4,'Paso 3 Redacción RA'!I$3:I$12,'Paso 3 Redacción RA'!C$3:C$12,,0,1) -> Saber | B4: Identifica fenómenos contemporáneos y su relación con la profesión, para determinar sus impactos e influencia en la sociedad, de forma responsable y crítica. | C4: 1 | D4: Cultura, Política Y Sociedad | E4: Reconoce las problemáticas, escenarios y mecanismos de participación ciudadana en el marco de sociedades de información y digitales para abordarlas desde iniciativas investigativas. Identifica los objetivos de desarrollo sostenible para la comprensión de problemáticas sociales, ambientales y culturales. Reflexiona los impactos de avances tecnológicos en su contexto profesional y ciudadano para el análisis de contextos situados. | F4: TP | G4: X | J4: 3 | K4: =16*J4 -> 48 | L4: =32*J4 -> 96 | M4: =SUM(K4:L4) -> 144 | N4: 1. ODS, problemas locales: una mirada a Colombia, territorio en búsqueda de la consolidación de la Paz. 2. Ciudadanía y su lugar: relaciones, dinámicas, construcción, expresión y mecanismos de participación. 3. Ecosistemas digitales: relaciones, dinámicas, construcción, expresión e impactos en el contexto profesional. 4. Narrativas y contenidos digitales: análisis de contextos situados. | O4: Trabajo directo: Clase magistral activa combinada con estrategias de aprendizaje basado en investigación Trabajo independiente: Lecturas Laboratorios Talleres Estudios de caso | P4: Evaluación formativa: Construcción de textos argumentativos sobre problemáticas en las sociedades de la información. ,elaboración de ejercicios para la citación en APA última edición., cartografías sociales de problemáticas sociales, culturales y ambientales., elaboración de árbol de problemas, construcción de objetivos generales y específicos, desarrollo de anteproyectos, talleres experienciales con juegos de roles, realización de exposición a través de la caja italiana para el manejo del espacio, la lectura y la oralidad, exposiciones creativas del PIF en el marco del evento “Feria de proyectos” Evaluación sumativa comprende los logros obtenidos en cada actividad y en todo el proceso, representados en porcentajes acumulativos según la parametrización de 0 a 5; Árbol de problemas, Exposiciones Creativas , Seguimiento , Entre Proyecto: Parte 1, Quiz , Seguimiento , Entre Proyecto: Parte 1I , Entrevista a expertos , Feria de proyectos , Seguimiento | Q4: Las acciones de retroalimentación giran en torno a las siguientes. Formar: donde se crean las condiciones para que los estudiantes adquieran conocimientos, habilidades, actitudes, aptitudes y destrezas. Además, debe promover su desarrollo integral y debe acompañarlos en las situaciones académicas que enfrenten durante el desarrollo de un módulo o una asignatura. Informar: para que los estudiantes identifiquen los cambios que pueden afectarlos directa o indirectamente tanto en el aula de clase como en otros espacios. Prevenir: con el fin de anticiparse a las situaciones académicas que pueden representar dificultad para los estudiantes. Esto se logra a través de la interacción individual con los estudiantes y del completo conocimiento del contexto educativo en que el tutor se desenvuelve. Ayudar a decidir: donde se orienta a los estudiantes para que tomen la mejor decisión ante una situación concreta. El objetivo es que el estudiante fortalezca su autonomía y la toma de decisiones responsable.
A5: =_xlfn.XLOOKUP(B5,'Paso 3 Redacción RA'!I$3:I$12,'Paso 3 Redacción RA'!C$3:C$12,,0,1) -> Saber | B5: Interpreta patrones de arquitectura y diseño de software, así como de infraestructura TIC, para determinar las necesidades técnicas y tecnológicas de los sistemas de información, según las condiciones que emergen en los proyectos de software. | C5: 1 | D5: Introducción a las Redes de Datos | E5: Identifica los elementos que hacen parte de una red de telecomunicaciones, para diseñar infraestructuras y servicios de tecnologías de la información y las comunicaciones, teniendo en cuenta condiciones, restricciones y requerimientos técnicos de un proyecto desde un abordaje teórico-práctico, a través de herramientas de simulación, análisis de casos y uso de equipos de laboratorio. Configura los elementos que hacen parte de una red de telecomunicaciones, para implementar infraestructuras y servicios de tecnologías de la información y las comunicaciones, teniendo en cuenta condiciones, restricciones y requerimientos técnicos de un proyecto desde un abordaje teórico-práctico, a través de herramientas de simulación, análisis de casos y uso de equipos de laboratorio. Emplea los elementos que hacen parte de una red de telecomunicaciones, para resolver problemas asociados a la administración de los sistemas de telecomunicaciones, infraestructuras TIC, teniendo en cuenta condiciones, restricciones y requerimientos técnicos, desde un abordaje teórico-práctico, a través de herramientas de simulación, análisis de casos y uso de equipos de laboratorio. | F5: TP | H5: X | J5: 3 | K5: =16*J5 -> 48 | L5: =32*J5 -> 96 | M5: =SUM(K5:L5) -> 144 | N5: 1. Fundamentos de redes de datos 2. Modelos de referencia OSI y TCP/IP 3. Protocolos de comunicación 4. Configuración básica de redes | O5: Las estrategias pueden variar entre estas y otras que emerjan en el proceso formativo. Trabajo directo: Prácticas guiadas de laboratorio y simulación. Clase magistral activa Trabajo independiente: Prácticas de laboratorio y simulación Lecturas Desarrollo de cuestionarios teórico-prácticos Desarrollo de proyectos de aula | P5: Formativa: Trabajo en clase. Sumativa: Pruebas conceptuales. Trabajo en clase. Exámenes. Avances del proyecto de aul | Q5: Las acciones de retroalimentación giran en torno a las siguientes. Formar: donde se crean las condiciones para que los estudiantes adquieran conocimientos, habilidades, actitudes, aptitudes y destrezas. Además, debe promover su desarrollo integral y debe acompañarlos en las situaciones académicas que enfrenten durante el desarrollo de un módulo o una asignatura. Informar: para que los estudiantes identifiquen los cambios que pueden afectarlos directa o indirectamente tanto en el aula de clase como en otros espacios. Prevenir: con el fin de anticiparse a las situaciones académicas que pueden representar dificultad para los estudiantes. Esto se logra a través de la interacción individual con los estudiantes y del completo conocimiento del contexto educativo en que el tutor se desenvuelve. Ayudar a decidir: donde se orienta a los estudiantes para que tomen la mejor decisión ante una situación concreta. El objetivo es que el estudiante fortalezca su autonomía y la toma de decisiones responsable.
A6: =_xlfn.XLOOKUP(B6,'Paso 3 Redacción RA'!I$3:I$12,'Paso 3 Redacción RA'!C$3:C$12,,0,1) -> Saber | B6: Analiza estructuras de representación de datos para determinar su idoneidad en la resolución de problemas computacionales, teniendo en cuenta los requerimientos tecnológicos del contexto.
A7: =_xlfn.XLOOKUP(B7,'Paso 3 Redacción RA'!I$3:I$12,'Paso 3 Redacción RA'!C$3:C$12,,0,1) -> SaberHacer | B7: Utiliza herramientas y tecnologías de almacenamiento, gestión y transformación de los datos para obtener información, según las condiciones y restricciones que se observen en el contexto.
A8: =_xlfn.XLOOKUP(B8,'Paso 3 Redacción RA'!I$3:I$12,'Paso 3 Redacción RA'!C$3:C$12,,0,1) -> Saber | B8: Interpreta patrones de arquitectura y diseño de software, así como de infraestructura TIC, para determinar las necesidades técnicas y tecnológicas de los sistemas de información, según las condiciones que emergen en los proyectos de software. | C8: 1 | D8: Introducción a la Ingeniería y Ciencias Básicas | E8: Reconoce conceptos básicos de ingeniería, herramientas técnicas y principios éticos para identificar problemas sencillos de ingeniería según su naturaleza técnica, social y ambiental. | F8: TP | H8: X | J8: 2 | K8: =16*J8 -> 32 | L8: =32*J8 -> 64 | M8: =SUM(K8:L8) -> 96 | N8: 1. Fundamentos de la Ingeniería 2. Herramientas y Técnicas de Ingeniería 3. Aplicaciones Prácticas y Proyectos 4. Ingeniería y Sostenibilidad | O8: Las estrategias pueden variar entre estas y otras que emerjan en el proceso formativo. Trabajo directo: Clase magistral activa Estudio de casos Resolución de problemas Trabajo independiente: Estudio de casos Resolución de problemas Desarrollo de proyectos Talleres Exposiciones Pruebas escritas | P8: Formativa: Exposiciones PIF Sumativa: Trabajos escritos Exposiciones PIF | Q8: Las acciones de retroalimentación giran en torno a las siguientes. Formar: donde se crean las condiciones para que los estudiantes adquieran conocimientos, habilidades, actitudes, aptitudes y destrezas. Además, debe promover su desarrollo integral y debe acompañarlos en las situaciones académicas que enfrenten durante el desarrollo de un módulo o una asignatura. Informar: para que los estudiantes identifiquen los cambios que pueden afectarlos directa o indirectamente tanto en el aula de clase como en otros espacios. Prevenir: con el fin de anticiparse a las situaciones académicas que pueden representar dificultad para los estudiantes. Esto se logra a través de la interacción individual con los estudiantes y del completo conocimiento del contexto educativo en que el tutor se desenvuelve. Ayudar a decidir: donde se orienta a los estudiantes para que tomen la mejor decisión ante una situación concreta. El objetivo es que el estudiante fortalezca su autonomía y la toma de decisiones responsable.
A9: =_xlfn.XLOOKUP(B9,'Paso 3 Redacción RA'!I$3:I$12,'Paso 3 Redacción RA'!C$3:C$12,,0,1) -> SaberSer | B9: Identifica los requisitos de sistemas que emergen en contextos de desarrollo tecnológico, teniendo en cuenta los referentes técnicos y normativos, para formular propuestas y proyectos, incorporando criterios de eficiencia e integridad en entornos empresariales u organizacionales.
A10: =_xlfn.XLOOKUP(B10,'Paso 3 Redacción RA'!I$3:I$12,'Paso 3 Redacción RA'!C$3:C$12,,0,1) -> Saber | B10: Articula principios de algoritmia y programación para establecer la viabilidad técnica de soluciones computacionales, según el tipo de usuario y las condiciones del entorno tecnológico.
A11: =_xlfn.XLOOKUP(B11,'Paso 3 Redacción RA'!I$3:I$12,'Paso 3 Redacción RA'!C$3:C$12,,0,1) -> Saber | B11: Analiza estructuras de representación de datos para determinar su idoneidad en la resolución de problemas computacionales, teniendo en cuenta los requerimientos tecnológicos del contexto. | C11: 1 | D11: Pensamiento Algorítmico | E11: Identifica variables relevantes, su naturaleza y la forma en que se relacionan para modelar un problema computacional básico. Implementa expresiones matemáticas y estructuras básicas de programación para desarrollar soluciones a problemas computacionales básicos. | F11: T | H11: X | J11: 2 | K11: =16*J11 -> 32 | L11: =32*J11 -> 64 | M11: =SUM(K11:L11) -> 96 | N11: 1. Fundamentos de pensamiento algorítmico 2. Modelado y especificación de problemas 3. Estructuras básicas de un algoritmo 4. Relaciones de recurrencias | O11: Las estrategias pueden variar entre estas y otras que emerjan en el proceso formativo. Trabajo directo: Clase magistral Ejemplos y talleres en clase Trabajo independiente: Lecturas complementarias Talleres de trabajo autónomo Actividades de refuerzo Tutorías o monitorias | P11: Formativa: Trabajo en clase. Sumativa: Pruebas conceptuales. Trabajo en clase. Exámenes. Avances del proyecto de aula. | Q11: Las acciones de retroalimentación giran en torno a las siguientes. Formar: donde se crean las condiciones para que los estudiantes adquieran conocimientos, habilidades, actitudes, aptitudes y destrezas. Además, debe promover su desarrollo integral y debe acompañarlos en las situaciones académicas que enfrenten durante el desarrollo de un módulo o una asignatura. Informar: para que los estudiantes identifiquen los cambios que pueden afectarlos directa o indirectamente tanto en el aula de clase como en otros espacios. Prevenir: con el fin de anticiparse a las situaciones académicas que pueden representar dificultad para los estudiantes. Esto se logra a través de la interacción individual con los estudiantes y del completo conocimiento del contexto educativo en que el tutor se desenvuelve. Ayudar a decidir: donde se orienta a los estudiantes para que tomen la mejor decisión ante una situación concreta. El objetivo es que el estudiante fortalezca su autonomía y la toma de decisiones responsable.
A12: =_xlfn.XLOOKUP(B12,'Paso 3 Redacción RA'!I$3:I$12,'Paso 3 Redacción RA'!C$3:C$12,,0,1) -> Saber | B12: Articula principios de algoritmia y programación para establecer la viabilidad técnica de soluciones computacionales, según el tipo de usuario y las condiciones del entorno tecnológico.
A13: =_xlfn.XLOOKUP(B13,'Paso 3 Redacción RA'!I$3:I$12,'Paso 3 Redacción RA'!C$3:C$12,,0,1) -> SaberHacer | B13: Implementa algoritmos para generar soluciones computacionales, siguiendo métodos, técnicas y estructuras propios de los paradigmas de programación.
