Workbook
Name actitudinalB: Tabla5785[ActitudinalB]
Name ActitudinalBAK: 'Taxonomias para RA'!$AC$3:$AG$3
Name AK: Tabla5987[AK]
Name AnálisisB: Tabla385280[AnálisisB]
Name AnálisisBAK: Tabla3865[AnálisisBAK]
Name AnálisisMK: Tabla99[AnálisisMK]
Name AnalizarLK: Tabla2129[AnalizarLK]
Name AplicaciónB: Tabla375179[AplicaciónB]
Name AplicaciónBAK: Tabla3764[AplicaciónBAK]
Name AplicarLK: Tabla2028[AplicarLK]
Name áreasprofesionales: #REF!
Name BAK: Tabla5886[BAK]
Name Bloom: 'Taxonomias para RA'!$G$3:$I$3
Name CaracterizarBAK: Tabla4776[CaracterizarBAK]
Name Cognitivo: 'Paso1 Analisis perfil egreso'!$E$3:$E$16
Name CognitivoAK: 'Taxonomias para RA'!$AL$4:$AQ$4
Name cognitivoB: Tabla5583[CognitivoB]
Name CognitivoBAK: 'Taxonomias para RA'!$S$3:$X$3
Name competencias: 'Paso 2 Redacción competen'!$F$3:$F$7
Name ComprenderLK: 'Taxonomias para RA'!$AM$5:$AM$27
Name ComprensionB: Tabla365078[ComprensiónB]
Name ComprensiónBAK: Tabla3663[ComprensiónBAK]
Name ComprensiónMK: Tabla98[ComprensiónMK]
Name ConceptosLK: Tabla91[ConceptosAK]
Name ConocimientoB: Tabla354977[ConocimientoB]
Name ConocimientoBAK: Tabla3555[ConocimientoBAK]
Name Conocimientos: 'Paso1 Analisis perfil egreso'!$E$3:$E$16
Name ControlBAK: Tabla4271[ControlBAK]
Name CrearLK: Tabla2333[CrearLK]
Name dominios: 'Paso1 Analisis perfil egreso'!$E$2:$G$2
Name EvaluaciónB: Tabla405482[EvaluaciónB]
Name EvaluaciónBAK: Tabla4067[EvaluaciónBAK]
Name EvaluarLK: 'Taxonomias para RA'!$AP$5:$AP$46
Name HechosLK: Tabla90[CognitivoAK]
Name ImitaciónBAK: Tabla1168[ImitaciónBAK]
Name ManipulaciónBAK: Tabla3069[ManipulaciónBAK]
Name MetacogniciónLK: Tabla93[MetacogniciónAK]
Name MetacogniciónMK: Tabla101[MetacogniciónMK]
Name MetocogniciónAK: Tabla101[MetacogniciónMK]
Name MK: Tabla6088[MK]
Name ocupacional: 'Paso1 Analisis perfil egreso'!#REF!
Name OrganizarBAK: Tabla4675[OrganizarBAK]
Name PercepciónBAK: 'Taxonomias para RA'!$AC$4:$AC$40
Name poblacionactuacion: #REF!
Name poblaciones: #REF!
Name poblacionesactuación: #REF!
Name PrecisiónBAK: Tabla4170[PrecisiónBAK]
Name procedimentalB: Tabla5684[ProcedimentalB]
Name ProcedimentalBAK: 'Taxonomias para RA'!$Y$3:$AB$3
Name ProcedimientosMK: Tabla92[ProcedimientosAK]
Name ProcesosAK: ProcesosMentalesMK[ProcesosMentalesMK]
Name PsicomotorMK: Tabla96[PsicomotorMK]
Name RecordarLK: 'Taxonomias para RA'!$AL$5:$AL$27
Name RecuperaciónMK: 'Taxonomias para RA'!$BB$5:$BB$27
Name ResponderBAK: Tabla4473[ResponderBAK]
Name resultadoaprendizaje: 'Paso 3 Redacción RA '!$I$3:$I$11
Name Saber: 'Paso1 Analisis perfil egreso'!$E$2:$E$5
Name Saberhacer: 'Paso1 Analisis perfil egreso'!$F$3:$F$15
Name saberser: 'Paso1 Analisis perfil egreso'!$G$3:$G$15
Name SíntesisB: Tabla395381[SíntesisB]

Sheet Paso1 Analisis perfil egreso
A1: [Escribir el nombre del programa] | B1: [Escribir la modalidad: presencial o virtual] | C1: [Escribir el perfil profesional del egresado.] | D1: [Escribir el perfil ocupacional del egresado.] | E1: Componentes fundamentales para definir competencias [Listar las palabras clave, no armar oraciones, respecto qué debe saber el egresado en las categorías de Saber -conocimientos, hechos, teorías-, Saber hacer -técnicas, procedimientos, metodologías-, y Saber ser -valores, condiciones. Esta información se estructura a partir del perfil profesional y cada saber hacer depende del saber ubicado a su izquierda, lo mismo ocurre con el saber ser.] | H1: Componentes fundamentales de la ocupación laboral del profesional [Listar, según lo escrito en el perfil ocupacional, en qué áreas, qué tareas potenciales y en qué poblaciones o contextos podrá laborar el profesional. Esta información es un listado general no requiere dependencia horizontal] | K1: Diferencial (valor agregado) del profesional [Listar, según lo escrito en los perfiles, los elementos que son diferenciales y generan un valor agregado al egresado. Debe ser disciplinar, asociado al perfil, ¿qué es lo que lo hace diferente a otros perfiles similares.]
A2: Programa | B2: Modalidad | C2: Perfil profesional | D2: Perfil ocupacional | E2: Saber | F2: Saberhacer | G2: Saberser | H2: ÁreasProfesionales | I2: TareasProfesionales | J2: PoblacionesActuacion | K2: ValorAgregado
A3: Maestría en Educación STEM | B3: Virtual | C3: El egresado es un ser humano que impulsa el cambio educativo en los diferentes niveles de formación del país, profundizando en la integración de las ciencias, la tecnología, la ingeniería y las matemáticas (STEM), para proyectar propuestas educativas o curriculares innovadoras enmarcadas en el estudio y la promoción del desarrollo de vocaciones STEM, el cierre de brechas e inclusión en las áreas STEM, y la apropiación social de la ciencia, la tecnología y la innovación, en la población estudiantil, de acuerdo con las condiciones y necesidades de las regiones. | D3: El egresado del programa tendrá habilidades para gestionar, asesorar, coordinar, diseñar, implementar y evaluar proyectos o propuestas educativas o curriculares en educación STEM, orientados al mejoramiento de la educación y la integración conocimientos de estas áreas disciplinares. | E3: Educación STEM | F3: para desarrollar competencias analíticas, sistémicas, críticas y de alfabetización digital, desde un enfoque integrador | G3: que transforme los procesos de enseñanza y de aprendizaje, en los distintos niveles de formación, de acuerdo con las condiciones locales o regionales de la comunidad educativa. | H3: Docencia Dirección de proyectos educativos Coordinación de proyectos educativos Gestión de proyectos educativos Consultoría | I3: Diseñar y orientar procesos de formación bajo el marco de la educación STEM en diferentes niveles educativos. Gestionar propuestas educativas innovadoras bajo un marco integrador de las ciencias, la tecnología, la ingeniería y las matemáticas. Direccionar el horizonte institucional atendiendo a los requerimientos del contexto local y regional. Coordinar equipo de trabajo en acciones asociadas a la educación STEM y dirigidos a la comunidad educativa. Asesorar y orientar procesos de gestión de proyectos educativos o currículos en educación formal y no formal. Promover y articular acciones, procesos y estrategias de gestión intrainstitucional e intersectorial en el marco de la educación STEM. | J3: Educación formal en diferentes niveles educativos. Instituciones cuyo propósito es la apropiación y divulgación de la ciencia y la tecnología para la apropiación social del conocimiento. | K3: Estar en la capacidad de generar propuestas o proyectos innovadores que contribuyen a la apropiación social del conocimiento. Desarrollar procesos y estrategias de educación STEM intrainstitucionales o intersectoriales.
E4: Vocaciones STEM, cierre de brechas e inclusión en STEM, apropiación social de CTeI | F4: para plantear estudios que permitan reconocer y comprender las necesidades formativas del país | G4: que emergen a partir de las diferencias y potencialidades regionales ante los cambios culturales y educativos que demanda la sociedad del conocimiento.
E5: Proyectos educativos y curriculares | F5: para materializar propuestas y experiencias en educación STEM | G5: que aborden los retos y problemas de la educación en el país, con una perspectiva analítica, reflexiva, crítica y constructiva.

Sheet Paso 2 Redacción competen
A1: [Enumerar las competencias que se van a declarar.] | B1: [A partir de la celda B2 dar clic sobre el ícono de lista desplegable y elegir el verbo que considere adecuado.] | C1: [A partir de la celda C2 dar clic sobre la lista desplegable y elegir el saber extraído del perfil de egreso.] | D1: [Escribir para qué se abordará el saber elegido. Se sugiere apoyarse en el saber hacer.] | E1: [Escribir la condición describiendo los referentes, parámetros, principios, requerimientos o retos que se necesitan para alcanzar las características del perfil en el contexto donde el egresado se desenvolverá.] | F1: [Articular los componentes. Iniciar con el verbo, continuar con el objeto conceptual, luego la finalidad y condición de contexto o referencia; estos últimos no requieren un orden particular.] | G1: [Escribir el tipo de competencia del perfil: Específica (si es del bloque Disciplinar para pregrado o de los componentes para el caso de posgrado) o Genérica (si aplica bloque institucional pregrado)]
A2: No. | B2: Verbo competencia | C2: Objeto conceptual | D2: Finalidad | E2: Condición de contexto o referencia | F2: Redacción competencia | G2: Tipo competencia
A3: 1 | B3: Dominar | C3: Educación STEM | D3: para desarrollar competencias analíticas, sistémicas, críticas y de alfabetización digital, desde un enfoque integrador | E3: que transforme los procesos de enseñanza y de aprendizaje, en los distintos niveles de formación, de acuerdo con las condiciones locales o regionales de la comunidad educativa. | F3: Dominar los elementos teóricos y prácticos de la educación STEM para el desarrollo de competencias analíticas, sistémicas, computacionales, críticas y de alfabetización digital, desde un enfoque integrador, que transforme los procesos de enseñanza y de aprendizaje, en los distintos niveles de formación, de acuerdo con las condiciones locales o regionales de la comunidad educativa. | G3: Específica
A4: 2 | B4: Analizar | C4: Vocaciones STEM, cierre de brechas e inclusión en STEM, apropiación social de CTeI | D4: para plantear estudios que permitan reconocer y comprender las necesidades formativas del país | E4: que emergen a partir de las diferencias y potencialidades regionales ante los cambios culturales y educativos que demanda la sociedad del conocimiento. | F4: Analiza problemáticas asociadas al desarrollo de vocaciones STEM, el cierre de brechas e inclusión en STEM y la apropiación social de CTI, para darles solución a través de estudios o propuestas de investigación en los que se reconozcan y comprendan las necesidades formativas del país, según las diferencias y potencialidades regionales que demandan los cambios culturales y educativos en la sociedad del conocimiento. | G4: Específica
A5: 3 | B5: Formular | C5: Proyectos educativos y curriculares | D5: para materializar propuestas y experiencias en educación STEM | E5: que aborden los retos y problemas de la educación en el país, con una perspectiva analítica, reflexiva, crítica y constructiva. | F5: Formula proyectos educativos y curriculares para materializar propuestas y experiencias educativas innovadoras en STEM, desde la práctica profesional, que aborden los retos y problemas de la educación en el país, con una perspectiva analítica, reflexiva, crítica y constructiva. | G5: Específica

Sheet Paso 3 Redacción RA 
A1: [A partir de la celda A2 dar clic en la lista desplegable y seleccionar la competencia redactada en el paso 2.] | B1: [Enumerar los resultados de aprendizaje que se van a declarar.] | C1: [A partir de la celda C2, dar clic en la lista desplegable y elegir el tipo de dominio a tratar en el resultado de aprendizaje.] | D1: [A partir de la cela D2, dar clic en la lista desplegable y elegir el saber correspondiente al dominio.] | E1: [A partir de la celda E2, dar clic en la lista desplegable y elegir la taxonomía que se considere adecuada, solo se elige una para todos los saberes.] | F1: [A partir de la celda F2, dar clic en la lista desplegable y elegir el dominio que se considera adecuado.] | G1: [A partir de la celda G2, dar clic en la lista desplegable y elegir el nivel del dominio que se considera adecuado.] | H1: [A partir de la celda H2, dar clic en la lista desplegable y elegir el verbo que se considera adecuado.] | I1: [Iniciar con el verbo elegido (columna H), en infinitivo, luego el objeto sobre el cual recae la acción (columna D) y finalmente la condición de contexto (académico, disciplinar, social u otro).]
A2: Competencia por desarrollar | B2: Número de resultado | C2: TipoSaber | D2: SaberAsociado | E2: Taxonomía | F2: Dominio Asociado | G2: Nivel Dominio | H2: Verbo RA | I2: Resultados Aprendizaje
A3: Domina los elementos teóricos y prácticos de la educación STEM para el desarrollo de competencias analíticas, sistémicas, computacionales, críticas y de alfabetización digital, desde un enfoque integrador, que transforme los procesos de enseñanza y de aprendizaje, en los distintos niveles de formación, de acuerdo con las condiciones locales o regionales de la comunidad educativa. | B3: 1 | C3: Saber | D3: Educación STEM | E3: BAK | F3: CognitivoBAK | G3: EvaluaciónBAK | H3: Determinar | I3: Determina las condiciones y estructuras de pensamiento que se requieren para impulsar el aprendizaje en la educación STEM, contrastando los factores que inciden en el desarrollo de competencias analíticas, sistémicas, computacionales, críticas y de alfabetización digital con los principios teóricos y prácticos de este marco educativo.
A4: Domina los elementos teóricos y prácticos de la educación STEM para el desarrollo de competencias analíticas, sistémicas, computacionales, críticas y de alfabetización digital, desde un enfoque integrador, que transforme los procesos de enseñanza y de aprendizaje, en los distintos niveles de formación, de acuerdo con las condiciones locales o regionales de la comunidad educativa. | B4: 2 | C4: Saberhacer | D4: para desarrollar competencias analíticas, sistémicas, críticas y de alfabetización digital, desde un enfoque integrador | E4: BAK | F4: ProcedimentalBAK | G4: PrecisiónBAK | H4: Elaborar | I4: Elabora una ruta pedagógica y didáctica que articule los factores que inciden en el desarrollo de competencias analíticas, sistémicas, computacionales, críticas y de alfabetización digital con los principios teóricos y prácticos de la educación STEM para definir una propuesta formativa.
A5: Domina los elementos teóricos y prácticos de la educación STEM para el desarrollo de competencias analíticas, sistémicas, computacionales, críticas y de alfabetización digital, desde un enfoque integrador, que transforme los procesos de enseñanza y de aprendizaje, en los distintos niveles de formación, de acuerdo con las condiciones locales o regionales de la comunidad educativa. | B5: 3 | C5: Saberser | D5: que transforme los procesos de enseñanza y de aprendizaje, en los distintos niveles de formación, de acuerdo con las condiciones locales o regionales de la comunidad educativa. | E5: BAK | F5: ActitudinalBAK | G5: CaracterizarBAK | H5: Evaluar | I5: Evalúa las condiciones y necesidades educativas del contexto local o regional para validar la pertinencia de estudios o propuestas formativas en educación STEM con una visión transformadora de los procesos de enseñanza y de aprendizaje.
A6: Analiza problemáticas asociadas al desarrollo de vocaciones STEM, el cierre de brechas e inclusión en STEM y la apropiación social de CTI, para darles solución a través de estudios o propuestas de investigación en los que se reconozcan y comprendan las necesidades formativas del país, según las diferencias y potencialidades regionales que demandan los cambios culturales y educativos en la sociedad del conocimiento. | B6: 4 | C6: Saber | D6: Vocaciones STEM, cierre de brechas e inclusión en STEM, apropiación social de CTeI | E6: BAK | F6: CognitivoBAK | G6: EvaluaciónBAK | H6: Diagnosticar | I6: Diagnostica los factores y necesidades formativas del país, según las diferencias y potencialidades regionales que demandan los cambios culturales y educativos, para identificar problemáticas asociadas al desarrollo de vocaciones STEM, el cierre de brechas e inclusión en STEM y la apropiación social de CTI.
A7: Analiza problemáticas asociadas al desarrollo de vocaciones STEM, el cierre de brechas e inclusión en STEM y la apropiación social de CTI, para darles solución a través de estudios o propuestas de investigación en los que se reconozcan y comprendan las necesidades formativas del país, según las diferencias y potencialidades regionales que demandan los cambios culturales y educativos en la sociedad del conocimiento. | B7: 5 | C7: Saberhacer | D7: para plantear estudios que permitan reconocer y comprender las necesidades formativas del país | E7: BAK | F7: ProcedimentalBAK | G7: ControlBAK | H7: Diseñar | I7: Diseña un estudio o una propuesta de investigación que aborde problemáticas asociadas al desarrollo de vocaciones STEM, el cierre de brechas e inclusión en STEM y la apropiación social de CTI, desde un enfoque integrador, incorporando una ruta pedagógica y didáctica para el desarrollo de competencias analíticas, sistémicas, computacionales, críticas y de alfabetización digital en la población estudiantil.
A8: Analiza problemáticas asociadas al desarrollo de vocaciones STEM, el cierre de brechas e inclusión en STEM y la apropiación social de CTI, para darles solución a través de estudios o propuestas de investigación en los que se reconozcan y comprendan las necesidades formativas del país, según las diferencias y potencialidades regionales que demandan los cambios culturales y educativos en la sociedad del conocimiento. | B8: 3 | C8: Saberser | D8: que emergen a partir de las diferencias y potencialidades regionales ante los cambios culturales y educativos que demanda la sociedad del conocimiento. | E8: BAK | F8: ActitudinalBAK | G8: CaracterizarBAK | H8: Evaluar | I8: Evalúa las condiciones y necesidades educativas del contexto local o regional para validar la pertinencia de estudios o propuestas formativas en educación STEM con una visión transformadora de los procesos de enseñanza y de aprendizaje.
A9: Formula proyectos educativos y curriculares para materializar propuestas y experiencias educativas innovadoras en STEM, desde la práctica profesional, que aborden los retos y problemas de la educación en el país, con una perspectiva analítica, reflexiva, crítica y constructiva. | B9: 4 | C9: Saber | D9: Proyectos educativos y curriculares | E9: BAK | F9: CognitivoBAK | G9: EvaluaciónBAK | H9: Diagnosticar | I9: Diagnostica los factores y necesidades formativas del país, según las diferencias y potencialidades regionales que demandan los cambios culturales y educativos, para identificar problemáticas asociadas al desarrollo de vocaciones STEM, el cierre de brechas e inclusión en STEM y la apropiación social de CTI.
A10: Formula proyectos educativos y curriculares para materializar propuestas y experiencias educativas innovadoras en STEM, desde la práctica profesional, que aborden los retos y problemas de la educación en el país, con una perspectiva analítica, reflexiva, crítica y constructiva. | B10: 6 | C10: Saberhacer | D10: para materializar propuestas y experiencias en educación STEM | E10: BAK | F10: ProcedimentalBAK | G10: ControlBAK | H10: Desarrollar | I10: Desarrolla un estudio o una propuesta educativa innovadora basada en la educación STEM desde un enfoque integrador, para abordar los retos y problemas de la educación en el país, con una perspectiva analítica, reflexiva, crítica y constructiva.
A11: Formula proyectos educativos y curriculares para materializar propuestas y experiencias educativas innovadoras en STEM, desde la práctica profesional, que aborden los retos y problemas de la educación en el país, con una perspectiva analítica, reflexiva, crítica y constructiva. | B11: 3 | C11: Saberser | D11: que aborden los retos y problemas de la educación en el país, con una perspectiva analítica, reflexiva, crítica y constructiva. | E11: BAK | F11: ActitudinalBAK | G11: CaracterizarBAK | H11: Evaluar | I11: Evalúa las condiciones y necesidades educativas del contexto local o regional para validar la pertinencia de estudios o propuestas formativas en educación STEM con una visión transformadora de los procesos de enseñanza y de aprendizaje.

Sheet Paso 4 Estrategias mesocurricu
A1: [A partir de la celda A3 despliegue el(los) resultado(s) de aprendizaje y elegir aquel (aquellos) al(a los) que se contribuye desde la estrategia.] | B1: [Escribir el nombre de la estrategia a desarrollar. Participación de los estudiantes en cursos, talleres, seminarios, conferencias, pruebas estandarizadas, investigaciones, actividades o experiencias, cuerpos académicos, redes, comunidades, la elaboración de textos y materiales, así como las publicaciones, entre otros.] | C1: [Describir la(s) estrategia(s) definidas por el programa.] | D1: [Escribir los indicadores de impacto de la estrategia. Se sugieren indicadores como: Valora el nivel de contribución de la estrategia a los resultados de aprendizaje; Número de estudiantes que participan en la estrategia; Número de veces que se realiza la estrategia, entre otros.] | E1: [Escribir las acciones de retroalimentación que usará el programa para comunicar a los estudiantes sobre el alcance de sus resultados de aprendizaje.] | F1: [Escribir, para cada indicador con qué instrumento se recogerá información para evidenciar el (los) impacto (s) declarados. Encuesta, lista de asistencia, informe, entre otros.]
A2: Resultado de aprendizaje | B2: Estrategia del programa | C2: Descripción | D2: Indicador de Impacto de la Estrategia | E2: Acciones de retroalimentación para los estudiantes | F2: Instrumentos de medición
A3: Evalúa las condiciones y necesidades educativas del contexto local o regional para validar la pertinencia de estudios o propuestas formativas en educación STEM con una visión transformadora de los procesos de enseñanza y de aprendizaje. | B3: Clases espejo | C3: Contacto con universidades a nivel nacional o internacional que tengan grupos de estudio, de investigación o planes de estudio cuyo objeto sea la Educación STEM. | D3: Valoración del nivel de contribución de la estrategia a los resultados de aprendizaje del programa, en una escala de 1 a 5. | E3: Informar y formar a los estudiantes sobre temas asociados a la Educación STEM a través de las clases y para quienes no puedan participar sincrónicamente se publicarán las grabaciones en la sección de anuncios de los módulos. | F3: Encuesta
A4: Diagnostica los factores y necesidades formativas del país, según las diferencias y potencialidades regionales que demandan los cambios culturales y educativos, para identificar problemáticas asociadas al desarrollo de vocaciones STEM, el cierre de brech | D4: Número de estudiantes y graduados que participan en la estrategia. | F4: Listado
A5: Diseña un estudio o una propuesta de investigación que aborde problemáticas asociadas al desarrollo de vocaciones STEM, el cierre de brechas e inclusión en STEM y la apropiación social de CTI, desde un enfoque integrador, incorporando una ruta pedagógica | D5: Número de veces que se realiza la estrategia en el tiempo que determine el programa. | F5: Informe o Reporte
A6: Determina las condiciones y estructuras de pensamiento que se requieren para impulsar el aprendizaje en la educación STEM, contrastando los factores que inciden en el desarrollo de competencias analíticas, sistémicas, computacionales, críticas y de alfabe | B6: Eventos con expertos | C6: Sesiones de encuentro sincrónico con expertos o líderes de proyectos de Educación STEM para el reconocimiento de experiencias llevadas a cabo a nivel nacional o internacional tanto en instituciones educativas como en instituciones cuyo propósito sea la apropiación y la divulgación de la ciencia y la tecnología..(internacionalización movilidad entrante); se relaciona con el sector externo. | D6: Valoración del nivel de contribución de la estrategia a los resultados de aprendizaje del programa, en una escala de 1 a 5. | E6: Informar y formar a los estudiantes sobre temas asociados a la Educación STEM a través de diálogos, foros, talleres o conferencias y para quienes no puedan participar sincrónicamente se publicarán las grabaciones en la sección de anuncios de los módulos. Ayudar a tomar decisiones respecto a los temas que se pueden abordar en los trabajos de investigación. | F6: Encuesta
A7: Elabora una ruta pedagógica y didáctica que articule los factores que inciden en el desarrollo de competencias analíticas, sistémicas, computacionales, críticas y de alfabetización digital con los principios teóricos y prácticos de la educación STEM para | D7: Número de estudiantes que participan en la estrategia. | F7: Listado
A8: Diagnostica los factores y necesidades formativas del país, según las diferencias y potencialidades regionales que demandan los cambios culturales y educativos, para identificar problemáticas asociadas al desarrollo de vocaciones STEM, el cierre de brech | D8: Número de veces que se realiza la estrategia en el tiempo que determine el programa. | F8: Informe o Reporte
A9: Diseña un estudio o una propuesta de investigación que aborde problemáticas asociadas al desarrollo de vocaciones STEM, el cierre de brechas e inclusión en STEM y la apropiación social de CTI, desde un enfoque integrador, incorporando una ruta pedagógica
A10: Determina las condiciones y estructuras de pensamiento que se requieren para impulsar el aprendizaje en la educación STEM, contrastando los factores que inciden en el desarrollo de competencias analíticas, sistémicas, computacionales, críticas y de alfabe | B10: Participación en el proyecto de proyección social Articulación TIC con Colegios | C10: Participar en el proyecto liderado por la Facultad de Ingeniería Diseño e Innovación a través del diseño de propuestas educativas para el fortalecimiento de las competencias TIC en estudiantes de educación inicial, básica y media de Colombia y como una estrategia de relación con el sector externo. | D10: Valoración del nivel de contribución de la estrategia a los resultados de aprendizaje del programa, en una escala de 1 a 5. | E10: Formar a los estudiantes sobre temas de proyectos educativo en STEM a través de un trabajo articulado con colegios y para quienes no puedan participar se socializarán los resultados parciales y finales de los proyectos. Prevenir y ayudar a tomar decisiones respecto a los temas que se pueden abordar en los trabajos de investigación y temas asociados a cómo investigar, cómo escribir, cómo divulgar y cómo validar propuestas educativas o de investigación. | F10: Encuesta
A11: Elabora una ruta pedagógica y didáctica que articule los factores que inciden en el desarrollo de competencias analíticas, sistémicas, computacionales, críticas y de alfabetización digital con los principios teóricos y prácticos de la educación STEM para | D11: Número de estudiantes que participan en la estrategia. | F11: Listado
A12: Evalúa las condiciones y necesidades educativas del contexto local o regional para validar la pertinencia de estudios o propuestas formativas en educación STEM con una visión transformadora de los procesos de enseñanza y de aprendizaje. | D12: Número de veces que se realiza la estrategia en el tiempo que determine el programa. | F12: Informe o Reporte
A13: Desarrolla un estudio o una propuesta educativa innovadora basada en la educación STEM desde un enfoque integrador, para abordar los retos y problemas de la educación en el país, con una perspectiva analítica, reflexiva, crítica y constructiva.

Sheet Paso 5 Estrategias micro
A1: [Estas celdas se diligencian automáticamente. No ajustar.] | B1: [A partir de la celda A3 despliegue el(los) resultado(s) de aprendizaje y elija aquel (aquellos) al(a los) que se contribuye desde la asignatura o módulo).] | C1: [Escribir el semestre en el que se cursa la asignatura o módulo.] | D1: [Escribir el nombre de la asignatura o módulo que contribuye al logro del resultado de aprendizaje.] | E1: [Redactar los indicadores iniciando con el verbo en presente indicativo, luego el objeto conceptual y finalmente el complemento de oración (que indique una condición o finalidad, con, para, de, entre otros conectores).] | F1: [Escribir la tipología: T (teórico), P (Práctico), TP (Teórico Práctico)] | G1: [Marcar con X el bloque o componente al que pertenece la asignatura o módulo. Por favor ajustar para posgrado, eliminar una columna y ubicar los títulos C.Fundamentación y C.Profundización.] | I1: [Escribir el número de créditos de la asignatura o módulo] | J1: [Escribir el número de horas de trabajo directo: 16*# o 12*#, para presencial o virtual, según sea el caso.] | K1: [Escribir el número de horas de trabajo independiente: 32*# columna J o 36*# columna J, para presencial o virtual, respectivamente.] | L1: [Escribir la suma de los números de horas de las dos celdas anteriores.] | M1: [Escribir el nombre de los cuatro núcleos temáticos que abordará la asignatura o el módulo.] | N1: [Escribir las lecturas, talleres, análisis, referentes, etc., que realiza el estudiante, clasificadas en trabajo directo e independiente.] | O1: [Escribir las actividades de evaluación que se emplean para identificar el alcance del (de los) indicador(es) de logro(s).] | P1: [Escribir las acciones de retroalimentación que se emplearán en la asignatura o módulo, para retroalimentar a los estudiantes respecto al alcance de los indicadores de logro. Recordar que son cuatro acciones: informar, formar, prevenir y ayudar a tomar decisiones e indique cómo.]
A2: Tipo de Saber | B2: Resultado de aprendizaje | C2: Semestre | D2: Nombre asignatura o módulo | E2: Indicadores de logro asignatura o módulo | F2: Tipología | G2: C.Fudamentación | H2: C.Profundización | I2: Créditos | J2: Número de horas trabajo directo | K2: Número de horas trabajo independiente | L2: Total de horas | M2: Núcleos temáticos | N2: Actividades de aprendizaje | O2: Actividades de evaluación | P2: Acciones de retroalimentación
A3: =_xlfn.XLOOKUP(B3,'Paso 3 Redacción RA '!I$3:I$11,'Paso 3 Redacción RA '!C$3:C$11,,0,1) -> Saber | B3: Diagnostica los factores y necesidades formativas del país, según las diferencias y potencialidades regionales que demandan los cambios culturales y educativos, para identificar problemáticas asociadas al desarrollo de vocaciones STEM, el cierre de brechas e inclusión en STEM y la apropiación social de CTI. | C3: 1 | D3: Equidad e Inclusión en la Educación STEM | E3: Reconoce la situación actual de participación y rendimiento en educación STEM de la población de un territorio local o regional, para identificar oportunidades de atención a través de propuestas educativas o estudios que articulen los factores que inciden en su mejoramiento. Examina programas y estrategias de intervención para la inclusión y cierre de brechas en STEM, para validar la pertinencia de su implementación teniendo en cuenta las condiciones y necesidades educativas del contexto local o regional. | F3: TP | H3: X | I3: 3 | J3: =12*I3 -> 36 | K3: =36*I3 -> 108 | L3: =SUM(J3:K5) -> 144 | M3: 1. Políticas para la inclusión y cierre de brechas en STEM 2. Estado actual de participación en STEM de grupos étnicos minoritarios 3. Caracterización de factores que influyen en la participación y rendimiento en STEM 4. Intervenciones estratégicas desde la educación STEM | N3: Trabajo directo: Encuentros sincrónicos, mensajeria interna, foros generales, anuncios. Trabajo independiente: Lecturas Fundamentales y complementarias Anuncios Foros Actividades de refuerzo y recursos del módulo | O3: Actividad de puntos evaluables (semana 2 – Cuestionario de 5 preguntas). Entrega previa 1 (semana 3 - Laboratorio, taller, ejercicios, resolución de casos o de problemas, desarrollo de procesos o ejecución de propuestas. Entrega de forma individual o grupal, según indicaciones del profesor). Parcial (semana 4 - Cuestionarios de entre 15 y 20 preguntas). Entrega previa 2 (semana 5 - Laboratorio, taller, ejercicios, resolución de casos o de problemas, desarrollo de procesos o ejecución de propuestas. Entrega de forma individual o grupal, según indicaciones dadas por el profesor). Entrega final (semana 7 - Laboratorio, taller, ejercicios, resolución de casos o de problemas, desarrollo de procesos o ejecución de propuestas. Entrega de forma individual o grupal, según indicaciones dadas por el profesor). Evaluación final (semana 8 - Cuestionario de entre 15 y 20 preguntas). | P3: Las acciones retroalimentación varían entre las siguientes, según las condiciones que identifique el tutor. Formar: donde se crean las condiciones para que los estudiantes adquieran conocimientos, habilidades, actitudes, aptitudes y destrezas. Además, debe promover su desarrollo integral y debe acompañarlos en las situaciones académicas que enfrenten durante el desarrollo de un módulo o una asignatura. Informar: para que los estudiantes identifiquen los cambios que pueden afectarlos directa o indirectamente tanto en el aula de clase como en otros espacios. Prevenir: con el fin de anticiparse a las situaciones académicas que pueden representar dificultad para los estudiantes. Esto se logra a través de la interacción individual con los estudiantes y del completo conocimiento del contexto educativo en que el tutor se desenvuelve. Ayudar a decidir: donde se orienta a los estudiantes para que tomen la mejor decisión ante una situación concreta. El objetivo es que el estudiante fortalezca su autonomía y la toma de decisiones responsable.
A4: =_xlfn.XLOOKUP(B4,'Paso 3 Redacción RA '!I$3:I$11,'Paso 3 Redacción RA '!C$3:C$11,,0,1) -> Saberhacer | B4: Diseña un estudio o una propuesta de investigación que aborde problemáticas asociadas al desarrollo de vocaciones STEM, el cierre de brechas e inclusión en STEM y la apropiación social de CTI, desde un enfoque integrador, incorporando una ruta pedagógica y didáctica para el desarrollo de competencias analíticas, sistémicas, computacionales, críticas y de alfabetización digital en la población estudiantil.
A5: =_xlfn.XLOOKUP(B5,'Paso 3 Redacción RA '!I$3:I$11,'Paso 3 Redacción RA '!C$3:C$11,,0,1) -> Saberser | B5: Evalúa las condiciones y necesidades educativas del contexto local o regional para validar la pertinencia de estudios o propuestas formativas en educación STEM con una visión transformadora de los procesos de enseñanza y de aprendizaje.
A6: =_xlfn.XLOOKUP(B6,'Paso 3 Redacción RA '!I$3:I$11,'Paso 3 Redacción RA '!C$3:C$11,,0,1) -> Saberhacer | B6: Elabora una ruta pedagógica y didáctica que articule los factores que inciden en el desarrollo de competencias analíticas, sistémicas, computacionales, críticas y de alfabetización digital con los principios teóricos y prácticos de la educación STEM para definir una propuesta formativa. | C6: 1 | D6: Territorios y Educación STEM | E6: Aplica estrategias y herramientas adecuadas que permiten evaluar las condiciones y necesidades educativas del territorio respecto al estado, equidad e inclusión en el desarrollo de competencias y vocaciones científicas y tecnológicas. Plantea una problemática asociada a las necesidades educativas de un contexto local o regional para ser abordada por medio del diseño de un estudio o propuesta formativa bajo el marco de la educación STEM. | F6: TP | H6: X | I6: 4 | J6: =12*I6 -> 48 | K6: =36*I6 -> 144 | L6: =SUM(J6:K10) -> 192 | M6: 1. Reconocimiento del contexto educativo en los territorios respecto a CTI 2. Análisis territorial de los elementos estratégicos que movilizan la educación STEM 3. Diagnóstico e interpretación de datos para al análisis de Educación STEM en el territorio 4. Delimitación del problema orientado a soluciones de contexto asociado a educación STEM y territorio | N6: Trabajo directo: Encuentros sincrónicos, mensajeria interna, foros generales, anuncios. Trabajo independiente: Lecturas Fundamentales y complementarias Anuncios Foros Actividades de refuerzo y recursos del módulo | O6: Actividad de puntos evaluables (semana 2 – Cuestionario de 5 preguntas). Entrega previa 1 (semana 3 - Laboratorio, taller, ejercicios, resolución de casos o de problemas, desarrollo de procesos o ejecución de propuestas. Entrega de forma individual o grupal, según indicaciones del profesor). Parcial (semana 4 - Cuestionarios de entre 15 y 20 preguntas). Entrega previa 2 (semana 5 - Laboratorio, taller, ejercicios, resolución de casos o de problemas, desarrollo de procesos o ejecución de propuestas. Entrega de forma individual o grupal, según indicaciones dadas por el profesor). Entrega final (semana 7 - Laboratorio, taller, ejercicios, resolución de casos o de problemas, desarrollo de procesos o ejecución de propuestas. Entrega de forma individual o grupal, según indicaciones dadas por el profesor). Evaluación final (semana 8 - Cuestionario de entre 15 y 20 preguntas). | P6: Formar: donde se crean las condiciones para que los estudiantes adquieran conocimientos, habilidades, actitudes, aptitudes y destrezas. Además, debe promover su desarrollo integral y debe acompañarlos en las situaciones académicas que enfrenten durante el desarrollo de un módulo o una asignatura. Informar: para que los estudiantes identifiquen los cambios que pueden afectarlos directa o indirectamente tanto en el aula de clase como en otros espacios. Prevenir: con el fin de anticiparse a las situaciones académicas que pueden representar dificultad para los estudiantes. Esto se logra a través de la interacción individual con los estudiantes y del completo conocimiento del contexto educativo en que el tutor se desenvuelve. Ayudar a decidir: donde se orienta a los estudiantes para que tomen la mejor decisión ante una situación concreta. El objetivo es que el estudiante fortalezca su autonomía y la toma de decisiones responsable.
A7: =_xlfn.XLOOKUP(B7,'Paso 3 Redacción RA '!I$3:I$11,'Paso 3 Redacción RA '!C$3:C$11,,0,1) -> Saber | B7: Diagnostica los factores y necesidades formativas del país, según las diferencias y potencialidades regionales que demandan los cambios culturales y educativos, para identificar problemáticas asociadas al desarrollo de vocaciones STEM, el cierre de brechas e inclusión en STEM y la apropiación social de CTI.
A8: =_xlfn.XLOOKUP(B8,'Paso 3 Redacción RA '!I$3:I$11,'Paso 3 Redacción RA '!C$3:C$11,,0,1) -> Saberhacer | B8: Diseña un estudio o una propuesta de investigación que aborde problemáticas asociadas al desarrollo de vocaciones STEM, el cierre de brechas e inclusión en STEM y la apropiación social de CTI, desde un enfoque integrador, incorporando una ruta pedagógica y didáctica para el desarrollo de competencias analíticas, sistémicas, computacionales, críticas y de alfabetización digital en la población estudiantil.
A9: =_xlfn.XLOOKUP(B9,'Paso 3 Redacción RA '!I$3:I$11,'Paso 3 Redacción RA '!C$3:C$11,,0,1) -> Saberhacer | B9: Desarrolla un estudio o una propuesta educativa innovadora basada en la educación STEM desde un enfoque integrador, para abordar los retos y problemas de la educación en el país, con una perspectiva analítica, reflexiva, crítica y constructiva.
A10: =_xlfn.XLOOKUP(B10,'Paso 3 Redacción RA '!I$3:I$11,'Paso 3 Redacción RA '!C$3:C$11,,0,1) -> Saberser | B10: Evalúa las condiciones y necesidades educativas del contexto local o regional para validar la pertinencia de estudios o propuestas formativas en educación STEM con una visión transformadora de los procesos de enseñanza y de aprendizaje.
A11: =_xlfn.XLOOKUP(B11,'Paso 3 Redacción RA '!I$3:I$11,'Paso 3 Redacción RA '!C$3:C$11,,0,1) -> Saber | B11: Determina las condiciones y estructuras de pensamiento que se requieren para impulsar el aprendizaje en la educación STEM, contrastando los factores que inciden en el desarrollo de competencias analíticas, sistémicas, computacionales, críticas y de alfabetización digital con los principios teóricos y prácticos de este marco educativo. | C11: 1 | D11: Competencias en STEM | E11: Reconoce las competencias que se promueven desde la educación STEM, para identificar su desarrollo en estrategias y experiencias educativas, de acuerdo con el nivel escolar y el contexto local o regional en el que se lleva a cabo su proceso formativo. | F11: TP | G11: X | I11: 2 | J11: =12*I11 -> 24 | K11: =36*I11 -> 72 | L11: =SUM(J11:K11) -> 96 | M11: 1. Condiciones y estructuras del pensamiento 2. Competencia analítica y crítica 3. Competencias sistémicas y de pensamiento computacional 4. Competencia de alfabetización digital | N11: Trabajo directo: Encuentros sincrónicos, mensajeria interna, foros generales, anuncios. Trabajo independiente: Lecturas Fundamentales y complementarias Anuncios Foros Actividades de refuerzo y recursos del módulo | O11: Actividad de puntos evaluables (semana 2 – Cuestionario de 5 preguntas). Entrega previa 1 (semana 3 - Laboratorio, taller, ejercicios, resolución de casos o de problemas, desarrollo de procesos o ejecución de propuestas. Entrega de forma individual o grupal, según indicaciones del profesor). Parcial (semana 4 - Cuestionarios de entre 15 y 20 preguntas). Entrega previa 2 (semana 5 - Laboratorio, taller, ejercicios, resolución de casos o de problemas, desarrollo de procesos o ejecución de propuestas. Entrega de forma individual o grupal, según indicaciones dadas por el profesor). Entrega final (semana 7 - Laboratorio, taller, ejercicios, resolución de casos o de problemas, desarrollo de procesos o ejecución de propuestas. Entrega de forma individual o grupal, según indicaciones dadas por el profesor). Evaluación final (semana 8 - Cuestionario de entre 15 y 20 preguntas). | P11: Las acciones retroalimentación varían entre las siguientes, según las condiciones que identifique el tutor. Formar: donde se crean las condiciones para que los estudiantes adquieran conocimientos, habilidades, actitudes, aptitudes y destrezas. Además, debe promover su desarrollo integral y debe acompañarlos en las situaciones académicas que enfrenten durante el desarrollo de un módulo o una asignatura. Informar: para que los estudiantes identifiquen los cambios que pueden afectarlos directa o indirectamente tanto en el aula de clase como en otros espacios. Prevenir: con el fin de anticiparse a las situaciones académicas que pueden representar dificultad para los estudiantes. Esto se logra a través de la interacción individual con los estudiantes y del completo conocimiento del contexto educativo en que el tutor se desenvuelve. Ayudar a decidir: donde se orienta a los estudiantes para que tomen la mejor decisión ante una situación concreta. El objetivo es que el estudiante fortalezca su autonomía y la toma de decisiones responsable.
A12: =_xlfn.XLOOKUP(B12,'Paso 3 Redacción RA '!I$3:I$11,'Paso 3 Redacción RA '!C$3:C$11,,0,1) -> Saberhacer | B12: Elabora una ruta pedagógica y didáctica que articule los factores que inciden en el desarrollo de competencias analíticas, sistémicas, computacionales, críticas y de alfabetización digital con los principios teóricos y prácticos de la educación STEM para definir una propuesta formativa.
A13: =_xlfn.XLOOKUP(B13,'Paso 3 Redacción RA '!I$3:I$11,'Paso 3 Redacción RA '!C$3:C$11,,0,1) -> Saberser | B13: Evalúa las condiciones y necesidades educativas del contexto local o regional para validar la pertinencia de estudios o propuestas formativas en educación STEM con una visión transformadora de los procesos de enseñanza y de aprendizaje.
A14: =_xlfn.XLOOKUP(B14,'Paso 3 Redacción RA '!I$3:I$11,'Paso 3 Redacción RA '!C$3:C$11,,0,1) -> Saber | B14: Diagnostica los factores y necesidades formativas del país, según las diferencias y potencialidades regionales que demandan los cambios culturales y educativos, para identificar problemáticas asociadas al desarrollo de vocaciones STEM, el cierre de brechas e inclusión en STEM y la apropiación social de CTI.
A15: =_xlfn.XLOOKUP(B15,'Paso 3 Redacción RA '!I$3:I$11,'Paso 3 Redacción RA '!C$3:C$11,,0,1) -> Saberhacer | B15: Diseña un estudio o una propuesta de investigación que aborde problemáticas asociadas al desarrollo de vocaciones STEM, el cierre de brechas e inclusión en STEM y la apropiación social de CTI, desde un enfoque integrador, incorporando una ruta pedagógica y didáctica para el desarrollo de competencias analíticas, sistémicas, computacionales, críticas y de alfabetización digital en la población estudiantil.
A16: =_xlfn.XLOOKUP(B16,'Paso 3 Redacción RA '!I$3:I$11,'Paso 3 Redacción RA '!C$3:C$11,,0,1) -> Saberhacer | B16: Desarrolla un estudio o una propuesta educativa innovadora basada en la educación STEM desde un enfoque integrador, para abordar los retos y problemas de la educación en el país, con una perspectiva analítica, reflexiva, crítica y constructiva.
A17: =_xlfn.XLOOKUP(B17,'Paso 3 Redacción RA '!I$3:I$11,'Paso 3 Redacción RA '!C$3:C$11,,0,1) -> Saber | B17: Determina las condiciones y estructuras de pensamiento que se requieren para impulsar el aprendizaje en la educación STEM, contrastando los factores que inciden en el desarrollo de competencias analíticas, sistémicas, computacionales, críticas y de alfabetización digital con los principios teóricos y prácticos de este marco educativo. | C17: 1 | D17: Fundamentos de la Educación STEM | E17: Contrasta los fundamentos de la educación STEM con las prácticas educativas del contexto local o regional para identificar oportunidades de transformación en los procesos formativos, a través de la integración de las áreas STEM y en correspondencia con los desafíos y condiciones del país. | F17: TP | G17: X | I17: 2 | J17: =I17*12 -> 24 | K17: =I17*32 -> 64 | L17: =SUM(J17:K17) -> 88 | M17: 1. Inicios y evolución del STEM y la educación STEM 2. Principios y alcance de la educación STEM 3. Relaciones entre las áreas STEM 4. Visión integradora de la educación STEM | N17: Trabajo directo: Encuentros sincrónicos, mensajeria interna, foros generales, anuncios. Trabajo independiente: Lecturas Fundamentales y complementarias Anuncios Foros Actividades de refuerzo y recursos del módulo | O17: Actividad de puntos evaluables (semana 2 – Cuestionario de 5 preguntas). Entrega previa 1 (semana 3 - Laboratorio, taller, ejercicios, resolución de casos o de problemas, desarrollo de procesos o ejecución de propuestas. Entrega de forma individual o grupal, según indicaciones del profesor). Parcial (semana 4 - Cuestionarios de entre 15 y 20 preguntas). Entrega previa 2 (semana 5 - Laboratorio, taller, ejercicios, resolución de casos o de problemas, desarrollo de procesos o ejecución de propuestas. Entrega de forma individual o grupal, según indicaciones dadas por el profesor). Entrega final (semana 7 - Laboratorio, taller, ejercicios, resolución de casos o de problemas, desarrollo de procesos o ejecución de propuestas. Entrega de forma individual o grupal, según indicaciones dadas por el profesor). Evaluación final (semana 8 - Cuestionario de entre 15 y 20 preguntas). | P17: Las acciones retroalimentación varían entre las siguientes, según las condiciones que identifique el tutor. Formar: donde se crean las condiciones para que los estudiantes adquieran conocimientos, habilidades, actitudes, aptitudes y destrezas. Además, debe promover su desarrollo integral y debe acompañarlos en las situaciones académicas que enfrenten durante el desarrollo de un módulo o una asignatura. Informar: para que los estudiantes identifiquen los cambios que pueden afectarlos directa o indirectamente tanto en el aula de clase como en otros espacios. Prevenir: con el fin de anticiparse a las situaciones académicas que pueden representar dificultad para los estudiantes. Esto se logra a través de la interacción individual con los estudiantes y del completo conocimiento del contexto educativo en que el tutor se desenvuelve. Ayudar a decidir: donde se orienta a los estudiantes para que tomen la mejor decisión ante una situación concreta. El objetivo es que el estudiante fortalezca su autonomía y la toma de decisiones responsable.
A18: =_xlfn.XLOOKUP(B18,'Paso 3 Redacción RA '!I$3:I$11,'Paso 3 Redacción RA '!C$3:C$11,,0,1) -> Saberhacer | B18: Elabora una ruta pedagógica y didáctica que articule los factores que inciden en el desarrollo de competencias analíticas, sistémicas, computacionales, críticas y de alfabetización digital con los principios teóricos y prácticos de la educación STEM para definir una propuesta formativa.
A19: =_xlfn.XLOOKUP(B19,'Paso 3 Redacción RA '!I$3:I$11,'Paso 3 Redacción RA '!C$3:C$11,,0,1) -> Saberhacer | B19: Desarrolla un estudio o una propuesta educativa innovadora basada en la educación STEM desde un enfoque integrador, para abordar los retos y problemas de la educación en el país, con una perspectiva analítica, reflexiva, crítica y constructiva.
A20: =_xlfn.XLOOKUP(B20,'Paso 3 Redacción RA '!I$3:I$11,'Paso 3 Redacción RA '!C$3:C$11,,0,1) -> Saberser | B20: Evalúa las condiciones y necesidades educativas del contexto local o regional para validar la pertinencia de estudios o propuestas formativas en educación STEM con una visión transformadora de los procesos de enseñanza y de aprendizaje.
A21: =_xlfn.XLOOKUP(B21,'Paso 3 Redacción RA '!I$3:I$11,'Paso 3 Redacción RA '!C$3:C$11,,0,1) -> Saberhacer | B21: Elabora una ruta pedagógica y didáctica que articule los factores que inciden en el desarrollo de competencias analíticas, sistémicas, computacionales, críticas y de alfabetización digital con los principios teóricos y prácticos de la educación STEM para definir una propuesta formativa. | C21: 1 | D21: Diseño Curricular y de Propuestas Educativas | E21: Analiza las representaciones de los enfoques implícitos del currículo teniendo en cuenta las dimensiones transversales de la educación bajo un enfoque STEM. Estructura una propuesta curricular o educativa para la transformación de los procesos formativos, que integre los fundamentos de la educación STEM para el desarrollo de competencias en estas áreas y que esté en correspondencia con los desafíos y condiciones del país. | F21: TP | G21: X | I21: 3 | J21: =12*I21 -> 36 | K21: =36*I21 -> 108 | L21: =SUM(J21:K23) -> 144 | M21: 1. El currículo 2. El diseño curricular 3. Las propuestas educativas 4. El diseño de propuestas educativas | N21: Trabajo directo: Encuentros sincrónicos, mensajeria interna, foros generales, anuncios. Trabajo independiente: Lecturas Fundamentales y complementarias Anuncios Foros Actividades de refuerzo y recursos del módulo | O21: Actividad de puntos evaluables (semana 2 – Cuestionario de 5 preguntas). Entrega previa 1 (semana 3 - Laboratorio, taller, ejercicios, resolución de casos o de problemas, desarrollo de procesos o ejecución de propuestas. Entrega de forma individual o grupal, según indicaciones del profesor). Parcial (semana 4 - Cuestionarios de entre 15 y 20 preguntas). Entrega previa 2 (semana 5 - Laboratorio, taller, ejercicios, resolución de casos o de problemas, desarrollo de procesos o ejecución de propuestas. Entrega de forma individual o grupal, según indicaciones dadas por el profesor). Entrega final (semana 7 - Laboratorio, taller, ejercicios, resolución de casos o de problemas, desarrollo de procesos o ejecución de propuestas. Entrega de forma individual o grupal, según indicaciones dadas por el profesor). Evaluación final (semana 8 - Cuestionario de entre 15 y 20 preguntas). | P21: Las acciones retroalimentación varían entre las siguientes, según las condiciones que identifique el tutor. Formar: donde se crean las condiciones para que los estudiantes adquieran conocimientos, habilidades, actitudes, aptitudes y destrezas. Además, debe promover su desarrollo integral y debe acompañarlos en las situaciones académicas que enfrenten durante el desarrollo de un módulo o una asignatura. Informar: para que los estudiantes identifiquen los cambios que pueden afectarlos directa o indirectamente tanto en el aula de clase como en otros espacios. Prevenir: con el fin de anticiparse a las situaciones académicas que pueden representar dificultad para los estudiantes. Esto se logra a través de la interacción individual con los estudiantes y del completo conocimiento del contexto educativo en que el tutor se desenvuelve. Ayudar a decidir: donde se orienta a los estudiantes para que tomen la mejor decisión ante una situación concreta. El objetivo es que el estudiante fortalezca su autonomía y la toma de decisiones responsable.
A22: =_xlfn.XLOOKUP(B22,'Paso 3 Redacción RA '!I$3:I$11,'Paso 3 Redacción RA '!C$3:C$11,,0,1) -> Saberhacer | B22: Diseña un estudio o una propuesta de investigación que aborde problemáticas asociadas al desarrollo de vocaciones STEM, el cierre de brechas e inclusión en STEM y la apropiación social de CTI, desde un enfoque integrador, incorporando una ruta pedagógica y didáctica para el desarrollo de competencias analíticas, sistémicas, computacionales, críticas y de alfabetización digital en la población estudiantil.
A23: =_xlfn.XLOOKUP(B23,'Paso 3 Redacción RA '!I$3:I$11,'Paso 3 Redacción RA '!C$3:C$11,,0,1) -> Saberhacer | B23: Desarrolla un estudio o una propuesta educativa innovadora basada en la educación STEM desde un enfoque integrador, para abordar los retos y problemas de la educación en el país, con una perspectiva analítica, reflexiva, crítica y constructiva. | Q23: =SUM(I3:I23) -> 14
A24: =_xlfn.XLOOKUP(B24,'Paso 3 Redacción RA '!I$3:I$11,'Paso 3 Redacción RA '!C$3:C$11,,0,1) -> Saberhacer | B24: Elabora una ruta pedagógica y didáctica que articule los factores que inciden en el desarrollo de competencias analíticas, sistémicas, computacionales, críticas y de alfabetización digital con los principios teóricos y prácticos de la educación STEM para definir una propuesta formativa. | C24: 2 | D24: Modelos y Metodologías Activas en Educación STEM | E24: Estructura una propuesta de transformación de una práctica educativa profesional, que atienda al fomento de competencias, a la inclusión o cierre de brechas, reconociendo modelos y metodologías para el aprendizaje activo y el desarrollo de procesos educativos en STEM, desde un enfoque integrador. | F24: TP | H24: X | I24: 3 | J24: =12*I24 -> 36 | K24: =36*I24 -> 108 | L24: =SUM(J24:K26) -> 144 | M24: 1. Modelos teóricos sobre educación STEM 2. Metodologías para el aprendizaje activo y social 3. Metodologías en educación STEM 4. Experiencias de educación STEM | N24: Trabajo directo: Encuentros sincrónicos, mensajeria interna, foros generales, anuncios. Trabajo independiente: Lecturas Fundamentales y complementarias Anuncios Foros Actividades de refuerzo y recursos del módulo | O24: Actividad de puntos evaluables (semana 2 – Cuestionario de 5 preguntas). Entrega previa 1 (semana 3 - Laboratorio, taller, ejercicios, resolución de casos o de problemas, desarrollo de procesos o ejecución de propuestas. Entrega de forma individual o grupal, según indicaciones del profesor). Parcial (semana 4 - Cuestionarios de entre 15 y 20 preguntas). Entrega previa 2 (semana 5 - Laboratorio, taller, ejercicios, resolución de casos o de problemas, desarrollo de procesos o ejecución de propuestas. Entrega de forma individual o grupal, según indicaciones dadas por el profesor). Entrega final (semana 7 - Laboratorio, taller, ejercicios, resolución de casos o de problemas, desarrollo de procesos o ejecución de propuestas. Entrega de forma individual o grupal, según indicaciones dadas por el profesor). Evaluación final (semana 8 - Cuestionario de entre 15 y 20 preguntas). | P24: Las acciones retroalimentación varían entre las siguientes, según las condiciones que identifique el tutor. Formar: donde se crean las condiciones para que los estudiantes adquieran conocimientos, habilidades, actitudes, aptitudes y destrezas. Además, debe promover su desarrollo integral y debe acompañarlos en las situaciones académicas que enfrenten durante el desarrollo de un módulo o una asignatura. Informar: para que los estudiantes identifiquen los cambios que pueden afectarlos directa o indirectamente tanto en el aula de clase como en otros espacios. Prevenir: con el fin de anticiparse a las situaciones académicas que pueden representar dificultad para los estudiantes. Esto se logra a través de la interacción individual con los estudiantes y del completo conocimiento del contexto educativo en que el tutor se desenvuelve. Ayudar a decidir: donde se orienta a los estudiantes para que tomen la mejor decisión ante una situación concreta. El objetivo es que el estudiante fortalezca su autonomía y la toma de decisiones responsable.
A25: =_xlfn.XLOOKUP(B25,'Paso 3 Redacción RA '!I$3:I$11,'Paso 3 Redacción RA '!C$3:C$11,,0,1) -> Saberhacer | B25: Diseña un estudio o una propuesta de investigación que aborde problemáticas asociadas al desarrollo de vocaciones STEM, el cierre de brechas e inclusión en STEM y la apropiación social de CTI, desde un enfoque integrador, incorporando una ruta pedagógica y didáctica para el desarrollo de competencias analíticas, sistémicas, computacionales, críticas y de alfabetización digital en la población estudiantil.
A26: =_xlfn.XLOOKUP(B26,'Paso 3 Redacción RA '!I$3:I$11,'Paso 3 Redacción RA '!C$3:C$11,,0,1) -> Saberhacer | B26: Desarrolla un estudio o una propuesta educativa innovadora basada en la educación STEM desde un enfoque integrador, para abordar los retos y problemas de la educación en el país, con una perspectiva analítica, reflexiva, crítica y constructiva.
A27: =_xlfn.XLOOKUP(B27,'Paso 3 Redacción RA '!I$3:I$11,'Paso 3 Redacción RA '!C$3:C$11,,0,1) -> Saberhacer | B27: Elabora una ruta pedagógica y didáctica que articule los factores que inciden en el desarrollo de competencias analíticas, sistémicas, computacionales, críticas y de alfabetización digital con los principios teóricos y prácticos de la educación STEM para definir una propuesta formativa. | C27: 2 | D27: La Pedagogía y el Enfoque Integrador | E27: Analiza el tipo de conexión, el énfasis disciplinario y los niveles de integración de las áreas STEM para establecer el alcance y la naturaleza de una propuesta educativa enmarcada en el desarrollo de competencias, de inclusión o de cierre de brechas en educación STEM. | F27: TP | G27: X | I27: 3 | J27: =I27*12 -> 36 | K27: =I27*36 -> 108 | L27: =SUM(J27:K30) -> 144 | M27: 1. Pedagogía 2. Pedagogía integradora 3. Niveles de integración disciplinar 4. Integración de las áreas STEM en la educación | N27: Trabajo directo: Encuentros sincrónicos, mensajeria interna, foros generales, anuncios. Trabajo independiente: Lecturas Fundamentales y complementarias Anuncios Foros Actividades de refuerzo y recursos del módulo | O27: Actividad de puntos evaluables (semana 2 – Cuestionario de 5 preguntas). Entrega previa 1 (semana 3 - Laboratorio, taller, ejercicios, resolución de casos o de problemas, desarrollo de procesos o ejecución de propuestas. Entrega de forma individual o grupal, según indicaciones del profesor). Parcial (semana 4 - Cuestionarios de entre 15 y 20 preguntas). Entrega previa 2 (semana 5 - Laboratorio, taller, ejercicios, resolución de casos o de problemas, desarrollo de procesos o ejecución de propuestas. Entrega de forma individual o grupal, según indicaciones dadas por el profesor). Entrega final (semana 7 - Laboratorio, taller, ejercicios, resolución de casos o de problemas, desarrollo de procesos o ejecución de propuestas. Entrega de forma individual o grupal, según indicaciones dadas por el profesor). Evaluación final (semana 8 - Cuestionario de entre 15 y 20 preguntas). | P27: Las acciones retroalimentación varían entre las siguientes, según las condiciones que identifique el tutor. Formar: donde se crean las condiciones para que los estudiantes adquieran conocimientos, habilidades, actitudes, aptitudes y destrezas. Además, debe promover su desarrollo integral y debe acompañarlos en las situaciones académicas que enfrenten durante el desarrollo de un módulo o una asignatura. Informar: para que los estudiantes identifiquen los cambios que pueden afectarlos directa o indirectamente tanto en el aula de clase como en otros espacios. Prevenir: con el fin de anticiparse a las situaciones académicas que pueden representar dificultad para los estudiantes. Esto se logra a través de la interacción individual con los estudiantes y del completo conocimiento del contexto educativo en que el tutor se desenvuelve. Ayudar a decidir: donde se orienta a los estudiantes para que tomen la mejor decisión ante una situación concreta. El objetivo es que el estudiante fortalezca su autonomía y la toma de decisiones responsable.
