Workbook
Name actitudinalB: Tabla5785[ActitudinalB]
Name ActitudinalBAK: 'Taxonomias para RA'!$AC$3:$AG$3
Name AK: Tabla5987[AK]
Name AnálisisB: Tabla385280[AnálisisB]
Name AnálisisBAK: Tabla3865[AnálisisBAK]
Name AnálisisMK: Tabla99[AnálisisMK]
Name AnalizarLK: Tabla2129[AnalizarLK]
Name AplicaciónB: Tabla375179[AplicaciónB]
Name AplicaciónBAK: Tabla3764[AplicaciónBAK]
Name AplicarLK: Tabla2028[AplicarLK]
Name áreasprofesionales: #REF!
Name BAK: Tabla5886[BAK]
Name Bloom: 'Taxonomias para RA'!$G$3:$I$3
Name CaracterizarBAK: Tabla4776[CaracterizarBAK]
Name Cognitivo: 'Paso1 Analisis perfil egreso'!$E$3:$E$15
Name CognitivoAK: 'Taxonomias para RA'!$AL$4:$AQ$4
Name cognitivoB: Tabla5583[CognitivoB]
Name CognitivoBAK: 'Taxonomias para RA'!$S$3:$X$3
Name competencias: 'Paso 2 Redacción competen'!$F$4:$F$14
Name ComprenderLK: 'Taxonomias para RA'!$AM$5:$AM$27
Name ComprensiónB: Tabla365078[ComprensiónB]
Name ComprensiónBAK: Tabla3663[ComprensiónBAK]
Name ComprensiónMK: Tabla98[ComprensiónMK]
Name ConceptosLK: Tabla91[ConceptosAK]
Name ConocimientoB: Tabla354977[ConocimientoB]
Name ConocimientoBAK: Tabla3555[ConocimientoBAK]
Name Conocimientos: 'Paso1 Analisis perfil egreso'!$E$3:$E$15
Name ControlBAK: Tabla4271[ControlBAK]
Name CrearLK: Tabla2333[CrearLK]
Name dominios: 'Paso1 Analisis perfil egreso'!$E$2:$G$2
Name elementosfinalidad: #REF!
Name EvaluaciónB: Tabla405482[EvaluaciónB]
Name EvaluaciónBAK: Tabla4067[EvaluaciónBAK]
Name EvaluarLK: 'Taxonomias para RA'!$AP$5:$AP$46
Name HechosLK: Tabla90[CognitivoAK]
Name ImitaciónBAK: Tabla1168[ImitaciónBAK]
Name ManipulaciónBAK: Tabla3069[ManipulaciónBAK]
Name MetacogniciónLK: Tabla93[MetacogniciónAK]
Name MetacogniciónMK: Tabla101[MetacogniciónMK]
Name MetocogniciónAK: Tabla101[MetacogniciónMK]
Name MK: Tabla6088[MK]
Name ocupacional: 'Paso1 Analisis perfil egreso'!#REF!
Name OrganizarBAK: Tabla4675[OrganizarBAK]
Name PercepciónBAK: 'Taxonomias para RA'!$AC$4:$AC$40
Name poblacionactuacion: #REF!
Name poblaciones: #REF!
Name poblacionesactuación: #REF!
Name PrecisiónBAK: Tabla4170[PrecisiónBAK]
Name procedimentalB: Tabla5684[ProcedimentalB]
Name ProcedimentalBAK: 'Taxonomias para RA'!$Y$3:$AB$3
Name ProcedimientosMK: Tabla92[ProcedimientosAK]
Name ProcesosAK: ProcesosMentalesMK[ProcesosMentalesMK]
Name PsicomotorMK: Tabla96[PsicomotorMK]
Name RecordarLK: 'Taxonomias para RA'!$AL$5:$AL$27
Name RecuperaciónMK: 'Taxonomias para RA'!$BB$5:$BB$27
Name ResponderBAK: Tabla4473[ResponderBAK]
Name resultadoaprendizaje: 'Paso 3 Redacción RA '!$I$3:$I$22
Name Saber: 'Paso1 Analisis perfil egreso'!$E$3:$E$9
Name Saberhacer: 'Paso1 Analisis perfil egreso'!$F$3:$F$15
Name saberser: 'Paso1 Analisis perfil egreso'!$G$3:$G$15

Sheet Paso1 Analisis perfil egreso
A1: [Escribir el nombre del programa] | B1: [Escribir la modalidad: presencial o virtual] | C1: [Escribir el perfil profesional del egresado.] | D1: [Escribir el perfil ocupacional del egresado.] | E1: Componentes fundamentales aplicables a la solución de problemas en la vida profesional [Listar, según lo escrito en el perfil profesional, qué debe saber el egresado en las categorías de Saber -conocimientos, hechos, teorías-, Saber hacer -técnicas, procedimientos, metodologías-, y Saber ser -valores, condiciones, etc.] | H1: Componentes fundamentales de la ocupación laboral del profesional [Listar, según lo escrito en el perfil ocupacional, en qué áreas, qué tareas potenciales y en qué poblaciones o contextos podrá laborar el profesional.] | K1: Diferencial (valor agregado) del profesional [Listar, según lo escrito en los perfiles, los elementos que son diferenciales y generan un valor agregado al egresado.]
A2: Programa | B2: Modalidad | C2: Perfil profesional | D2: Perfil ocupacional | E2: Saber | F2: Saberhacer | G2: Saberser | H2: ÁreasProfesionales | I2: TareasProfesionales | J2: PoblacionesActuacion | K2: ValorAgregado
A3: Diseño Gráfico | B3: Presencial | C3: El egresado maneja criterios teóricos y tecnológicos del diseño que le permiten proyectar soluciones de diseño empleando recursos de la comunicación visual y multimedial, integrando líneas temáticas como la animación, la ilustración, la gráfica publicitaria, el medio editorial y la grafía para la moda, gestionando la información para la configuración de artefactos funcionales y accesibles. | D3: Estará en condiciones de vincularse con empresas manufactureras, de servicios, de producción o de comunicación, en tareas de análisis, planificación, producción y gestión de proyectos de diseño gráfico, reconociendo las necesidades de diseño de la organización para elaborar y gestionar su aplicación. También podrá ejercer bajo la figura de profesional independiente como consultor o a través del emprendimiento de proyectos personales y en agencias o empresas vinculadas al sector moda. | E3: Estrategias de comunicación visual | F3: resolver de problemas de diseño gráfico | G3: acordes con el contexto de aplicación. | H3: Creatividad publicitaria/Producción audiovisual/Medios editoriales/Comunicaciones corporativas/Empresas culturales/Departamentos de Marketing y Comunicación/Área de diseño y desarrollo de productos/Dirección creativa o Departamentos de arte/Profesional independiente | I3: Creación de propuestas gráficas/Planificación, coordinación y ejecución de proyectos de diseño gráfico/Diseño de contenido gráfico/Creación de materiales impresos y digitales/Asesor o consultor de diseño/Desarrollo de proyectos personalizados/Dirección y desarrollo de conceptos visuales | J3: Agencias de publicidad y marketing/Medios de comunicación y productoras audiovisuales/Empresas manufactureras y de moda/Empresas de comercio electrónico/Emprendimientos y consultorías/Sector cultural/ | K3: Enfoque integral que incorpora la aplicación tecnológica y la gestión de la información para la creación de soluciones visuales y multimediales. Desarrollo de líneas temáticas que amplían el espectro de habilidades en grafía para la moda, gráfica publicitaria y medios editoriales lo que permite abordar diversas áreas del diseño gráfico.
E4: Herramientas tecnológicas en el desarrollo de artefactos de diseño | F4: atender las necesidades en los entornos multimediales | G4: de acuerdo con el contexto en el que son pertinentes.
E5: Necesidades del contexto social y cultural así como del usuario | F5: desarrollar artefactos | G5: funcionales y accesibles.
E6: Correlaciones entre artefacto, contexto y usuario | F6: construir representaciones visuales | G6: que atiendan a las necesidades de diseño en situaciones o contextos que lo requieran.
E7: Proyectos y metodologías de diseño | F7: configurar artefactos | G7: acordes y pertinentes, funcionales y accesibles.
E8: Diseño de artefactos | F8: intervenir contextos en el sector de la moda | G8: con tendencias, estilismo y producción gráfica definidas.
E9: Fenómenos contemporáneos | F9: reconocer sus afectaciones o contribuciones | G9: en el marco de las ciudadanías globales y de una sociedad responsable y sostenible.

Sheet Hoja1

Sheet Paso 2 Redacción competen
A1: Elementos para redactar las competencias que desarrollará el programa
A2: [Enumerar las competencias que se van a declarar.] | B2: [A partir de la celda B2 dar clic sobre el ícono de lista desplegable y elegir el verbo que considere adecuado.] | C2: [A partir de la celda C2 dar clic sobre la lista desplegable y elegir el saber extraído del perfil de egreso.] | D2: [Escribir para qué se abordará el saber elegido. Se sugiere apoyarse en el saber hacer.] | E2: [Escribir la condición describiendo los referentes, parámetros, principios, requerimientos o retos que se necesitan para alcanzar las características del perfil en el contexto donde el egresado se desenvolverá.] | F2: [Articular los componentes. Iniciar con el verbo, continuar con el objeto conceptual, luego la finalidad y condición de contexto o referencia; estos últimos no requieren un orden particular.] | G2: [Escribir el tipo de competencia del perfil: Específica (si es del bloque Disciplinar para pregrado o de los componentes para el caso de posgrado) o Genérica (si aplica bloque institucional pregrado)]
A3: No. | B3: Verbo Competencia | C3: Objeto conceptual | D3: Finalidad | E3: Condición de contexto o referencia | F3: RedacciónCompetencia | G3: Tipo de Competencia
A4: 1 | B4: Formular | C4: Estrategias de comunicación visual | D4: resolver de problemas de diseño gráfico | E4: acordes con el contexto de aplicación. | F4: Formular estrategias de comunicación visual para resolver problemas de diseño gráfico acordes con el contexto de aplicación. | G4: Específica
A5: 2 | B5: Gestionar | C5: Herramientas tecnológicas en el desarrollo de artefactos de diseño | D5: atender las necesidades en los entornos multimediales | E5: de acuerdo con el contexto en el que son pertinentes. | F5: Gestionar herramientas tecnológicas en el desarrollo de artefactos de diseño, de acuerdo con el contexto en el que son pertinentes, para atender las necesidades en los entornos multimediales. | G5: Específica
A6: 3 | B6: Evaluar | C6: Necesidades del contexto social y cultural así como del usuario | D6: desarrollar artefactos | E6: funcionales y accesibles. | F6: Evaluar las necesidades del contexto social y cultural así como del usuario para desarrollar artefactos funcionales y accesibles. | G6: Específica
A7: 4 | B7: Construir | C7: Correlaciones entre artefacto, contexto y usuario | D7: construir representaciones visuales | E7: que atiendan a las necesidades de diseño en situaciones o contextos que lo requieran. | F7: Construir representaciones gráficas, que atiendan a las necesidades de diseño en las situaciones que lo requieran, para comunicar las correlaciones entre artefacto, contexto y usuario. | G7: Específica
A8: 5 | B8: Aplicar | C8: Proyectos y metodologías de diseño | D8: configurar artefactos | E8: acordes y pertinentes, funcionales y accesibles. | F8: Aplica metodologías de diseño, acordes y pertinentes, para desarrollar proyectos y configurar artefactos funcionales y accesibles. | G8: Específica
A9: 6 | B9: Diseñar | C9: Diseño de artefactos | D9: intervenir contextos en el sector de la moda | E9: con tendencias, estilismo y producción gráfica definidas. | F9: Diseñar artefactos para intervenir contextos en el sector de la moda con tendencias, estilismo y producción gráfica definidas. | G9: Específica
A10: 7 | B10: Analizar | C10: Fenómenos contemporáneos | D10: reconocer sus afectaciones o contribuciones | E10: en el marco de las ciudadanías globales y de una sociedad responsable y sostenible. | F10: Analizar los fenómenos contemporáneos desde una perspectiva glocal, soportada en datos, con una mirada ética y crítica, para reconocer sus afectaciones o contribuciones en el marco de las ciudadanías globales y de una sociedad responsable y sostenible. | G10: Genérica

Sheet Paso 3 Redacción RA 
A1: [A partir de la celda A2 dar clic en la lista desplegable y seleccionar la competencia redactada en el paso 2.] | B1: [Enumerar los resultados de aprendizaje que se van a declarar.] | C1: [A partir de la celda C2, dar clic en la lista desplegable y elegir el tipo de dominio a tratar en el resultado de aprendizaje.] | D1: [A partir de la cela D2, dar clic en la lista desplegable y elegir el saber correspondiente al dominio.] | E1: [A partir de la celda E2, dar clic en la lista desplegable y elegir la taxonomía que se considere adecuada, solo se elige una para todos los saberes.] | F1: [A partir de la celda F2, dar clic en la lista desplegable y elegir el dominio que se considera adecuado.] | G1: [A partir de la celda G2, dar clic en la lista desplegable y elegir el nivel del dominio que se considera adecuado.] | H1: [A partir de la celda H2, dar clic en la lista desplegable y elegir el verbo que se considera adecuado.] | I1: [Iniciar con el verbo elegido (columna H), en infinitivo, luego el objeto sobre el cual recae la acción (columna D) y finalmente la condición de contexto (académico, disciplinar, social u otro).]
A2: Competencia por desarrollar | B2: Número de resultado | C2: Tipo Saber | D2: Saber Asociado | E2: Taxonomía | F2: Dominio Asociado | G2: Nivel Dominio | H2: Verbo RA | I2: Resultados Aprendizaje
A3: Formular estrategias de comunicación visual para resolver problemas de diseño gráfico acordes con el contexto de aplicación. | B3: 1 | C3: Saber | D3: Estrategias de comunicación visual | E3: BAK | F3: CognitivoBAK | G3: AnálisisBAK | H3: Relacionar | I3: Relaciona estrategias de comunicación visual con las necesidades de diseño para tomar decisiones en procesos creativos.
A4: Formular estrategias de comunicación visual para resolver problemas de diseño gráfico acordes con el contexto de aplicación. | B4: 6 | C4: Saberhacer | D4: resolver de problemas de diseño gráfico | E4: BAK | F4: ProcedimentalBAK | G4: ControlBAK | H4: Diseñar | I4: Diseña artefactos visuales, en diversos medios y formatos, para desarrollar proyectos que respondan de manera funcional a las necesidades del usuario y de la estrategia de comunicación definida.
A5: Formular estrategias de comunicación visual para resolver problemas de diseño gráfico acordes con el contexto de aplicación. | B5: 8 | C5: Saberser | D5: acordes con el contexto de aplicación. | E5: BAK | F5: ActitudinalBAK | G5: OrganizarBAK | H5: Determinar | I5: Determina los recursos técnicos, visuales y conceptuales necesarios para generar artefactos de diseño funcionales y accesibles, a partir del análisis del problema y el contexto de aplicación.
A6: Gestionar herramientas tecnológicas en el desarrollo de artefactos de diseño, de acuerdo con el contexto en el que son pertinentes, para atender las necesidades en los entornos multimediales. | B6: 2 | C6: Saber | D6: Herramientas tecnológicas en el desarrollo de artefactos de diseño | E6: BAK | F6: CognitivoBAK | G6: ComprensiónBAK | H6: Identificar | I6: Identifica dispositivos, herramientas y plataformas tecnológicas para determinar sus posibilidades de uso en proyectos de diseño.
A7: Gestionar herramientas tecnológicas en el desarrollo de artefactos de diseño, de acuerdo con el contexto en el que son pertinentes, para atender las necesidades en los entornos multimediales. | B7: 7 | C7: Saberhacer | D7: atender las necesidades en los entornos multimediales | E7: BAK | F7: ProcedimentalBAK | G7: ManipulaciónBAK | H7: Explorar | I7: Explora las posibilidades expresivas de las herramientas y los medios tecnológicos para generar soluciones en contextos de diseño.
A8: Gestionar herramientas tecnológicas en el desarrollo de artefactos de diseño, de acuerdo con el contexto en el que son pertinentes, para atender las necesidades en los entornos multimediales. | B8: 8 | C8: Saberser | D8: de acuerdo con el contexto en el que son pertinentes. | E8: BAK | F8: ActitudinalBAK | G8: OrganizarBAK | H8: Determinar | I8: Determina los recursos técnicos, visuales y conceptuales necesarios para generar artefactos de diseño funcionales y accesibles, a partir del análisis del problema y el contexto de aplicación.
A9: Evaluar las necesidades del contexto social y cultural así como del usuario para desarrollar artefactos funcionales y accesibles. | B9: 3 | C9: Saber | D9: Necesidades del contexto social y cultural así como del usuario | E9: BAK | F9: CognitivoBAK | G9: AnálisisBAK | H9: Analizar | I9: Analiza las variables relacionadas con las necesidades del contexto y el usuario para tomar decisiones de diseño.
A10: Evaluar las necesidades del contexto social y cultural así como del usuario para desarrollar artefactos funcionales y accesibles. | B10: 6 | C10: Saberhacer | D10: desarrollar artefactos | E10: BAK | F10: ProcedimentalBAK | G10: ControlBAK | H10: Diseñar | I10: Diseña artefactos visuales, en diversos medios y formatos, para desarrollar proyectos que respondan de manera funcional a las necesidades del usuario y de la estrategia de comunicación definida.
A11: Evaluar las necesidades del contexto social y cultural así como del usuario para desarrollar artefactos funcionales y accesibles. | B11: 8 | C11: Saberser | D11: funcionales y accesibles. | E11: BAK | F11: ActitudinalBAK | G11: OrganizarBAK | H11: Determinar | I11: Determina los recursos técnicos, visuales y conceptuales necesarios para generar artefactos de diseño funcionales y accesibles, a partir del análisis del problema y el contexto de aplicación.
A12: Construir representaciones gráficas, que atiendan a las necesidades de diseño en las situaciones que lo requieran, para comunicar las correlaciones entre artefacto, contexto y usuario. | B12: 1 | C12: Saber | D12: Correlaciones entre artefacto, contexto y usuario | E12: BAK | F12: CognitivoBAK | G12: AnálisisBAK | H12: Relacionar | I12: Relaciona estrategias de comunicación visual con las necesidades de diseño para tomar decisiones en procesos creativos.
A13: Construir representaciones gráficas, que atiendan a las necesidades de diseño en las situaciones que lo requieran, para comunicar las correlaciones entre artefacto, contexto y usuario. | B13: 7 | C13: Saberhacer | D13: construir representaciones visuales | E13: BAK | F13: ProcedimentalBAK | G13: ManipulaciónBAK | H13: Explorar | I13: Explora las posibilidades expresivas de las herramientas y los medios tecnológicos para generar soluciones en contextos de diseño.
A14: Construir representaciones gráficas, que atiendan a las necesidades de diseño en las situaciones que lo requieran, para comunicar las correlaciones entre artefacto, contexto y usuario. | B14: 8 | C14: Saberser | D14: que atiendan a las necesidades de diseño en situaciones o contextos que lo requieran. | E14: BAK | F14: ActitudinalBAK | G14: OrganizarBAK | H14: Determinar | I14: Determina los recursos técnicos, visuales y conceptuales necesarios para generar artefactos de diseño funcionales y accesibles, a partir del análisis del problema y el contexto de aplicación.
... A21: Analizar los fenómenos contemporáneos desde una perspectiva glocal, soportada en datos, con una mirada ética y crítica, para reconocer sus afectaciones o contribuciones en el marco de las ciudadanías globales y de una sociedad responsable y sostenible. | B21: 5 | C21: Saber | D21: Fenómenos contemporáneos | E21: Bloom | F21: CognitivoB | G21: ComprensiónB | H21: Identificar | I21: Identifica fenómenos contemporáneos y su relación con la profesión, para determinar sus impactos e influencia en la sociedad, de forma responsable y crítica.

Sheet Paso 4 Estrategias mesocurricu
A1: [A partir de la celda A3 despliegue el(los) resultado(s) de aprendizaje y elegir aquel (aquellos) al(a los) que se contribuye desde la estrategia.] | B1: [Escribir el nombre de la estrategia a desarrollar. Participación de los estudiantes en cursos, talleres, seminarios, conferencias, pruebas estandarizadas, investigaciones, actividades o experiencias, cuerpos académicos, redes, comunidades, la elaboración de textos y materiales, así como las publicaciones, entre otros.] | C1: [Describir la(s) estrategia(s) definidas por el programa.] | D1: [Escribir los indicadores de impacto de la estrategia. Se sugieren indicadores como: Valora el nivel de contribución de la estrategia a los resultados de aprendizaje; Número de estudiantes que participan en la estrategia; Número de veces que se realiza la estrategia, entre otros.] | E1: [Escribir las acciones de retroalimentación que usará el programa para comunicar a los estudiantes sobre el alcance de sus resultados de aprendizaje.] | F1: [Escribir, para cada indicador con qué instrumento se recogerá información para evidenciar el (los) impacto (s) declarados. Encuesta, lista de asistencia, informe, entre otros.]
A2: Resultado de aprendizaje | B2: Estrategia del programa | C2: Descripción | D2: Indicador de Impacto de la Estrategia | E2: Acciones de retroalimentación para los estudiantes | F2: Instrumentos de medición
A3: Relaciona estrategias de comunicación visual con las necesidades de diseño para tomar decisiones en procesos creativos. | B3: Semilleros | C3: • Icono media: semillero de investigación en el que participan los estudiantes de los programas adscritos a la Escuela de Diseño y en el cual se abordan diversos temas relacionados con estudios en comunicación e industrias culturales y creativas. • LogoLab: semillero en el que participan los estudiantes del programa de Diseño Gráfico y en el cual se llevan a cabo ejercicios de proyección social con comunidades de emprendimiento. • Lumen: semillero en el que participan estudiantes del programa de Diseño Gráfico y en el cual se realizan ejercicios de investigación-creación entorno al proceso fotográfico. | D3: Número de proyectos desarrollados en los semilleros. | E3: Formar a los estudiantes que participan en la estrategia en los temas que allí se aborden. | F3: Reporte o Informe
A4: Diseña artefactos visuales, en diversos medios y formatos, para desarrollar proyectos que respondan de manera funcional a las necesidades del usuario y de la estrategia de comunicación definida. | D4: Número de estudiantes que participan en la estrategia. | F4: Listados de participación
A5: Determina los recursos técnicos, visuales y conceptuales necesarios para generar artefactos de diseño funcionales y accesibles, a partir del análisis del problema y el contexto de aplicación. | D5: Valoración a la contribución de la estrategia a los resultados de aprendizaje del programa. | F5: Encuesta
A6: Determina los recursos técnicos, visuales y conceptuales necesarios para generar artefactos de diseño funcionales y accesibles, a partir del análisis del problema y el contexto de aplicación. | B6: Publicaciones PIF | C6: Proyectos resultados procesos de investigación formativa que derivan en publicaciones en revistas de divulgación propias de la Escuela de Diseño entorno a procesos editoriales y de ilustración. | D6: Número de actividades de divulgación del proyecto y de asignaturas que presentan PIF. | E6: Formar a los estudiantes que participan en la estrategia en los temas que allí se aborden. Formar a los estudiantes que participan en la estrategia en la generación y divulgación de conocimiento exponiendo o presentando los alcances obtenidos en cada proceso ejecutado. | F6: Reporte o Informe
A7: Explora las posibilidades expresivas de las herramientas y los medios tecnológicos para generar soluciones en contextos de diseño. | D7: Número de estudiantes que participan en la estrategia. | F7: Listados de participación
A8: Diseña artefactos visuales, en diversos medios y formatos, para desarrollar proyectos que respondan de manera funcional a las necesidades del usuario y de la estrategia de comunicación definida. | D8: Valoración a la contribución de la estrategia a los resultados de aprendizaje del programa. | F8: Encuesta
A9: Diseña artefactos visuales, en diversos medios y formatos, para desarrollar proyectos que respondan de manera funcional a las necesidades del usuario y de la estrategia de comunicación definida. | B9: Muestra de Proyectos Escuela de Diseño | C9: Evento semestral organizado por la Escuela de Diseño en el que los estudiantes del programa tienen oportunidad de socializar los resultados de sus proyectos desarrollados en clase. Cuenta con un proceso de curaduría. | D9: Número de proyectos presentados. | E9: Formar a los estudiantes que participan en la estrategia en los temas que allí se aborden. Formar a los estudiantes que participan en la estrategia de generación y divulgación de conocimiento exponiendo o presentando los alcances obtenidos en cada proceso ejecutado. | F9: Reporte o Informe
A10: Determina los recursos técnicos, visuales y conceptuales necesarios para generar artefactos de diseño funcionales y accesibles, a partir del análisis del problema y el contexto de aplicación. | D10: Número de estudiantes que participan en la estrategia. | F10: Listados de participación
A11: Explora las posibilidades expresivas de las herramientas y los medios tecnológicos para generar soluciones en contextos de diseño. | D11: Valoración a la contribución de la estrategia a los resultados de aprendizaje del programa. | F11: Encuesta
A12: Diseña artefactos visuales, en diversos medios y formatos, para desarrollar proyectos que respondan de manera funcional a las necesidades del usuario y de la estrategia de comunicación definida. | B12: Actividades de Proyección Social | C12: Acciones encaminadas a procesos de acompañamiento entorno a identidades visuales que realizan estudiantes del programa con el liderazgo docente para el fortalecimiento de emprendimientos y proyectos al interior de la institución como de comunidad externa generando vinculación con el sector real. | D12: Número de proyectos realizados. | E12: Formar a los estudiantes que participan en la estrategia de generación y divulgación de conocimiento exponiendo o presentando los alcances obtenidos en cada proceso ejecutado. | F12: Reporte o Informe
A13: Explora las posibilidades expresivas de las herramientas y los medios tecnológicos para generar soluciones en contextos de diseño. | D13: Número de estudiantes que participan en la estrategia | F13: Listados de participación
A14: Analiza las variables relacionadas con las necesidades del contexto y el usuario para tomar decisiones de diseño. | D14: Valoración a la contribución de la estrategia a los resultados de aprendizaje del programa. | F14: Encuesta
A15: Determina los recursos técnicos, visuales y conceptuales necesarios para generar artefactos de diseño funcionales y accesibles, a partir del análisis del problema y el contexto de aplicación. | B15: Actividades Formativas y de internacionalización | C15: • Clases Espejo: Actividad desarrollada desde el programa de Diseño Gráfico en el contexto de internacionalización que involucra un intercambio temático con docentes y grupos de universidades externas. | D15: Número de veces que se realiza la estrategia por el periodo que establezca el programa. | E15: Formar a los estudiantes que participan en la estrategia en los temas que allí se aborden. Informar a los estudiantes sobre temas o tópicos en tendencia del campo profesional. | F15: Reporte o Informe
A16: Identifica dispositivos, herramientas y plataformas tecnológicas para determinar sus posibilidades de uso en proyectos de diseño. | C16: • Misiones Internacionales: Actividades desarrolladas desde la Escuela de Diseño en el contexto de internacionalización que ofrece a los estudiantes la opción de cursar un seminario Internacional a través de plataformas digitales o de manera presencial en el lugar de desarrollo. | D16: Número de estudiantes que participan en la estrategia | F16: Listados de participación
A17: Analiza las variables relacionadas con las necesidades del contexto y el usuario para tomar decisiones de diseño. | C17: • COIL: Estrategia que permite el desarrollo de proyectos colaborativos entre instituciones de diferentes países. | D17: Valoración a la contribución de la estrategia a los resultados de aprendizaje del programa. | F17: Encuesta
A18: Analiza las variables relacionadas con las necesidades del contexto y el usuario para tomar decisiones de diseño. | C18: • Webinars: Actividades de charlas mediadas en plataformas online para el intercambio de saberes con las comunidades académicas en el ámbito internacional e interinstitucional.
A19: Relaciona estrategias de comunicación visual con las necesidades de diseño para tomar decisiones en procesos creativos. | C19: • Charlas con invitados externos: Actividades con invitados internacionales y nacionales para el desarrollo de charlas y/o conferencias en temas asociados al diseño.

Sheet Paso 5 Estrategias micro
A1: [Estas celdas se diligencian automáticamente. No ajustar.] | B1: [A partir de la celda A3 despliegue el(los) resultado(s) de aprendizaje y elija aquel (aquellos) al(a los) que se contribuye desde la asignatura o módulo).] | C1: [Escribir el semestre en el que se cursa la asignatura o módulo.] | D1: [Escribir el nombre de la asignatura o módulo que contribuye al logro del resultado de aprendizaje.] | E1: [Redactar los indicadores iniciando con el verbo en presente indicativo, luego el objeto conceptual y finalmente el complemento de oración (que indique una condición o finalidad, con, para, de, entre otros conectores).] | F1: [Escribir la tipología: T (teórico), P (Práctico), TP (Teórico Práctico)] | G1: [Marcar con X el bloque o componente al que pertenece la asignatura o módulo. Por favor ajustar para posgrado, eliminar una columna y ubicar los títulos C.Fundamentación y C.Profundización.] | J1: [Escribir el número de créditos de la asignatura o módulo] | K1: [Escribir el número de horas de trabajo directo: 16*# o 12*#, para presencial o virtual, según sea el caso.] | L1: [Escribir el número de horas de trabajo independiente: 32*# columna J o 36*# columna J, para presencial o virtual, respectivamente.] | M1: [Escribir la suma de los números de horas de las dos celdas anteriores.] | N1: [Escribir el nombre de los cuatro núcleos temáticos que abordará la asignatura o el módulo.] | O1: [Escribir las lecturas, talleres, análisis, referentes, etc., que realiza el estudiante, clasificadas en trabajo directo e independiente.] | P1: [Escribir las actividades de evaluación que se emplean para identificar el alcance del (de los) indicador(es) de logro(s).] | Q1: [Escribir las acciones de retroalimentación que se emplearán en la asignatura o módulo, para retroalimentar a los estudiantes respecto al alcance de los indicadores de logro. Recordar que son cuatro acciones: informar, formar, prevenir y ayudar a tomar decisiones e indique cómo.]
A2: Tipo de Saber | B2: Resultado de aprendizaje | C2: Semestre | D2: Nombre asignatura o módulo | E2: Indicadores de logro asignatura o módulo | F2: Tipología | G2: B.Institucional | H2: B.Disciplinar | I2: B.Electivo | J2: Créditos | K2: Número de horas trabajo directo | L2: Número de horas trabajo independiente | M2: Total de horas | N2: Núcleos temáticos | O2: Actividades de aprendizaje | P2: Actividades de evaluación | Q2: Acciones de retroalimentación
A3: =_xlfn.XLOOKUP(B3,'Paso 3 Redacción RA '!I$3:I$21,'Paso 3 Redacción RA '!C$3:C$21,,0,1) -> Saber | B3: Identifica fenómenos contemporáneos y su relación con la profesión, para determinar sus impactos e influencia en la sociedad, de forma responsable y crítica. | C3: 1 | D3: Razonamiento Cuantitativo | E3: Analiza datos numéricos presentados en tablas, gráficos o textos para proponer soluciones informadas a situaciones problema del contexto. | F3: TP | G3: X | J3: 3 | K3: =16*J3 -> 48 | L3: =32*J3 -> 96 | M3: =SUM(K3:L3) -> 144 | N3: 1. Pensamiento numérico. Interpretación y representación de información numérica 2. Pensamiento algebraico. Desde la representación de regularidades y patrones 3. Pensamiento algebraico. Desde las relaciones de comparación entre cantidades o expresiones numéricas 4. Pensamiento geométrico. Propiedades, formas y relaciones espaciales | O3: Trabajo directo: Clase magistral activa Trabajo independiente: Lecturas. Laboratorios, talleres, resolución de problemas | P3: Las estrategias pueden variar entre las siguientes u otras que puedan ser pertinentes para el proceso de aprendizaje. Evaluación formativa: Preguntas intercaladas, presentaciones de situaciones problema, juegos de roles, mesa redonda. Evaluación sumativa: Valoración de laboratorios, talleres, estudios de casos y una evaluación final | Q3: Las acciones de retroalimentación giran en torno a las siguientes. Formar: donde se crean las condiciones para que los estudiantes adquieran conocimientos, habilidades, actitudes, aptitudes y destrezas. Además, debe promover su desarrollo integral y debe acompañarlos en las situaciones académicas que enfrenten durante el desarrollo de un módulo o una asignatura. Informar: para que los estudiantes identifiquen los cambios que pueden afectarlos directa o indirectamente tanto en el aula de clase como en otros espacios. Prevenir: con el fin de anticiparse a las situaciones académicas que pueden representar dificultad para los estudiantes. Esto se logra a través de la interacción individual con los estudiantes y del completo conocimiento del contexto educativo en que el tutor se desenvuelve. Ayudar a decidir: donde se orienta a los estudiantes para que tomen la mejor decisión ante una situación concreta. El objetivo es que el estudiante fortalezca su autonomía y la toma de decisiones responsable.
A4: =_xlfn.XLOOKUP(B4,'Paso 3 Redacción RA '!I$3:I$21,'Paso 3 Redacción RA '!C$3:C$21,,0,1) -> Saber | B4: Identifica fenómenos contemporáneos y su relación con la profesión, para determinar sus impactos e influencia en la sociedad, de forma responsable y crítica. | C4: 1 | D4: Cultura, Política y Sociedad | E4: Reconoce las problemáticas, escenarios y mecanismos de participación ciudadana en el marco de sociedades de información y digitales para abordarlas desde iniciativas investigativas. Identifica los objetivos de desarrollo sostenible para la comprensión de problemáticas sociales, ambientales y culturales. Reflexiona los impactos de avances tecnológicos en su contexto profesional y ciudadano para el análisis de contextos situados. | F4: TP | G4: X | J4: 3 | K4: =16*J4 -> 48 | L4: =32*J4 -> 96 | M4: =SUM(K4:L4) -> 144 | N4: 1. ODS, problemas locales: una mirada a Colombia, territorio en búsqueda de la consolidación de la Paz 2. Ciudadanía y su lugar: relaciones, dinámicas, construcción, expresión y mecanismos de participación 3. Ecosistemas digitales: relaciones, dinámicas, construcción, expresión e impactos en el contexto profesional 4. Narrativas y contenidos digitales: análisis de contextos situados | O4: Trabajo directo: Clase magistral activa combinada con estrategias de aprendizaje basado en investigación Trabajo independiente: Lecturas, Laboratorios, talleres, estudios de caso | P4: Evaluación formativa: Construcción de textos argumentativos sobre problemáticas en las sociedades de la información. ,elaboración de ejercicios para la citación en APA última edición., cartografías sociales de problemáticas sociales, culturales y ambientales., elaboración de árbol de problemas, construcción de objetivos generales y específicos, desarrollo de anteproyectos., talleres experienciales con juegos de roles, realización de exposición a través de la caja italiana para el manejo del espacio, la lectura y la oralidad, exposiciones creativas del PIF en el marco del evento “Feria de proyectos” Evaluación sumativa comprende los logros obtenidos en cada actividad y en todo el proceso, representados en porcentajes acumulativos según la parametrización de 0 a 5; Árbol de problemas, Exposiciones Creativas , Seguimiento , Entre Proyecto: Parte 1, Quiz , Seguimiento , Entre Proyecto: Parte 1I , Entrevista a expertos , Feria de proyectos , Seguimiento | Q4: Las acciones de retroalimentación giran en torno a las siguientes. Formar: donde se crean las condiciones para que los estudiantes adquieran conocimientos, habilidades, actitudes, aptitudes y destrezas. Además, debe promover su desarrollo integral y debe acompañarlos en las situaciones académicas que enfrenten durante el desarrollo de un módulo o una asignatura. Informar: para que los estudiantes identifiquen los cambios que pueden afectarlos directa o indirectamente tanto en el aula de clase como en otros espacios. Prevenir: con el fin de anticiparse a las situaciones académicas que pueden representar dificultad para los estudiantes. Esto se logra a través de la interacción individual con los estudiantes y del completo conocimiento del contexto educativo en que el tutor se desenvuelve. Ayudar a decidir: donde se orienta a los estudiantes para que tomen la mejor decisión ante una situación concreta. El objetivo es que el estudiante fortalezca su autonomía y la toma de decisiones responsable.
A5: =_xlfn.XLOOKUP(B5,'Paso 3 Redacción RA '!I$3:I$21,'Paso 3 Redacción RA '!C$3:C$21,,0,1) -> Saber | B5: Relaciona estrategias de comunicación visual con las necesidades de diseño para tomar decisiones en procesos creativos. | C5: 1 | D5: Procesos de Comunicación | E5: Analiza los procesos de comunicación en distintos contextos socioculturales de los siglos XX y XXI, para interpretar sus transformaciones en la historia reciente. | F5: T | H5: X | J5: 3 | K5: =16*J5 -> 48 | L5: =32*J5 -> 96 | M5: =SUM(K5:L7) -> 144 | N5: 1. Conceptos y enfoques para el estudio de la comunicación 2. La comunicación durante las dos guerras mundiales del siglo XX 3. La comunicación a partir de la Guerra Fría 4. La comunicación y sus transformaciones en la guerra de la información informática | O5: Trabajo directo: Clases magistrales Talleres / Laboratorios Uso de herramientas computacionales Uso de herrramientas para el diseño Resolución de problemas Trabajo independiente: Lecturas Resolución de problemas Uso de herramientas computacionales Uso de herramientas para el diseño | P5: Las estrategias pueden variar entre las siguientes u otras que puedan ser pertinentes para el proceso de aprendizaje. Evaluación formativa: Resolución de problemas Uso de herramientas computacionales Proyectos Evaluación sumativa: Taller / Laboratorios Presentación y sustentación de proyectos Piezas gráficas | Q5: Las acciones de retroalimentación giran en torno a las siguientes. Formar: donde se crean las condiciones para que los estudiantes adquieran conocimientos, habilidades, actitudes, aptitudes y destrezas. Además, debe promover su desarrollo integral y debe acompañarlos en las situaciones académicas que enfrenten durante el desarrollo de un módulo o una asignatura. Informar: para que los estudiantes identifiquen los cambios que pueden afectarlos directa o indirectamente tanto en el aula de clase como en otros espacios. Prevenir: con el fin de anticiparse a las situaciones académicas que pueden representar dificultad para los estudiantes. Esto se logra a través de la interacción individual con los estudiantes y del completo conocimiento del contexto educativo en que el tutor se desenvuelve. Ayudar a decidir: donde se orienta a los estudiantes para que tomen la mejor decisión ante una situación concreta. El objetivo es que el estudiante fortalezca su autonomía y la toma de decisiones responsable. Retroalimentación formativa y sumativa. - Autoevaluación / Coevaluación. - Muestras de los proyectos destacados. - Observación. - Heteroevaluación. - Socialización de trabajos de clases. - Socialización de actividades de evaluación.
A6: =_xlfn.XLOOKUP(B6,'Paso 3 Redacción RA '!I$3:I$21,'Paso 3 Redacción RA '!C$3:C$21,,0,1) -> Saber | B6: Analiza las variables relacionadas con las necesidades del contexto y el usuario para tomar decisiones de diseño.
A7: =_xlfn.XLOOKUP(B7,'Paso 3 Redacción RA '!I$3:I$21,'Paso 3 Redacción RA '!C$3:C$21,,0,1) -> Saber | B7: Interpreta tendencias de la moda para diseñar productos gráficos acordes a su contexto de aplicación.
A8: =_xlfn.XLOOKUP(B8,'Paso 3 Redacción RA '!I$3:I$21,'Paso 3 Redacción RA '!C$3:C$21,,0,1) -> Saber | B8: Relaciona estrategias de comunicación visual con las necesidades de diseño para tomar decisiones en procesos creativos. | C8: 1 | D8: Teoría del Diseño | E8: Analiza los fundamentos disciplinares, teóricos y metodológicos del diseño para formular proyectos que respondan a problemáticas vinculadas con usuarios y contextos específicos. | F8: TP | H8: X | J8: 3 | K8: =16*J8 -> 48 | L8: =32*J8 -> 96 | M8: =SUM(K8:L14) -> 144 | N8: 1. Qué es el diseño 2. Diseño y otras disciplinas 3. El diseño y sus metodologías 4. Otros diseños | O8: Trabajo directo: Clases magistrales Uso de herramientas tecnológicas Resolución de problemas Exposiciones magistrales Análisis de casos Talleres Trabajo independiente: Lecturas Resolución de problemas Uso de herramientas tecnológicas Revisión de literatura Estado del arte | P8: Las estrategias pueden variar entre las siguientes u otras que puedan ser pertinentes para el proceso de aprendizaje. Evaluación formativa: Exposiciones grupales Trabajo colaborativo Actividades para desarrollar el pensamiento crítico. Evaluación sumativa: Exposiciones grupales Actividades para desarrollar el pensamiento crítico (foros) Trabajos escritos | Q8: Las acciones de retroalimentación giran en torno a las siguientes. Formar: donde se crean las condiciones para que los estudiantes adquieran conocimientos, habilidades, actitudes, aptitudes y destrezas. Además, debe promover su desarrollo integral y debe acompañarlos en las situaciones académicas que enfrenten durante el desarrollo de un módulo o una asignatura. Informar: para que los estudiantes identifiquen los cambios que pueden afectarlos directa o indirectamente tanto en el aula de clase como en otros espacios. Prevenir: con el fin de anticiparse a las situaciones académicas que pueden representar dificultad para los estudiantes. Esto se logra a través de la interacción individual con los estudiantes y del completo conocimiento del contexto educativo en que el tutor se desenvuelve. Ayudar a decidir: donde se orienta a los estudiantes para que tomen la mejor decisión ante una situación concreta. El objetivo es que el estudiante fortalezca su autonomía y la toma de decisiones responsable. Retroalimentación formativa y sumativa. - Autoevaluación / Coevaluación. - Observación. - Heteroevaluación. - Socialización de trabajos de clases. - Socialización de actividades de evaluación.
A9: =_xlfn.XLOOKUP(B9,'Paso 3 Redacción RA '!I$3:I$21,'Paso 3 Redacción RA '!C$3:C$21,,0,1) -> Saberhacer | B9: Diseña artefactos visuales, en diversos medios y formatos, para desarrollar proyectos que respondan de manera funcional a las necesidades del usuario y de la estrategia de comunicación definida.
A10: =_xlfn.XLOOKUP(B10,'Paso 3 Redacción RA '!I$3:I$21,'Paso 3 Redacción RA '!C$3:C$21,,0,1) -> Saberser | B10: Determina los recursos técnicos, visuales y conceptuales necesarios para generar artefactos de diseño funcionales y accesibles, a partir del análisis del problema y el contexto de aplicación.
A11: =_xlfn.XLOOKUP(B11,'Paso 3 Redacción RA '!I$3:I$21,'Paso 3 Redacción RA '!C$3:C$21,,0,1) -> Saber | B11: Identifica dispositivos, herramientas y plataformas tecnológicas para determinar sus posibilidades de uso en proyectos de diseño.
A12: =_xlfn.XLOOKUP(B12,'Paso 3 Redacción RA '!I$3:I$21,'Paso 3 Redacción RA '!C$3:C$21,,0,1) -> Saberhacer | B12: Explora las posibilidades expresivas de las herramientas y los medios tecnológicos para generar soluciones en contextos de diseño.
A13: =_xlfn.XLOOKUP(B13,'Paso 3 Redacción RA '!I$3:I$21,'Paso 3 Redacción RA '!C$3:C$21,,0,1) -> Saber | B13: Analiza las variables relacionadas con las necesidades del contexto y el usuario para tomar decisiones de diseño.
A14: =_xlfn.XLOOKUP(B14,'Paso 3 Redacción RA '!I$3:I$21,'Paso 3 Redacción RA '!C$3:C$21,,0,1) -> Saber | B14: Interpreta tendencias de la moda para diseñar productos gráficos acordes a su contexto de aplicación.
A15: =_xlfn.XLOOKUP(B15,'Paso 3 Redacción RA '!I$3:I$21,'Paso 3 Redacción RA '!C$3:C$21,,0,1) -> Saber | B15: Relaciona estrategias de comunicación visual con las necesidades de diseño para tomar decisiones en procesos creativos. | C15: 1 | D15: Imagen Digital | E15: Aplica técnicas de representación bi y tridimensional en medios digitales, para proponer soluciones de diseño que respondan a necesidades de usuario y contexto. | F15: TP | H15: X | J15: 3 | K15: =16*J15 -> 48 | L15: =32*J15 -> 96 | M15: =SUM(K15:L20) -> 144 | N15: 1. Introducción a la imagen digital 2. Dibujo vectorial 3. Color y pinceles 4. Texto, calco y finalización | O15: Trabajo directo Clase magistral activa Estudio de casos Talleres individuales Trabajo con herramientas digitales Trabajo independiente Lecturas Resolución de problemas Uso de herramientas computacionales Proyectos individuales | P15: Las estrategias pueden variar entre las siguientes u otras que puedan ser pertinentes para el proceso de aprendizaje. Evaluación formativa: Proyectos Uso de herramientas digitales Talleres Sustentación de proyectos Evaluación sumativa: Taller Presentación y sustentación de proyectos Piezas gráficas Exposiciones grupales | Q15: Las acciones de retroalimentación giran en torno a las siguientes. Formar: donde se crean las condiciones para que los estudiantes adquieran conocimientos, habilidades, actitudes, aptitudes y destrezas. Además, debe promover su desarrollo integral y debe acompañarlos en las situaciones académicas que enfrenten durante el desarrollo de un módulo o una asignatura. Informar: para que los estudiantes identifiquen los cambios que pueden afectarlos directa o indirectamente tanto en el aula de clase como en otros espacios. Prevenir: con el fin de anticiparse a las situaciones académicas que pueden representar dificultad para los estudiantes. Esto se logra a través de la interacción individual con los estudiantes y del completo conocimiento del contexto educativo en que el tutor se desenvuelve. Ayudar a decidir: donde se orienta a los estudiantes para que tomen la mejor decisión ante una situación concreta. El objetivo es que el estudiante fortalezca su autonomía y la toma de decisiones responsable. Retroalimentación formativa Autoevaluación/Coevaluación. Muestras de proyectos destacados Asesorías Retroalimentación sumativa Rúbricas Heteroevaluación Socialización de trabajos de clase Socialización de actividades de evaluación.
A16: =_xlfn.XLOOKUP(B16,'Paso 3 Redacción RA '!I$3:I$21,'Paso 3 Redacción RA '!C$3:C$21,,0,1) -> Saberhacer | B16: Diseña artefactos visuales, en diversos medios y formatos, para desarrollar proyectos que respondan de manera funcional a las necesidades del usuario y de la estrategia de comunicación definida.
A17: =_xlfn.XLOOKUP(B17,'Paso 3 Redacción RA '!I$3:I$21,'Paso 3 Redacción RA '!C$3:C$21,,0,1) -> Saberser | B17: Determina los recursos técnicos, visuales y conceptuales necesarios para generar artefactos de diseño funcionales y accesibles, a partir del análisis del problema y el contexto de aplicación.
A18: =_xlfn.XLOOKUP(B18,'Paso 3 Redacción RA '!I$3:I$21,'Paso 3 Redacción RA '!C$3:C$21,,0,1) -> Saber | B18: Identifica dispositivos, herramientas y plataformas tecnológicas para determinar sus posibilidades de uso en proyectos de diseño.
A19: =_xlfn.XLOOKUP(B19,'Paso 3 Redacción RA '!I$3:I$21,'Paso 3 Redacción RA '!C$3:C$21,,0,1) -> Saberhacer | B19: Explora las posibilidades expresivas de las herramientas y los medios tecnológicos para generar soluciones en contextos de diseño.
A20: =_xlfn.XLOOKUP(B20,'Paso 3 Redacción RA '!I$3:I$21,'Paso 3 Redacción RA '!C$3:C$21,,0,1) -> Saber | B20: Interpreta tendencias de la moda para diseñar productos gráficos acordes a su contexto de aplicación.
A21: =_xlfn.XLOOKUP(B21,'Paso 3 Redacción RA '!I$3:I$21,'Paso 3 Redacción RA '!C$3:C$21,,0,1) -> Saber | B21: Relaciona estrategias de comunicación visual con las necesidades de diseño para tomar decisiones en procesos creativos. | C21: 1 | D21: Dibujo y Perspectiva | E21: Identifica los elementos y técnicas del dibujo bidimensional para desarrollar representaciones bidimensionales analógicas y artefactos de diseño con capacidad expresiva.. | F21: TP | H21: X | J21: 3 | K21: =16*J21 -> 48 | L21: =32*J21 -> 96 | M21: =SUM(K21:L24) -> 144 | N21: 1. Perspectivas axonométricas 2. Perspectiva cónica 3. Volumen 4. Dibujo de Expresión | O21: Trabajo directo Clase magistral activa Talleres individuales Trabajo independiente Lecturas Resolución de problemas Uso de herramientas computacionales Uso de herramientas para el diseño | P21: Las estrategias pueden variar entre las siguientes u otras que puedan ser pertinentes para el proceso de aprendizaje. Evaluación formativa: Resolución de problemas Proyectos Taller Evaluación sumativa: Talleres Presentación y sustentación de proyectos Piezas gráficas | Q21: Las acciones de retroalimentación giran en torno a las siguientes. Formar: donde se crean las condiciones para que los estudiantes adquieran conocimientos, habilidades, actitudes, aptitudes y destrezas. Además, debe promover su desarrollo integral y debe acompañarlos en las situaciones académicas que enfrenten durante el desarrollo de un módulo o una asignatura. Informar: para que los estudiantes identifiquen los cambios que pueden afectarlos directa o indirectamente tanto en el aula de clase como en otros espacios. Prevenir: con el fin de anticiparse a las situaciones académicas que pueden representar dificultad para los estudiantes. Esto se logra a través de la interacción individual con los estudiantes y del completo conocimiento del contexto educativo en que el tutor se desenvuelve. Ayudar a decidir: donde se orienta a los estudiantes para que tomen la mejor decisión ante una situación concreta. El objetivo es que el estudiante fortalezca su autonomía y la toma de decisiones responsable. Retroalimentación formativa Autoevaluación/Coevaluación. Muestras de proyectos destacados Asesorías Retroalimentación sumativa Rúbricas Heteroevaluación Socialización de trabajos de clase Socialización de actividades de evaluación.
A22: =_xlfn.XLOOKUP(B22,'Paso 3 Redacción RA '!I$3:I$21,'Paso 3 Redacción RA '!C$3:C$21,,0,1) -> Saberhacer | B22: Diseña artefactos visuales, en diversos medios y formatos, para desarrollar proyectos que respondan de manera funcional a las necesidades del usuario y de la estrategia de comunicación definida.
A23: =_xlfn.XLOOKUP(B23,'Paso 3 Redacción RA '!I$3:I$21,'Paso 3 Redacción RA '!C$3:C$21,,0,1) -> Saberhacer | B23: Explora las posibilidades expresivas de las herramientas y los medios tecnológicos para generar soluciones en contextos de diseño.
A24: =_xlfn.XLOOKUP(B24,'Paso 3 Redacción RA '!I$3:I$21,'Paso 3 Redacción RA '!C$3:C$21,,0,1) -> Saber | B24: Analiza las variables relacionadas con las necesidades del contexto y el usuario para tomar decisiones de diseño. | R24: =SUM(J3:J24) -> 18
A25: =_xlfn.XLOOKUP(B25,'Paso 3 Redacción RA '!I$3:I$21,'Paso 3 Redacción RA '!C$3:C$21,,0,1) -> Saber | B25: Identifica fenómenos contemporáneos y su relación con la profesión, para determinar sus impactos e influencia en la sociedad, de forma responsable y crítica. | C25: 2 | D25: Análisis y Visualización de Datos | E25: Identifica conceptos básicos relacionados con el análisis y visualización de datos con el propósito de comunicar información relevante de manera efectiva en diversos contextos. Utiliza herramientas para realizar análisis y transformación de datos que garanticen una visualización sencilla y eficiente. Utiliza asistentes virtuales para realizar tareas prácticas y resolver problemas en su campo de estudio. Evalúa la presencia de sesgos y cuestiones éticas en el análisis y tratamiento de dato para garantizar que su uso esté desprovisto de efectos negativos en el entorno. | F25: TP | G25: X | J25: 3 | K25: =16*J25 -> 48 | L25: =32*J25 -> 96 | M25: =SUM(K25:L25) -> 144 | N25: 1. Contextualización 2. Análisis de Datos y Visualización 3. Usos de la Inteligencia Artificial 4. Casos de Estudio | O25: Trabajo directo: Clase magistral activa combinada con estrategias de metodologías activas Trabajo independiente: Lecturas. Laboratorios, talleres, estudios de caso | P25: Las estrategias pueden variar entre las siguientes u otras que puedan ser pertinentes para el proceso de aprendizaje. Evaluación formativa: Preguntas intercaladas, presentaciones de situaciones problema, juegos de roles, mesa redonda. Evaluación sumativa: Valoración de laboratorios, talleres, estudios de casos y una evaluación final | Q25: Las acciones de retroalimentación giran en torno a las siguientes. Formar: donde se crean las condiciones para que los estudiantes adquieran conocimientos, habilidades, actitudes, aptitudes y destrezas. Además, debe promover su desarrollo integral y debe acompañarlos en las situaciones académicas que enfrenten durante el desarrollo de un módulo o una asignatura. Informar: para que los estudiantes identifiquen los cambios que pueden afectarlos directa o indirectamente tanto en el aula de clase como en otros espacios. Prevenir: con el fin de anticiparse a las situaciones académicas que pueden representar dificultad para los estudiantes. Esto se logra a través de la interacción individual con los estudiantes y del completo conocimiento del contexto educativo en que el tutor se desenvuelve. Ayudar a decidir: donde se orienta a los estudiantes para que tomen la mejor decisión ante una situación concreta. El objetivo es que el estudiante fortalezca su autonomía y la toma de decisiones responsable.
A26: =_xlfn.XLOOKUP(B26,'Paso 3 Redacción RA '!I$3:I$21,'Paso 3 Redacción RA '!C$3:C$21,,0,1) -> Saber | B26: Relaciona estrategias de comunicación visual con las necesidades de diseño para tomar decisiones en procesos creativos. | C26: 2 | D26: Tipografía | E26: Identifica los principios de la composición tipográfica y sus tecnologías de construcción para desarrollar propuestas de diseño acordes a la funcionalidad y finalidad comunicativa. Aplica los principios de tipografía y composición tipográfica para construir mensajes visuales acordes al público objetivo y su medio de distribución. | F26: TP | H26: X | J26: 4 | K26: =16*J26 -> 64 | L26: =32*J26 -> 128 | M26: =SUM(K26:L31) -> 192 | N26: 1. Historia de las tecnologías de la escritura y de la impresión. 2. Anatomía de los tipos, estilos, familias y fuentes tipográficas. 3. Principios de composición tipográfica. 4. Composición tipográfica para medios digitales. | O26: Trabajo directo: Clases magistrales Talleres / Laboratorios Uso de herramientas computacionales Uso de herrramientas para el diseño Resolución de problemas Trabajo independiente: Lecturas Resolución de problemas Uso de herramientas computacionales Uso de herramientas para el diseño | P26: Las estrategias pueden variar entre las siguientes u otras que puedan ser pertinentes para el proceso de aprendizaje. Evaluación formativa: Exposiciones grupales Trabajo colaborativo Actividades para desarrollar el pensamiento crítico Evaluación sumativa: Exposiciones grupales Actividades para desarrollar el pensamiento crítico (foros) Trabajos escritos | Q26: Las acciones de retroalimentación giran en torno a las siguientes. Formar: donde se crean las condiciones para que los estudiantes adquieran conocimientos, habilidades, actitudes, aptitudes y destrezas. Además, debe promover su desarrollo integral y debe acompañarlos en las situaciones académicas que enfrenten durante el desarrollo de un módulo o una asignatura. Informar: para que los estudiantes identifiquen los cambios que pueden afectarlos directa o indirectamente tanto en el aula de clase como en otros espacios. Prevenir: con el fin de anticiparse a las situaciones académicas que pueden representar dificultad para los estudiantes. Esto se logra a través de la interacción individual con los estudiantes y del completo conocimiento del contexto educativo en que el tutor se desenvuelve. Ayudar a decidir: donde se orienta a los estudiantes para que tomen la mejor decisión ante una situación concreta. El objetivo es que el estudiante fortalezca su autonomía y la toma de decisiones responsable. Retroalimentación formativa Autoevaluación/Coevaluación. Muestras de proyectos destacados Asesorías Retroalimentación sumativa Rúbricas Heteroevaluación Socialización de trabajos de clase Socialización de actividades de evaluación.
A27: =_xlfn.XLOOKUP(B27,'Paso 3 Redacción RA '!I$3:I$21,'Paso 3 Redacción RA '!C$3:C$21,,0,1) -> Saberhacer | B27: Diseña artefactos visuales, en diversos medios y formatos, para desarrollar proyectos que respondan de manera funcional a las necesidades del usuario y de la estrategia de comunicación definida.
A28: =_xlfn.XLOOKUP(B28,'Paso 3 Redacción RA '!I$3:I$21,'Paso 3 Redacción RA '!C$3:C$21,,0,1) -> Saberser | B28: Determina los recursos técnicos, visuales y conceptuales necesarios para generar artefactos de diseño funcionales y accesibles, a partir del análisis del problema y el contexto de aplicación.
A29: =_xlfn.XLOOKUP(B29,'Paso 3 Redacción RA '!I$3:I$21,'Paso 3 Redacción RA '!C$3:C$21,,0,1) -> Saber | B29: Identifica dispositivos, herramientas y plataformas tecnológicas para determinar sus posibilidades de uso en proyectos de diseño.
A30: =_xlfn.XLOOKUP(B30,'Paso 3 Redacción RA '!I$3:I$21,'Paso 3 Redacción RA '!C$3:C$21,,0,1) -> Saberhacer | B30: Explora las posibilidades expresivas de las herramientas y los medios tecnológicos para generar soluciones en contextos de diseño.
A31: =_xlfn.XLOOKUP(B31,'Paso 3 Redacción RA '!I$3:I$21,'Paso 3 Redacción RA '!C$3:C$21,,0,1) -> Saber | B31: Analiza las variables relacionadas con las necesidades del contexto y el usuario para tomar decisiones de diseño.
A32: =_xlfn.XLOOKUP(B32,'Paso 3 Redacción RA '!I$3:I$21,'Paso 3 Redacción RA '!C$3:C$21,,0,1) -> Saber | B32: Relaciona estrategias de comunicación visual con las necesidades de diseño para tomar decisiones en procesos creativos. | C32: 2 | D32: Composición y Color | E32: Identifica los conceptos de composición visual para desarrollar soluciones de diseño que den respuesta a los objetivos comunicacionales. Interpreta las intenciones comunicativas del color para su aplicación en artefactos de diseño. Articula fundamentos de composición visual e intenciones comunicativas del color para desarrollar proyectos de comunicación visual. | F32: TP | H32: X | J32: 4 | K32: =16*J32 -> 64 | L32: =32*J32 -> 128 | M32: =SUM(K32:L38) -> 192 | N32: 1. Sintaxis de la imagen 2. Intención comunicativa del color en el diseño 3. Proceso compositivo de la imagen 4. El color y la experiencia de usuario | O32: Trabajo directo: Clases magistrales Uso de herramientas tecnológicas Resolución de problemas Exposiciones magistrales Análisis de casos Talleres Trabajo independiente: Lecturas Resolución de problemas Uso de herramientas tecnológicas Revisión de literatura Estado del arte | P32: Las estrategias pueden variar entre las siguientes u otras que puedan ser pertinentes para el proceso de aprendizaje. Evaluación formativa: Exposiciones grupales Trabajo colaborativo Actividades para desarrollar el pensamiento crítico Evaluación sumativa: Exposiciones grupales Actividades para desarrollar el pensamiento crítico (foros) Trabajos escritos | Q32: Las acciones de retroalimentación giran en torno a las siguientes. Formar: donde se crean las condiciones para que los estudiantes adquieran conocimientos, habilidades, actitudes, aptitudes y destrezas. Además, debe promover su desarrollo integral y debe acompañarlos en las situaciones académicas que enfrenten durante el desarrollo de un módulo o una asignatura. Informar: para que los estudiantes identifiquen los cambios que pueden afectarlos directa o indirectamente tanto en el aula de clase como en otros espacios. Prevenir: con el fin de anticiparse a las situaciones académicas que pueden representar dificultad para los estudiantes. Esto se logra a través de la interacción individual con los estudiantes y del completo conocimiento del contexto educativo en que el tutor se desenvuelve. Ayudar a decidir: donde se orienta a los estudiantes para que tomen la mejor decisión ante una situación concreta. El objetivo es que el estudiante fortalezca su autonomía y la toma de decisiones responsable. Retroalimentación formativa y sumativa. - Autoevaluación / Coevaluación. - Observación. - Heteroevaluación. - Socialización de trabajos de clases. - Socialización de actividades de evaluación.
A33: =_xlfn.XLOOKUP(B33,'Paso 3 Redacción RA '!I$3:I$21,'Paso 3 Redacción RA '!C$3:C$21,,0,1) -> Saberhacer | B33: Diseña artefactos visuales, en diversos medios y formatos, para desarrollar proyectos que respondan de manera funcional a las necesidades del usuario y de la estrategia de comunicación definida.
A34: =_xlfn.XLOOKUP(B34,'Paso 3 Redacción RA '!I$3:I$21,'Paso 3 Redacción RA '!C$3:C$21,,0,1) -> Saberser | B34: Determina los recursos técnicos, visuales y conceptuales necesarios para generar artefactos de diseño funcionales y accesibles, a partir del análisis del problema y el contexto de aplicación.
