Workbook
Name ActitudinalBAK: 'Taxonomias para RA'!$AC$3:$AG$3
Name Áreasprofesionales: #REF!
Name Bloom: 'Taxonomias para RA'!$G$3:$I$3
Name CognitivoBAK: 'Taxonomias para RA'!$S$3:$X$3
Name ComponentesCompetencias: 'Paso1 Analisis perfil egreso'!$E$2:$G$2
Name ComponentesCompetencias: #REF!
Name ComprenderLK: 'Taxonomias para RA'!$AM$5:$AM$27
Name Creditos: #REF!,#REF!,#REF!,#REF!,#REF!,#REF!,#REF!,#REF!,#REF!
Name EvaluarLK: 'Taxonomias para RA'!$AP$5:$AP$46
Name FACULTADES: #REF!
Name Ocupación: #REF!
Name PercepciónBAK: 'Taxonomias para RA'!$AC$4:$AC$40
Name PrecisiónBAK: Tabla4170[PrecisiónBAK]
Name ProcedimentalB: Tabla5684[ProcedimentalB]
Name ProcedimentalBAK: 'Taxonomias para RA'!$Y$3:$AB$3
Name ProcedimientosLK: Tabla92[ProcedimientosLK]
Name ProcesosAK: Tabla95[ProcesosAK]
Name RA: #REF!
Name RecordarLK: 'Taxonomias para RA'!$AL$5:$AL$27
Name RecuperaciónAK: 'Taxonomias para RA'!$AT$4:$AT$27
Name resultadoaprendizaje: #REF!
Name SíntesisB: Tabla395381[SíntesisB]
Name SíntesisBAK: Tabla3966[SíntesisBAK]
Name taxonomiasra: Tabla1715[Taxonomías]
Name UsoConocimientoAK: 'Taxonomias para RA'!$AW$4:$AW$70
Name ValorarBAK: Tabla4574[ValorarBAK]

Sheet Paso1 Analisis perfil egreso
A1: [Escribir el nombre del programa] | B1: [Escribir la modalidad: presencial o virtual] | C1: [Escribir el perfil profesional del egresado.] | D1: [Escribir el perfil ocupacional del egresado.] | E1: Componentes fundamentales aplicables a la solución de problemas en la vida profesional [Listar, según lo escrito en el perfil profesional, qué debe saber el egresado en las categorías de Saber -conocimientos, hechos, teorías-, Saber hacer -técnicas, procedimientos, metodologías-, y Saber ser -valores, condiciones, etc.] | H1: Componentes fundamentales de la ocupación laboral del profesional [Listar, según lo escrito en el perfil ocupacional, en qué áreas, qué tareas potenciales y en qué poblaciones o contextos podrá laborar el profesional.] | K1: Diferencial (valor agregado) del profesional [Listar, según lo escrito en los perfiles, los elementos que son diferenciales y generan un valor agregado al egresado.]
A2: Programa | B2: Modalidad | C2: Perfil profesional | D2: Perfil ocupacional | E2: Saber | F2: SaberHacer | G2: SaberSer | H2: Áreas profesionales | I2: Tareas profesionales | J2: Poblaciones actuación | K2: Valor agregado
A3: Técnica Profesional Judicial | B3: Virtual | C3: El Técnico Profesional Judicial aplica con visión crítica, ética e integral, los procedimientos y las técnicas jurídicas asociadas a las diferentes áreas del derecho, para asistir al abogado en la resolución de conflictos, de acuerdo con la realidad de la zona geográfica en la que se encuentre, aprovechando diversas tecnologías en los entornos virtuales o presenciales y caracterizándose por su capacidad oral, elaboración de textos jurídicos, así como por la implementación de técnicas archivísticas, de gestión documental, derecho inmobiliario y digitalización del derecho. | D3: El Técnico Profesional Judicial del Politécnico Grancolombiano está en capacidad de: - Ejercer cargos auxiliares o asistenciales con conocimientos legales claros y prácticos en asuntos sustanciales, procedimentales y logísticos tanto en el sector público como en el privado. - Desempeñar actividades que requieran el uso de tecnologías de la información y la comunicación, implementando sistemas de información documental de acuerdo con las técnicas archivísticas, y de elaboración de textos jurídicos y contractuales asignados en sus labores operativas dentro del área judicial, en cargos tales como escribientes, de secretariado, asistentes, sustanciadores, archivistas, entre otros. | E3: Procesos y procedimientos en derecho penal, laboral, civil, público y mercantil | F3: gestionar una correcta administración de justicia | G3: con un criterio ético y responsable en la aplicación de las normas | H3: Asistente jurídico / Auxiliar judicial / Auxiliar de tribunales / Secretario jurídico / Redactor jurídico / Técnico sustanciador / Citador sustanciador / Técnico en documentación procesal / Auxiliar de archivo jurídico / Gestor de gestión documental / Documentalista legal / Operador de digitalización jurídica / Gestor de información jurídica / Técnico administrativo jurídico / Técnico en seguimiento normativo / Asistente administrativo jurídico / Facilitador de resolución de conflictos / Asistente de conciliación / Técnico en mediación legal / Analista auxiliar de riesgos legales / Coordinador de agenda jurídica / Secretario ejecutivo judicial / Técnico investigador judicial / Investigador judicial / Gestor de proyectos de justicia digital / Auxiliar jurídico en entidades judiciales públicas o privadas / Técnico o asistente en derecho de consumo y competencia / Auxiliar en derecho registral e inmobiliario / Técnico en derecho laboral y seguridad social / Auxiliar de apoyo en derecho empresarial y societario / Técnico o gestor en acciones constitucionales / Auxiliar de análisis de datos jurídicos y estadística judicial / Técnico en procedimientos administrativos y control de términos / Apoyo técnico en investigación penal y criminalística básica. | I3: Elaborar escritos jurídicos como demandas, memoriales y oficios según lineamientos procesales / Apoyar en la organización y seguimiento de procesos judiciales y administrativos / Recopilar información normativa y jurisprudencial para apoyar sustanciaciones / Redactar contratos, actas, poderes y minutas con base en modelos normativos vigentes / Revisar la coherencia y la estructura legal de documentos antes de su firma o radicación / Clasificar expedientes judiciales según su naturaleza y fase procesal / Cargar, actualizar y consultar información jurídica en sistemas de gestión documental / Digitalizar expedientes físicos asegurando calidad de imagen y respaldo en la nube / Apoyar la elaboración de actas de audiencia de conciliación y acuerdos logrados / Orientar a las partes en los pasos para acceder a mecanismos alternativos de resolución / Sistematizar casos atendidos en centros de conciliación mediante bases de datos / Elaborar oficios, comunicaciones internas y reportes para entidades jurídicas / Coordinar el uso de recursos logísticos para el desarrollo de actividades legales / Participar en la recopilación de datos legales para análisis de riesgos normativos / Apoyar la implementación de herramientas tecnológicas para la transformación digital en entornos jurídicos / Elaborar reportes técnicos sobre cumplimiento documental y normativo / Tramitar y registrar documentos de propiedad y actos de comercio ante cámaras de comercio y notarías / Gestionar trámites relacionados con compraventa, arrendamiento y sociedades / Apoyar la preparación de acciones constitucionales (tutelas, habeas corpus, habeas data) / Realizar seguimiento al cumplimiento de fallos constitucionales o administrativos / Tramitar solicitudes ante entidades públicas y realizar control de términos legales / Apoyar la radicación y seguimiento de denuncias penales / Colaborar en la organización de expedientes y pruebas en procesos penales / Gestionar citaciones y notificaciones en procedimientos penales / Elaborar liquidaciones básicas de prestaciones sociales y nómina / Tramitar afiliaciones, novedades y reportes ante el sistema de seguridad social / Gestionar reclamaciones laborales ante el Ministerio de Trabajo o juzgados laborales / Realizar estudios de títulos básicos y verificación de certificados de tradición y libertad / Tramitar inscripciones, cancelaciones e hipotecas ante oficinas de registro / Gestionar licencias o autorizaciones para actos jurídicos sobre inmuebles / Implementar bases de datos para análisis de procesos judiciales y administrativos / Elaborar visualizaciones y reportes estadísticos sobre la gestión jurídica / Administrar repositorios digitales de información legal con control de acceso / Facilitar procesos de mediación comunitaria o empresarial / Tramitar reclamaciones de consumidores ante autoridades competentes / Apoyar en investigaciones sobre prácticas restrictivas de la competencia / Elaborar informes de cumplimiento de normas de protección al consumidor / Apoyar en la constitución, modificación y disolución de sociedades / Elaborar actas de asambleas y juntas de socios / Gestionar registros y renovaciones de matrícula mercantil / Diseñar y presentar propuestas de servicios jurídicos para emprendimientos / Elaborar planes de negocio para empresas del sector legal / Coordinar alianzas estratégicas con otras entidades o profesionales. | J3: Juzgados, tribunales y altas cortes / Fiscalías y procuradurías/ Contralorías y personerías municipales o departamentales / Centros de conciliación y arbitraje / Ministerios y secretarías con áreas jurídicas /Alcaldías y gobernaciones / Entidades descentralizadas con gestión legal (superintendencias, institutos, agencias) / Empresas y corporaciones con unidades legales internas / Firmas de abogados y consultoras jurídicas / Cámaras de comercio y gremios empresariales/Compañías de seguros y bancos en gestión legal y de contratos / Notarías urbanas y rurales/Oficinas de registro de instrumentos públicos / Dependencias de registro mercantil / Empresas de custodia y digitalización de archivos / Dependencias archivísticas de entidades públicas o privadas con alto volumen documental jurídico / Organizaciones no gubernamentales con proyectos de acceso a la justicia. | K3: El egresado de la Técnica Profesional Judicial del Politécnico Grancolombiano se forma con una combinación de fundamentos jurídicos en las diferentes áreas del derecho y herramientas tecnológicas aplicadas al ejercicio legal, que incluyen digitalización del derecho, análisis de datos jurídicos y prácticas en ambientes simulados que replican escenarios reales de la administración de justicia. Esta formación le permite desenvolverse con solvencia en la gestión de expedientes y procesos tanto en entornos físicos como virtuales, responder a los retos de transformación digital en el sector legal y adaptarse a diferentes contextos de trabajo. La articulación de estos elementos con las exigencias actuales del mercado fortalece su proyección laboral en notarías, despachos judiciales, áreas jurídicas corporativas y organismos de control, generando una preparación alineada con las tendencias de modernización y eficiencia en la administración de justicia.
E4: Procesos archivísticos y de digitalización del derecho | F4: categorizar la información judicial de los expedientes | G4: de acuerdo con las necesidades de la organización
E5: Textos jurídicos y contractuales en las diferentes áreas del derecho | F5: documentar la voluntad de las partes | G5: teniendo en cuenta el orden y las etapas necesarias de los actos jurídicos.
E6: Conflictos objeto de negociación | F6: apoyar en su resolución | G6: a través de métodos alternativos hetero compositivos y autocompositivos
E7: Fenómenos contemporáneos | F7: reconocer sus afectaciones o contribuciones en el marco de las ciudadanías globales y de una sociedad responsable y sostenible | G7: desde una perspectiva glocal, soportada en datos, con una mirada ética y crítica

Sheet Paso 2 Redacción competen
A1: Elementos para redactar las competencias que desarrollará el programa
A2: [Enumerar las competencias que se van a declarar.] | B2: [A partir de la celda B2 dar clic sobre el ícono de lista desplegable y elegir el verbo que considere adecuado.] | C2: [A partir de la celda C2 dar clic sobre la lista desplegable y elegir el saber extraído del perfil de egreso.] | D2: [Escribir para qué se abordará el saber elegido. Se sugiere apoyarse en el saber hacer.] | E2: [Escribir la condición describiendo los referentes, parámetros, principios, requerimientos o retos que se necesitan para alcanzar las características del perfil en el contexto donde el egresado se desenvolverá.] | F2: [Articular los componentes. Iniciar con el verbo, continuar con el objeto conceptual, luego la finalidad y condición de contexto o referencia; estos últimos no requieren un orden particular.] | G2: [Escribir el tipo de competencia del perfil: Específica (si es del bloque Disciplinar para pregrado o de los componentes para el caso de posgrado) o Genérica (si aplica bloque institucional pregrado)]
A3: No. | B3: VerboCompetencia | C3: Objeto conceptual | D3: Finalidad | E3: Condición de contexto o referencia | F3: RedacciónCompetencia | G3: Tipo de Competencia
A4: 1 | B4: Desarrollar | C4: Procesos y procedimientos en derecho penal, laboral, civil, público y mercantil | D4: gestionar una correcta administración de justicia, | E4: con un criterio ético y responsable en la aplicación de las normas | F4: Desarrollar procesos y procedimientos en derecho penal, laboral, civil, público y mercantil para gestionar una correcta administración de justicia, con un criterio ético y responsable en la aplicación de las normas. | G4: Específica
A5: 2 | B5: Implementar | C5: Procesos archivísticos y de digitalización del derecho | D5: categorizar la información judicial de los expedientes | E5: de acuerdo con las necesidades de la organización | F5: Implementar procesos archivísticos y de digitalización del derecho de acuerdo con las necesidades de la organización, para categorizar la información judicial de los expedientes. | G5: Específica
A6: 3 | B6: Elaborar | C6: Textos jurídicos y contractuales en las diferentes áreas del derecho | D6: documentar la voluntad de las partes | E6: teniendo en cuenta el orden y las etapas necesarias de los actos jurídicos. | F6: Elaborar textos jurídicos y contractuales en las diferentes áreas del derecho para documentar la voluntad de las partes, teniendo en cuenta el orden y las etapas necesarias de los actos jurídicos. | G6: Específica
A7: 4 | B7: Conocer | C7: Conflictos objeto de negociación | D7: apoyar en su resolución | E7: a través de métodos alternativos hetero compositivos y autocompositivos | F7: Conocer los conflictos objeto de negociación para apoyar en su resolución a través de métodos alternativos hetero compositivos y autocompositivos. | G7: Específica
A8: 5 | B8: Analizar | C8: Fenómenos contemporáneos | D8: reconocer sus afectaciones o contribuciones en el marco de las ciudadanías globales y de una sociedad responsable y sostenible | E8: desde una perspectiva glocal, soportada en datos, con una mirada ética y crítica | F8: Analizar los fenómenos contemporáneos desde una perspectiva glocal, soportada en datos, con una mirada ética y crítica, para reconocer sus afectaciones o contribuciones en el marco de las ciudadanías globales y de una sociedad responsable y sostenible. | G8: Genérica

Sheet Paso 3 Redacción RA 
A1: [A partir de la celda A2 dar clic en la lista desplegable y seleccionar la competencia redactada en el paso 2.] | B1: [Enumerar los resultados de aprendizaje que se van a declarar.] | C1: [A partir de la celda C2, dar clic en la lista desplegable y elegir el tipo de dominio a tratar en el resultado de aprendizaje.] | D1: [A partir de la cela D2, dar clic en la lista desplegable y elegir el saber correspondiente al dominio.] | E1: [A partir de la celda E2, dar clic en la lista desplegable y elegir la taxonomía que se considere adecuada, solo se elige una para todos los saberes.] | F1: [A partir de la celda F2, dar clic en la lista desplegable y elegir el dominio que se considera adecuado.] | G1: [A partir de la celda G2, dar clic en la lista desplegable y elegir el nivel del dominio que se considera adecuado.] | H1: [A partir de la celda H2, dar clic en la lista desplegable y elegir el verbo que se considera adecuado.] | I1: [Iniciar con el verbo elegido (columna H), en infinitivo, luego el objeto sobre el cual recae la acción (columna D) y finalmente la condición de contexto (académico, disciplinar, social u otro).]
A2: Competencia por desarrollar | B2: Número de resultado | C2: TipoSaber | D2: SaberAsociado | E2: Taxonomía | F2: Dominio Asociado | G2: Nivel Dominio | H2: Verbo RA | I2: Resultados Aprendizaje
A3: Desarrollar procesos y procedimientos en derecho penal, laboral, civil, público y mercantil para gestionar una correcta administración de justicia, con un criterio ético y responsable en la aplicación de las normas. | B3: 1 | C3: Saber | D3: Procesos y procedimientos en derecho penal, laboral, civil, público y mercantil | E3: Bloom | F3: CognitivoB | G3: ComprensiónB | H3: Identificar | I3: Identifica los procesos y procedimientos asociados a las diferentes áreas del derecho para estructurar las etapas necesarias y lo que de ellas se deriva, en la resolución de conflictos judiciales y extra judiciales.
A4: Desarrollar procesos y procedimientos en derecho penal, laboral, civil, público y mercantil para gestionar una correcta administración de justicia, con un criterio ético y responsable en la aplicación de las normas. | B4: 4 | C4: Saberhacer | D4: gestionar una correcta administración de justicia, | E4: Bloom | F4: ProcedimentalB | G4: AplicaciónB | H4: Emplear | I4: Emplea los procesos y procedimientos que permiten gestionar una correcta administración de justicia, para generar los soportes documentales o verbales que apoyan la resolución de conflictos objeto de negociación, en las diferentes áreas del derecho.
A5: Desarrollar procesos y procedimientos en derecho penal, laboral, civil, público y mercantil para gestionar una correcta administración de justicia, con un criterio ético y responsable en la aplicación de las normas. | B5: 6 | C5: Saberser | D5: con un criterio ético y responsable en la aplicación de las normas. | E5: Bloom | F5: ActitudinalB | G5: AplicaciónB | H5: Aplicar | I5: Aplica adecuadamente técnicas, procesos, procedimientos y métodos propios del actuar jurídico y de la gestión documental judicial, para plantear soluciones acordes con la normatividad y con las necesidades identificadas en el contexto o en el objeto de negociación en la etapa judicial o extra judicial, según corresponda.
A6: Implementar procesos archivísticos y de digitalización del derecho de acuerdo con las necesidades de la organización, para categorizar la información judicial de los expedientes. | B6: 2 | C6: Saber | D6: Procesos archivísticos y de digitalización del derecho | E6: Bloom | F6: CognitivoB | G6: ConocimientoB | H6: Reconocer | I6: Reconoce los textos jurídicos y contractuales que se deben generar en las diferentes áreas del derecho, para determinar el proceso archivístico o de digitalización que permite organizar y gestionar la documentación de información en las entidades.
A7: Implementar procesos archivísticos y de digitalización del derecho de acuerdo con las necesidades de la organización, para categorizar la información judicial de los expedientes. | B7: 5 | C7: Saberhacer | D7: categorizar la información judicial de los expedientes | E7: Bloom | F7: ProcedimentalB | G7: AplicaciónB | H7: Aplicar | I7: Aplica técnicas para categorizar o documentar información acatando los requisitos establecidos en la normatividad sustancial y procesal, así como de la voluntad de los intervinientes.
A8: Implementar procesos archivísticos y de digitalización del derecho de acuerdo con las necesidades de la organización, para categorizar la información judicial de los expedientes. | B8: 6 | C8: Saberser | D8: de acuerdo con las necesidades de la organización | E8: Bloom | F8: ActitudinalB | G8: AplicaciónB | H8: Aplicar | I8: Aplica adecuadamente técnicas, procesos, procedimientos y métodos propios del actuar jurídico y de la gestión documental judicial, para plantear soluciones acordes con la normatividad y con las necesidades identificadas en el contexto o en el objeto de negociación en la etapa judicial o extra judicial, según corresponda.
A9: Elaborar textos jurídicos y contractuales en las diferentes áreas del derecho para documentar la voluntad de las partes, teniendo en cuenta el orden y las etapas necesarias de los actos jurídicos. | B9: 2 | C9: Saber | D9: Textos jurídicos y contractuales en las diferentes áreas del derecho | E9: Bloom | F9: CognitivoB | G9: Conocimientos | H9: Reconocer | I9: Reconoce los textos jurídicos y contractuales que se deben generar en las diferentes áreas del derecho, para determinar el proceso archivístico o de digitalización que permite organizar y gestionar la documentación de información en las entidades.
A10: Elaborar textos jurídicos y contractuales en las diferentes áreas del derecho para documentar la voluntad de las partes, teniendo en cuenta el orden y las etapas necesarias de los actos jurídicos. | B10: 5 | C10: Saberhacer | D10: documentar la voluntad de las partes, | E10: Bloom | F10: ProcedimentalB | G10: AplicaciónB | H10: Aplicar | I10: Aplica técnicas para categorizar o documentar información acatando los requisitos establecidos en la normatividad sustancial y procesal, así como de la voluntad de los intervinientes.
A11: Elaborar textos jurídicos y contractuales en las diferentes áreas del derecho para documentar la voluntad de las partes, teniendo en cuenta el orden y las etapas necesarias de los actos jurídicos. | B11: 6 | C11: Saberser | D11: teniendo en cuenta el orden y las etapas necesarias de los actos jurídicos. | E11: Bloom | F11: ActitudinalB | G11: AplicaciónB | H11: Aplicar | I11: Aplica adecuadamente técnicas, procesos, procedimientos y métodos propios del actuar jurídico y de la gestión documental judicial, para plantear soluciones acordes con la normatividad y con las necesidades identificadas en el contexto o en el objeto de negociación en la etapa judicial o extra judicial, según corresponda.
A12: Conocer los conflictos objeto de negociación para apoyar en su resolución a través de métodos alternativos hetero compositivos y autocompositivos. | B12: 1 | C12: Saber | D12: Conflictos objeto de negociación | E12: Bloom | F12: CognitivoB | G12: ComprensiónB | H12: Identificar | I12: Identifica los procesos y procedimientos asociados a las diferentes áreas del derecho para estructurar las etapas necesarias y lo que de ellas se deriva, en la resolución de conflictos judiciales y extra judiciales.
A13: Conocer los conflictos objeto de negociación para apoyar en su resolución a través de métodos alternativos hetero compositivos y autocompositivos. | B13: 4 | C13: Saberhacer | D13: apoyar en su resolución | E13: Bloom | F13: ProcedimentalB | G13: AplicaciónB | H13: Emplear | I13: Emplea los procesos y procedimientos que permiten gestionar una correcta administración de justicia, para generar los soportes documentales o verbales que apoyan la resolución de conflictos objeto de negociación, en las diferentes áreas del derecho.
A14: Conocer los conflictos objeto de negociación para apoyar en su resolución a través de métodos alternativos hetero compositivos y autocompositivos. | B14: 6 | C14: Saberser | D14: a través de métodos alternativos hetero compositivos y autocompositivos. | E14: Bloom | F14: ActitudinalB | G14: AplicaciónB | H14: Aplicar | I14: Aplica adecuadamente técnicas, procesos, procedimientos y métodos propios del actuar jurídico y de la gestión documental judicial, para plantear soluciones acordes con la normatividad y con las necesidades identificadas en el contexto o en el objeto de negociación en la etapa judicial o extra judicial, según corresponda.
A15: Analizar los fenómenos contemporáneos desde una perspectiva glocal, soportada en datos, con una mirada ética y crítica, para reconocer sus afectaciones o contribuciones en el marco de las ciudadanías globales y de una sociedad responsable y sostenible. | B15: 3 | C15: Saber | D15: Fenómenos contemporáneos | E15: Bloom | F15: CognitivoB | G15: ComprensiónB | H15: Identificar | I15: Identifica fenómenos contemporáneos y su relación con la profesión, para determinar sus impactos e influencia en la sociedad, de forma responsable y crítica.

Sheet Paso 4 Estrategias mesocurricu
A1: [A partir de la celda A3 despliegue el(los) resultado(s) de aprendizaje y elegir aquel (aquellos) al(a los) que se contribuye desde la estrategia.] | B1: [Escribir el nombre de la estrategia a desarrollar. Participación de los estudiantes en cursos, talleres, seminarios, conferencias, pruebas estandarizadas, investigaciones, actividades o experiencias, cuerpos académicos, redes, comunidades, la elaboración de textos y materiales, así como las publicaciones, entre otros.] | C1: [Describir la(s) estrategia(s) definidas por el programa.] | D1: [Escribir los indicadores de impacto de la estrategia. Se sugieren indicadores como: Valora el nivel de contribución de la estrategia a los resultados de aprendizaje; Número de estudiantes que participan en la estrategia; Número de veces que se realiza la estrategia, entre otros.] | E1: [Escribir las acciones de retroalimentación que usará el programa para comunicar a los estudiantes sobre el alcance de sus resultados de aprendizaje.] | F1: [Escribir, para cada indicador con qué instrumento se recogerá información para evidenciar el (los) impacto (s) declarados. Encuesta, lista de asistencia, informe, entre otros.]
A2: Resultado de aprendizaje | B2: Estrategia del programa | C2: Descripción | D2: Indicador de Impacto de la Estrategia | E2: Acciones de retroalimentación para los estudiantes | F2: Instrumentos de medición
A3: Identifica los procesos y procedimientos asociados al derecho penal, laboral, civil, público y mercantil, para estructurar su forma de uso en el desarrollo de conflictos objeto de negociación. | B3: Eventos académicos nacionales e internacionales | C3: Organización de encuentros con expertos nacionales e internacionales del ámbito jurídico, orientados a la actualización en tendencias, análisis en derecho comparado, cambios normativos y buenas prácticas del derecho. Estos espacios fortalecen el pensamiento crítico, amplían la perspectiva profesional y fomentan redes de contacto en el sector legal. | D3: Número de estudiantes del programa que participan en la estrategia. | E3: Informar y formar sobre las tendencias, cambios normativos y buenas prácticas compartidas por expertos, promoviendo su apropiación y aplicación en contextos jurídicos reales. | F3: Listado de participación
A4: Aplica las técnicas para categorizar o documentar información acatando los requisitos establecidos en la normatividad sustancial y procesal, así como de la voluntad de los intervinientes. | D4: Valoración de los estudiantes de la contribución que da la estrategia a los resultados de aprendizaje asociados. | F4: Encuesta
A5: Emplea los procesos y procedimientos que permiten gestionar una correcta administración de justicia, para generar los soportes documentales o verbales que apoyan la resolución de conflictos objeto de negociación, en las diferentes áreas del derecho. | D5: Número de eventos realizados en el periodo de tiempo que establezca el programa. | F5: Reporte o Informe
A6: Emplea los procesos y procedimientos que permiten gestionar una correcta administración de justicia, para generar los soportes documentales o verbales que apoyan la resolución de conflictos objeto de negociación, en las diferentes áreas del derecho. | B6: Misiones internacionales | C6: Experiencias académicas y culturales con entidades, organismos o expertos disciplinares del exterior que incluyen congresos, seminarios, diplomados y encuentros, permitiendo ampliar el conocimiento de diversos sistemas jurídicos con análisis en derecho comparado y el intercambio de buenas prácticas en la administración de justicia. | D6: Número de estudiantes del programa que participan en la estrategia. | E6: Formar y ayudar a decidir sobre la participación en experiencias académicas internacionales, orientando al estudiante en la valoración de beneficios académicos y profesionales. | F6: Listado de participación
A7: Aplica adecuadamente técnicas, procesos y métodos propios del actuar jurídico y de la gestión documental judicial, para plantear soluciones acordes a las necesidades identificadas en el contexto o al objeto de negociación cuando corresponda. | D7: Valoración de los estudiantes de la contribución que da la estrategia a los resultados de aprendizaje asociados. | F7: Encuesta
A8: Aplica adecuadamente técnicas, procesos y métodos propios del actuar jurídico y de la gestión documental judicial, para plantear soluciones acordes a las necesidades identificadas en el contexto o al objeto de negociación cuando corresponda. | D8: Número de misiones realizadas en el periodo de tiempo que establezca el programa. | F8: Reporte o Informe
A9: Identifica los procesos y procedimientos asociados al derecho penal, laboral, civil, público y mercantil, para estructurar su forma de uso en el desarrollo de conflictos objeto de negociación. | B9: Análisis de empleabilidad y proyección de impacto como egresados hacia las comunidades | C9: Revisión sistemática de la demanda laboral de técnicos judiciales en el sector público y privado, identificando oportunidades de inserción laboral y áreas de impacto social, con el propósito de retroalimentar el plan de estudios y fortalecer la pertinencia del perfil profesional. | D9: Número de estudiantes que participan en las convocatorias a concursos de la rama judicial o que están vinculados laboralmente en actividades jurídicas. | E9: Informar y prevenir respecto a las tendencias del mercado laboral para técnicos judiciales, anticipando competencias y habilidades requeridas por el sector público y privado. | F9: Listado de participación
A10: Aplica las técnicas para categorizar o documentar información acatando los requisitos establecidos en la normatividad sustancial y procesal, así como de la voluntad de los intervinientes. | D10: Número de veces que se participa en las convocatorias a concursos de la rama judicial. | F10: Reporte o Informe
A11: Emplea los procesos y procedimientos que permiten gestionar una correcta administración de justicia, para generar los soportes documentales o verbales que apoyan la resolución de conflictos objeto de negociación, en las diferentes áreas del derecho.
A12: Reconoce los textos jurídicos y contractuales que se deben generar en las situaciones jurídicas de las diferentes áreas del derecho, para determinar el proceso archivístico y de gestión documental que permite organizar la información en las entidades judiciales.
A13: Aplica adecuadamente técnicas, procesos y métodos propios del actuar jurídico y de la gestión documental judicial, para plantear soluciones acordes a las necesidades identificadas en el contexto o al objeto de negociación cuando corresponda.
A14: Identifica los procesos y procedimientos asociados al derecho penal, laboral, civil, público y mercantil, para estructurar su forma de uso en el desarrollo de conflictos objeto de negociación. | B14: Elaboración de textos jurídicos | C14: Desarrollo de talleres y ejercicios prácticos enfocados en la producción de documentos jurídicos contractuales y procedimentales, con énfasis en la estructura normativa, el rigor técnico y el uso preciso del lenguaje jurídico para contextos reales. | D14: Número de estudiantes del programa que participan en la estrategia. | E14: Formar y prevenir sobre errores comunes en la redacción de documentos jurídicos, fortaleciendo la precisión técnica en materia de elementos esenciales y de validez y el uso correcto del lenguaje jurídico. | F14: Listado de participación
A15: Emplea los procesos y procedimientos que permiten gestionar una correcta administración de justicia, para generar los soportes documentales o verbales que apoyan la resolución de conflictos objeto de negociación, en las diferentes áreas del derecho. | D15: Número de documentos y situaciones simuladas generados en el curso de práctica simulada. | F15: Reporte o Informe
A16: Aplica adecuadamente técnicas, procesos y métodos propios del actuar jurídico y de la gestión documental judicial, para plantear soluciones acordes a las necesidades identificadas en el contexto o al objeto de negociación cuando corresponda. | D16: Número de documentos publicados producto de proyectos de semilleros. | F16: Registros en Alejandría u otros repositorios
A17: Reconoce los textos jurídicos y contractuales que se deben generar en las situaciones jurídicas de las diferentes áreas del derecho, para determinar el proceso archivístico y de gestión documental que permite organizar la información en las entidades judiciales.
A18: Aplica las técnicas para categorizar o documentar información acatando los requisitos establecidos en la normatividad sustancial y procesal, así como de la voluntad de los intervinientes.
A19: Identifica los procesos y procedimientos asociados al derecho penal, laboral, civil, público y mercantil, para estructurar su forma de uso en el desarrollo de conflictos objeto de negociación. | B19: Clases espejo nacional e internacional | C19: Implementación de sesiones académicas sincrónicas en modalidad de una o doble vía, donde docentes y estudiantes interactúan con grupos de universidades nacionales e internacionales para contrastar enfoques jurídicos, conocer postulados internacionales y reforzar el aprendizaje en disciplinas del derecho sustancial. | D19: Participación de los estudiantes en las clases espejo en doble vía a las que son convocados. | E19: Formar e informar sobre enfoques y postulados jurídicos nacionales e internacionales, incentivando la comparación crítica normativa y la aplicación contextualizada del conocimiento. | F19: Listados de participación
A20: Emplea los procesos y procedimientos que permiten gestionar una correcta administración de justicia, para generar los soportes documentales o verbales que apoyan la resolución de conflictos objeto de negociación, en las diferentes áreas del derecho. | D20: Número de tutores del programa que participan en la estrategia. | F20: Listados de participación
A21: Aplica adecuadamente técnicas, procesos y métodos propios del actuar jurídico y de la gestión documental judicial, para plantear soluciones acordes a las necesidades identificadas en el contexto o al objeto de negociación cuando corresponda. | D21: Número de veces que se implementa la estrategia semestralmente. | F21: Reporte o Informe
A22: Reconoce los textos jurídicos y contractuales que se deben generar en las situaciones jurídicas de las diferentes áreas del derecho, para determinar el proceso archivístico y de gestión documental que permite organizar la información en las entidades judiciales.
A23: Aplica las técnicas para categorizar o documentar información acatando los requisitos establecidos en la normatividad sustancial y procesal, así como de la voluntad de los intervinientes.
A24: Identifica los procesos y procedimientos asociados al derecho penal, laboral, civil, público y mercantil, para estructurar su forma de uso en el desarrollo de conflictos objeto de negociación. | B24: Socialización prácticas simuladas del programa | C24: Presentación de casos y textos jurídicos elaborados en el módulo virtual de prácticas simuladas, evidenciando la aplicación práctica de procedimientos judiciales y la suficiencia en el manejo de las diferentes áreas del derecho, con retroalimentación académica entre pares y docentes. | D24: Valoración de los estudiantes de la contribución que da la estrategia a los resultados de aprendizaje asociados. | E24: Formar a los estudiantes en temas disciplinares y en su aplicación dentro de contextos procedimentales. Informar y formar mediante la apropiación social del conocimiento, compartiendo las experiencias de prácticas en ambientes simulados y el saber generado por los estudiantes del programa. | F24: Reporte o Informe
A25: Emplea los procesos y procedimientos que permiten gestionar una correcta administración de justicia, para generar los soportes documentales o verbales que apoyan la resolución de conflictos objeto de negociación, en las diferentes áreas del derecho. | D25: Presenta la fundamentación jurídica en la sustentación de argumentos verbales que permitan resolver un caso ante jurados, desde los diferentes énfasis del derecho con uso de MASC en primera instancia. | F25: Reporte o Informe participación en eventos de proyección social con las comunidades
A26: Aplica adecuadamente técnicas, procesos y métodos propios del actuar jurídico y de la gestión documental judicial, para plantear soluciones acordes a las necesidades identificadas en el contexto o al objeto de negociación cuando corresponda. | D26: Desarrolla la solución de problemas formulados a partir de un cuestionario que integra todas las áreas el derecho y los MASC. | F26: Reporte o Informe resultado de las pruebas Saber TyT
A27: Reconoce los textos jurídicos y contractuales que se deben generar en las situaciones jurídicas de las diferentes áreas del derecho, para determinar el proceso archivístico y de gestión documental que permite organizar la información en las entidades judiciales. | D27: Estudiantes que aprueban con promedio superior a 450 puntos de 500, el módulo de practica en ambiente simulados. | F27: Reporte o Informe
A28: Aplica las técnicas para categorizar o documentar información acatando los requisitos establecidos en la normatividad sustancial y procesal, así como de la voluntad de los intervinientes.
A29: Identifica los procesos y procedimientos asociados al derecho penal, laboral, civil, público y mercantil, para estructurar su forma de uso en el desarrollo de conflictos objeto de negociación. | B29: Curso de preparación para el examen Saber TyT | C29: Programa de formación virtual semestral tipo MOOC orientado a reforzar las competencias genéricas evaluadas en el examen Saber TyT, que incluye caja de herramientas, cápsulas de formación, guías de orientación Saber TyT ICFES, sesiones sincrónicas con expertos en competencias ciudadanas, inglés, razonamiento cuantitativo, comunicación escrita y lectura crítica. | D29: Número de estudiantes del programa que participan en la estrategia. | E29: Formar a los estudiantes en contenidos y competencias clave de la profesión evaluadas en las pruebas Saber TyT. Prevenir dificultades y orientar la toma de decisiones académicas a partir del análisis de los resultados obtenidos durante el proceso de preparación y simulación del examen. | F29: Listados de participación
A30: Emplea los procesos y procedimientos que permiten gestionar una correcta administración de justicia, para generar los soportes documentales o verbales que apoyan la resolución de conflictos objeto de negociación, en las diferentes áreas del derecho. | D30: Número de veces que se implementa la estrategia semestralmente. | F30: Reporte o Informe
A31: Aplica adecuadamente técnicas, procesos y métodos propios del actuar jurídico y de la gestión documental judicial, para plantear soluciones acordes a las necesidades identificadas en el contexto o al objeto de negociación cuando corresponda. | D31: Resultados de las pruebas Saber TyT en comparación con la media de resultados institucional y nacional. | F31: Reporte o Informe
A32: Reconoce los textos jurídicos y contractuales que se deben generar en las situaciones jurídicas de las diferentes áreas del derecho, para determinar el proceso archivístico y de gestión documental que permite organizar la información en las entidades judiciales. | D32: Puntaje superior en la solución de problemas formulados para la redacción del texto argumentativo que se requieren en la prueba general de Saber TyT. | F32: Reporte o Informe

Sheet Paso 5 Estrategias micro
A1: [Estas celdas se diligencian automáticamente. No ajustar.] | B1: [A partir de la celda A3 despliegue el(los) resultado(s) de aprendizaje y elija aquel (aquellos) al(a los) que se contribuye desde la asignatura o módulo).] | C1: [Escribir el semestre en el que se cursa la asignatura o módulo.] | D1: [Escribir el nombre de la asignatura o módulo que contribuye al logro del resultado de aprendizaje.] | E1: [Redactar los indicadores iniciando con el verbo en presente indicativo, luego el objeto conceptual y finalmente el complemento de oración (que indique una condición o finalidad, con, para, de, entre otros conectores).] | F1: [Escribir la tipología: T (teórico), P (Práctico), TP (Teórico Práctico)] | G1: [Marcar con X el bloque o componente al que pertenece la asignatura o módulo. Por favor ajustar para posgrado, eliminar una columna y ubicar los títulos C.Fundamentación y C.Profundización.] | J1: [Escribir el número de créditos de la asignatura o módulo] | K1: [Escribir el número de horas de trabajo directo: 16*# o 12*#, para presencial o virtual, según sea el caso.] | L1: [Escribir el número de horas de trabajo independiente: 32*# columna J o 36*# columna J, para presencial o virtual, respectivamente.] | M1: [Escribir la suma de los números de horas de las dos celdas anteriores.] | N1: [Escribir el nombre de los cuatro núcleos temáticos que abordará la asignatura o el módulo.] | O1: [Escribir las lecturas, talleres, análisis, referentes, etc., que realiza el estudiante, clasificadas en trabajo directo e independiente.] | P1: [Escribir las actividades de evaluación que se emplean para identificar el alcance del (de los) indicador(es) de logro(s).] | Q1: [Escribir las acciones de retroalimentación que se emplearán en la asignatura o módulo, para retroalimentar a los estudiantes respecto al alcance de los indicadores de logro. Recordar que son cuatro acciones: informar, formar, prevenir y ayudar a tomar decisiones e indique cómo.]
A2: Tipo de Saber | B2: Resultado de aprendizaje | C2: Semestre | D2: Nombre de la asignatura o módulo | E2: Indicadores de logro de la asignatura y/o módulo | F2: Tipología | G2: B.Institucional | H2: B.Disciplinar | I2: B.Electivo | J2: Créditos | K2: Número de horas de trabajo directo | L2: Número de horas de trabajo independiente | M2: Total de horas | N2: Núcleos temáticos | O2: Actividades de aprendizaje | P2: Actividades de evaluación | Q2: Acciones de retroalimentación
A3: {=_xlfn.XLOOKUP(B3,'Paso 3 Redacción RA '!$I$3:$I$15,'Paso 3 Redacción RA '!$C$3:$C$15,,0,1)} -> Saber | B3: Identifica los procesos y procedimientos asociados a las diferentes áreas del derecho para estructurar las etapas necesarias y lo que de ellas se deriva, en la resolución de conflictos judiciales y extra judiciales. | C3: 1 | D3: Introducción al Derecho | E3: Analiza las concepciones del derecho, sus escuelas y corrientes, así como los principios y fuentes del derecho para establecer el derecho en la resolución de casos mediante la argumentación. | F3: T | H3: X | J3: 3 | K3: =12*J3 -> 36 | L3: =36*J3 -> 108 | M3: =SUM(K3:L7) -> 144 | N3: 1. Nociones fundamentales de Derecho. 2. Introducción a la filosofía del Derecho. 3. Fuentes del Derecho. 4. Principios generales del Derecho. | O3: Trabajo directo: Encuentros sincrónicos Mensajería interna Anuncios Trabajo independiente: Lecturas fundamentales y complementarias Recursos de apoyo Trabajo Colaborativo Foros de discusión grupal | P3: Quiz (semana 2 - Cuestionario de 5 preguntas). Entrega inicial (semana 3 – Ensayo, artículo, cuadro comparativo, revisión documental, entre otros). Foro analítico o argumentativo (semanas 5 y 6 – Participación en el espacio correspondiente del aula). Entrega final (semana 7 – Ensayo, artículo, cuadro comparativo, revisión documental, entre otros). Evaluación final (semana 8 – Cuestionario de entre 15 y 20 preguntas). | Q3: Las acciones de retroalimentación giran en torno a las siguientes. Formar: donde se crean las condiciones para que los estudiantes adquieran conocimientos, habilidades, actitudes, aptitudes y destrezas. Además, debe promover su desarrollo integral y debe acompañarlos en las situaciones académicas que enfrenten durante el desarrollo de un módulo o una asignatura. Informar: para que los estudiantes identifiquen los cambios que pueden afectarlos directa o indirectamente tanto en el aula de clase como en otros espacios. Prevenir: con el fin de anticiparse a las situaciones académicas que pueden representar dificultad para los estudiantes. Esto se logra a través de la interacción individual con los estudiantes y del completo conocimiento del contexto educativo en que el tutor se desenvuelve. Ayudar a decidir: donde se orienta a los estudiantes para que tomen la mejor decisión ante una situación concreta. El objetivo es que el estudiante fortalezca su autonomía y la toma de decisiones responsable.
A4: {=_xlfn.XLOOKUP(B4,'Paso 3 Redacción RA '!$I$3:$I$15,'Paso 3 Redacción RA '!$C$3:$C$15,,0,1)} -> Saberhacer | B4: Emplea los procesos y procedimientos que permiten gestionar una correcta administración de justicia, para generar los soportes documentales o verbales que apoyan la resolución de conflictos objeto de negociación, en las diferentes áreas del derecho.
A5: {=_xlfn.XLOOKUP(B5,'Paso 3 Redacción RA '!$I$3:$I$15,'Paso 3 Redacción RA '!$C$3:$C$15,,0,1)} -> Saberser | B5: Aplica adecuadamente técnicas, procesos, procedimientos y métodos propios del actuar jurídico y de la gestión documental judicial, para plantear soluciones acordes con la normatividad y con las necesidades identificadas en el contexto o en el objeto de negociación en la etapa judicial o extra judicial, según corresponda.
A6: {=_xlfn.XLOOKUP(B6,'Paso 3 Redacción RA '!$I$3:$I$15,'Paso 3 Redacción RA '!$C$3:$C$15,,0,1)} -> Saber | B6: Reconoce los textos jurídicos y contractuales que se deben generar en las diferentes áreas del derecho, para determinar el proceso archivístico o de digitalización que permite organizar y gestionar la documentación de información en las entidades.
A7: {=_xlfn.XLOOKUP(B7,'Paso 3 Redacción RA '!$I$3:$I$15,'Paso 3 Redacción RA '!$C$3:$C$15,,0,1)} -> Saberhacer | B7: Aplica técnicas para categorizar o documentar información acatando los requisitos establecidos en la normatividad sustancial y procesal, así como de la voluntad de los intervinientes.
A8: {=_xlfn.XLOOKUP(B8,'Paso 3 Redacción RA '!$I$3:$I$15,'Paso 3 Redacción RA '!$C$3:$C$15,,0,1)} -> Saber | B8: Identifica fenómenos contemporáneos y su relación con la profesión, para determinar sus impactos e influencia en la sociedad, de forma responsable y crítica. | C8: 1 | D8: Razonamiento Cuantitativo | E8: Analiza datos numéricos presentados en tablas, gráficos o textos para proponer soluciones informadas a situaciones problema del contexto. | F8: TP | G8: X | J8: 3 | K8: =12*J8 -> 36 | L8: =36*J8 -> 108 | M8: =SUM(K8:L8) -> 144 | N8: 1. Pensamiento numérico. Interpretación y representación de información numérica. 2. Pensamiento algebraico desde la representación de regularidades y patrones. 3. Pensamiento algebraico desde las relaciones de comparación entre cantidades o expresiones numéricas. 4. Pensamiento geométrico. Propiedades, formas y relaciones espaciales. | O8: Trabajo Directo: Desarrollo de encuentros sincrónicos Acompañamiento en foros Mensajería interna con la reflexión o síntesis de los resultados alcanzados por el grupo Trabajo Independiente: Revisión de lecturas fundamentales Revisión y desarrollo del material de trabajo Participación en foros de discusión, de actividades formativas o de resolución de dudas Revisión de material complementario | P8: Evaluación diagnóstica (semana 1- Cuestionario inicial de, mínimo, cinco preguntas, que recopila información sobre el conocimiento previo y las habilidades del estudiante. ) Actividad formativa (semana 2 - Foro individual o grupal, creado para que el estudiante participe activamente en la construcción de su conocimiento y desarrollo de habilidades. Varía entre una actividad entregable y la participación en un foro.) Actividades de entrega (semana 4 - Actividad individual o grupal, diseñada para evaluar de manera integral el nivel de conocimiento, comprensión y el desempeño de los indicadores de logro. Varía entre entregas independientes o secuenciales. Al ser un módulo teórico, ésta es la única actividad de entrega. ) Actividad formativa (semana 5 - Foro individual o grupal, creado para que el estudiante participe activamente en la construcción de su conocimiento y desarrollo de habilidades. Varía entre una actividad entregable y la participación en un foro.) Actividad evaluativa (semana 6 - Cuestionario de, mínimo, cinco preguntas, que da cuenta del desarrollo total o parcial de los indicadores de logro y el desarrollo de los temas vistos hasta la unidad 3. ) Examen final (semana 8 - Cuestionario de, mínimo, quince preguntas, que da cuenta del desarrollo total o parcial de los indicadores de logro y el desarrollo de los temas vistos en el módulo. ) Autoevaluación (semana 8 - Cuestionario final de, mínimo, cinco preguntas, en el cual el estudiante reflexiona sobre su propio desempeño, habilidades y resultados en un contexto específico. ) | Q8: Las acciones de retroalimentación giran en torno a las siguientes. Formar: donde se crean las condiciones para que los estudiantes adquieran conocimientos, habilidades, actitudes, aptitudes y destrezas. Además, debe promover su desarrollo integral y debe acompañarlos en las situaciones académicas que enfrenten durante el desarrollo de un módulo o una asignatura. Informar: para que los estudiantes identifiquen los cambios que pueden afectarlos directa o indirectamente tanto en el aula de clase como en otros espacios. Prevenir: con el fin de anticiparse a las situaciones académicas que pueden representar dificultad para los estudiantes. Esto se logra a través de la interacción individual con los estudiantes y del completo conocimiento del contexto educativo en que el tutor se desenvuelve. Ayudar a decidir: donde se orienta a los estudiantes para que tomen la mejor decisión ante una situación concreta. El objetivo es que el estudiante fortalezca su autonomía y la toma de decisiones responsable.
A9: {=_xlfn.XLOOKUP(B9,'Paso 3 Redacción RA '!$I$3:$I$15,'Paso 3 Redacción RA '!$C$3:$C$15,,0,1)} -> Saber | B9: Identifica los procesos y procedimientos asociados a las diferentes áreas del derecho para estructurar las etapas necesarias y lo que de ellas se deriva, en la resolución de conflictos judiciales y extra judiciales. | C9: 1 | D9: Habilidades de Negociación y Manejo de Conflictos | E9: Analiza las nociones de conflicto, negociación, así como los diferentes mecanismos que componen la resolución de conflictos para establecer la mejor estrategia de solución desde la perspectiva jurídica y socio humanística. | F9: TP | H9: X | J9: 3 | K9: =12*J9 -> 36 | L9: =36*J9 -> 108 | M9: =SUM(K9:L14) -> 144 | N9: 1. El conflicto y las controversias jurídicas. 2. Técnicas y habilidades de negociación. 3. Mecanismos alternativos de solución de conflictos autocompositivos. 4. Mecanismos alternativos de solución de conflictos hetero compositivos. | O9: Trabajo directo: Encuentros sincrónicos Mensajería interna Anuncios Trabajo independiente: Lecturas fundamentales y complementarias Recursos de apoyo Trabajo Colaborativo Foros de discusión grupal | P9: Actividad de puntos evaluables (semana 2 – Cuestionario de 5 preguntas). Entrega previa 1 (semana 3 - Laboratorio, taller, ejercicios, resolución de casos o de problemas, desarrollo de procesos o ejecución de propuestas. Entrega de forma individual o grupal, según indicaciones del profesor). Parcial (semana 4 - Cuestionarios de entre 15 y 20 preguntas). Entrega previa 2 (semana 5 - Laboratorio, taller, ejercicios, resolución de casos o de problemas, desarrollo de procesos o ejecución de propuestas. Entrega de forma individual o grupal, según indicaciones dadas por el profesor). Entrega final (semana 7 - Laboratorio, taller, ejercicios, resolución de casos o de problemas, desarrollo de procesos o ejecución de propuestas. Entrega de forma individual o grupal, según indicaciones dadas por el profesor). Evaluación final (semana 8 - Cuestionario de entre 15 y 20 preguntas). | Q9: Las acciones de retroalimentación giran en torno a las siguientes. Formar: donde se crean las condiciones para que los estudiantes adquieran conocimientos, habilidades, actitudes, aptitudes y destrezas. Además, debe promover su desarrollo integral y debe acompañarlos en las situaciones académicas que enfrenten durante el desarrollo de un módulo o una asignatura. Informar: para que los estudiantes identifiquen los cambios que pueden afectarlos directa o indirectamente tanto en el aula de clase como en otros espacios. Prevenir: con el fin de anticiparse a las situaciones académicas que pueden representar dificultad para los estudiantes. Esto se logra a través de la interacción individual con los estudiantes y del completo conocimiento del contexto educativo en que el tutor se desenvuelve. Ayudar a decidir: donde se orienta a los estudiantes para que tomen la mejor decisión ante una situación concreta. El objetivo es que el estudiante fortalezca su autonomía y la toma de decisiones responsable.
A10: {=_xlfn.XLOOKUP(B10,'Paso 3 Redacción RA '!$I$3:$I$15,'Paso 3 Redacción RA '!$C$3:$C$15,,0,1)} -> Saberhacer | B10: Emplea los procesos y procedimientos que permiten gestionar una correcta administración de justicia, para generar los soportes documentales o verbales que apoyan la resolución de conflictos objeto de negociación, en las diferentes áreas del derecho.
A11: {=_xlfn.XLOOKUP(B11,'Paso 3 Redacción RA '!$I$3:$I$15,'Paso 3 Redacción RA '!$C$3:$C$15,,0,1)} -> Saberser | B11: Aplica adecuadamente técnicas, procesos, procedimientos y métodos propios del actuar jurídico y de la gestión documental judicial, para plantear soluciones acordes con la normatividad y con las necesidades identificadas en el contexto o en el objeto de negociación en la etapa judicial o extra judicial, según corresponda.
A12: {=_xlfn.XLOOKUP(B12,'Paso 3 Redacción RA '!$I$3:$I$15,'Paso 3 Redacción RA '!$C$3:$C$15,,0,1)} -> Saber | B12: Reconoce los textos jurídicos y contractuales que se deben generar en las diferentes áreas del derecho, para determinar el proceso archivístico o de digitalización que permite organizar y gestionar la documentación de información en las entidades.
A13: {=_xlfn.XLOOKUP(B13,'Paso 3 Redacción RA '!$I$3:$I$15,'Paso 3 Redacción RA '!$C$3:$C$15,,0,1)} -> Saber | B13: Identifica fenómenos contemporáneos y su relación con la profesión, para determinar sus impactos e influencia en la sociedad, de forma responsable y crítica.
A14: {=_xlfn.XLOOKUP(B14,'Paso 3 Redacción RA '!$I$3:$I$15,'Paso 3 Redacción RA '!$C$3:$C$15,,0,1)} -> Saberhacer | B14: Aplica técnicas para categorizar o documentar información acatando los requisitos establecidos en la normatividad sustancial y procesal, así como de la voluntad de los intervinientes.
A15: {=_xlfn.XLOOKUP(B15,'Paso 3 Redacción RA '!$I$3:$I$15,'Paso 3 Redacción RA '!$C$3:$C$15,,0,1)} -> Saber | B15: Identifica fenómenos contemporáneos y su relación con la profesión, para determinar sus impactos e influencia en la sociedad, de forma responsable y crítica. | C15: 1 | D15: Cultura, Política y Sociedad | E15: Reconoce las problemáticas, escenarios y mecanismos de participación ciudadana en el marco de sociedades de información y digitales para abordarlas desde iniciativas investigativas. Identifica los objetivos de desarrollo sostenible para llevar a cabo análisis de problemáticas sociales, ambientales y culturales. Reflexiona sobre los impactos de los avances tecnológicos en el ámbito profesional y ciudadano para generar análisis alrededor de éstos, en contextos situados. | F15: TP | G15: X | J15: 3 | K15: =12*J15 -> 36 | L15: =36*J15 -> 108 | M15: =SUM(K15:L15) -> 144 | N15: 1. ODS, problemas locales: una mirada a Colombia, territorio en búsqueda de la consolidación de la Paz. 2. Ciudadanía y su lugar: relaciones, dinámicas, construcción, expresión y mecanismos de participación. 3. Ecosistemas digitales: relaciones, dinámicas, construcción, expresión e impactos en el contexto profesional. 4. Narrativas y contenidos digitales: análisis de contextos situados. | O15: Trabajo Directo: Desarrollo de encuentros sincrónicos Acompañamiento en foros Mensajería interna con la reflexión o síntesis de los resultados alcanzados por el grupo Trabajo Independiente: Revisión de lecturas fundamentales Revisión y desarrollo del material de trabajo Participación en foros de discusión, de actividades formativas o de resolución de dudas Revisión de material complementario | P15: Evaluación diagnóstica (semana 1- Cuestionario inicial de, mínimo, cinco preguntas, que recopila información sobre el conocimiento previo y las habilidades del estudiante. ) Actividad formativa (semana 2 - Foro individual o grupal, creado para que el estudiante participe activamente en la construcción de su conocimiento y desarrollo de habilidades. Varía entre una actividad entregable y la participación en un foro.) Actividades de entrega I (semana 4 - Actividad individual o grupal, diseñada para evaluar de manera integral el nivel de conocimiento, comprensión y el desempeño de los indicadores de logro. Varía entre entregas independientes o secuenciales. Al ser un módulo teórico, ésta es la única actividad de entrega. ) Actividad formativa (semana 5 - Foro individual o grupal, creado para que el estudiante participe activamente en la construcción de su conocimiento y desarrollo de habilidades. Varía entre una actividad entregable y la participación en un foro.) Actividades de entrega 2 (semana 6 - Actividad individual o grupal, diseñada para evaluar de manera integral el nivel de conocimiento, comprensión y el desempeño de los indicadores de logro. Varía entre entregas independientes o secuenciales. Al ser un módulo teórico, ésta es la única actividad de entrega. ) Autoevaluación (semana 8 - Cuestionario final de, mínimo, cinco preguntas, en el cual el estudiante reflexiona sobre su propio desempeño, habilidades y resultados en un contexto específico. ) | Q15: Las acciones de retroalimentación giran en torno a las siguientes. Formar: donde se crean las condiciones para que los estudiantes adquieran conocimientos, habilidades, actitudes, aptitudes y destrezas. Además, debe promover su desarrollo integral y debe acompañarlos en las situaciones académicas que enfrenten durante el desarrollo de un módulo o una asignatura. Informar: para que los estudiantes identifiquen los cambios que pueden afectarlos directa o indirectamente tanto en el aula de clase como en otros espacios. Prevenir: con el fin de anticiparse a las situaciones académicas que pueden representar dificultad para los estudiantes. Esto se logra a través de la interacción individual con los estudiantes y del completo conocimiento del contexto educativo en que el tutor se desenvuelve. Ayudar a decidir: donde se orienta a los estudiantes para que tomen la mejor decisión ante una situación concreta. El objetivo es que el estudiante fortalezca su autonomía y la toma de decisiones responsable.
