Workbook
Name ActitudinalBAK: 'Taxonomias para RA'!$AC$3:$AG$3
Name Bloom: 'Taxonomias para RA'!$G$3:$I$3
Name Circutos: 'Paso 2 Redacción competen'!$F$4
Name CognitivoBAK: 'Taxonomias para RA'!$S$3:$X$3
Name CompetenciaEspecifica1: 'Paso 2 Redacción competen'!$F$4
Name competencias: #REF!
Name ComponentesCompetencias: 'Paso1 Analisis perfil egreso'!$E$2:$G$2
Name Conocimientos: #REF!
Name FACULTADES: #REF!
Name ProcedimentalBAK: 'Taxonomias para RA'!$Y$3:$AB$3
Name RA: 'Paso 5 Estrategias micro'!$B$8
Name resultadoaprendizaje: '[2]Paso 3 Redacción RA '!$I$2:$I$21
Name Saber: 'Paso1 Analisis perfil egreso'!$E$3:$E$6
Name SaberHacer: 'Paso1 Analisis perfil egreso'!$F$3:$F$6
Name SaberSer: 'Paso1 Analisis perfil egreso'!$G$3:$G$6
Name taxonomiasra: [3]!Tabla1715[Taxonomías]
Name TIC: 'Paso 2 Redacción competen'!$F$7

Sheet Paso1 Analisis perfil egreso
A1: [Escribir el nombre del programa] | B1: [Escribir la modalidad: presencial o virtual] | C1: [Escribir el perfil profesional del egresado.] | D1: [Escribir el perfil ocupacional del egresado.] | E1: Componentes fundamentales aplicables a la solución de problemas en la vida profesional [Listar, según lo escrito en el perfil profesional, qué debe saber el egresado en las categorías de Saber -conocimientos, hechos, teorías-, Saber hacer -técnicas, procedimientos, metodologías-, y Saber ser -valores, condiciones, etc.] | H1: Componentes fundamentales de la ocupación laboral del profesional [Listar, según lo escrito en el perfil ocupacional, en qué áreas, qué tareas potenciales y en qué poblaciones o contextos podrá laborar el profesional.] | K1: Diferencial (valor agregado) del profesional [Listar, según lo escrito en los perfiles, los elementos que son diferenciales y generan un valor agregado al egresado.]
A2: Programa | B2: Modalidad | C2: Perfil profesional | D2: Perfil ocupacional | E2: Saber | F2: SaberHacer | G2: SaberSer | H2: Áreas profesionales | I2: Tareas profesionales | J2: Poblaciones actuación | K2: Valor agregado
A3: Administración de Empresas | B3: Presencial | C3: El profesional en Administración de Empresas del Politécnico Grancolombiano formula y ejecuta estrategias organizacionales innovadoras, integrando conocimientos en gestión organizacional con metodologías de análisis de información. Su formación integral le permite tomar decisiones informadas en contextos cambiantes, liderar proyectos empresariales, y promover modelos de negocio sostenibles, aportando a la generación de valor organizacional. Se caracteriza por su pensamiento crítico y compromiso con el desarrollo organizacional, según las dinámicas del entorno y el marco legal vigente. | D3: El administrador de empresas del Politécnico Grancolombiano está capacitado para desarrollar estrategias corporativas alineadas con la dinámica del entorno y la competitividad empresarial. Su formación le permite gestionar áreas funcionales clave con visión sostenible y criterio estratégico, dirigir equipos de trabajo según las tendencias organizacionales, implementar planes estratégicos, tácticos y operativos, y administrar sistemas de gestión empresarial. Además, cuenta con las competencias necesarias para identificar oportunidades de negocio y convertirlas en iniciativas productivas que generen valor en distintos sectores económicos. | E3: Principios económicos y sociales, y normatividad empresarial | F3: tomar decisiones informadas | G3: considerando tanto criterios de sostenibilidad como la legislación vigente en contextos organizacionales y empresariales. | H3: Gerencia administrativa. Gestión empresarial. Gestión de proyectos. Análisis estratégico. Consultoría empresarial. | I3: Coordinar o liderar áreas de empresas, así como proyectos empresariales. Estructurar e implementar planes estratégicos, tácticos y operativos. Desarrollar proyectos empresariales. Realizar consultoría en el campo de la gestión empresarial. Emprender iniciativas empresariales emergentes. Gerenciar y administrar cualquier tipo de empresa, especialmente medianas o pequeñas. Gerenciar proyectos de cualquier tipo de organización. | J3: Empresas privadas o de economía mixta, existentes o emergentes, de cualquier sector de la economía. StarUps. Organizaciones no gubernamentales. Sector público. Ecosistemas de innovación y emprendimiento. | K3: El programa de Administración de Empresas del Politécnico Grancolombiano ofrece un enfoque distintivo en estrategia empresarial, articulando análisis, planeación y ejecución con el uso de herramientas para la toma de decisiones y la creación de valor sostenible. Forma profesionales capaces de liderar procesos de transformación en organizaciones que enfrentan entornos cambiantes, con visión económica, social y ambiental
E4: Planeación estratégica y gestión de procesos | F4: desarrollar estrategias empresariales | G4: contribuyendo a la generación de valor dentro entornos organizacionales cambiantes.
E5: Habilidades poderosas o socioemocionales | F5: liderar equipos y procesos con enfoque humano | G5: orientados a la adapatación y al desarrollo organizacional, según las dinámicas del entorno.
E6: Modelos de negocio | F6: impulsar iniciativas o proyectos de emprendimiento | G6: teniendo en cuenta las necesidades económicas, ambientales y sociales del entorno.
E7: Fenómenos contemporáneos | F7: reconocer sus afectaciones o contribuciones en el marco de las ciudadanías globales y de una sociedad responsable y sostenible. | G7: desde una perspectiva global, soportada en datos, con una mirada ética y crítica.

Sheet Paso 2 Redacción competen
A1: Elementos para redactar las competencias que desarrollará el programa
A2: [Enumerar las competencias que se van a declarar.] | B2: [A partir de la celda B2 dar clic sobre el ícono de lista desplegable y elegir el verbo que considere adecuado.] | C2: [A partir de la celda C2 dar clic sobre la lista desplegable y elegir el saber extraído del perfil de egreso.] | D2: [Escribir para qué se abordará el saber elegido. Se sugiere apoyarse en el saber hacer.] | E2: [Escribir la condición describiendo los referentes, parámetros, principios, requerimientos o retos que se necesitan para alcanzar las características del perfil en el contexto donde el egresado se desenvolverá.] | F2: [Articular los componentes. Iniciar con el verbo, continuar con el objeto conceptual, luego la finalidad y condición de contexto o referencia; estos últimos no requieren un orden particular.] | G2: [Escribir el tipo de competencia del perfil: Específica (si es del bloque Disciplinar para pregrado o de los componentes para el caso de posgrado) o Genérica (si aplica bloque institucional pregrado)]
A3: No. | B3: Verbo competencia | C3: Objeto conceptual | D3: Finalidad | E3: Condición de contexto o referencia | F3: Redacción competencia | G3: Tipo de competencia
A4: 1 | B4: Analizar | C4: Principios económicos y sociales, y normatividad empresarial | D4: tomar decisiones informadas | E4: considerando tanto criterios de sostenibilidad como la legislación vigente en contextos organizacionales y empresariales. | F4: Analizar los principios económicos y sociales, así como la normatividad empresarial, para tomar decisiones informadas, considerando tanto criterios de sostenibilidad como la legislación vigente en contextos organizacionales y empresariales. | G4: Específica
A5: 2 | B5: Gestionar | C5: Planeación estratégica y procesos funcionales | D5: desarrollar estrategias empresariales | E5: contribuyendo a la generación de valor dentro entornos organizacionales cambiantes. | F5: Gestiona procesos funcionales y de planeación estratégica para desarrollar estrategias empresariales, contribuyendo a la generación de valor dentro entornos organizacionales cambiantes. | G5: Específica
A6: 3 | B6: Aplicar | C6: Habilidades poderosas o socioemocionales | D6: liderar equipos y procesos con enfoque humano | E6: orientados a la adapatación y al desarrollo organizacional, según las dinámicas del entorno. | F6: Aplicar habilidades poderosas o socioemocionales para liderar equipos y procesos con enfoque humano, orientados a la adapatación y al desarrollo organizacional, según las dinámicas del entorno. | G6: Específica
A7: 4 | B7: Desarrollar | C7: Modelos de negocio | D7: impulsar iniciativas o proyectos de emprendimiento | E7: teniendo en cuenta las necesidades económicas, ambientales y sociales del entorno. | F7: Desarrolla modelos de negocio para impulsar iniciativas o proyectos de emprendimiento teniendo en cuenta las necesidades económicas, ambientales y sociales del entorno. | G7: Específica
A8: 5 | B8: Analizar | C8: Fenómenos contemporáneos | D8: reconocer sus afectaciones o contribuciones en el marco de las ciudadanías globales y de una sociedad responsable y sostenible. | E8: desde una perspectiva global, soportada en datos, con una mirada ética y crítica | F8: Analizar los fenómenos contemporáneos desde una perspectiva glocal, soportada en datos, con una mirada ética y crítica, para reconocer sus afectaciones o contribuciones en el marco de las ciudadanías globales y de una sociedad responsable y sostenible. | G8: Genérica

Sheet Paso 3 Redacción RA
A1: [A partir de la celda A2 dar clic en la lista desplegable y seleccionar la competencia redactada en el paso 2.] | B1: [Enumerar los resultados de aprendizaje que se van a declarar.] | C1: [A partir de la celda C2, dar clic en la lista desplegable y elegir el tipo de dominio a tratar en el resultado de aprendizaje.] | D1: [A partir de la cela D2, dar clic en la lista desplegable y elegir el saber correspondiente al dominio.] | E1: [A partir de la celda E2, dar clic en la lista desplegable y elegir la taxonomía que se considere adecuada, solo se elige una para todos los saberes.] | F1: [A partir de la celda F2, dar clic en la lista desplegable y elegir el dominio que se considera adecuado.] | G1: [A partir de la celda G2, dar clic en la lista desplegable y elegir el nivel del dominio que se considera adecuado.] | H1: [A partir de la celda H2, dar clic en la lista desplegable y elegir el verbo que se considera adecuado.] | I1: [Iniciar con el verbo elegido (columna H), en infinitivo, luego el objeto sobre el cual recae la acción (columna D) y finalmente la condición de contexto (académico, disciplinar, social u otro).]
A2: Competencia por desarrollar | B2: Número de resultado | C2: TipoSaber | D2: SaberAsociado | E2: Taxonomía | F2: Dominio Asociado | G2: Nivel Dominio | H2: Verbo RA | I2: Resultados Aprendizaje
A3: Analizar los principios económicos y sociales, así como la normatividad empresarial, para tomar decisiones informadas, considerando tanto criterios de sostenibilidad como la legislación vigente en contextos organizacionales y empresariales. | B3: 1 | C3: Saber | D3: Principios económicos y sociales, y normatividad empresarial | E3: BAK | F3: CognitivoBAK | G3: AnálisisBAK | H3: Analizar | I3: Analiza los principios económicos y sociales, así como la normatividad empresarial para determinar rutas estratégicas de acción y procesos asociados a la gestión, según el funcionamiento de los entornos internos y externos que operan en los contextos organizacionales.
A4: Analizar los principios económicos y sociales, así como la normatividad empresarial, para tomar decisiones informadas, considerando tanto criterios de sostenibilidad como la legislación vigente en contextos organizacionales y empresariales. | B4: 3 | C4: SaberHacer | D4: tomar decisiones informadas | E4: BAK | F4: ProcedimentalBAK | G4: ControlBAK | H4: Ejecutar | I4: Ejecuta acciones de gestión de equipos y procesos, para tomar decisiones informadas que promuevan el liderazgo colaborativo en escenarios organizacionales.
A5: Analizar los principios económicos y sociales, así como la normatividad empresarial, para tomar decisiones informadas, considerando tanto criterios de sostenibilidad como la legislación vigente en contextos organizacionales y empresariales. | B5: 4 | C5: SaberSer | D5: considerando tanto criterios de sostenibilidad como la legislación vigente en contextos organizacionales y empresariales. | E5: BAK | F5: ActitudinalBAK | G5: ValorarBAK | H5: Integrar | I5: Integra criterios económicos, sociales y jurídicos que apoyen la toma de decisiones, para contribuir a la generación de valor y al desarrollo organizacional, considerando principios de sostenibilidad, así como las dinámicas y necesidades del entorno.
A6: Gestiona procesos funcionales y de planeación estratégica para desarrollar estrategias empresariales, contribuyendo a la generación de valor dentro entornos organizacionales cambiantes. | B6: 1 | C6: Saber | D6: Planeación estratégica y gestión de procesos | E6: BAK | F6: CognitivoBAK | G6: AnálisisBAK | H6: Analizar | I6: Analiza los principios económicos y sociales, así como la normatividad empresarial para determinar rutas estratégicas de acción y procesos asociados a la gestión, según el funcionamiento de los entornos internos y externos que operan en los contextos organizacionales.
A7: Gestiona procesos funcionales y de planeación estratégica para desarrollar estrategias empresariales, contribuyendo a la generación de valor dentro entornos organizacionales cambiantes. | B7: 5 | C7: SaberHacer | D7: desarrollar estrategias empresariales | E7: BAK | F7: ProcedimentalBAK | G7: ControlBAK | H7: Diseñar | I7: Diseña estrategias empresariales para estructurar propuestas de mejora orientadas al fortalecimiento de la competitividad empresarial y al desarrollo de iniciativas de emprendimiento e intraemprendimiento.
A8: Gestiona procesos funcionales y de planeación estratégica para desarrollar estrategias empresariales, contribuyendo a la generación de valor dentro entornos organizacionales cambiantes. | B8: 4 | C8: SaberSer | D8: contribuyendo a la generación de valor dentro entornos organizacionales cambiantes. | E8: BAK | F8: ActitudinalBAK | G8: ValorarBAK | H8: Integrar | I8: Integra criterios económicos, sociales y jurídicos que apoyen la toma de decisiones, para contribuir a la generación de valor y al desarrollo organizacional, considerando principios de sostenibilidad, así como las dinámicas y necesidades del entorno.
A9: Aplicar habilidades poderosas o socioemocionales para liderar equipos y procesos con enfoque humano, orientados a la adapatación y al desarrollo organizacional, según las dinámicas del entorno. | B9: 6 | C9: Saber | D9: Habilidades poderosas o socioemocionales | E9: BAK | F9: CognitivoBAK | G9: AnálisisBAK | H9: Reconocer | I9: Reconoce las habilidades poderosas o socioemocionales que intervienen en escenarios organizacionales y en las relaciones humanas, para determinar aquellas que son pertinentes en el abordaje de situaciones propias de los distintos ámbitos de la gestión empresarial.
A10: Aplicar habilidades poderosas o socioemocionales para liderar equipos y procesos con enfoque humano, orientados a la adapatación y al desarrollo organizacional, según las dinámicas del entorno. | B10: 3 | C10: SaberHacer | D10: liderar equipos y procesos con enfoque humano | E10: BAK | F10: ProcedimentalBAK | G10: ControlBAK | H10: Ejecutar | I10: Ejecuta acciones de gestión de equipos y procesos, para tomar decisiones informadas que promuevan el liderazgo colaborativo en escenarios organizacionales.
A11: Aplicar habilidades poderosas o socioemocionales para liderar equipos y procesos con enfoque humano, orientados a la adapatación y al desarrollo organizacional, según las dinámicas del entorno. | B11: 4 | C11: SaberSer | D11: orientados a la adapatación y al desarrollo organizacional, según las dinámicas del entorno. | E11: BAK | F11: ActitudinalBAK | G11: ValorarBAK | H11: Integrar | I11: Integra criterios económicos, sociales y jurídicos que apoyen la toma de decisiones, para contribuir a la generación de valor y al desarrollo organizacional, considerando principios de sostenibilidad, así como las dinámicas y necesidades del entorno.
A12: Desarrolla modelos de negocio para impulsar iniciativas o proyectos de emprendimiento teniendo en cuenta las necesidades económicas, ambientales y sociales del entorno. | B12: 7 | C12: Saber | D12: Modelos de negocio | E12: BAK | F12: CognitivoBAK | G12: AnálisisBAK | H12: Reconocer | I12: Reconoce distintos modelos de negocio y de innovación aplicables tanto a intraemprendimientos como a nuevos negocios, para seleccionar el más adecuado en el diseño de propuestas empresariales sostenibles y coherentes con el entorno.
A13: Desarrolla modelos de negocio para impulsar iniciativas o proyectos de emprendimiento teniendo en cuenta las necesidades económicas, ambientales y sociales del entorno. | B13: 5 | C13: SaberHacer | D13: impulsar iniciativas o proyectos de emprendimiento | E13: BAK | F13: ProcedimentalBAK | G13: ControlBAK | H13: Diseñar | I13: Diseña estrategias empresariales para estructurar propuestas de mejora orientadas al fortalecimiento de la competitividad empresarial y al desarrollo de iniciativas de emprendimiento e intraemprendimiento.
A14: Desarrolla modelos de negocio para impulsar iniciativas o proyectos de emprendimiento teniendo en cuenta las necesidades económicas, ambientales y sociales del entorno. | B14: 4 | C14: SaberSer | D14: teniendo en cuenta las necesidades económicas, ambientales y sociales del entorno. | E14: BAK | F14: ActitudinalBAK | G14: ValorarBAK | H14: Integrar | I14: Integra criterios económicos, sociales y jurídicos que apoyen la toma de decisiones, para contribuir a la generación de valor y al desarrollo organizacional, considerando principios de sostenibilidad, así como las dinámicas y necesidades del entorno.
A15: Analizar los fenómenos contemporáneos desde una perspectiva glocal, soportada en datos, con una mirada ética y crítica, para reconocer sus afectaciones o contribuciones en el marco de las ciudadanías globales y de una sociedad responsable y sostenible. | B15: 2 | C15: Saber | D15: Fenómenos contemporáneos | E15: Bloom | F15: CognitivoB | G15: ComprensiónB | H15: Identificar | I15: Identifica fenómenos contemporáneos y su relación con la profesión, para determinar sus impactos e influencia en la sociedad, de forma responsable y crítica.

Sheet Paso 3 Redacción RA - Backup 
A1: [A partir de la celda A2 dar clic en la lista desplegable y seleccionar la competencia redactada en el paso 2.] | B1: [Enumerar los resultados de aprendizaje que se van a declarar.] | C1: [A partir de la celda C2, dar clic en la lista desplegable y elegir el tipo de dominio a tratar en el resultado de aprendizaje.] | D1: [A partir de la cela D2, dar clic en la lista desplegable y elegir el saber correspondiente al dominio.] | E1: [A partir de la celda E2, dar clic en la lista desplegable y elegir la taxonomía que se considere adecuada, solo se elige una para todos los saberes.] | F1: [A partir de la celda F2, dar clic en la lista desplegable y elegir el dominio que se considera adecuado.] | G1: [A partir de la celda G2, dar clic en la lista desplegable y elegir el nivel del dominio que se considera adecuado.] | H1: [A partir de la celda H2, dar clic en la lista desplegable y elegir el verbo que se considera adecuado.] | I1: [Iniciar con el verbo elegido (columna H), en infinitivo, luego el objeto sobre el cual recae la acción (columna D) y finalmente la condición de contexto (académico, disciplinar, social u otro).]
A2: Competencia por desarrollar | B2: Número de resultado | C2: TipoSaber | D2: SaberAsociado | E2: Taxonomía | F2: Dominio Asociado | G2: Nivel Dominio | H2: Verbo RA | I2: Resultados Aprendizaje
A3: Dominar los elementos de teoría de circuitos y transmisión de información para diseñar, implementar o administrar la infraestructura eléctrica y los dispositivos electrónicos que dan soporte a los sistemas de telecomunicaciones alineado con prácticas basadas en estándares del sector y la normatividad vigente, teniendo en cuenta las condiciones, restricciones y requerimientos técnicos del entorno. | B3: 1 | C3: Saber | D3: los elementos de teoría de circuitos y transmisión de información | E3: BAK | F3: CognitivoBAK | G3: ComprensiónBAK | H3: Identificar | I3: Identifica los elementos de teoría de circuitos, de transmisión de información, de seguridad de la información, de redes de comunicaciones, de sistemas de cómputo, de estandares y marcos de referencia que hacen parte de la gestión de proyectos como del desarrollo de actividades relacionadas a las infraestructuras de TIC, para explicar soluciones de diseño, administración o implementación a problemáticas del sector, desde un abordaje teórico-práctico, a través de herramientas de simulación, análisis de casos prácticos y uso de equipos de laboratorio.
A4: Dominar los elementos de teoría de circuitos y transmisión de información para diseñar, implementar o administrar la infraestructura eléctrica y los dispositivos electrónicos que dan soporte a los sistemas de telecomunicaciones alineado con prácticas basadas en estándares del sector y la normatividad vigente, teniendo en cuenta las condiciones, restricciones y requerimientos técnicos del entorno. | B4: 4 | C4: SaberHacer | D4: para diseñar, implementar o administrar la infraestructura eléctrica y los dispositivos electrónicos que dan soporte a los sistemas de telecomunicaciones | E4: BAK | F4: ProcedimentalBAK | G4: ManipulaciónBAK | H4: Aplicar | I4: Aplica los elementos de teoría de circuitos, de transmisión de información, de seguridad de la información, de redes de comunicaciones, de sistemas de cómputo, de estandares tecnológicos y marcos de referencia que hacen parte de la gestión de proyectos como del desarrollo de actividades relacionadas a las infraestructuras de TIC, para construir propuestas de diseño, implementación o administración de infraestructura eléctrica, dispositivos electrónicos, servicios de comunicaciones en nube o en sitio, sistemas de telecomunicaciones, a través de herramientas de simulación, análisis de casos prácticos y uso de equipos de laboratorio.
A5: Dominar los elementos de teoría de circuitos y transmisión de información para diseñar, implementar o administrar la infraestructura eléctrica y los dispositivos electrónicos que dan soporte a los sistemas de telecomunicaciones alineado con prácticas basadas en estándares del sector y la normatividad vigente, teniendo en cuenta las condiciones, restricciones y requerimientos técnicos del entorno. | B5: 7 | C5: SaberSer | D5: alineado con prácticas basadas en estándares del sector y la normatividad vigente, teniendo en cuenta las condiciones, restricciones y requerimientos técnicos del entorno. | E5: BAK | F5: ActitudinalBAK | G5: ValorarBAK | H5: Emplear | I5: Emplea las buenas prácticas de teoría de circuitos y transmisión, y de seguridad de la información, redes y sistemas de cómputo basadas en estándares del sector y la normatividad vigente, teniendo en cuenta las condiciones, restricciones y requerimientos técnicos de un proyecto, para formular soluciones en infraestructuras TIC o del área de las telecomunicaciones.
A6: Dominar los elementos de seguridad de la información, redes de comunicaciones y sistemas de cómputo que hacen parte de infraestructuras TIC para diseñar, implementar o administrar infraestructuras y servicios de comunicaciones en sitio o en nube alineado con prácticas basadas en estándares del sector y la normatividad vigente, teniendo en cuenta las condiciones, restricciones y requerimientos técnicos del entorno. | B6: 1 | C6: Saber | D6: los elementos de seguridad de la información, redes de comunicaciones y sistemas de cómputo que hacen parte de infraestructuras TIC | E6: BAK | F6: CognitivoBAK | G6: ComprensiónBAK | H6: Identificar | I6: Identifica los elementos de teoría de circuitos, de transmisión de información, de seguridad de la información, de redes de comunicaciones, de sistemas de cómputo, de estandares y marcos de referencia que hacen parte de la gestión de proyectos como del desarrollo de actividades relacionadas a las infraestructuras de TIC, para evaluar soluciones a problemáticas del sector, desde un abordaje teórico-práctico, a través de herramientas de simulación, análisis de casos prácticos y uso de equipos de laboratorio.
A7: Dominar los elementos de seguridad de la información, redes de comunicaciones y sistemas de cómputo que hacen parte de infraestructuras TIC para diseñar, implementar o administrar infraestructuras y servicios de comunicaciones en sitio o en nube alineado con prácticas basadas en estándares del sector y la normatividad vigente, teniendo en cuenta las condiciones, restricciones y requerimientos técnicos del entorno. | B7: 5 | C7: SaberHacer | D7: para diseñar, implementar o administrar infraestructuras y servicios de comunicaciones en sitio o en nube | E7: BAK | F7: ProcedimentalBAK | G7: ManipulaciónBAK | H7: Aplicar | I7: Aplica los elementos de teoría de circuitos, de transmisión de información, de seguridad de la información, de redes de comunicaciones, de sistemas de cómputo, de estandares tecnológicos y marcos de referencia que hacen parte de la gestión de proyectos como del desarrollo de actividades relacionadas a las infraestructuras de TIC, para construir propuestas de diseño, implementación o administración de infraestructura eléctrica, dispositivos electrónicos, servicios de comunicaciones en nube o en sitio, sistemas de telecomunicaciones, a través de herramientas de simulación, análisis de casos prácticos y uso de equipos de laboratorio.
A8: Dominar los elementos de seguridad de la información, redes de comunicaciones y sistemas de cómputo que hacen parte de infraestructuras TIC para diseñar, implementar o administrar infraestructuras y servicios de comunicaciones en sitio o en nube alineado con prácticas basadas en estándares del sector y la normatividad vigente, teniendo en cuenta las condiciones, restricciones y requerimientos técnicos del entorno. | B8: 7 | C8: SaberSer | D8: alineado con prácticas basadas en estándares del sector y la normatividad vigente, teniendo en cuenta las condiciones, restricciones y requerimientos técnicos del entorno. | E8: BAK | F8: ActitudinalBAK | G8: ValorarBAK | H8: Emplear | I8: Emplea las buenas prácticas de teoría de circuitos y transmisión, y de seguridad de la información, redes y sistemas de cómputo basadas en estándares del sector y la normatividad vigente, teniendo en cuenta las condiciones, restricciones y requerimientos técnicos de un proyecto, para formular soluciones en infraestructuras TIC o del área de las telecomunicaciones.
A9: Conocer los estándares y marcos de referencia asociados tanto a la gestión de proyectos como al desarrollo de actividades relacionadas a las tecnologías de la información para diseñar, implementar o administrar soluciones del área de las telecomunicaciones, la seguridad de la información y la infraestructura TIC manteniendo una postura socialmente responsable, autónoma, teniendo en cuenta las condiciones, restricciones y requerimientos técnicos del entorno. | B9: 2 | C9: Saber | D9: los estándares y marcos de referencia asociados tanto a la gestión de proyectos como al desarrollo de actividades relacionadas a las tecnologías de la información | E9: BAK | F9: CognitivoBAK | G9: ComprensiónBAK | H9: Identificar | I9: Identifica los elementos de teoría de circuitos, de transmisión de información, de seguridad de la información, de redes de comunicaciones, de sistemas de cómputo, de estandares y marcos de referencia que hacen parte de la gestión de proyectos como del desarrollo de actividades relacionadas a las infraestructuras de TIC, para evaluar soluciones a problemáticas del sector, desde un abordaje teórico-práctico, a través de herramientas de simulación, análisis de casos prácticos y uso de equipos de laboratorio.
A10: Conocer los estándares y marcos de referencia asociados tanto a la gestión de proyectos como al desarrollo de actividades relacionadas a las tecnologías de la información para diseñar, implementar o administrar soluciones del área de las telecomunicaciones, la seguridad de la información y la infraestructura TIC manteniendo una postura socialmente responsable, autónoma, teniendo en cuenta las condiciones, restricciones y requerimientos técnicos del entorno. | B10: 6 | C10: SaberHacer | D10: para diseñar, implementar o administrar soluciones del área de las telecomunicaciones, la seguridad de la información y la infraestructura TIC | E10: BAK | F10: ProcedimentalBAK | G10: ManipulaciónBAK | H10: Aplicar | I10: Aplica los elementos de teoría de circuitos, de transmisión de información, de seguridad de la información, de redes de comunicaciones, de sistemas de cómputo, de estandares tecnológicos y marcos de referencia que hacen parte de la gestión de proyectos como del desarrollo de actividades relacionadas a las infraestructuras de TIC, para construir propuestas de diseño, implementación o administración de infraestructura eléctrica, dispositivos electrónicos, servicios de comunicaciones en nube o en sitio, sistemas de telecomunicaciones, a través de herramientas de simulación, análisis de casos prácticos y uso de equipos de laboratorio.
A11: Conocer los estándares y marcos de referencia asociados tanto a la gestión de proyectos como al desarrollo de actividades relacionadas a las tecnologías de la información para diseñar, implementar o administrar soluciones del área de las telecomunicaciones, la seguridad de la información y la infraestructura TIC manteniendo una postura socialmente responsable, autónoma, teniendo en cuenta las condiciones, restricciones y requerimientos técnicos del entorno. | B11: 7 | C11: SaberSer | D11: manteniendo una postura socialmente responsable, autónoma, teniendo en cuenta las condiciones, restricciones y requerimientos técnicos del entorno. | E11: BAK | F11: ActitudinalBAK | G11: ValorarBAK | H11: Emplear | I11: Emplea las buenas prácticas de teoría de circuitos y transmisión, y de seguridad de la información, redes y sistemas de cómputo basadas en estándares del sector y la normatividad vigente, teniendo en cuenta las condiciones, restricciones y requerimientos técnicos de un proyecto, para formular soluciones en infraestructuras TIC o del área de las telecomunicaciones.
A12: Analizar los fenómenos contemporáneos desde una perspectiva glocal, soportada en datos, con una mirada ética y crítica, para reconocer sus afectaciones o contribuciones en el marco de las ciudadanías globales y de una sociedad responsable y sostenible. | B12: 3 | C12: Saber | D12: Fenómenos contemporáneos | E12: Bloom | F12: CognitivoB | G12: ComprensiónB | H12: Identificar | I12: Identifica fenómenos contemporáneos y su relación con la profesión, para determinar sus impactos e influencia en la sociedad, de forma responsable y crítica.

Sheet Paso 4 Estrategias mesocurricu
A1: [A partir de la celda A3 despliegue el(los) resultado(s) de aprendizaje y elegir aquel (aquellos) al(a los) que se contribuye desde la estrategia.] | B1: [Escribir el nombre de la estrategia a desarrollar. Participación de los estudiantes en cursos, talleres, seminarios, conferencias, pruebas estandarizadas, investigaciones, actividades o experiencias, cuerpos académicos, redes, comunidades, la elaboración de textos y materiales, así como las publicaciones, entre otros.] | C1: [Describir la(s) estrategia(s) definidas por el programa.] | D1: [Escribir los indicadores de impacto de la estrategia. Se sugieren indicadores como: Valora el nivel de contribución de la estrategia a los resultados de aprendizaje; Número de estudiantes que participan en la estrategia; Número de veces que se realiza la estrategia, entre otros.] | E1: [Escribir las acciones de retroalimentación que usará el programa para comunicar a los estudiantes sobre el alcance de sus resultados de aprendizaje.] | F1: [Escribir, para cada indicador con qué instrumento se recogerá información para evidenciar el (los) impacto (s) declarados. Encuesta, lista de asistencia, informe, entre otros.]
A2: Resultado de aprendizaje | B2: Estrategia del programa | C2: Descripción | D2: Indicador de Impacto de la Estrategia | E2: Acciones de retroalimentación para los estudiantes | F2: Instrumentos de medición
A3: Analiza los principios económicos y sociales, así como la normatividad empresarial para determinar rutas estratégicas de acción y procesos asociados a la gestión, según el funcionamiento de los entornos internos y externos que operan en los contextos organizacionales. | B3: Prueba estandandarizada (simulacro Pruebas Saber Pro) | C3: El proyecto ser pro es un proyecto en el cual la escuela de administracion y competitividad realiza actividades en cuatro frentes. El primero es la capacitacion de docentes en la elaboracion de preguntas por competencias, el segundo es la elaboracion de simulacros de presentacion de pruebas saber pro, en especial en el componente especifico de nucleo básico del conocimiento, el tercero son los talleres de refuerzo para que los estudiantes mejoren sus competencias en la presentacion de las pruebas de estado y por ultimo, en el cuarto frente se encuentra el desarrollo de concursos institucionales e interinstitucionales sustentados en la metodologia de preguntas saber pro. | D3: Número de veces que se realiza la estrategia por periodo académico. | E3: Informar sobre el desempeño alcanzado en los simulacros, destacando avances y brechas frente al promedio del programa. Formar en el uso de estrategias para resolver preguntas por competencias, enfocadas en los componentes de menor desempeño. | F3: Informe o Reporte.
A4: Integra criterios económicos, sociales y jurídicos que apoyen la toma de decisiones, para contribuir a la generación de valor y al desarrollo organizacional, considerando principios de sostenibilidad, así como las dinámicas y necesidades del entorno. | D4: Número de estudiantes que participan en la estrategia por periodo académico. | F4: Listados de participación.
A5: Reconoce las habilidades poderosas o socioemocionales que intervienen en escenarios organizacionales y en las relaciones humanas, para determinar aquellas que son pertinentes en el abordaje de situaciones propias de los distintos ámbitos de la gestión empresarial. | D5: Valoración del nivel de aporte de la estrategia a los resultados de aprendizaje del programa. | F5: Encuesta de valoración.
A6: Reconoce distintos modelos de negocio y de innovación aplicables tanto a intraemprendimientos como a nuevos negocios, para seleccionar el más adecuado en el diseño de propuestas empresariales sostenibles y coherentes con el entorno.
A7: Analiza los principios económicos y sociales, así como la normatividad empresarial para determinar rutas estratégicas de acción y procesos asociados a la gestión, según el funcionamiento de los entornos internos y externos que operan en los contextos organizacionales. | B7: Consultoría a empresas | C7: El proceso de consultoría estratégica inicia con la búsqueda de empresa por parte del estudiante, para esta empresa se genera un contrato de consultoría a costo cero y al final del proceso a la empresa se le entrega una propuesta estratégica, que se sugiere sea implementada en los años posteriores en la compañía. El proceso termina cuando la empresa entrega a la institución una carta de recibido a conformidad del plan estratégico propuesto. | D7: Número de estudiantes que participan en la estrategia por periodo académico. | E7: Formar en la aplicación rigurosa de herramientas diagnósticas y en la formulación de propuestas alineadas con las necesidades reales de la empresa. Ayudar a tomar decisiones sobre las estrategias que pueden ser priorizadas según el contexto empresarial identificado. | F7: Listados de participación.
A8: Ejecuta acciones de gestión de equipos y procesos, para tomar decisiones informadas que promuevan el liderazgo colaborativo en escenarios organizacionales. | D8: Número de veces que se realiza la estrategia por periodo académico. | F8: Informe o Reporte.
A9: Integra criterios económicos, sociales y jurídicos que apoyen la toma de decisiones, para contribuir a la generación de valor y al desarrollo organizacional, considerando principios de sostenibilidad, así como las dinámicas y necesidades del entorno. | D9: Valoración del nivel de aporte de la estrategia a los resultados de aprendizaje del programa. | F9: Encuesta de valoración.
A10: Diseña estrategias empresariales para estructurar propuestas de mejora orientadas al fortalecimiento de la competitividad empresarial y al desarrollo de iniciativas de emprendimiento e intraemprendimiento.
A11: Ejecuta acciones de gestión de equipos y procesos, para tomar decisiones informadas que promuevan el liderazgo colaborativo en escenarios organizacionales.
A12: Analiza los principios económicos y sociales, así como la normatividad empresarial para determinar rutas estratégicas de acción y procesos asociados a la gestión, según el funcionamiento de los entornos internos y externos que operan en los contextos organizacionales. | B12: Diagnóstico de habilidades gerenciales | C12: El desarrollo de habilidades gerenciales en los estudiantes del programa es fundamental, para ello desde el centro de liderazgo 360, este se aborda desde las ópticas del liderazgo personal, liderazgo organizacional y liderazgo social. En este sentido, los estudiantes desarrollan actividades y talleres que complementan las labores académicas del programa. | D12: Número de estudiantes que participan en la estrategia. | E12: Informar sobre el nivel de desarrollo de habilidades blandas evidenciado en las actividades realizadas. Formar en la identificación de estilos de liderazgo y su aplicación práctica según situaciones organizacionales. | F12: Listados de participación.
A13: Ejecuta acciones de gestión de equipos y procesos, para tomar decisiones informadas que promuevan el liderazgo colaborativo en escenarios organizacionales. | D13: Número de oportunidades de consultoría, auditoría e interventoría desarrolladas con medición semestral. | F13: Informe o Reporte.
A14: Integra criterios económicos, sociales y jurídicos que apoyen la toma de decisiones, para contribuir a la generación de valor y al desarrollo organizacional, considerando principios de sostenibilidad, así como las dinámicas y necesidades del entorno. | D14: Valoración del nivel de aporte de la estrategia a los resultados de aprendizaje del programa. | F14: Encuesta de valoración.
A15: Analiza los principios económicos y sociales, así como la normatividad empresarial para determinar rutas estratégicas de acción y procesos asociados a la gestión, según el funcionamiento de los entornos internos y externos que operan en los contextos organizacionales. | B15: Publicación de libros académicos (resultados de las investigaciones de los estudiantes) | C15: La convocatoria a publicación de libros académicos se realiza principalmente para los trabajos que surgen de la colaboracion estudiante-docente, de este modo, las publicaciones son conjuntas. El propósito de esta actividad es generar espacios que incentiven el desarrollo de competencias investigativas en los estudiantes del programa. | D15: Número de estudiantes que participan en la estrategia por periodo académico. | E15: Formar en prácticas de escritura académica, citación y construcción de argumentación sólida, así como en procesos de investigación. | F15: Listados de participación.
A16: Integra criterios económicos, sociales y jurídicos que apoyen la toma de decisiones, para contribuir a la generación de valor y al desarrollo organizacional, considerando principios de sostenibilidad, así como las dinámicas y necesidades del entorno. | D16: Relación de actividades desarrolladas en el grupo de interés con actividades del perfil ocupacional del programa. | F16: Informe o Reporte.
A17: Reconoce las habilidades poderosas o socioemocionales que intervienen en escenarios organizacionales y en las relaciones humanas, para determinar aquellas que son pertinentes en el abordaje de situaciones propias de los distintos ámbitos de la gestión empresarial. | D17: Valoración del nivel de aporte de la estrategia a los resultados de aprendizaje del programa. | F17: Encuesta de valoración.
A18: Reconoce distintos modelos de negocio y de innovación aplicables tanto a intraemprendimientos como a nuevos negocios, para seleccionar el más adecuado en el diseño de propuestas empresariales sostenibles y coherentes con el entorno.
A19: Analiza los principios económicos y sociales, así como la normatividad empresarial para determinar rutas estratégicas de acción y procesos asociados a la gestión, según el funcionamiento de los entornos internos y externos que operan en los contextos organizacionales. | B19: Coloquios y encuentros de investigación (investigación formativa) | C19: Existen dos eventos específicos desarrollados, uno es un evento de facultad denominado POLIPIF, en el cual participan los mejores proyectos de investigación formativa de la facultad y tambien participan estudiantes de otras universidades. En segundo lugar, se encuentra el Coloquio de Investigación en Diagnóstico Empresarial, el cual se enfoca en los resultados de investigación del campo de la consultoría empresarial. | D19: Número de estudiantes que participan en la estrategia por periodo académico. | E19: Formar en habilidades de comunicación científica y sustentación de proyectos ante audiencias académicas. Ayudar a tomar decisiones sobre cómo continuar el proceso investigativo o transformar el proyecto en otra producción académica. | F19: Listados de participación.
A20: Ejecuta acciones de gestión de equipos y procesos, para tomar decisiones informadas que promuevan el liderazgo colaborativo en escenarios organizacionales. | D20: Número de veces que se realiza la estrategia por periodo académico. | F20: Informe o Reporte.
A21: Integra criterios económicos, sociales y jurídicos que apoyen la toma de decisiones, para contribuir a la generación de valor y al desarrollo organizacional, considerando principios de sostenibilidad, así como las dinámicas y necesidades del entorno. | D21: Valoración del nivel de aporte de la estrategia a los resultados de aprendizaje del programa. | F21: Encuesta de valoración.
A22: Reconoce distintos modelos de negocio y de innovación aplicables tanto a intraemprendimientos como a nuevos negocios, para seleccionar el más adecuado en el diseño de propuestas empresariales sostenibles y coherentes con el entorno.
A23: Analiza los principios económicos y sociales, así como la normatividad empresarial para determinar rutas estratégicas de acción y procesos asociados a la gestión, según el funcionamiento de los entornos internos y externos que operan en los contextos organizacionales. | B23: Fomento al empredimiento | C23: El fomento al emprendimiento se desarrolla bajo el liderazgo del centro de emprendimiento adscrito a la Escuela de Administración y Competitividad. El centro de emprendimiento se descata principalmente por desarrollar actividades de formación, encuentros con emprendedores, concursos de emprendimiento y acompañamiento a emprendedores para hacer hacer realidad su idea de negocio. | D23: Número de estudiantes que participan en la estrategia en el periodo de su realización. | E23: Informar sobre los elementos clave que debe contener un modelo de negocio para ser competitivo. Ayudar a tomar decisiones sobre las acciones requeridas para avanzar o ajustar el desarrollo del proyecto emprendedor. | F23: Listas de participación.
A24: Ejecuta acciones de gestión de equipos y procesos, para tomar decisiones informadas que promuevan el liderazgo colaborativo en escenarios organizacionales. | D24: Número de veces que se realiza la estrategia por periodo académico. | F24: Informe o Reporte.
A25: Diseña estrategias empresariales para estructurar propuestas de mejora orientadas al fortalecimiento de la competitividad empresarial y al desarrollo de iniciativas de emprendimiento e intraemprendimiento. | D25: Valoración del nivel de aporte de la estrategia a los resultados de aprendizaje del programa. | F25: Encuesta de valoración.
A26: Reconoce las habilidades poderosas o socioemocionales que intervienen en escenarios organizacionales y en las relaciones humanas, para determinar aquellas que son pertinentes en el abordaje de situaciones propias de los distintos ámbitos de la gestión empresarial.
A27: Reconoce distintos modelos de negocio y de innovación aplicables tanto a intraemprendimientos como a nuevos negocios, para seleccionar el más adecuado en el diseño de propuestas empresariales sostenibles y coherentes con el entorno.

Sheet Paso 5 Estrategias micro
A1: [Estas celdas se diligencian automáticamente. No ajustar.] | B1: [A partir de la celda A3 despliegue el(los) resultado(s) de aprendizaje y elija aquel (aquellos) al(a los) que se contribuye desde la asignatura o módulo).] | C1: [Escribir el semestre en el que se cursa la asignatura o módulo.] | D1: [Escribir el nombre de la asignatura o módulo que contribuye al logro del resultado de aprendizaje.] | E1: [Redactar los indicadores iniciando con el verbo en presente indicativo, luego el objeto conceptual y finalmente el complemento de oración (que indique una condición o finalidad, con, para, de, entre otros conectores).] | F1: [Escribir la tipología: T (teórico), P (Práctico), TP (Teórico Práctico)] | G1: [Marcar con X el bloque o componente al que pertenece la asignatura o módulo. Por favor ajustar para posgrado, eliminar una columna y ubicar los títulos C.Fundamentación y C.Profundización.] | J1: [Escribir el número de créditos de la asignatura o módulo] | K1: [Escribir el número de horas de trabajo directo: 16*# o 12*#, para presencial o virtual, según sea el caso.] | L1: [Escribir el número de horas de trabajo independiente: 32*# columna J o 36*# columna J, para presencial o virtual, respectivamente.] | M1: [Escribir la suma de los números de horas de las dos celdas anteriores.] | N1: [Escribir el nombre de los cuatro núcleos temáticos que abordará la asignatura o el módulo.] | O1: [Escribir las lecturas, talleres, análisis, referentes, etc., que realiza el estudiante, clasificadas en trabajo directo e independiente.] | P1: [Escribir las actividades de evaluación que se emplean para identificar el alcance del (de los) indicador(es) de logro(s).] | Q1: [Escribir las acciones de retroalimentación que se emplearán en la asignatura o módulo, para retroalimentar a los estudiantes respecto al alcance de los indicadores de logro. Recordar que son cuatro acciones: informar, formar, prevenir y ayudar a tomar decisiones e indique cómo.]
A2: Tipo de Saber | B2: Resultado de aprendizaje | C2: Semestre | D2: Nombre asignatura o módulo | E2: Indicadores de logro asignatura o módulo | F2: Tipología | G2: B.Institucional | H2: B.Disciplinar | I2: B.Electivo | J2: Créditos | K2: Número de horas trabajo directo | L2: Número de horas trabajo independiente | M2: Total de horas | N2: Núcleos temáticos | O2: Actividades de aprendizaje | P2: Actividades de evaluación | Q2: Acciones de retroalimentación
A3: =_xlfn.XLOOKUP(B3,'Paso 3 Redacción RA'!I$3:I$15,'Paso 3 Redacción RA'!C$3:C$15,,0,1) -> Saber | B3: Identifica fenómenos contemporáneos y su relación con la profesión, para determinar sus impactos e influencia en la sociedad, de forma responsable y crítica. | C3: 1 | D3: Razonamiento Cuantitativo | E3: Analiza datos numéricos presentados en tablas, gráficos o textos para proponer soluciones informadas a situaciones problema del contexto. | F3: TP | G3: X | J3: 3 | K3: =16*J3 -> 48 | L3: =32*J3 -> 96 | M3: =SUM(K3:L3) -> 144 | N3: 1. Pensamiento numérico. Interpretación y representación de información numérica 2. Pensamiento algebraico. Desde la representación de regularidades y patrones 3. Pensamiento algebraico. Desde las relaciones de comparación entre cantidades o expresiones numéricas 4. Pensamiento geométrico. Propiedades, formas y relaciones espaciales | O3: Trabajo directo: Clase magistral activa Trabajo independiente: Lecturas Laboratorios, talleres, resolución de problemas | P3: Se sugiere emplear estrategias como las siguientes. Evaluación formativa: Preguntas intercaladas, presentaciones de situaciones problema. Evaluación sumativa: Valoración de laboratorios, talleres, estudios de casos y una evaluación final. | Q3: Informar oportunamente a través de la plataforma institucional y sesiones sincrónicas sobre el propósito, el proceso de realización, entrega de la actividad y criterios de evaluación. En las sesiones sincrónicas, atender las inquietudes y dar orientaciones al respecto, así como invitar a tomar asesorías ofrecidas por la Escuela de Ciencia Básicas, como estrategia de prevención y ayuda. Ayudar a tomar decisiones a través de preguntas orientadoras y actividades de refuerzo dentro del trabajo directo y autónomo. Retroalimentación por medio de rúbrica que indica el nivel de alcance del logro obtenido. Retroalimentación general del docente acorde a los resultados alcanzados por el grupo
A4: =_xlfn.XLOOKUP(B4,'Paso 3 Redacción RA'!I$3:I$15,'Paso 3 Redacción RA'!C$3:C$15,,0,1) -> Saber | B4: Identifica fenómenos contemporáneos y su relación con la profesión, para determinar sus impactos e influencia en la sociedad, de forma responsable y crítica. | C4: 1 | D4: Cultura, Política y Sociedad | E4: Reconoce las problemáticas, escenarios y mecanismos de participación ciudadana en el marco de sociedades de información y digitales para abordarlas desde iniciativas investigativas. Identifica los objetivos de desarrollo sostenible para la comprensión de problemáticas sociales, ambientales y culturales. Reflexiona los impactos de avances tecnológicos en su contexto profesional y ciudadano para el análisis de contextos situados. | F4: TP | G4: X | J4: 3 | K4: =16*J4 -> 48 | L4: =32*J4 -> 96 | M4: =SUM(K4:L4) -> 144 | N4: 1. ODS, problemas locales: una mirada a Colombia, territorio en búsqueda de la consolidación de la Paz. 2. Ciudadanía y su lugar: relaciones, dinámicas, construcción, expresión y mecanismos de participación. 3. Ecosistemas digitales: relaciones, dinámicas, construcción, expresión e impactos en el contexto profesional. 4. Narrativas y contenidos digitales: análisis de contextos situados. | O4: Trabajo directo: Clase magistral activa combinada con estrategias de aprendizaje basado en investigación Trabajo independiente: Lecturas Laboratorios Talleres Estudios de caso | P4: Evaluación formativa: Construcción de textos argumentativos sobre problemáticas en las sociedades de la información. ,elaboración de ejercicios para la citación en APA última edición., cartografías sociales de problemáticas sociales, culturales y ambientales., elaboración de árbol de problemas, construcción de objetivos generales y específicos, desarrollo de anteproyectos, talleres experienciales con juegos de roles, realización de exposición a través de la caja italiana para el manejo del espacio, la lectura y la oralidad, exposiciones creativas del PIF en el marco del evento “Feria de proyectos” Evaluación sumativa comprende los logros obtenidos en cada actividad y en todo el proceso, representados en porcentajes acumulativos según la parametrización de 0 a 5; Árbol de problemas, Exposiciones Creativas , Seguimiento , Entre Proyecto: Parte 1, Quiz , Seguimiento , Entre Proyecto: Parte 1I , Entrevista a expertos , Feria de proyectos , Seguimiento | Q4: Las acciones de retroalimentación giran en torno a las siguientes. Formar: donde se crean las condiciones para que los estudiantes adquieran conocimientos, habilidades, actitudes, aptitudes y destrezas. Además, debe promover su desarrollo integral y debe acompañarlos en las situaciones académicas que enfrenten durante el desarrollo de un módulo o una asignatura. Informar: para que los estudiantes identifiquen los cambios que pueden afectarlos directa o indirectamente tanto en el aula de clase como en otros espacios. Prevenir: con el fin de anticiparse a las situaciones académicas que pueden representar dificultad para los estudiantes. Esto se logra a través de la interacción individual con los estudiantes y del completo conocimiento del contexto educativo en que el tutor se desenvuelve. Ayudar a decidir: donde se orienta a los estudiantes para que tomen la mejor decisión ante una situación concreta. El objetivo es que el estudiante fortalezca su autonomía y la toma de decisiones responsable.
A5: =_xlfn.XLOOKUP(B5,'Paso 3 Redacción RA'!I$3:I$15,'Paso 3 Redacción RA'!C$3:C$15,,0,1) -> Saber | B5: Analiza los principios económicos y sociales, así como la normatividad empresarial para determinar rutas estratégicas de acción y procesos asociados a la gestión, según el funcionamiento de los entornos internos y externos que operan en los contextos organizacionales. | C5: 1 | D5: Derecho Comercial y Laboral | E5: Caracteriza los negocios jurídicos tanto en los actos de comercio como en las relaciones laborales en atención a la legislación vigente para crear modelos de empresas o contratos civiles, comerciales y laborales. | F5: TP | H5: X | J5: 3 | K5: =J5*16 -> 48 | L5: =32*J5 -> 96 | M5: =SUM(K5:L5) -> 144 | N5: 1. Acercamiento al derecho comercial 2. Costumbre mercantil 3. Historia, principios generales y fuentes del derecho laboral 4. Contrato de trabajo, jornada laboral, salario y prestaciones sociales | O5: Las estrategias pueden variar entre estas u otras: Trabajo directo: Clases magistrales Talleres / Laboratorios Soluciones numéricas Uso de herramientas computacionales Resolución de problemas Trabajo independiente: Lecturas Resolución de problemas Soluciones numéricas Uso de herramientas computacionales | P5: Se sugiere emplear estrategias como las siguientes. Formativa: Talleres Exposiciones Proyectos Sumativa: Trabajos escritos Pruebas conceptuales Examenes Exposiciones | Q5: Las acciones de retroalimentación giran en torno a las siguientes. Formar: donde se crean las condiciones para que los estudiantes adquieran conocimientos, habilidades, actitudes, aptitudes y destrezas. Además, debe promover su desarrollo integral y debe acompañarlos en las situaciones académicas que enfrenten durante el desarrollo de un módulo o una asignatura. Informar: para que los estudiantes identifiquen los cambios que pueden afectarlos directa o indirectamente tanto en el aula de clase como en otros espacios. Prevenir: con el fin de anticiparse a las situaciones académicas que pueden representar dificultad para los estudiantes. Esto se logra a través de la interacción individual con los estudiantes y del completo conocimiento del contexto educativo en que el tutor se desenvuelve. Ayudar a decidir: donde se orienta a los estudiantes para que tomen la mejor decisión ante una situación concreta. El objetivo es que el estudiante fortalezca su autonomía y la toma de decisiones responsable.
A6: =_xlfn.XLOOKUP(B6,'Paso 3 Redacción RA'!I$3:I$15,'Paso 3 Redacción RA'!C$3:C$15,,0,1) -> Saber | B6: Reconoce las habilidades poderosas o socioemocionales que intervienen en escenarios organizacionales y en las relaciones humanas, para determinar aquellas que son pertinentes en el abordaje de situaciones propias de los distintos ámbitos de la gestión empresarial.
A7: =_xlfn.XLOOKUP(B7,'Paso 3 Redacción RA'!I$3:I$15,'Paso 3 Redacción RA'!C$3:C$15,,0,1) -> SaberSer | B7: Integra criterios económicos, sociales y jurídicos que apoyen la toma de decisiones, para contribuir a la generación de valor y al desarrollo organizacional, considerando principios de sostenibilidad, así como las dinámicas y necesidades del entorno.
A8: =_xlfn.XLOOKUP(B8,'Paso 3 Redacción RA'!I$3:I$15,'Paso 3 Redacción RA'!C$3:C$15,,0,1) -> Saber | B8: Analiza los principios económicos y sociales, así como la normatividad empresarial para determinar rutas estratégicas de acción y procesos asociados a la gestión, según el funcionamiento de los entornos internos y externos que operan en los contextos organizacionales. | C8: 1 | D8: Contabilidad General | E8: Elabora el registro de las operaciones, conforme a la normatividad vigente y la técnica contable a partir del objeto social de una organización, teniendo en cuenta el marco conceptual de las normas internacionales de información financiera para elaborar los estados financieros. | F8: TP | H8: X | J8: 3 | K8: =J8*16 -> 48 | L8: =32*J8 -> 96 | M8: =SUM(K8:L8) -> 144 | N8: 1. Fundamentación teórica y técnica contable 2. Elementos de los Estados Financieros y sus características 3. Transacciones comerciales y operaciones con cuentas de resultado 4. Estructura de los Estados Financieros | O8: Las estrategias pueden variar entre estas u otras: Trabajo directo Clase magistral activa/Análisis o Estudio de casos/Resolución de problemas/Talleres prácticos Trabajo independiente Lecturas relacionadas o de materiales complementarios/Resolución de problemas/Ejercicios aplicados/Desarrollo de proyectos/Talleres grupales o individuales/Análisis o Estudio de casos/Elaboración de informes o documentos técnicos | P8: Las actividades varían entre las siguientes y otras que pueda considerar el profesor y funcionan como formativas o sumativas, según sea el caso. Estudio de casos Resolución de problemas Desarrollo de proyectos Talleres Exposiciones Pruebas escritas | Q8: Las acciones de retroalimentación giran en torno a las siguientes. Formar: donde se crean las condiciones para que los estudiantes adquieran conocimientos, habilidades, actitudes, aptitudes y destrezas. Además, debe promover su desarrollo integral y debe acompañarlos en las situaciones académicas que enfrenten durante el desarrollo de un módulo o una asignatura. Informar: para que los estudiantes identifiquen los cambios que pueden afectarlos directa o indirectamente tanto en el aula de clase como en otros espacios. Prevenir: con el fin de anticiparse a las situaciones académicas que pueden representar dificultad para los estudiantes. Esto se logra a través de la interacción individual con los estudiantes y del completo conocimiento del contexto educativo en que el tutor se desenvuelve. Ayudar a decidir: donde se orienta a los estudiantes para que tomen la mejor decisión ante una situación concreta. El objetivo es que el estudiante fortalezca su autonomía y la toma de decisiones responsable.
A9: =_xlfn.XLOOKUP(B9,'Paso 3 Redacción RA'!I$3:I$15,'Paso 3 Redacción RA'!C$3:C$15,,0,1) -> SaberHacer | B9: Diseña estrategias empresariales para estructurar propuestas de mejora orientadas al fortalecimiento de la competitividad empresarial y al desarrollo de iniciativas de emprendimiento e intraemprendimiento.
A10: =_xlfn.XLOOKUP(B10,'Paso 3 Redacción RA'!I$3:I$15,'Paso 3 Redacción RA'!C$3:C$15,,0,1) -> Saber | B10: Reconoce distintos modelos de negocio y de innovación aplicables tanto a intraemprendimientos como a nuevos negocios, para seleccionar el más adecuado en el diseño de propuestas empresariales sostenibles y coherentes con el entorno.
