Workbook
Name actitudinalB: Tabla5785[ActitudinalB]
Name actitudinalB: Tabla5785[ActitudinalB]
Name ActitudinalBAK: 'Taxonomias para RA'!$AC$3:$AG$3
Name AK: Tabla6088[AK]
Name AK: Tabla6088[AK]
Name AnálisisAK: Tabla99[AnálisisAK]
Name AnálisisAK: Tabla99[AnálisisAK]
Name AnálisisB: Tabla385280[AnálisisB]
Name AnálisisB: Tabla385280[AnálisisB]
Name AnálisisBAK: Tabla3865[AnálisisBAK]
Name AnálisisBAK: Tabla3865[AnálisisBAK]
Name AnalizarLK: Tabla2129[AnalizarLK]
Name AnalizarLK: Tabla2129[AnalizarLK]
Name AplicaciónB: Tabla375179[AplicaciónB]
Name AplicaciónB: Tabla375179[AplicaciónB]
Name AplicaciónBAK: Tabla3764[AplicaciónBAK]
Name AplicaciónBAK: Tabla3764[AplicaciónBAK]
Name AplicarLK: Tabla2028[AplicarLK]
Name AplicarLK: Tabla2028[AplicarLK]
Name áreasprofesionales: 'Paso1 Analisis perfil egreso'!$H$3:$H$14
Name áreasprofesionales: 'Paso1 Analisis perfil egreso'!$H$3:$H$14
Name BAK: Tabla5886[BAK]
Name BAK: Tabla5886[BAK]
Name Bloom: 'Taxonomias para RA'!$G$3:$I$3
Name CaracterizarBAK: Tabla4776[CaracterizarBAK]
Name CaracterizarBAK: Tabla4776[CaracterizarBAK]
Name Cognitivo: 'Paso1 Analisis perfil egreso'!$E$3:$E$15
Name Cognitivo: 'Paso1 Analisis perfil egreso'!$E$3:$E$15
Name cognitivoB: Tabla5583[CognitivoB]
Name cognitivoB: Tabla5583[CognitivoB]
Name CognitivoBAK: 'Taxonomias para RA'!$S$3:$X$3
Name competencias: 'Paso 2 Redacción competen'!$F$4:$F$13
Name ComponentesCompetencias: '[1]Paso1 Analisis perfil egreso'!$E$2:$G$2
Name ComprenderLK: 'Taxonomias para RA'!$AM$5:$AM$27
Name ComprensiónAK: Tabla98[ComprensiónAK]
Name ComprensiónAK: Tabla98[ComprensiónAK]
Name ComprensiónB: Tabla365078[ComprensiónB]
Name ComprensiónB: Tabla365078[ComprensiónB]
Name ComprensiónBAK: Tabla3663[ComprensiónBAK]
Name ComprensiónBAK: Tabla3663[ComprensiónBAK]
Name ConceptosLK: Tabla91[ConceptosLK]
Name ConceptosLK: Tabla91[ConceptosLK]
Name ConocimientoB: Tabla354977[ConocimientoB]
Name ConocimientoB: Tabla354977[ConocimientoB]
Name ConocimientoBAK: Tabla3555[ConocimientoBAK]
Name ConocimientoBAK: Tabla3555[ConocimientoBAK]
Name Conocimientos: 'Paso1 Analisis perfil egreso'!$E$3:$E$15
Name Conocimientos: 'Paso1 Analisis perfil egreso'!$E$3:$E$15
Name ControlBAK: Tabla4271[ControlBAK]
Name ControlBAK: Tabla4271[ControlBAK]
Name CrearLK: Tabla2333[CrearLK]
Name CrearLK: Tabla2333[CrearLK]
Name dominios: 'Paso1 Analisis perfil egreso'!$E$2:$G$2
Name EvaluaciónB: Tabla405482[EvaluaciónB]
Name EvaluaciónB: Tabla405482[EvaluaciónB]
Name EvaluaciónBAK: Tabla4067[EvaluaciónBAK]
Name EvaluaciónBAK: Tabla4067[EvaluaciónBAK]
Name EvaluarLK: 'Taxonomias para RA'!$AP$5:$AP$46
Name HechosLK: Tabla90[HechosLK]
Name HechosLK: Tabla90[HechosLK]

Sheet Paso1 Analisis perfil egreso
A1: [Escribir el nombre del programa] | B1: [Escribir la modalidad: presencial o virtual] | C1: [Escribir el perfil profesional del egresado.] | D1: [Escribir el perfil ocupacional del egresado.] | E1: Componentes fundamentales para definir competencias [Listar las palabras clave, no armar oraciones, respecto qué debe saber el egresado en las categorías de Saber -conocimientos, hechos, teorías-, Saber hacer -técnicas, procedimientos, metodologías-, y Saber ser -valores, condiciones. Esta información se estructura a partir del perfil profesional y cada saber hacer depende del saber ubicado a su izquierda, lo mismo ocurre con el saber ser.] | H1: Componentes fundamentales de la ocupación laboral del profesional [Listar, según lo escrito en el perfil ocupacional, en qué áreas, qué tareas potenciales y en qué poblaciones o contextos podrá laborar el profesional. Esta información es un listado general no requiere dependencia horizontal] | K1: Diferencial (valor agregado) del profesional [Listar, según lo escrito en los perfiles, los elementos que son diferenciales y generan un valor agregado al egresado. Debe ser disciplinar, asociado al perfil, ¿qué es lo que lo hace diferente a otros perfiles similares.]
A2: Programa | B2: Modalidad | C2: Perfil profesional | D2: Perfil ocupacional | E2: Saber | F2: Saberhacer | G2: Saberser | H2: ÁreasProfesionales | I2: TareasProfesionales | J2: PoblacionesActuacion | K2: ValorAgregado
A3: Contaduría Pública | B3: Virtual | C3: El profesional en Contaduría Pública del Politécnico Grancolombiano conoce los principios contables, las normas tributarias, los estándares internacionales de información financiera, los procedimientos de auditoría y los sistemas de control interno. Con este saber, analiza la información contable, gestiona obligaciones fiscales, ejecuta auditorías y evalúa la calidad y consistencia técnica de la información financiera de personas naturales, jurídicas y organizaciones, con el propósito de garantizar el cumplimiento normativo y dar soporte a la toma de decisiones informadas. Ejerce su rol con responsabilidad frente a la fe pública y con una perspectiva contable orientada a contextos nacionales e internacionales en distintos entornos organizacionales. | D3: El profesional en Contaduría Pública del Politécnico Grancolombiano analiza y valida la información contable de las organizaciones, asegurando su conformidad con los principios contables nacionales e internacionales, y ejerciendo su rol como garante de la fe pública sobre la calidad y legalidad de los registros contables. Asesora a los usuarios de la información contable y financiera mediante la interpretación de datos, el análisis de riesgos y la verificación de la coherencia técnica y normativa de la información contable que sustenta los estados financieros. Gestiona las obligaciones fiscales de personas naturales, jurídicas u organizaciones en cumplimiento de la normatividad tributaria vigente, y ejecuta auditorías aplicando técnicas y procedimientos especializados para evaluar la fiabilidad de la información contable y el cumplimiento de disposiciones regulatorias. Utiliza herramientas tecnológicas y métodos cuantitativos para generar análisis que respalden procesos de aseguramiento, control y proyección financiera en diversos contextos organizacionales. | E3: Normas contables, financieras y procedimientos de registro | F3: sustentar técnicamente los estados financieros y respaldar su conformidad legal | G3: con responsabilidad frente a la fe pública y compromiso con la transparencia. | H3: Área de Contabilidad o Dirección Financiera/Gerencia de Contabilidad / Subdirección Financiera/Dirección Financiera / Planeación Financiera y Control/Dirección de Contabilidad / Finanzas Corporativas/Unidad de Registro Financiero/ Direcció u Oficina de Control Interno / Auditoría Gubernamental/ Gerencia General / Consultoría/Departamento Tributario /Consultoría Fiscal /Departamento de Cumplimiento / Riesgo Operativo/Auditoría Interna Cumplimiento y Riesgos/Oficina de Revisoría Fiscal / Junta Directiva/Firmas de Auditoría Externa / Contratista Independiente | I3: Preparar y analizar estados financieros (balance, estado de resultados, flujos de efectivo)/Gestionar registros contables, conciliaciones y ciclos contables/Supervisar procesos de cierre contable, presupuestación, proyecciones financieras y control de flujo de efectivo/Coordinar auditorías internas y externas/Registrar, ordenar y respaldar transacciones financieras/Gestionar requerimientos y plazos, aplicando procedimientos establecidos de control interno/Organizar y mantener actualizada la información financiera/Analizar informes financieros para evaluar el rendimiento y rentabilidad organizacional/Realizar proyecciones y evaluaciones de inversiones, identificando oportunidades de mejora/Elaborar recomendaciones estratégicas para optimizar recursos y maximizar resultados financieros/Gestionar obligaciones fiscales, preparar declaraciones de impuestos y cumplir con normativas tributarias vigentes/Optimizar cargas fiscales mediante planificación y aprovechamiento de incentivos legales/Evaluar sistemas de control interno y riesgo operativo, proponiendo mejoras sistemáticas/Aplicar análisis detallados para sustentar evidencias legales y formular recomendaciones de control/Investigar irregularidades contables, fraudes o incumplimientos mediante técnicas de auditoría forense/Verificar el cumplimiento legal y fiduciario de la información financiera/Emitir dictámenes independientes sobre la integridad y veracidad de los estados contables. | J3: Micro, pequeñas, medianas y grandes empresas de todos los sectores económicos (comercial, industrial, financiero, agroindustrial, servicios, etc.)/Alcaldías, gobernaciones, ministerios, superintendencias, entidades descentralizadas/Empresas especializadas en servicios contables, fiscales, financieros y de aseguramiento de la información/Empresas multinacionales y grupos empresariales/Organizaciones no gubernamentales (ONG) y fundaciones/Personas naturales y pequeños contribuyentes/Empresas del sector solidario y cooperativo/Organismos de control | K3: El egresado del programa de Contaduría Pública del Politécnico Grancolombiano articula la formación contable, financiera, tributaria y de aseguramiento con el uso de tecnologías y la analítica de datos para fortalecer procesos integrales en la adecuada gestión de las organizaciones. Su formación en control, auditoría forense, gestión de riesgos y cumplimiento normativo orienta su ejercicio profesional hacia la toma de decisiones basada en información confiable.
E4: Normativa tributaria y procedimientos fiscales | F4: gestionar el cumplimiento tributario en distintos tipos de contribuyentes | G4: con rigurosidad técnica y sentido ético.
E5: Auditoría, aseguramiento y control de la información | F5: verificar la confiabilidad técnica de la información financiera y su alineación con las disposiciones regulatorias | G5: con criterio profesional y enfoque en la consistencia normativa.
E6: Herramientas tecnológicas, métodos cuantitativos y análisis financiero | F6: preparar informes contables y estados financieros de personas naturales, jurídicas u organizaciones, | G6: que sirvan de base en la toma de decisiones, con visión estratégica y adaptación a entornos globales.
E7: Fenómenos contemporáneos | F7: reconocer sus afectaciones o contribuciones en el marco de las ciudadanías globales y de una sociedad responsable y sostenible. | G7: desde una perspectiva glocal, soportada en datos, con una mirada ética y crítica

Sheet Paso 2 Redacción competen
A1: Elementos para redactar las competencias que desarrollará el programa
A2: [Enumerar las competencias que se van a declarar.] | B2: [A partir de la celda B2 dar clic sobre el ícono de lista desplegable y elegir el verbo que considere adecuado.] | C2: [A partir de la celda C2 dar clic sobre la lista desplegable y elegir el saber extraído del perfil de egreso.] | D2: [Escribir para qué se abordará el saber elegido. Se sugiere apoyarse en el saber hacer.] | E2: [Escribir la condición describiendo los referentes, parámetros, principios, requerimientos o retos que se necesitan para alcanzar las características del perfil en el contexto donde el egresado se desenvolverá.] | F2: [Articular los componentes. Iniciar con el verbo, continuar con el objeto conceptual, luego la finalidad y condición de contexto o referencia; estos últimos no requieren un orden particular.] | G2: [Escribir el tipo de competencia del perfil: Específica (si es del bloque Disciplinar para pregrado o de los componentes para el caso de posgrado) o Genérica (si aplica bloque institucional pregrado)]
A3: No. | B3: Verbo competencia | C3: Objeto conceptual | D3: Finalidad | E3: Condición de contexto o referencia | F3: Redacción competencia | G3: Tipo competencia
A4: 1 | B4: Validar | C4: Normas contables, financieras y procedimientos de registro | D4: sustentar técnicamente los estados financieros y respaldar su conformidad legal | E4: con responsabilidad frente a la fe pública y compromiso con la transparencia. | F4: Validar la información contable y financiera con base en normas contables, financieras y procedimientos de registro para sustentar técnicamente los estados financieros y respaldar su conformidad legal, con responsabilidad frente a la fe pública y compromiso con la transparencia. | G4: Específica
A5: 2 | B5: Dominar | C5: Normativa tributaria y procedimientos fiscales | D5: gestionar el cumplimiento tributario en distintos tipos de contribuyentes | E5: con rigurosidad técnica, sentido ético y adaptación a entornos globales. | F5: Dominar la normativa tributaria y los procedimientos fiscales para gestionar el cumplimiento de las obligaciones tributarias en distintos tipos de contribuyentes, con rigurosidad técnica, sentido ético y adaptación a entornos globales. | G5: Específica
A6: 3 | B6: Desarrollar | C6: Auditoría, aseguramiento y control de la información | D6: verificar la confiabilidad técnica de la información financiera y su alineación con las disposiciones regulatorias | E6: con criterio profesional y enfoque en la consistencia normativa. | F6: Desarrollar procesos de auditoría, aseguramiento y control de la información para verificar la confiabilidad técnica de la información financiera y su alineación con las disposiciones regulatorias, con criterio profesional y enfoque en la consistencia normativa. | G6: Específica
A7: 4 | B7: Aplicar | C7: Herramientas tecnológicas, métodos cuantitativos y análisis financiero | D7: preparar informes contables y estados financieros de personas naturales, jurídicas u organizaciones, | E7: que sirvan de base en la toma de decisiones, con visión estratégica . | F7: Aplicar herramientas tecnológicas, métodos cuantitativos y análisis financiero para preparar informes contables y estados financieros de personas naturales, jurídicas u organizaciones que sirvan de base en la toma de decisiones, con visión estratégica. | G7: Específica
A8: 5 | B8: Analizar | C8: Fenómenos contemporáneos | D8: reconocer sus afectaciones o contribuciones en el marco de las ciudadanías globales y de una sociedad responsable y sostenible. | E8: desde una perspectiva glocal, soportada en datos, con una mirada ética y crítica | F8: Analizar los fenómenos contemporáneos desde una perspectiva glocal, soportada en datos, con una mirada ética y crítica, para reconocer sus afectaciones o contribuciones en el marco de las ciudadanías globales y de una sociedad responsable y sostenible. | G8: Genérica

Sheet Paso 3 Redacción RA 
A1: [A partir de la celda A2 dar clic en la lista desplegable y seleccionar la competencia redactada en el paso 2.] | B1: [Enumerar los resultados de aprendizaje que se van a declarar.] | C1: [A partir de la celda C2, dar clic en la lista desplegable y elegir el tipo de dominio a tratar en el resultado de aprendizaje.] | D1: [A partir de la cela D2, dar clic en la lista desplegable y elegir el saber correspondiente al dominio.] | E1: [A partir de la celda E2, dar clic en la lista desplegable y elegir la taxonomía que se considere adecuada, solo se elige una para todos los saberes.] | F1: [A partir de la celda F2, dar clic en la lista desplegable y elegir el dominio que se considera adecuado.] | G1: [A partir de la celda G2, dar clic en la lista desplegable y elegir el nivel del dominio que se considera adecuado.] | H1: [A partir de la celda H2, dar clic en la lista desplegable y elegir el verbo que se considera adecuado.] | I1: [Iniciar con el verbo elegido (columna H), en infinitivo, luego el objeto sobre el cual recae la acción (columna D) y finalmente la condición de contexto (académico, disciplinar, social u otro).]
A2: Competencia por desarrollar | B2: Número de resultado | C2: TipoSaber | D2: SaberAsociado | E2: Taxonomía | F2: Dominio Asociado | G2: Nivel Dominio | H2: Verbo RA | I2: Resultados Aprendizaje
A3: Dominar la normativa tributaria y los procedimientos fiscales para gestionar el cumplimiento de las obligaciones tributarias en distintos tipos de contribuyentes, con rigurosidad técnica, sentido ético y adaptación a entornos globales. | B3: 1 | C3: Saber | D3: Normativa tributaria y procedimientos fiscales | E3: Bloom | F3: CognitivoB | G3: AnálisisB | H3: Analizar | I3: Analiza la normativa vigentes en la preparación y revisión de información contable, financiera y tributaria para identificar criterios técnicos y legales que permitan abordar situaciones contables y fiscales, según el contexto de aplicación.
A4: Dominar la normativa tributaria y los procedimientos fiscales para gestionar el cumplimiento de las obligaciones tributarias en distintos tipos de contribuyentes, con rigurosidad técnica, sentido ético y adaptación a entornos globales. | B4: 5 | C4: Saberhacer | D4: gestionar el cumplimiento tributario en distintos tipos de contribuyentes | E4: Bloom | F4: ProcedimentalB | G4: AnálisisB | H4: Desarrollar | I4: Desarrolla procedimientos contables y tributarios para construir estados financieros conforme a la normativa aplicable, integrando el cumplimiento de obligaciones fiscales de personas naturales y jurídicas.
A5: Dominar la normativa tributaria y los procedimientos fiscales para gestionar el cumplimiento de las obligaciones tributarias en distintos tipos de contribuyentes, con rigurosidad técnica, sentido ético y adaptación a entornos globales. | B5: 8 | C5: Saberser | D5: con rigurosidad técnica y sentido ético. | E5: Bloom | F5: ActitudinalB | G5: AnálisisB | H5: Reconocer | I5: Reconoce criterios éticos, legales, sociales y estratégicos del saber contable, tributario, financiero y de auditoría para aplicarlos con rigor técnico en la preparación de información de personas naturales y jurídicas, según el contexto o situación.
A6: Validar la información contable y financiera con base en normas contables, financieras y procedimientos de registro para sustentar técnicamente los estados financieros y respaldar su conformidad legal, con responsabilidad frente a la fe pública y compromiso con la transparencia. | B6: 1 | C6: Saber | D6: Normas contables, financieras y procedimientos de registro | E6: Bloom | F6: CognitivoB | G6: AnálisisB | H6: Analizar | I6: Analiza la normativa vigentes en la preparación y revisión de información contable, financiera y tributaria para identificar criterios técnicos y legales que permitan abordar situaciones contables y fiscales, según el contexto de aplicación.
A7: Validar la información contable y financiera con base en normas contables, financieras y procedimientos de registro para sustentar técnicamente los estados financieros y respaldar su conformidad legal, con responsabilidad frente a la fe pública y compromiso con la transparencia. | B7: 5 | C7: Saberhacer | D7: sustentar técnicamente los estados financieros y respaldar su conformidad legal | E7: Bloom | F7: ProcedimentalB | G7: AnálisisB | H7: Desarrollar | I7: Desarrolla procedimientos contables y tributarios para construir estados financieros conforme a la normativa aplicable, integrando el cumplimiento de obligaciones fiscales de personas naturales y jurídicas.
A8: Validar la información contable y financiera con base en normas contables, financieras y procedimientos de registro para sustentar técnicamente los estados financieros y respaldar su conformidad legal, con responsabilidad frente a la fe pública y compromiso con la transparencia. | B8: 8 | C8: Saberser | D8: con responsabilidad frente a la fe pública y compromiso con la transparencia. | E8: Bloom | F8: ActitudinalB | G8: AnálisisB | H8: Reconocer | I8: Reconoce criterios éticos, legales, sociales y estratégicos del saber contable, tributario, financiero y de auditoría para aplicarlos con rigor técnico en la preparación de información de personas naturales y jurídicas, según el contexto o situación.
A9: Desarrollar procesos de auditoría, aseguramiento y control de la información para verificar la confiabilidad técnica de la información financiera y su alineación con las disposiciones regulatorias, con criterio profesional y enfoque en la consistencia normativa. | B9: 2 | C9: Saber | D9: Auditoría, aseguramiento y control de la información | E9: Bloom | F9: CognitivoB | G9: ComprensiónB | H9: Interpretar | I9: Interpreta la información contable, financiera y tributaria en contextos de aseguramiento y control para establecer su pertinencia y confiabilidad en la resolución de situaciones contables organizacionales.
A10: Desarrollar procesos de auditoría, aseguramiento y control de la información para verificar la confiabilidad técnica de la información financiera y su alineación con las disposiciones regulatorias, con criterio profesional y enfoque en la consistencia normativa. | B10: 6 | C10: Saberhacer | D10: verificar la confiabilidad técnica de la información financiera y su alineación con las disposiciones regulatorias | E10: Bloom | F10: ProcedimentalB | G10: AplicaciónB | H10: Utilizar | I10: Utiliza información contable, financiera, tributaria y de auditoría para elaborar reportes, y proyecciones que faciliten la toma de decisiones de distintos tipos de usuarios, considerando sus necesidades y características.
A11: Desarrollar procesos de auditoría, aseguramiento y control de la información para verificar la confiabilidad técnica de la información financiera y su alineación con las disposiciones regulatorias, con criterio profesional y enfoque en la consistencia normativa. | B11: 8 | C11: Saberser | D11: con criterio profesional y enfoque en la consistencia normativa. | E11: Bloom | F11: ActitudinalB | G11: AnálisisB | H11: Reconocer | I11: Reconoce criterios éticos, legales, sociales y estratégicos del saber contable, tributario, financiero y de auditoría para aplicarlos con rigor técnico en la preparación de información de personas naturales y jurídicas, según el contexto o situación.
A12: Aplicar herramientas tecnológicas, métodos cuantitativos y análisis financiero para preparar informes contables y estados financieros de personas naturales, jurídicas u organizaciones que sirvan de base en la toma de decisiones, con visión estratégica. | B12: 3 | C12: Saber | D12: Herramientas tecnológicas, métodos cuantitativos y análisis financiero | E12: Bloom | F12: CognitivoB | G12: ComprensiónB | H12: Relacionar | I12: Relaciona métodos cuantitativos y modelos de planeación financiera para explicar dinámicas contables y financieras según el contexto analizado, usando herramientas tecnológicas.
A13: Aplicar herramientas tecnológicas, métodos cuantitativos y análisis financiero para preparar informes contables y estados financieros de personas naturales, jurídicas u organizaciones que sirvan de base en la toma de decisiones, con visión estratégica. | B13: 7 | C13: Saberhacer | D13: preparar informes contables y estados financieros de personas naturales, jurídicas u organizaciones, | E13: Bloom | F13: ProcedimentalB | G13: AplicaciónB | H13: Utilizar | I13: Utiliza métodos cuantitativos y herramientas tecnológicas para elaborar reportes sobre la situación contable y financiera de personas naturales, personas jurídicas y organizaciones, a partir de datos y contextos definidos.
A14: Aplicar herramientas tecnológicas, métodos cuantitativos y análisis financiero para preparar informes contables y estados financieros de personas naturales, jurídicas u organizaciones que sirvan de base en la toma de decisiones, con visión estratégica. | B14: 8 | C14: Saberser | D14: que sirvan de base en la toma de decisiones, con visión estratégica y adaptación a entornos globales. | E14: Bloom | F14: ActitudinalB | G14: AnálisisB | H14: Reconocer | I14: Reconoce criterios éticos, legales, sociales y estratégicos del saber contable, tributario, financiero y de auditoría para aplicarlos con rigor técnico en la preparación de información de personas naturales y jurídicas, según el contexto o situación.
A15: Analizar los fenómenos contemporáneos desde una perspectiva glocal, soportada en datos, con una mirada ética y crítica, para reconocer sus afectaciones o contribuciones en el marco de las ciudadanías globales y de una sociedad responsable y sostenible. | B15: 4 | C15: Saber | D15: Fenómenos contemporáneos | E15: Bloom | F15: CognitivoB | G15: ComprensiónB | H15: Identificar | I15: Identifica fenómenos contemporáneos y su relación con la profesión, para determinar sus impactos e influencia en la sociedad, de forma responsable y crítica.

Sheet Paso 4 Estrategias mesocurricu
A1: [A partir de la celda A3 despliegue el(los) resultado(s) de aprendizaje y elegir aquel (aquellos) al(a los) que se contribuye desde la estrategia.] | B1: [Escribir el nombre de la estrategia a desarrollar. Participación de los estudiantes en cursos, talleres, seminarios, conferencias, pruebas estandarizadas, investigaciones, actividades o experiencias, cuerpos académicos, redes, comunidades, la elaboración de textos y materiales, así como las publicaciones, entre otros.] | C1: [Describir la(s) estrategia(s) definidas por el programa.] | D1: [Escribir los indicadores de impacto de la estrategia. Se sugieren indicadores como: Valora el nivel de contribución de la estrategia a los resultados de aprendizaje; Número de estudiantes que participan en la estrategia; Número de veces que se realiza la estrategia, entre otros.] | E1: [Escribir las acciones de retroalimentación que usará el programa para comunicar a los estudiantes sobre el alcance de sus resultados de aprendizaje.] | F1: [Escribir, para cada indicador con qué instrumento se recogerá información para evidenciar el (los) impacto (s) declarados. Encuesta, lista de asistencia, informe, entre otros.]
A2: Resultado de aprendizaje | B2: Estrategia del programa | C2: Descripción | D2: Indicador de Impacto de la Estrategia | E2: Acciones de retroalimentación para los estudiantes | F2: Instrumentos de medición
A3: Analiza la normativa vigentes en la preparación y revisión de información contable, financiera y tributaria para identificar criterios técnicos y legales que permitan abordar situaciones contables y fiscales, según el contexto de aplicación. | B3: Congresos, conversatorios, capacitaciones seminarios y workshoop | C3: Estrategia que promueve la participación activa de la comunidad académica en eventos nacionales e internacionales que fortalecen el conocimiento disciplinar, fomentan el pensamiento crítico y permiten el intercambio de experiencias académicas y profesionales. | D3: Número de veces que se realiza la estrategia por periodo académico. | E3: Formar: para ampliar los saberes disciplinares, fortaleciendo conocimientos técnicos, habilidades comunicativas y pensamiento crítico. Informar: para mantener a la comunidad académica actualizada sobre avances normativos, tecnológicos y tendencias del entorno profesional. Ayudar a decidir: a través de la exposición a diversos enfoques y experiencias que permiten perfilar intereses académicos y profesionales. | F3: Informe o Reporte.
A4: Interpreta la información contable, financiera y tributaria en contextos de aseguramiento y control para establecer su pertinencia y confiabilidad en la resolución de situaciones contables organizacionales. | D4: Número de estudiantes que participan en la estrategia por periodo académico. | F4: Listados de participación.
A5: Relaciona métodos cuantitativos y modelos de planeación financiera para explicar dinámicas contables y financieras según el contexto analizado, usando herramientas tecnológicas. | D5: Valoración del nivel de aporte de la estrategia a los resultados de aprendizaje del programa. | F5: Encuesta de valoración.
A6: Reconoce criterios éticos, legales, sociales y estratégicos del saber contable, tributario, financiero y de auditoría para aplicarlos con rigor técnico en la preparación de información de personas naturales y jurídicas, según el contexto o situación.
A7: Analiza la normativa vigentes en la preparación y revisión de información contable, financiera y tributaria para identificar criterios técnicos y legales que permitan abordar situaciones contables y fiscales, según el contexto de aplicación. | B7: Semilleros de investigación | C7: Espacios extracurriculares orientados al aprendizaje colectivo, donde estudiantes y docentes desarrollan procesos investigativos que permiten profundizar en temas clave del saber contable, tributario, financiero y de aseguramiento. | D7: Número de estudiantes que participan en la estrategia por periodo académico. | E7: Formar: para fortalecer habilidades investigativas, el trabajo colaborativo y el pensamiento analítico. Prevenir: a través de la profundización temática que permite anticipar vacíos de conocimiento o dificultades académicas. Ayudar a decidir: para orientar la elección de líneas de investigación, temas de trabajo de grado o proyección académica. | F7: Listados de participación.
A8: Interpreta la información contable, financiera y tributaria en contextos de aseguramiento y control para establecer su pertinencia y confiabilidad en la resolución de situaciones contables organizacionales. | D8: Número de veces que se realiza la estrategia por periodo académico. | F8: Informe o Reporte.
A9: Relaciona métodos cuantitativos y modelos de planeación financiera para explicar dinámicas contables y financieras según el contexto analizado, usando herramientas tecnológicas. | D9: Valoración del nivel de aporte de la estrategia a los resultados de aprendizaje del programa. | F9: Encuesta de valoración.
A10: Desarrolla procedimientos contables y tributarios para construir estados financieros conforme a la normativa aplicable, integrando el cumplimiento de obligaciones fiscales de personas naturales y jurídicas.
A11: Reconoce criterios éticos, legales, sociales y estratégicos del saber contable, tributario, financiero y de auditoría para aplicarlos con rigor técnico en la preparación de información de personas naturales y jurídicas, según el contexto o situación.
A12: Analiza la normativa vigentes en la preparación y revisión de información contable, financiera y tributaria para identificar criterios técnicos y legales que permitan abordar situaciones contables y fiscales, según el contexto de aplicación. | B12: Consultorio tributario | C12: Servicio de consultoría presencial y virtual liderado por estudiantes y profesionales expertos, que brinda orientación gratuita en temas tributarios y empresariales a diferentes poblaciones, como parte de la proyección social de la Facultad de Negocios, Gestión y Sostenibilidad. | D12: Número de estudiantes que participan en la estrategia. | E12: Formar: a través de la aplicación práctica del saber contable y tributario en contextos reales. Informar: para evidenciar la normativa vigente y su aplicación en escenarios empresariales y sociales. Ayudar a decidir: mediante el análisis de casos reales que aportan elementos éticos y técnicos en la toma de decisiones. | F12: Listados de participación.
A13: Desarrolla procedimientos contables y tributarios para construir estados financieros conforme a la normativa aplicable, integrando el cumplimiento de obligaciones fiscales de personas naturales y jurídicas. | D13: Número de oportunidades de consultoría, auditoría e interventoría desarrolladas con medición semestral. | F13: Informe o Reporte.
A14: Reconoce criterios éticos, legales, sociales y estratégicos del saber contable, tributario, financiero y de auditoría para aplicarlos con rigor técnico en la preparación de información de personas naturales y jurídicas, según el contexto o situación. | D14: Valoración del nivel de aporte de la estrategia a los resultados de aprendizaje del programa. | F14: Encuesta de valoración.
A15: Interpreta la información contable, financiera y tributaria en contextos de aseguramiento y control para establecer su pertinencia y confiabilidad en la resolución de situaciones contables organizacionales.
A16: Utiliza información contable, financiera, tributaria y de auditoría para elaborar reportes, y proyecciones que faciliten la toma de decisiones de distintos tipos de usuarios, considerando sus necesidades y características.
A17: Relaciona métodos cuantitativos y modelos de planeación financiera para explicar dinámicas contables y financieras según el contexto analizado, usando herramientas tecnológicas.
A18: Utiliza métodos cuantitativos y herramientas tecnológicas para elaborar reportes sobre la situación contable y financiera de personas naturales, personas jurídicas y organizaciones, a partir de datos y contextos definidos.
A19: Analiza la normativa vigentes en la preparación y revisión de información contable, financiera y tributaria para identificar criterios técnicos y legales que permitan abordar situaciones contables y fiscales, según el contexto de aplicación. | B19: Proyección social y extensión (Diplomados -MOOC - Videos de reforzamiento curricular) | C19: Iniciativas que articulan la academia con el entorno social a través de programas de formación continua, difusión del conocimiento y actividades orientadas al bienestar de la comunidad y al fortalecimiento del aprendizaje a lo largo de la vida. | D19: Número de estudiantes que participan en la estrategia por periodo académico. | E19: Formar: para complementar el proceso académico formal, promoviendo el aprendizaje autónomo y continuo. Informar: a través de la difusión de contenidos actualizados y pertinentes sobre el ejercicio profesional. Prevenir: para reforzar áreas de bajo rendimiento y anticipar dificultades académicas. | F19: Listados de participación.
A20: Desarrolla procedimientos contables y tributarios para construir estados financieros conforme a la normativa aplicable, integrando el cumplimiento de obligaciones fiscales de personas naturales y jurídicas. | D20: Relación de actividades desarrolladas en el grupo de interés con actividades del perfil ocupacional del programa. | F20: Informe o Reporte.
A21: Interpreta la información contable, financiera y tributaria en contextos de aseguramiento y control para establecer su pertinencia y confiabilidad en la resolución de situaciones contables organizacionales. | D21: Valoración del nivel de aporte de la estrategia a los resultados de aprendizaje del programa. | F21: Encuesta de valoración.
A22: Utiliza información contable, financiera, tributaria y de auditoría para elaborar reportes, y proyecciones que faciliten la toma de decisiones de distintos tipos de usuarios, considerando sus necesidades y características.
A23: Analiza la normativa vigentes en la preparación y revisión de información contable, financiera y tributaria para identificar criterios técnicos y legales que permitan abordar situaciones contables y fiscales, según el contexto de aplicación. | B23: Clases espejo | C23: Estrategia de internacionalización del currículo que conecta a estudiantes y docentes con tendencias académicas globales, promoviendo el intercambio de saberes y el diálogo académico con instituciones aliadas en diferentes países. | D23: Número de estudiantes que participan en la estrategia por periodo académico. | E23: Formar: para fomentar la comprensión intercultural y el pensamiento global aplicado al saber contable. Informar: a través de la exposición a metodologías y enfoques internacionales. Ayudar a decidir: para apoyar decisiones sobre internacionalización del currículo y orientación profesional. | F23: Listados de participación.
A24: Desarrolla procedimientos contables y tributarios para construir estados financieros conforme a la normativa aplicable, integrando el cumplimiento de obligaciones fiscales de personas naturales y jurídicas. | D24: Número de veces que se realiza la estrategia por periodo académico. | F24: Informe o Reporte.
A25: Interpreta la información contable, financiera y tributaria en contextos de aseguramiento y control para establecer su pertinencia y confiabilidad en la resolución de situaciones contables organizacionales. | D25: Valoración del nivel de aporte de la estrategia a los resultados de aprendizaje del programa. | F25: Encuesta de valoración.
A26: Utiliza información contable, financiera, tributaria y de auditoría para elaborar reportes, y proyecciones que faciliten la toma de decisiones de distintos tipos de usuarios, considerando sus necesidades y características.
A27: Analiza la normativa vigentes en la preparación y revisión de información contable, financiera y tributaria para identificar criterios técnicos y legales que permitan abordar situaciones contables y fiscales, según el contexto de aplicación. | B27: Participación en Centros de Emprendimiento, Liderazgo y Empresa Simulada | C27: Iniciativa que vincula a los estudiantes con espacios de formación práctica en emprendimiento, liderazgo y habilidades para la gestión, fortaleciendo su rol como agentes de cambio con impacto en sus comunidades y en el entorno empresarial. | D27: Número de estudiantes que participan en la estrategia en el periodo de su realización. | E27: Formar: para desarrollar habilidades gerenciales, de liderazgo y toma de decisiones empresariales. Prevenir: mediante la preparación para enfrentar escenarios organizacionales complejos desde la academia. Ayudar a decidir: para orientar la creación de iniciativas propias o el fortalecimiento del perfil emprendedor. | F27: Listas de participación.
A28: Desarrolla procedimientos contables y tributarios para construir estados financieros conforme a la normativa aplicable, integrando el cumplimiento de obligaciones fiscales de personas naturales y jurídicas. | D28: Número de veces que se realiza la estrategia por periodo académico. | F28: Informe o Reporte.
A29: Reconoce criterios éticos, legales, sociales y estratégicos del saber contable, tributario, financiero y de auditoría para aplicarlos con rigor técnico en la preparación de información de personas naturales y jurídicas, según el contexto o situación. | D29: Valoración del nivel de aporte de la estrategia a los resultados de aprendizaje del programa. | F29: Encuesta de valoración.
A30: Interpreta la información contable, financiera y tributaria en contextos de aseguramiento y control para establecer su pertinencia y confiabilidad en la resolución de situaciones contables organizacionales.
A31: Utiliza información contable, financiera, tributaria y de auditoría para elaborar reportes, y proyecciones que faciliten la toma de decisiones de distintos tipos de usuarios, considerando sus necesidades y características.
A32: Analiza la normativa vigentes en la preparación y revisión de información contable, financiera y tributaria para identificar criterios técnicos y legales que permitan abordar situaciones contables y fiscales, según el contexto de aplicación. | B32: Programa radial | C32: Estrategia de divulgación del conocimiento, a través de Poliradio, que amplía el alcance de los contenidos académicos y promueve el acceso abierto a la información de valor formativo. | D32: Número de estudiantes que participan en la estrategia por periodo académico. | E32: Informar: para facilitar el acceso a contenidos relevantes y actualizados del área contable y financiera. Formar: a través del estímulo al aprendizaje autónomo y el interés por la divulgación académica. | F32: Listas de participación.
A33: Reconoce criterios éticos, legales, sociales y estratégicos del saber contable, tributario, financiero y de auditoría para aplicarlos con rigor técnico en la preparación de información de personas naturales y jurídicas, según el contexto o situación. | D33: Número de veces que se realiza la estrategia por periodo académico. | F33: Informe o Reporte.
A34: Interpreta la información contable, financiera y tributaria en contextos de aseguramiento y control para establecer su pertinencia y confiabilidad en la resolución de situaciones contables organizacionales. | D34: Valoración del nivel de aporte de la estrategia a los resultados de aprendizaje del programa. | F34: Encuesta de valoración.
A35: Analiza la normativa vigentes en la preparación y revisión de información contable, financiera y tributaria para identificar criterios técnicos y legales que permitan abordar situaciones contables y fiscales, según el contexto de aplicación. | B35: Redes | C35: Participación en redes académicas y profesionales a nivel nacional e internacional, que ofrecen acceso a cursos, conferencias, proyectos y comunidades interdisciplinares, fortaleciendo la formación continua y las competencias investigativas. | D35: Número de estudiantes que participan en la estrategia por periodo académico. | E35: Formar: para enriquecer la experiencia académica mediante el contacto con comunidades de práctica nacionales e internacionales. Informar: a través del acceso a oportunidades formativas y eventos de interés académico. Ayudar a decidir: para brindar referentes que orienten decisiones sobre especialización o vinculación profesional. | F35: Listas de participación.
A36: Desarrolla procedimientos contables y tributarios para construir estados financieros conforme a la normativa aplicable, integrando el cumplimiento de obligaciones fiscales de personas naturales y jurídicas. | D36: Número de veces que se realiza la estrategia por periodo académico. | F36: Informe o Reporte.
A37: Reconoce criterios éticos, legales, sociales y estratégicos del saber contable, tributario, financiero y de auditoría para aplicarlos con rigor técnico en la preparación de información de personas naturales y jurídicas, según el contexto o situación. | D37: Valoración del nivel de aporte de la estrategia a los resultados de aprendizaje del programa. | F37: Encuesta de valoración.
A38: Interpreta la información contable, financiera y tributaria en contextos de aseguramiento y control para establecer su pertinencia y confiabilidad en la resolución de situaciones contables organizacionales.
A39: Utiliza información contable, financiera, tributaria y de auditoría para elaborar reportes, y proyecciones que faciliten la toma de decisiones de distintos tipos de usuarios, considerando sus necesidades y características.
A40: Relaciona métodos cuantitativos y modelos de planeación financiera para explicar dinámicas contables y financieras según el contexto analizado, usando herramientas tecnológicas.
...

Sheet Paso 5 Estrategias micro
A1: [Estas celdas se diligencian automáticamente. No ajustar.] | B1: [A partir de la celda A3 despliegue el(los) resultado(s) de aprendizaje y elija aquel (aquellos) al(a los) que se contribuye desde la asignatura o módulo).] | C1: [Escribir el semestre en el que se cursa la asignatura o módulo.] | D1: [Escribir el nombre de la asignatura o módulo que contribuye al logro del resultado de aprendizaje.] | E1: [Redactar los indicadores iniciando con el verbo en presente indicativo, luego el objeto conceptual y finalmente el complemento de oración (que indique una condición o finalidad, con, para, de, entre otros conectores).] | F1: [Escribir la tipología: T (teórico), P (Práctico), TP (Teórico Práctico)] | G1: [Marcar con X el bloque o componente al que pertenece la asignatura o módulo. Por favor ajustar para posgrado, eliminar una columna y ubicar los títulos C.Fundamentación y C.Profundización.] | J1: [Escribir el número de créditos de la asignatura o módulo] | K1: [Escribir el número de horas de trabajo directo: 16*# o 12*#, para presencial o virtual, según sea el caso.] | L1: [Escribir el número de horas de trabajo independiente: 32*# columna J o 36*# columna J, para presencial o virtual, respectivamente.] | M1: [Escribir la suma de los números de horas de las dos celdas anteriores.] | N1: [Escribir el nombre de los cuatro núcleos temáticos que abordará la asignatura o el módulo.] | O1: [Escribir las lecturas, talleres, análisis, referentes, etc., que realiza el estudiante, clasificadas en trabajo directo e independiente.] | P1: [Escribir las actividades de evaluación que se emplean para identificar el alcance del (de los) indicador(es) de logro(s).] | Q1: [Escribir las acciones de retroalimentación que se emplearán en la asignatura o módulo, para retroalimentar a los estudiantes respecto al alcance de los indicadores de logro. Recordar que son cuatro acciones: informar, formar, prevenir y ayudar a tomar decisiones e indique cómo.]
A2: Tipo de Saber | B2: Resultado de aprendizaje | C2: Semestre | D2: Nombre asignatura o módulo | E2: Indicadores de logro asignatura o módulo | F2: Tipología | G2: B.Institucional | H2: B.Disciplinar | I2: B.Electivo | J2: Créditos | K2: Número de horas trabajo directo | L2: Número de horas trabajo independiente | M2: Total de horas | N2: Núcleos temáticos | O2: Actividades de aprendizaje | P2: Actividades de evaluación | Q2: Acciones de retroalimentación
A3: =_xlfn.XLOOKUP(B3,'Paso 3 Redacción RA '!I$3:I$15,'Paso 3 Redacción RA '!C$3:C$15,,0,1) -> Saber | B3: Identifica fenómenos contemporáneos y su relación con la profesión, para determinar sus impactos e influencia en la sociedad, de forma responsable y crítica. | C3: 1 | D3: Razonamiento Cuantitativo | E3: Analiza datos numéricos presentados en tablas, gráficos o textos para proponer soluciones informadas a situaciones problema del contexto. | F3: TP | G3: X | J3: 3 | K3: =12*J3 -> 36 | L3: =36*J3 -> 108 | M3: =SUM(K3:L3) -> 144 | N3: 1. Pensamiento numérico. Interpretación y representación de información numérica 2. Pensamiento algebraico. Desde la representación de regularidades y patrones 3. Pensamiento algebraico. Desde las relaciones de comparación entre cantidades o expresiones numéricas 4. Pensamiento geométrico. Propiedades, formas y relaciones espaciales | O3: Trabajo directo: Ecuentros sincrónicos Mensajería interna Anuncios Trabajo independiente: Lecturas fundamentales y complementarias Material de trabajo Participación en foros | P3: Evaluación diagnóstica: Cuestionario inicial de, mínimo, cinco preguntas, que recopila información sobre el conocimiento previo y las habilidades del estudiante. Actividad formativa: Foro individual o grupal, creado para que el estudiante participe activamente en la construcción de su conocimiento y desarrollo de habilidades. Varía entre una actividad entregable y la participación en un foro. Actividad de entrega: Actividad individual o grupal, diseñada para evaluar de manera integral el nivel de conocimiento, comprensión y el desempeño de los indicadores de logro. Varía entre entregas independientes o secuenciales. Al ser un módulo teórico, ésta es la única actividad de entrega. Actividad evaluativa: Cuestionario de, mínimo, cinco preguntas, que da cuenta del desarrollo total o parcial de los indicadores de logro y el desarrollo de los temas vistos hasta la unidad 3. Examen final: Cuestionario de, mínimo, quince preguntas, que da cuenta del desarrollo total o parcial de los indicadores de logro y el desarrollo de los temas vistos en el módulo. Autoevaluación: Cuestionario final de, mínimo, cinco preguntas, en el cual el estudiante reflexiona sobre su propio desempeño, habilidades y resultados en un contexto específico. | Q3: Informar oportunamente a través de la plataforma institucional y sesiones sincrónicas sobre el propósito, el proceso de realización, entrega de la actividad y criterios de evaluación. En las sesiones sincrónicas, atender las inquietudes y dar orientaciones al respecto, así como invitar a tomar asesorías ofrecidas por la Escuela de Ciencia Básicas, como estrategia de prevención y ayuda. Ayudar a tomar decisiones a través de preguntas orientadoras y actividades de refuerzo dentro del trabajo directo y autónomo. Retroalimentación por medio de rúbrica que indica el nivel de alcance del logro obtenido. Retroalimentación general del docente acorde a los resultados alcanzados por el grupo
A4: =_xlfn.XLOOKUP(B4,'Paso 3 Redacción RA '!I$3:I$15,'Paso 3 Redacción RA '!C$3:C$15,,0,1) -> Saber | B4: Identifica fenómenos contemporáneos y su relación con la profesión, para determinar sus impactos e influencia en la sociedad, de forma responsable y crítica. | C4: 1 | D4: Cultura, Política y Sociedad | E4: Reconoce las problemáticas, escenarios y mecanismos de participación ciudadana en el marco de sociedades de información y digitales para abordarlas desde iniciativas investigativas. Identifica los objetivos de desarrollo sostenible para la comprensión de problemáticas sociales, ambientales y culturales. Reflexiona sobre los impactos de los avances tecnológicos en el ámbito profesional y ciudadano para generar análisis alrededor de estos en contextos situados. | F4: TP | G4: X | J4: 3 | K4: =12*J4 -> 36 | L4: =36*J4 -> 108 | M4: =SUM(K4:L4) -> 144 | N4: 1. ODS, problemas locales: una mirada a Colombia, territorio en búsqueda de la consolidación de la Paz. 2. Ciudadanía y su lugar: relaciones, dinámicas, construcción, expresión y mecanismos de participación. 3. Ecosistemas digitales: relaciones, dinámicas, construcción, expresión e impactos en el contexto profesional. 4. Narrativas y contenidos digitales: análisis de contextos situados. | O4: Trabajo directo: Ecuentros sincrónicos Mensajería interna Anuncios Trabajo independiente: Lecturas fundamentales y complementarias Material de trabajo Participación en foros | P4: Evaluación diagnóstica escenario 1: Cuestionario inicial de mínimo cinco preguntas que recopila información sobre el conocimiento previo y las habilidades del estudiante. Actividad formativa escenario 2: Foro individual o grupal, creado para que el estudiante participe activamente en la construcción de su conocimiento y desarrollo de habilidades. Varía entre una actividad entregable y la participación en un foro. Actividad de entrega 1 escenario 4: Actividad individual o grupal, diseñada para evaluar de manera integral el nivel de conocimiento, comprensión y el desempeño de los indicadores de logro. Varía entre entregas independientes o secuenciales. Actividad formativa escenario 5: Foro individual o grupal, creado para que el estudiante participe activamente en la construcción de su conocimiento y desarrollo de habilidades. Varía entre una actividad entregable y la participación en un foro. Actividad evaluativa escenario 6: Cuestionario de, mínimo, cinco preguntas, que da cuenta del desarrollo total o parcial de los indicadores de logro y el desarrollo de los temas vistos hasta la unidad 3. Actividad de entrega 2 escenario 7: Actividad individual o grupal, diseñada para evaluar de manera integral el nivel de conocimiento, comprensión y el desempeño de los indicadores de logro. Varía entre entregas independientes o secuenciales. Autoevaluación escenario 8: Cuestionario final de mínimo cinco preguntas en el cual el estudiante reflexiona sobre su propio desempeño, habilidades y resultados en un contexto específico. | Q4: Las acciones de retroalimentación giran en torno a las siguientes. Formar: donde se crean las condiciones para que los estudiantes adquieran conocimientos, habilidades, actitudes, aptitudes y destrezas. Además, debe promover su desarrollo integral y debe acompañarlos en las situaciones académicas que enfrenten durante el desarrollo de un módulo o una asignatura. Informar: para que los estudiantes identifiquen los cambios que pueden afectarlos directa o indirectamente tanto en el aula de clase como en otros espacios. Prevenir: con el fin de anticiparse a las situaciones académicas que pueden representar dificultad para los estudiantes. Esto se logra a través de la interacción individual con los estudiantes y del completo conocimiento del contexto educativo en que el tutor se desenvuelve. Ayudar a decidir: donde se orienta a los estudiantes para que tomen la mejor decisión ante una situación concreta. El objetivo es que el estudiante fortalezca su autonomía y la toma de decisiones responsable.
A5: =_xlfn.XLOOKUP(B5,'Paso 3 Redacción RA '!I$3:I$15,'Paso 3 Redacción RA '!C$3:C$15,,0,1) -> Saber | B5: Analiza la normativa vigentes en la preparación y revisión de información contable, financiera y tributaria para identificar criterios técnicos y legales que permitan abordar situaciones contables y fiscales, según el contexto de aplicación. | C5: 1 | D5: Contabilidad General | E5: Elabora el registro de las operaciones, conforme a la normatividad vigente y la técnica contable a partir del objeto social de una organización, teniendo en cuenta el marco conceptual de las normas internacionales de información financiera para elaborar los estados financieros. | F5: TP | H5: X | J5: 3 | K5: =12*J5 -> 36 | L5: =36*J5 -> 108 | M5: =SUM(K5:L5) -> 144 | N5: 1. Fundamentación teórica y técnica contable 2. Elementos de los Estados Financieros y sus características 3. Transacciones comerciales y operaciones con cuentas de resultado 4. Estructura de los Estados Financieros | O5: Las estrategias pueden variar entre estas u otras: Trabajo directo Clase magistral activa/Análisis o Estudio de casos/Resolución de problemas/Talleres prácticos Trabajo independiente Lecturas relacionadas o de materiales complementarios/Resolución de problemas/Ejercicios aplicados/Desarrollo de proyectos/Talleres grupales o individuales/Análisis o Estudio de casos/Elaboración de informes o documentos técnicos | P5: Actividad de puntos evaluables (semana 2 – Cuestionario de 5 preguntas). Entrega previa 1 (semana 3 - Laboratorio, taller, ejercicios, resolución de casos o de problemas, desarrollo de procesos o ejecución de propuestas. Entrega de forma individual o grupal, según indicaciones del profesor). Parcial (semana 4 - Cuestionarios de entre 15 y 20 preguntas). Entrega previa 2 (semana 5 - Laboratorio, taller, ejercicios, resolución de casos o de problemas, desarrollo de procesos o ejecución de propuestas. Entrega de forma individual o grupal, según indicaciones dadas por el profesor). Entrega final (semana 7 - Laboratorio, taller, ejercicios, resolución de casos o de problemas, desarrollo de procesos o ejecución de propuestas. Entrega de forma individual o grupal, según indicaciones dadas por el profesor). Evaluación final (semana 8 - Cuestionario de entre 15 y 20 preguntas). | Q5: Las acciones de retroalimentación giran en torno a las siguientes. Formar: donde se crean las condiciones para que los estudiantes adquieran conocimientos, habilidades, actitudes, aptitudes y destrezas. Además, debe promover su desarrollo integral y debe acompañarlos en las situaciones académicas que enfrenten durante el desarrollo de un módulo o una asignatura. Informar: para que los estudiantes identifiquen los cambios que pueden afectarlos directa o indirectamente tanto en el aula de clase como en otros espacios. Prevenir: con el fin de anticiparse a las situaciones académicas que pueden representar dificultad para los estudiantes. Esto se logra a través de la interacción individual con los estudiantes y del completo conocimiento del contexto educativo en que el tutor se desenvuelve. Ayudar a decidir: donde se orienta a los estudiantes para que tomen la mejor decisión ante una situación concreta. El objetivo es que el estudiante fortalezca su autonomía y la toma de decisiones responsable.
A6: =_xlfn.XLOOKUP(B6,'Paso 3 Redacción RA '!I$3:I$15,'Paso 3 Redacción RA '!C$3:C$15,,0,1) -> Saberhacer | B6: Desarrolla procedimientos contables y tributarios para construir estados financieros conforme a la normativa aplicable, integrando el cumplimiento de obligaciones fiscales de personas naturales y jurídicas.
A7: =_xlfn.XLOOKUP(B7,'Paso 3 Redacción RA '!I$3:I$15,'Paso 3 Redacción RA '!C$3:C$15,,0,1) -> Saber | B7: Interpreta la información contable, financiera y tributaria en contextos de aseguramiento y control para establecer su pertinencia y confiabilidad en la resolución de situaciones contables organizacionales.
A8: =_xlfn.XLOOKUP(B8,'Paso 3 Redacción RA '!I$3:I$15,'Paso 3 Redacción RA '!C$3:C$15,,0,1) -> Saberhacer | B8: Utiliza información contable, financiera, tributaria y de auditoría para elaborar reportes, y proyecciones que faciliten la toma de decisiones de distintos tipos de usuarios, considerando sus necesidades y características.
A9: =_xlfn.XLOOKUP(B9,'Paso 3 Redacción RA '!I$3:I$15,'Paso 3 Redacción RA '!C$3:C$15,,0,1) -> Saberser | B9: Reconoce criterios éticos, legales, sociales y estratégicos del saber contable, tributario, financiero y de auditoría para aplicarlos con rigor técnico en la preparación de información de personas naturales y jurídicas, según el contexto o situación. | C9: 1 | D9: Epistemología Contable | E9: Identifica los desarrollos epistemológicos de la contabilidad y la incidencia de estos en el pensamiento contable y las prácticas profesionales, con el fin de analizar la relación que existe entre teoría contable, el desarrollo histórico del pensamiento contable, las perspectivas contemporáneas y su problematización en el contexto global. | F9: T | H9: X | J9: 3 | K9: =12*J9 -> 36 | L9: =36*J9 -> 108 | M9: =SUM(K9:L9) -> 144 | N9: 1. Fundamentos de epistemología y el saber contable. 2. Construcción de pensamiento y teoría contable. 3. Contexto actual de la teoría contable. 4. Contexto contemporáneo del campo contable. | O9: Las estrategias pueden variar entre estas u otras: Trabajo directo Clase magistral activa/Análisis o Estudio de casos/Resolución de problemas/Talleres prácticos Trabajo independiente Lecturas relacionadas o de materiales complementarios/Resolución de problemas/Ejercicios aplicados/Desarrollo de proyectos/Talleres grupales o individuales/Análisis o Estudio de casos/Elaboración de informes o documentos técnicos | P9: Quiz (semana 2 - Cuestionario de 5 preguntas). Entrega inicial (semana 3 – Ensayo, artículo, cuadro comparativo, revisión documental, entre otros). Foro analítico o argumentativo (semanas 5 y 6 – Participación en el espacio correspondiente del aula). Entrega final (semana 7 – Ensayo, artículo, cuadro comparativo, revisión documental, entre otros). Evaluación final (semana 8 – Cuestionario de entre 15 y 20 preguntas). | Q9: Las acciones de retroalimentación giran en torno a las siguientes. Formar: donde se crean las condiciones para que los estudiantes adquieran conocimientos, habilidades, actitudes, aptitudes y destrezas. Además, debe promover su desarrollo integral y debe acompañarlos en las situaciones académicas que enfrenten durante el desarrollo de un módulo o una asignatura. Informar: para que los estudiantes identifiquen los cambios que pueden afectarlos directa o indirectamente tanto en el aula de clase como en otros espacios. Prevenir: con el fin de anticiparse a las situaciones académicas que pueden representar dificultad para los estudiantes. Esto se logra a través de la interacción individual con los estudiantes y del completo conocimiento del contexto educativo en que el tutor se desenvuelve. Ayudar a decidir: donde se orienta a los estudiantes para que tomen la mejor decisión ante una situación concreta. El objetivo es que el estudiante fortalezca su autonomía y la toma de decisiones responsable.
A10: =_xlfn.XLOOKUP(B10,'Paso 3 Redacción RA '!I$3:I$15,'Paso 3 Redacción RA '!C$3:C$15,,0,1) -> Saber | B10: Interpreta la información contable, financiera y tributaria en contextos de aseguramiento y control para establecer su pertinencia y confiabilidad en la resolución de situaciones contables organizacionales.
A11: =_xlfn.XLOOKUP(B11,'Paso 3 Redacción RA '!I$3:I$15,'Paso 3 Redacción RA '!C$3:C$15,,0,1) -> Saberhacer | B11: Utiliza información contable, financiera, tributaria y de auditoría para elaborar reportes, y proyecciones que faciliten la toma de decisiones de distintos tipos de usuarios, considerando sus necesidades y características.
A12: =_xlfn.XLOOKUP(B12,'Paso 3 Redacción RA '!I$3:I$15,'Paso 3 Redacción RA '!C$3:C$15,,0,1) -> Saber | B12: Relaciona métodos cuantitativos y modelos de planeación financiera para explicar dinámicas contables y financieras según el contexto analizado, usando herramientas tecnológicas.
