Workbook
Name actitudinalB: Tabla5785[ActitudinalB]
Name actitudinalB: Tabla5785[ActitudinalB]
Name ActitudinalBAK: 'Taxonomias para RA'!$AC$3:$AG$3
Name AK: Tabla6088[AK]
Name AK: Tabla6088[AK]
Name AnálisisAK: Tabla99[AnálisisAK]
Name AnálisisAK: Tabla99[AnálisisAK]
Name AnálisisB: Tabla385280[AnálisisB]
Name AnálisisB: Tabla385280[AnálisisB]
Name AnálisisBAK: Tabla3865[AnálisisBAK]
Name AnálisisBAK: Tabla3865[AnálisisBAK]
Name AnalizarLK: Tabla2129[AnalizarLK]
Name AnalizarLK: Tabla2129[AnalizarLK]
Name AplicaciónB: Tabla375179[AplicaciónB]
Name AplicaciónB: Tabla375179[AplicaciónB]
Name AplicaciónBAK: Tabla3764[AplicaciónBAK]
Name AplicaciónBAK: Tabla3764[AplicaciónBAK]
Name AplicarLK: Tabla2028[AplicarLK]
Name AplicarLK: Tabla2028[AplicarLK]
Name áreasprofesionales: 'Paso1 Analisis perfil egreso'!$H$3:$H$14
Name áreasprofesionales: 'Paso1 Analisis perfil egreso'!$H$3:$H$14
Name BAK: Tabla5886[BAK]
Name BAK: Tabla5886[BAK]
Name Bloom: 'Taxonomias para RA'!$G$3:$I$3
Name CaracterizarBAK: Tabla4776[CaracterizarBAK]
Name CaracterizarBAK: Tabla4776[CaracterizarBAK]
Name Cognitivo: Saber[Saber]
Name Cognitivo: Saber[Saber]
Name cognitivoB: Tabla5583[CognitivoB]
Name cognitivoB: Tabla5583[CognitivoB]
Name CognitivoBAK: 'Taxonomias para RA'!$S$3:$X$3
Name competencias: 'Paso 2 Redacción competen'!$F$3:$F$22
Name competencias: 'Paso 2 Redacción competen'!$F$3:$F$22
Name ComprenderLK: 'Taxonomias para RA'!$AM$5:$AM$27
Name ComprensiónAK: Tabla98[ComprensiónAK]
Name ComprensiónAK: Tabla98[ComprensiónAK]
Name ComprensionB: Tabla365078[ComprensiónB]
Name ComprensionB: Tabla365078[ComprensiónB]
Name ComprensiónBAK: Tabla3663[ComprensiónBAK]
Name ComprensiónBAK: Tabla3663[ComprensiónBAK]
Name ConceptosLK: Tabla91[ConceptosLK]
Name ConceptosLK: Tabla91[ConceptosLK]
Name ConocimientoB: Tabla354977[ConocimientoB]
Name ConocimientoB: Tabla354977[ConocimientoB]
Name ConocimientoBAK: Tabla3555[ConocimientoBAK]
Name ConocimientoBAK: Tabla3555[ConocimientoBAK]
Name Conocimientos: Saber[Saber]
Name Conocimientos: Saber[Saber]
Name ControlBAK: Tabla4271[ControlBAK]
Name ControlBAK: Tabla4271[ControlBAK]
Name CrearLK: Tabla2333[CrearLK]
Name CrearLK: Tabla2333[CrearLK]
Name dominios: 'Paso1 Analisis perfil egreso'!$E$2:$G$2
Name EvaluaciónB: Tabla405482[EvaluaciónB]
Name EvaluaciónB: Tabla405482[EvaluaciónB]
Name EvaluaciónBAK: Tabla4067[EvaluaciónBAK]
Name EvaluaciónBAK: Tabla4067[EvaluaciónBAK]
Name EvaluarLK: 'Taxonomias para RA'!$AP$5:$AP$46
Name HechosLK: Tabla90[HechosLK]
Name HechosLK: Tabla90[HechosLK]

Sheet Paso1 Analisis perfil egreso
A1: [Escribir el nombre del programa] | B1: [Escribir la modalidad: presencial o virtual] | C1: [Escribir el perfil profesional del egresado.] | D1: [Escribir el perfil ocupacional del egresado.] | E1: Componentes fundamentales para definir competencias [Listar las palabras clave, no armar oraciones, respecto qué debe saber el egresado en las categorías de Saber -conocimientos, hechos, teorías-, Saber hacer -técnicas, procedimientos, metodologías-, y Saber ser -valores, condiciones. Esta información se estructura a partir del perfil profesional y cada saber hacer depende del saber ubicado a su izquierda, lo mismo ocurre con el saber ser.] | H1: Componentes fundamentales de la ocupación laboral del profesional [Listar, según lo escrito en el perfil ocupacional, en qué áreas, qué tareas potenciales y en qué poblaciones o contextos podrá laborar el profesional. Esta información es un listado general no requiere dependencia horizontal] | K1: Diferencial (valor agregado) del profesional [Listar, según lo escrito en los perfiles, los elementos que son diferenciales y generan un valor agregado al egresado. Debe ser disciplinar, asociado al perfil, ¿qué es lo que lo hace diferente a otros perfiles similares.]
A2: Programa | B2: Modalidad | C2: Perfil profesional | D2: Perfil ocupacional | E2: Saber | F2: Saberhacer | G2: Saberser | H2: ÁreasProfesionales | I2: TareasProfesionales | J2: PoblacionesActuacion | K2: ValorAgregado
A3: Especialización en Gerencia de Proyectos en Inteligencia de Negocios | B3: Virtual | C3: El egresado de la Especialización en Gerencia de Proyectos en Inteligencia de Negocios del Politécnico Grancolombiano estará en capacidad de determinar los recursos tecnológicos y los procesos administrativos, adecuados y acordes con el tamaño de las empresas, para construir soluciones de inteligencia de Negocios a través de la formulación de proyectos, que permitan establecer los objetivos, estrategias, indicadores y metas a medir, con el fin de orientar la toma de decisiones respecto a las necesidades del mercado actual y futuro. | D3: El egresado de la especialización en Gerencia de Proyectos en Inteligencia de Negocios posee habilidades para el desarrollo de proyectos, el manejo de datos y la formulación de soluciones que den valor agregado al ambiente industrial, consideren el movimiento y las necesidades del mercado, y tengan en cuenta las buenas prácticas denotadas por el PMI y la inteligencia de negocios. | E3: Soluciones de inteligencia de negocios | F3: Comprender las realidades y fenómenos, y resolver problemas organizacionales | G3: a partir de la aplicación de conocimientos relacionados con teorías, procedimientos y herramientas administrativas, organizacionales, estratégicas y prospectivas. | H3: gerente, director o coordinador de equipos de proyectos en diferentes áreas de actividad; consultor y/o auditor | I3: procesos de planeación, ejecución, control y cierre de proyectos; líder de proyectos de investigación aplicada, desarrollo e innovación para la consolidación de metodologías, técnicas e instrumentos para la gestión de proyectos que incorporen agilidad y formador de equipos de proyectos efectivos. | J3: Empleados en empresa particular (262) | K3: “Data Science y computación de alto desempeño“, esta línea es de carácter aplicado toda vez que tiene como finalidad la solución de problemas planteados en el medio profesional-disciplinar y en el empresarial, en ella el estudiante después de identificar un problema en su empresa o en su contexto particular, formula un proyecto que aporte a la solución de dicho problema aplicando y practicando las habilidades y competencias como gerente de proyectos en el área específica de la inteligencia de negocios en diferentes sectores productivos. Esto genera beneficios directos e indirectos a las empresas en la medida en que, en muchos casos, el proyecto de grado avanza y se convierte en una iniciativa del área al cual pertenece el egresado, mejorando procesos o generando nuevas líneas de negocio.
E4: Evaluación de información de las organizaciones | F4: Proponer soluciones estratégicas que permitan la toma de decisiones de inversión y financiamiento de proyectos de inteligencia de negocio | G4: que generen valor y produzcan transformaciones digitales en estas. | H4: Análisis de datos | I4: Analista | J4: Empleados del estado (86) | K4: Proyectos de trasformación digital en la Industria 4,0 e incorporando temas de desarrollo sostenible
E5: Metodológicas para el desarrollo de proyectos en inteligencia de negocios | F5: Desarrollo de proyectos en inteligencia de negocios | G5: analizando las necesidades tecnológicas y de interconectividad para un sistema completo, así como del manejo de datos, transformación y carga de estos. | I5: Operativo | J5: Trabajador independiente (15) | K5: Los egresados tienen la posibilidad de presentar el examen de certificación de PMP y las materias que vieron de su especialización como son gerencia de proyectos 1 y gerencia de proyectos 2, La Institución Universitaria Politécnico Grancolombiano le certifica el tiempo de 72 horas de capacitación en dirección de proyectos, con lo cual si cumple con los otros requisitos puede presentar el examen de PMP.
J6: Empresarios(5)
J7: Empleado en empresa familiar (4)

Sheet Paso 2 Redacción competen
A1: [Enumerar las competencias que se van a declarar.] | B1: [A partir de la celda B2 dar clic sobre el ícono de lista desplegable y elegir el verbo que considere adecuado.] | C1: [A partir de la celda C2 dar clic sobre la lista desplegable y elegir el saber extraído del perfil de egreso.] | D1: [Escribir para qué se abordará el saber elegido. Se sugiere apoyarse en el saber hacer.] | E1: [Escribir la condición describiendo los referentes, parámetros, principios, requerimientos o retos que se necesitan para alcanzar las características del perfil en el contexto donde el egresado se desenvolverá.] | F1: [Articular los componentes. Iniciar con el verbo, continuar con el objeto conceptual, luego la finalidad y condición de contexto o referencia; estos últimos no requieren un orden particular.] | G1: [Escribir el tipo de competencia del perfil: Específica (si es del bloque Disciplinar para pregrado o de los componentes para el caso de posgrado) o Genérica (si aplica bloque institucional pregrado)]
A2: No. | B2: Verbo competencia | C2: Objeto conceptual | D2: Finalidad | E2: Condición de contexto o referencia | F2: Redacción competencia | G2: Tipo competencia
A3: 1 | B3: Formular | C3: Soluciones de inteligencia de negocios | D3: Comprender las realidades y fenómenos, y resolver problemas organizacionales | E3: a partir de la aplicación de conocimientos relacionados con teorías, procedimientos y herramientas administrativas, organizacionales, estratégicas y prospectivas. | F3: Formular alternativas de solución en Inteligencia de Negocios para comprender las realidades y fenómenos, así como el resolver problemas organizacionales, a partir de la aplicación de conocimientos relacionados con teorías, procedimientos y herramientas administrativas, organizacionales, estratégicas y prospectivas. | G3: Específica
A4: 2 | B4: Evaluar | C4: Evaluación de información de las organizaciones | D4: Proponer soluciones estratégicas que permitan la toma de decisiones de inversión y financiamiento de proyectos de inteligencia de negocio | E4: que generen valor y produzcan transformaciones digitales en estas. | F4: Evaluar información basada en las necesidades de las organizaciones para proponer soluciones estratégicas que permitan la toma de decisiones de inversión y financiamiento de proyectos de inteligencia de negocio que generen valor y produzcan transformaciones digitales en estas. | G4: Específica
A5: 3 | B5: Conocer | C5: Metodológicas para el desarrollo de proyectos en inteligencia de negocios | D5: Desarrollo de proyectos en inteligencia de negocios | E5: analizando las necesidades tecnológicas y de interconectividad para un sistema completo, así como del manejo de datos, transformación y carga de estos. | F5: Proponer herramientas metodológicas para el desarrollo de proyectos en inteligencia de negocios, analizando las necesidades tecnológicas y de interconectividad para un sistema completo, así como del manejo de datos, transformación y carga de estos. | G5: Específica

Sheet Paso 3 Redacción RA
A1: [A partir de la celda A2 dar clic en la lista desplegable y seleccionar la competencia redactada en el paso 2.] | B1: [Enumerar los resultados de aprendizaje que se van a declarar.] | C1: [A partir de la celda C2, dar clic en la lista desplegable y elegir el tipo de dominio a tratar en el resultado de aprendizaje.] | D1: [A partir de la cela D2, dar clic en la lista desplegable y elegir el saber correspondiente al dominio.] | E1: [A partir de la celda E2, dar clic en la lista desplegable y elegir la taxonomía que se considere adecuada, solo se elige una para todos los saberes.] | F1: [A partir de la celda F2, dar clic en la lista desplegable y elegir el dominio que se considera adecuado.] | G1: [A partir de la celda G2, dar clic en la lista desplegable y elegir el nivel del dominio que se considera adecuado.] | H1: [A partir de la celda H2, dar clic en la lista desplegable y elegir el verbo que se considera adecuado.] | I1: [Iniciar con el verbo elegido (columna H), en infinitivo, luego el objeto sobre el cual recae la acción (columna D) y finalmente la condición de contexto (académico, disciplinar, social u otro).]
A2: Competencia por desarrollar | B2: Número de resultado | C2: TipoSaber | D2: SaberAsociado | E2: Taxonomía | F2: Dominio Asociado | G2: Nivel Dominio | H2: Verbo RA | I2: Resultados Aprendizaje
A3: Formular alternativas de solución en Inteligencia de Negocios para comprender las realidades y fenómenos, así como el resolver problemas organizacionales, a partir de la aplicación de conocimientos relacionados con teorías, procedimientos y herramientas administrativas, organizacionales, estratégicas y prospectivas. | B3: 1 | C3: Saber | D3: Soluciones de inteligencia de negocios | E3: Bloom | F3: CognitivoB | G3: AnálisisB | H3: Reconocer | I3: Reconoce los conceptos, técnicas y metodologías usadas en el desarrollo de proyectos de inteligencia de negocios para determinar los elementos y factores que se requieren en la formulación de soluciones tecnológicas que atiendan las necesidades del sector industrial y de las organizaciones.
A4: Formular alternativas de solución en Inteligencia de Negocios para comprender las realidades y fenómenos, así como el resolver problemas organizacionales, a partir de la aplicación de conocimientos relacionados con teorías, procedimientos y herramientas administrativas, organizacionales, estratégicas y prospectivas. | B4: 3 | C4: Saberhacer | D4: Comprender las realidades y fenómenos, y resolver problemas organizacionales | E4: Bloom | F4: ProcedimentalB | G4: SíntesisB | H4: Diseñar | I4: Diseña estrategias, herramientas y proyectos de inteligencia de negocios para dar soluciones adecuadas y transformadoras a problemas complejos organizacionales, teniendo en cuenta las necesidades y condiciones financieras y económicas del contexto.
A5: Formular alternativas de solución en Inteligencia de Negocios para comprender las realidades y fenómenos, así como el resolver problemas organizacionales, a partir de la aplicación de conocimientos relacionados con teorías, procedimientos y herramientas administrativas, organizacionales, estratégicas y prospectivas. | B5: 4 | C5: Saberser | D5: a partir de la aplicación de conocimientos relacionados con teorías, procedimientos y herramientas administrativas, organizacionales, estratégicas y prospectivas. | E5: Bloom | F5: ActitudinalB | G5: SíntesisB | H5: Establecer | I5: Establece los elementos o factores que contribuyen a la generación de valor y a la transformación digital de las organizaciones para incorporarlos en el diseño de proyectos de inteligencia de negocios que impacten la gestión organizacional, de acuerdo con las condiciones de estas y el contexto en el que se encuentra.
A6: Evaluar información basada en las necesidades de las organizaciones para proponer soluciones estratégicas que permitan la toma de decisiones de inversión y financiamiento de proyectos de inteligencia de negocio que generen valor y produzcan transformaciones digitales en estas. | B6: 2 | C6: Saber | D6: Evaluación de información de las organizaciones | E6: Bloom | F6: CognitivoB | G6: EvaluaciónB | H6: Evaluar | I6: Evalúa información de las organizaciones, a partir del análisis de datos y la aplicación de metodologías de la inteligencia de negocios para determinar los proyectos y programas que se pueden diseñar e implementar en las organizaciones, de acuerdo con las necesidades que estas presentan.
A7: Evaluar información basada en las necesidades de las organizaciones para proponer soluciones estratégicas que permitan la toma de decisiones de inversión y financiamiento de proyectos de inteligencia de negocio que generen valor y produzcan transformaciones digitales en estas. | B7: 3 | C7: Saberhacer | D7: Proponer soluciones estratégicas que permitan la toma de decisiones de inversión y financiamiento de proyectos de inteligencia de negocio | E7: Bloom | F7: ProcedimentalB | G7: SíntesisB | H7: Diseñar | I7: Diseña estrategias, herramientas y proyectos de inteligencia de negocios para dar soluciones adecuadas y transformadoras a problemas complejos organizacionales, teniendo en cuenta las necesidades y condiciones financieras y económicas del contexto.
A8: Evaluar información basada en las necesidades de las organizaciones para proponer soluciones estratégicas que permitan la toma de decisiones de inversión y financiamiento de proyectos de inteligencia de negocio que generen valor y produzcan transformaciones digitales en estas. | B8: 4 | C8: Saberser | D8: que generen valor y produzcan transformaciones digitales en estas. | E8: Bloom | F8: ActitudinalB | G8: SíntesisB | H8: Establecer | I8: Establece los elementos o factores que contribuyen a la generación de valor y a la transformación digital de las organizaciones para incorporarlos en el diseño de proyectos de inteligencia de negocios que impacten la gestión organizacional, de acuerdo con las condiciones de estas y el contexto en el que se encuentra.
A9: Proponer herramientas metodológicas para el desarrollo de proyectos en inteligencia de negocios, analizando las necesidades tecnológicas y de interconectividad para un sistema completo, así como del manejo de datos, transformación y carga de estos. | B9: 1 | C9: Saber | D9: Metodológicas para el desarrollo de proyectos en inteligencia de negocios | E9: Bloom | F9: CognitivoB | G9: AnálisisB | H9: Reconocer | I9: Reconoce los conceptos, técnicas y metodologías usadas en el desarrollo de proyectos de inteligencia de negocios para determinar los elementos y factores que se requieren en la formulación de soluciones tecnológicas que atiendan las necesidades del sector industrial y de las organizaciones.
A10: Proponer herramientas metodológicas para el desarrollo de proyectos en inteligencia de negocios, analizando las necesidades tecnológicas y de interconectividad para un sistema completo, así como del manejo de datos, transformación y carga de estos. | B10: 3 | C10: Saberhacer | D10: Desarrollo de proyectos en inteligencia de negocios | E10: Bloom | F10: ProcedimentalB | G10: SíntesisB | H10: Diseñar | I10: Diseña estrategias, herramientas y proyectos de inteligencia de negocios para dar soluciones adecuadas y transformadoras a problemas complejos organizacionales, teniendo en cuenta las necesidades y condiciones financieras y económicas del contexto.
A11: Proponer herramientas metodológicas para el desarrollo de proyectos en inteligencia de negocios, analizando las necesidades tecnológicas y de interconectividad para un sistema completo, así como del manejo de datos, transformación y carga de estos. | B11: 4 | C11: Saberser | D11: que generen valor y produzcan transformaciones digitales en estas. | E11: Bloom | F11: ActitudinalB | G11: SíntesisB | H11: Establecer | I11: Establece los elementos o factores que contribuyen a la generación de valor y a la transformación digital de las organizaciones para incorporarlos en el diseño de proyectos de inteligencia de negocios que impacten la gestión organizacional, de acuerdo con las condiciones de estas y el contexto en el que se encuentra.

Sheet Paso 4 Estrategias mesocurricu
A1: [A partir de la celda A3 despliegue el(los) resultado(s) de aprendizaje y elegir aquel (aquellos) al(a los) que se contribuye desde la estrategia.] | B1: [Escribir el nombre de la estrategia a desarrollar. Participación de los estudiantes en cursos, talleres, seminarios, conferencias, pruebas estandarizadas, investigaciones, actividades o experiencias, cuerpos académicos, redes, comunidades, la elaboración de textos y materiales, así como las publicaciones, entre otros.] | C1: [Describir la(s) estrategia(s) definidas por el programa.] | D1: [Escribir los indicadores de impacto de la estrategia. Se sugieren indicadores como: Valora el nivel de contribución de la estrategia a los resultados de aprendizaje; Número de estudiantes que participan en la estrategia; Número de veces que se realiza la estrategia, entre otros.] | E1: [Escribir las acciones de retroalimentación que usará el programa para comunicar a los estudiantes sobre el alcance de sus resultados de aprendizaje.] | F1: [Escribir, para cada indicador con qué instrumento se recogerá información para evidenciar el (los) impacto (s) declarados. Encuesta, lista de asistencia, informe, entre otros.]
A2: Resultado de aprendizaje | B2: Estrategia del programa | C2: Descripción | D2: Indicador de Impacto de la Estrategia | E2: Acciones de retroalimentación para los estudiantes | F2: Instrumentos de medición
A3: Reconoce los conceptos, técnicas y metodologías usadas en el desarrollo de proyectos de inteligencia de negocios para determinar los elementos y factores que se requieren en la formulación de soluciones tecnológicas que atiendan las necesidades del sector industrial y de las organizaciones. | B3: Estudios alternativos | C3: Recomendaciones y sugerencias por parte del cuerpo docente para el desarrollo de cursos de profundización, con ampliaciones en investigaciones permanentes para el uso de nuevas tecnologías y aplicaciones de las mismas en el ambiente. Propuestas de los docentes de diferentes MOOC | D3: Valoración de los estudiantes respecto a la contribución de la estrategia a los resultados de aprendizaje del programa. | E3: Informar por medio de los anuncios del módulo, los estudios alternativos sugeridos o recomendados para los estudiantes de la especialización | F3: Encuesta
A4: Diseña estrategias, herramientas y proyectos de inteligencia de negocios para dar soluciones adecuadas y transformadoras a problemas complejos organizacionales, teniendo en cuenta las necesidades y condiciones financieras y económicas del contexto. | D4: Número de cursos o teorías en desarrollo, recomendadas o sugeridas por el cuerpo profesoral a los estudiantes. | F4: Informe o Reporte
D5: Número de estudiantes que participan en la estrategia. | F5: Listados de participación
A6: Reconoce los conceptos, técnicas y metodologías usadas en el desarrollo de proyectos de inteligencia de negocios para determinar los elementos y factores que se requieren en la formulación de soluciones tecnológicas que atiendan las necesidades del sector industrial y de las organizaciones. | B6: Congreso de inteligencia de negocios, con énfasis en gerencia de proyectos. | C6: La idea del congreso es mostrar cómo se mueve el ambiente y las tendencias de análisis de datos y de manejo de gerencia de proyectos en diferentes aspecto mundiales. | D6: Valoración de los estudiantes respecto a la contribución de la estrategia a los resultados de aprendizaje del programa. | E6: Informar por medio de los anuncios del módulo sobre las fechas de realización del congreso de inteligencia de negocios, los estudios alternativos sugeridos o recomendados para los estudiantes de la especialización. Formar a los estudiantes a través de las grabaciones de las sesiones de los congresos de inteligencia de negocios por POLITV. | F6: Encuesta
A7: Diseña estrategias, herramientas y proyectos de inteligencia de negocios para dar soluciones adecuadas y transformadoras a problemas complejos organizacionales, teniendo en cuenta las necesidades y condiciones financieras y económicas del contexto. | D7: Número de estudiantes del programa que participan en la estrategia. | F7: Listados de participación
D8: Número de veces que se desarrolla la estrategia en los periodos de tiempo que determine el programa. | F8: Informe o Reporte
A9: Diseña estrategias, herramientas y proyectos de inteligencia de negocios para dar soluciones adecuadas y transformadoras a problemas complejos organizacionales, teniendo en cuenta las necesidades y condiciones financieras y económicas del contexto. | B9: Relacionamiento con IPMA | C9: Participación del cuerpo profesoral y de los estudiantes en el reconocimiento de las variaciones que presenta IPMA en términos de la creación y gestión de proyectos. | D9: Valoración de los estudiantes respecto a la contribución de la estrategia a los resultados de aprendizaje del programa. | E9: Informar por medio de los anuncios del módulo los talleres que se plantean en conjunto con IPMA, los estudios alternativos sugeridos o recomendados para los estudiantes. | F9: Encuesta
A10: Establece los elementos o factores que contribuyen a la generación de valor y a la transformación digital de las organizaciones para incorporarlos en el diseño de proyectos de inteligencia de negocios que impacten la gestión organizacional, de acuerdo con las condiciones de estas y el contexto en el que se encuentra. | D10: Número de estudiantes del programa que participan en la estrategia. | E10: Formar con respecto a las metodologías expuestas por IPMA en el relacionamiento de los casos de estudio presentados. | F10: Listados de participación
A11: Evalúa información de las organizaciones, a partir del análisis de datos y la aplicación de metodologías de la inteligencia de negocios para determinar los proyectos y programas que se pueden diseñar e implementar en las organizaciones, de acuerdo con las necesidades que estas presentan. | D11: Número de profesores que participan en la estrategia. | F11: Informe o Reporte

Sheet Paso 5 Estrategias micro
A1: [Estas celdas se diligencian automáticamente. No ajustar.] | B1: [A partir de la celda A3 despliegue el(los) resultado(s) de aprendizaje y elija aquel (aquellos) al(a los) que se contribuye desde la asignatura o módulo).] | C1: [Escribir el semestre en el que se cursa la asignatura o módulo.] | D1: [Escribir el nombre de la asignatura o módulo que contribuye al logro del resultado de aprendizaje.] | E1: [Redactar los indicadores iniciando con el verbo en presente indicativo, luego el objeto conceptual y finalmente el complemento de oración (que indique una condición o finalidad, con, para, de, entre otros conectores).] | F1: [Escribir la tipología: T (teórico), P (Práctico), TP (Teórico Práctico)] | G1: [Marcar con X el bloque o componente al que pertenece la asignatura o módulo. Por favor ajustar para posgrado, eliminar una columna y ubicar los títulos C.Fundamentación y C.Profundización.] | I1: [Escribir el número de créditos de la asignatura o módulo] | J1: [Escribir el número de horas de trabajo directo: 16*# o 12*#, para presencial o virtual, según sea el caso.] | K1: [Escribir el número de horas de trabajo independiente: 32*# columna J o 36*# columna J, para presencial o virtual, respectivamente.] | L1: [Escribir la suma de los números de horas de las dos celdas anteriores.] | M1: [Escribir el nombre de los cuatro núcleos temáticos que abordará la asignatura o el módulo.] | N1: [Escribir las lecturas, talleres, análisis, referentes, etc., que realiza el estudiante, clasificadas en trabajo directo e independiente.] | O1: [Escribir las actividades de evaluación que se emplean para identificar el alcance del (de los) indicador(es) de logro(s).] | P1: [Escribir las acciones de retroalimentación que se emplearán en la asignatura o módulo, para retroalimentar a los estudiantes respecto al alcance de los indicadores de logro. Recordar que son cuatro acciones: informar, formar, prevenir y ayudar a tomar decisiones e indique cómo.]
A2: Tipo de Saber | B2: Resultado de aprendizaje | C2: Semestre | D2: Nombre asignatura o módulo | E2: Indicadores de logro asignatura o módulo | F2: Tipología | G2: C.Fundamentación | H2: C.Profundización | I2: Créditos | J2: Número de horas trabajo directo | K2: Número de horas trabajo independiente | L2: Total de horas | M2: Núcleos temáticos | N2: Actividades de aprendizaje | O2: Actividades de evaluación | P2: Acciones de retroalimentación
A3: =_xlfn.XLOOKUP(B3,'Paso 3 Redacción RA'!I$3:I$11,'Paso 3 Redacción RA'!C$3:C$11,,0,1) -> Saber | B3: Reconoce los conceptos, técnicas y metodologías usadas en el desarrollo de proyectos de inteligencia de negocios para determinar los elementos y factores que se requieren en la formulación de soluciones tecnológicas que atiendan las necesidades del sector industrial y de las organizaciones. | C3: 1 | D3: Gerencia de Proyectos: Áreas Fundamentales | E3: Reconoce los conceptos de dirección de proyectos con base en las buenas prácticas establecidas en la Guía PMBOK® para aplicar las herramientas y técnicas de los dominios de desempeño de interesados, desarrollo, entrega y planificación en la gestión de proyectos. | F3: TP | H3: X | I3: 3 | J3: =12*I3 -> 36 | K3: =36*I3 -> 108 | L3: =SUM(J3:K6) -> 144 | M3: 1. Marco de Referencia de la Dirección de Proyectos y Gestión de la Integración 2. Dominio de Desempeño Interesados y Dominio de Desempeño de Entrega (Alcance) 3. Dominio de Desempeño Planificación (Cronograma) 4. Dominio de Desempeño Planificación (Costos) | N3: Trabajo directo: Encuentros sincronicos, mensajeria interna, foros generales, anuncios. Trabajo independiente: Lecturas Fundamentales y complementarias Anuncios Foros Actividades de refuerzo y recursos del modulo Revision de bases de datos lecturas en revistas indexadas. | O3: Evaluacion Formativa: Preguntas intercaladas durante los encuentros sincronicos y los foros. Sugerencias y recomendaciones dadas en los anuncios y en los diferentes tipos de comunicación con los estudiantes. Evaluacion Sumativa: Entrega Proyecto I Entrega Proyecto II Entrega Final y Sustentación | P3: Informar: a través de los anuncios, mensajeri o foros sobre las bases de datos para el desarrollo de las investigaciones necesarias para los casos de estudio propuestos por los estudiantes. Formar: con el analisis de los documentos presentados a los largo del modulo, se analizan las respuesta de los estudiantes y a partir de ello se realizan las anotaciones sobre las necesidades del caso expuesto para contribuir a la mejora del proyecto propuesto. Prevenir: a través de foros de participacion en los que los estudiantes pueden exponer sus dudas. Ayudar a tomar de tomar decisiones: con respecto a las investigaciones en el tema a tratar.
A4: =_xlfn.XLOOKUP(B4,'Paso 3 Redacción RA'!I$3:I$11,'Paso 3 Redacción RA'!C$3:C$11,,0,1) -> Saberhacer | B4: Diseña estrategias, herramientas y proyectos de inteligencia de negocios para dar soluciones adecuadas y transformadoras a problemas complejos organizacionales, teniendo en cuenta las necesidades y condiciones financieras y económicas del contexto.
A5: =_xlfn.XLOOKUP(B5,'Paso 3 Redacción RA'!I$3:I$11,'Paso 3 Redacción RA'!C$3:C$11,,0,1) -> Saberser | B5: Establece los elementos o factores que contribuyen a la generación de valor y a la transformación digital de las organizaciones para incorporarlos en el diseño de proyectos de inteligencia de negocios que impacten la gestión organizacional, de acuerdo con las condiciones de estas y el contexto en el que se encuentra.
A6: =_xlfn.XLOOKUP(B6,'Paso 3 Redacción RA'!I$3:I$11,'Paso 3 Redacción RA'!C$3:C$11,,0,1) -> Saber | B6: Evalúa información de las organizaciones, a partir del análisis de datos y la aplicación de metodologías de la inteligencia de negocios para determinar los proyectos y programas que se pueden diseñar e implementar en las organizaciones, de acuerdo con las necesidades que estas presentan.
A7: =_xlfn.XLOOKUP(B7,'Paso 3 Redacción RA'!I$3:I$11,'Paso 3 Redacción RA'!C$3:C$11,,0,1) -> Saber | B7: Reconoce los conceptos, técnicas y metodologías usadas en el desarrollo de proyectos de inteligencia de negocios para determinar los elementos y factores que se requieren en la formulación de soluciones tecnológicas que atiendan las necesidades del sector industrial y de las organizaciones. | C7: 1 | D7: Estado del Arte de la Gestión y de la Administración de la Información | E7: Reconoce el tipo de información necesaria en la creación de tableros de indicadores de gestión, para identificar las necesidades del caso de análisis de acuerdo con las herramientas de ofimática. | F7: T | G7: X | I7: 2 | J7: =12*I7 -> 24 | K7: =36*I7 -> 72 | L7: =SUM(J7:K10) -> 96 | M7: 1. Gestión de la información. 2. Retos que afronta el Business Intelligence y niveles de madurez del modelo de evolución de la información 3. Visualización de la información 4. Business Inteligencie Competency Center and Big Data Analytics | N7: Trabajo directo: Encuentros sincrónicos, mensajería interna, foros generales, anuncios. Trabajo independiente: Lecturas Fundamentales y complementarias Anuncios Foros Actividades de refuerzo y recursos del modulo Revisión de bases de datos lecturas en revistas indexadas. | O7: Evaluación Formativa: Preguntas intercaladas durante los encuentros sincrónicos y los foros. Sugerencias y recomendaciones dadas en los anuncios y en los diferentes tipos de comunicación con los estudiantes. Evaluación Sumativa: Evaluación Sumativa: Actividad en contexto (2) Foro analítico o argumentativo Quiz Evaluación final | P7: Informar: a través de los anuncios, mensajera o foros sobre las bases de datos para el desarrollo de las investigaciones necesarias para los casos de estudio propuestos por los estudiantes. Formar: con el análisis de los documentos presentados a los largo del módulo, se analizan las respuesta de los estudiantes y a partir de ello se realizan las anotaciones sobre las necesidades del caso expuesto para contribuir a la mejora del proyecto propuesto. Prevenir: a través de foros de participación en los que los estudiantes pueden exponer sus dudas. Ayudar a tomar de tomar decisiones: con respecto a las investigaciones en el tema a tratar. | U7: Comprender la importancia que tiene la gestión de información en las organizaciones para el cumplimiento de sus objetivos y el logro de una mejor salud financiera. Comprender que existe una relación directa entre el nivel de madurez del BI que posee una empresa, y los beneficios que la información le ofrece a esa organización al identificar oportunidades que conlleven a reducir costos o descubrir oportunidades para aumentar los ingresos. Comprender la importancia que tiene la visualización de la información en las organizaciones, es la forma conocer el estado real de la efectividad y eficiencia de los procesos, así como el cumplimiento de las metas asociadas a los objetivos estratégicos de la empresa. Los centros de competencias para la inteligencia de negocios son los garantes de la correcta gestión de información en las organizaciones, por lo tanto, se requiere las responsabilidades que tiene cada una de sus áreas funcionales.
A8: =_xlfn.XLOOKUP(B8,'Paso 3 Redacción RA'!I$3:I$11,'Paso 3 Redacción RA'!C$3:C$11,,0,1) -> Saberhacer | B8: Diseña estrategias, herramientas y proyectos de inteligencia de negocios para dar soluciones adecuadas y transformadoras a problemas complejos organizacionales, teniendo en cuenta las necesidades y condiciones financieras y económicas del contexto.
A9: =_xlfn.XLOOKUP(B9,'Paso 3 Redacción RA'!I$3:I$11,'Paso 3 Redacción RA'!C$3:C$11,,0,1) -> Saberser | B9: Establece los elementos o factores que contribuyen a la generación de valor y a la transformación digital de las organizaciones para incorporarlos en el diseño de proyectos de inteligencia de negocios que impacten la gestión organizacional, de acuerdo con las condiciones de estas y el contexto en el que se encuentra.
A10: =_xlfn.XLOOKUP(B10,'Paso 3 Redacción RA'!I$3:I$11,'Paso 3 Redacción RA'!C$3:C$11,,0,1) -> Saber | B10: Evalúa información de las organizaciones, a partir del análisis de datos y la aplicación de metodologías de la inteligencia de negocios para determinar los proyectos y programas que se pueden diseñar e implementar en las organizaciones, de acuerdo con las necesidades que estas presentan.
A11: =_xlfn.XLOOKUP(B11,'Paso 3 Redacción RA'!I$3:I$11,'Paso 3 Redacción RA'!C$3:C$11,,0,1) -> Saber | B11: Reconoce los conceptos, técnicas y metodologías usadas en el desarrollo de proyectos de inteligencia de negocios para determinar los elementos y factores que se requieren en la formulación de soluciones tecnológicas que atiendan las necesidades del sector industrial y de las organizaciones. | C11: 1 | D11: Fundamentos de Bases de Datos | E11: Reconoce los conceptos básicos, teóricos y prácticos del manejo de bases datos, para aplicarlos en los procesos de transformación de los datos y los futuros manejos de estos. | F11: TP | G11: X | I11: 2 | J11: =12*I11 -> 24 | K11: =36*I11 -> 72 | L11: =SUM(J11:K13) -> 96 | M11: 1. Generalidades en las bases de datos 2. Normalización, algebra y calculo relacional 3. Lenguaje de consulta estructurado SQL 4. Arquitectura de la bases de datos para la toma de decisiones | N11: Trabajo directo: Encuentros sincrónicos, mensajería interna, foros generales, anuncios. Trabajo independiente: Lecturas Fundamentales y complementarias Anuncios Foros Actividades de refuerzo y recursos del modulo Revisión de bases de datos lecturas en revistas indexadas. | O11: Evaluación Formativa: Preguntas intercaladas durante los encuentros sincrónicos y los foros. Sugerencias y recomendaciones dadas en los anuncios y en los diferentes tipos de comunicación con los estudiantes. Evaluación Sumativa: Actividad en contexto (2) Foro analítico o argumentativo Quiz Evaluación final | P11: Informar: a través de los anuncios, mensajera o foros sobre las bases de datos para el desarrollo de las investigaciones necesarias para los casos de estudio propuestos por los estudiantes. Formar: con el análisis de los documentos presentados a los largo del módulo, se analizan las respuesta de los estudiantes y a partir de ello se realizan las anotaciones sobre las necesidades del caso expuesto para contribuir a la mejora del proyecto propuesto. Prevenir: a través de foros de participación en los que los estudiantes pueden exponer sus dudas. Ayudar a tomar de tomar decisiones: con respecto a las investigaciones en el tema a tratar.
A12: =_xlfn.XLOOKUP(B12,'Paso 3 Redacción RA'!I$3:I$11,'Paso 3 Redacción RA'!C$3:C$11,,0,1) -> Saberhacer | B12: Diseña estrategias, herramientas y proyectos de inteligencia de negocios para dar soluciones adecuadas y transformadoras a problemas complejos organizacionales, teniendo en cuenta las necesidades y condiciones financieras y económicas del contexto.
A13: =_xlfn.XLOOKUP(B13,'Paso 3 Redacción RA'!I$3:I$11,'Paso 3 Redacción RA'!C$3:C$11,,0,1) -> Saber | B13: Evalúa información de las organizaciones, a partir del análisis de datos y la aplicación de metodologías de la inteligencia de negocios para determinar los proyectos y programas que se pueden diseñar e implementar en las organizaciones, de acuerdo con las necesidades que estas presentan.
A14: =_xlfn.XLOOKUP(B14,'Paso 3 Redacción RA'!I$3:I$11,'Paso 3 Redacción RA'!C$3:C$11,,0,1) -> Saber | B14: Reconoce los conceptos, técnicas y metodologías usadas en el desarrollo de proyectos de inteligencia de negocios para determinar los elementos y factores que se requieren en la formulación de soluciones tecnológicas que atiendan las necesidades del sector industrial y de las organizaciones. | C14: I | D14: Gerencia de Proyectos: Áreas Complementarias | E14: Reconoce los conceptos de dirección de proyectos con base en las buenas prácticas establecidas en la Guía PMBOK® para aplicar las herramientas y técnicas de los dominios de desempeño entrega, incertidumbre, equipo y desarrollo en la gestión de proyectos. | F14: TP | H14: X | I14: 3 | J14: =12*I14 -> 36 | K14: =36*I14 -> 108 | L14: =SUM(J14:K17) -> 144 | M14: 1. El dominio de desempeño entrega de proyectos (Calidad) 2. El dominio de desempeño Incertidumbre de proyectos 3. El dominio de desempeño Equipo de proyectos 4. El dominio de desempeño Desarrollo de proyectos (recursos y adquisidores) | N14: Trabajo directo: Encuentros sincrónicos, mensajería interna, foros generales, anuncios. Trabajo independiente: Lecturas Fundamentales y complementarias Anuncios Foros Actividades de refuerzo y recursos del modulo Revisión de bases de datos lecturas en revistas indexadas. | O14: Evaluación Formativa: Preguntas intercaladas durante los encuentros sincrónicos y los foros. Sugerencias y recomendaciones dadas en los anuncios y en los diferentes tipos de comunicación con los estudiantes. Evaluación Sumativa: Entrega Proyecto I Entrega Proyecto II Entrega Final y Sustentación | P14: Informar: a través de los anuncios, mensajera o foros sobre las bases de datos para el desarrollo de las investigaciones necesarias para los casos de estudio propuestos por los estudiantes. Formar: con el análisis de los documentos presentados a los largo del módulo, se analizan las respuesta de los estudiantes y a partir de ello se realizan las anotaciones sobre las necesidades del caso expuesto para contribuir a la mejora del proyecto propuesto. Prevenir: a través de foros de participación en los que los estudiantes pueden exponer sus dudas. Ayudar a tomar de tomar decisiones: con respecto a las investigaciones en el tema a tratar.
A15: =_xlfn.XLOOKUP(B15,'Paso 3 Redacción RA'!I$3:I$11,'Paso 3 Redacción RA'!C$3:C$11,,0,1) -> Saberhacer | B15: Diseña estrategias, herramientas y proyectos de inteligencia de negocios para dar soluciones adecuadas y transformadoras a problemas complejos organizacionales, teniendo en cuenta las necesidades y condiciones financieras y económicas del contexto.
A16: =_xlfn.XLOOKUP(B16,'Paso 3 Redacción RA'!I$3:I$11,'Paso 3 Redacción RA'!C$3:C$11,,0,1) -> Saberser | B16: Establece los elementos o factores que contribuyen a la generación de valor y a la transformación digital de las organizaciones para incorporarlos en el diseño de proyectos de inteligencia de negocios que impacten la gestión organizacional, de acuerdo con las condiciones de estas y el contexto en el que se encuentra.
A17: =_xlfn.XLOOKUP(B17,'Paso 3 Redacción RA'!I$3:I$11,'Paso 3 Redacción RA'!C$3:C$11,,0,1) -> Saber | B17: Evalúa información de las organizaciones, a partir del análisis de datos y la aplicación de metodologías de la inteligencia de negocios para determinar los proyectos y programas que se pueden diseñar e implementar en las organizaciones, de acuerdo con las necesidades que estas presentan.
A18: =_xlfn.XLOOKUP(B18,'Paso 3 Redacción RA'!I$3:I$11,'Paso 3 Redacción RA'!C$3:C$11,,0,1) -> Saberhacer | B18: Diseña estrategias, herramientas y proyectos de inteligencia de negocios para dar soluciones adecuadas y transformadoras a problemas complejos organizacionales, teniendo en cuenta las necesidades y condiciones financieras y económicas del contexto. | C18: 1 | D18: Conceptualización y Análisis Financiero | E18: Conoce las normas internacionales de información financiera NIIF, utilizados para expresar los estados financieros con el fin de interpretar las cifras de la organización. Aplica herramientas de análisis financiero para determinar la situación financiera en un periodo determinado. Explica los indicadores de generación de valor, para determinar si el proyecto genera o destruye valor. | F18: TP | G18: X | I18: 3 | J18: =12*I18 -> 36 | K18: =36*I18 -> 108 | L18: =SUM(J18:K18) -> 144 | M18: 1. Las cuentas derivadas en el desarrollo del negocio empresarial 2. Los estados financieros 3. Introducción al análisis financiero 4. Gerencia financiera basada en valor | N18: Trabajo directo: Encuentros sincrónicos, mensajería interna, foros generales, anuncios. Trabajo independiente: Lecturas Fundamentales y complementarias Anuncios Foros Actividades de refuerzo y recursos del modulo Revisión de bases de datos lecturas en revistas indexadas. | O18: Evaluación Formativa: Preguntas intercaladas durante los encuentros sincrónicos y a través de los foros. Sugerencias y recomendaciones dadas en los anuncios y en los diferentes tipos de comunicación con los estudiantes. Evaluación Sumativa: Actividad en contexto (2) Foro analítico o argumentativo Quiz Evaluación final | P18: Informar: a través de los anuncios, mensajera o foros sobre las bases de datos para el desarrollo de las investigaciones necesarias para los casos de estudio propuestos por los estudiantes. Formar: con el análisis de los documentos presentados a los largo del módulo, se analizan las respuesta de los estudiantes y a partir de ello se realizan las anotaciones sobre las necesidades del caso expuesto para contribuir a la mejora del proyecto propuesto. Prevenir: a través de foros de participación en los que los estudiantes pueden exponer sus dudas. Ayudar a tomar de tomar decisiones: con respecto a las investigaciones en el tema a tratar.
A19: =_xlfn.XLOOKUP(B19,'Paso 3 Redacción RA'!I$3:I$11,'Paso 3 Redacción RA'!C$3:C$11,,0,1) -> Saberser | B19: Establece los elementos o factores que contribuyen a la generación de valor y a la transformación digital de las organizaciones para incorporarlos en el diseño de proyectos de inteligencia de negocios que impacten la gestión organizacional, de acuerdo con las condiciones de estas y el contexto en el que se encuentra.
A20: =_xlfn.XLOOKUP(B20,'Paso 3 Redacción RA'!I$3:I$11,'Paso 3 Redacción RA'!C$3:C$11,,0,1) -> Saber | B20: Evalúa información de las organizaciones, a partir del análisis de datos y la aplicación de metodologías de la inteligencia de negocios para determinar los proyectos y programas que se pueden diseñar e implementar en las organizaciones, de acuerdo con las necesidades que estas presentan.
A21: =_xlfn.XLOOKUP(B21,'Paso 3 Redacción RA'!I$3:I$11,'Paso 3 Redacción RA'!C$3:C$11,,0,1) -> Saber | B21: Reconoce los conceptos, técnicas y metodologías usadas en el desarrollo de proyectos de inteligencia de negocios para determinar los elementos y factores que se requieren en la formulación de soluciones tecnológicas que atiendan las necesidades del sector industrial y de las organizaciones. | C21: 2 | D21: Minería de Datos | E21: Reconoce las técnicas de segmentación, clasificación y asociación en la minería de datos, en grandes bases de datos de manera automática y semiautomática, para encontrar patrones repetitivos o tendencias que expliquen el comportamiento de los datos. | F21: TP | H21: X | I21: 3 | J21: =12*I21 -> 36 | K21: =36*I21 -> 108 | L21: =SUM(J21:K23) -> 144 | M21: 1. Introducción a la minería de datos 2. Análisis en la clasificación 3. Análisis de clúster 4. Reglas de asociación | N21: Trabajo directo: Encuentros sincrónicos, mensajería interna, foros generales, anuncios. Trabajo independiente: Lecturas Fundamentales y complementarias Anuncios Foros Actividades de refuerzo y recursos del modulo Revisión de bases de datos lecturas en revistas indexadas. | O21: Evaluación Formativa: Preguntas intercaladas durante los encuentros sincrónicos y los foros. Sugerencias y recomendaciones dadas en los anuncios y en los diferentes tipos de comunicación con los estudiantes. Evaluación Sumativa: Entrega Proyecto I Entrega Proyecto II Entrega Final y Sustentación | P21: Informar: a través de los anuncios, mensajera o foros sobre las bases de datos para el desarrollo de las investigaciones necesarias para los casos de estudio propuestos por los estudiantes. Formar: con el análisis de los documentos presentados a los largo del módulo, se analizan las respuesta de los estudiantes y a partir de ello se realizan las anotaciones sobre las necesidades del caso expuesto para contribuir a la mejora del proyecto propuesto. Prevenir: a través de foros de participación en los que los estudiantes pueden exponer sus dudas. Ayudar a tomar de tomar decisiones: con respecto a las investigaciones en el tema a tratar.
A22: =_xlfn.XLOOKUP(B22,'Paso 3 Redacción RA'!I$3:I$11,'Paso 3 Redacción RA'!C$3:C$11,,0,1) -> Saberhacer | B22: Diseña estrategias, herramientas y proyectos de inteligencia de negocios para dar soluciones adecuadas y transformadoras a problemas complejos organizacionales, teniendo en cuenta las necesidades y condiciones financieras y económicas del contexto.
A23: =_xlfn.XLOOKUP(B23,'Paso 3 Redacción RA'!I$3:I$11,'Paso 3 Redacción RA'!C$3:C$11,,0,1) -> Saber | B23: Evalúa información de las organizaciones, a partir del análisis de datos y la aplicación de metodologías de la inteligencia de negocios para determinar los proyectos y programas que se pueden diseñar e implementar en las organizaciones, de acuerdo con las necesidades que estas presentan.
A24: =_xlfn.XLOOKUP(B24,'Paso 3 Redacción RA'!I$3:I$11,'Paso 3 Redacción RA'!C$3:C$11,,0,1) -> Saber | B24: Reconoce los conceptos, técnicas y metodologías usadas en el desarrollo de proyectos de inteligencia de negocios para determinar los elementos y factores que se requieren en la formulación de soluciones tecnológicas que atiendan las necesidades del sector industrial y de las organizaciones. | C24: 2 | D24: Formulación y Evaluación de Proyectos | E24: Aplica el análisis de estudio de mercado en los procesos de toma de decisiones y los conceptos técnicos para reconocer la viabilidad de un proyecto y de esta manera tomar decisiones sobre la factibilidad de este. | F24: TP | G24: X | I24: 2 | J24: =12*I24 -> 24 | K24: =36*I24 -> 72 | L24: =SUM(J24:K27) -> 96 | M24: 1. Gestión de proyectos y estudios de mercados 2. Principios matemáticos y presupuesto básico 3. Indicadores financieros 4. Evaluación de proyectos y herramientas adicionales | N24: Trabajo directo: Encuentros sincrónicos, mensajería interna, foros generales, anuncios. Trabajo independiente: Lecturas Fundamentales y complementarias Anuncios Foros Actividades de refuerzo y recursos del modulo Revisión de bases de datos lecturas en revistas indexadas. | O24: Evaluación Formativa: Preguntas intercaladas durante los encuentros sincrónicos y los foros. Sugerencias y recomendaciones dadas en los anuncios y en los diferentes tipos de comunicación con los estudiantes. Evaluación Sumativa: Actividad en contexto (2) Foro analítico o argumentativo Quiz Evaluación final | P24: Informar: a través de los anuncios, mensajera o foros sobre las bases de datos para el desarrollo de las investigaciones necesarias para los casos de estudio propuestos por los estudiantes. Formar: con el análisis de los documentos presentados a los largo del módulo, se analizan las respuesta de los estudiantes y a partir de ello se realizan las anotaciones sobre las necesidades del caso expuesto para contribuir a la mejora del proyecto propuesto. Prevenir: a través de foros de participación en los que los estudiantes pueden exponer sus dudas. Ayudar a tomar de tomar decisiones: con respecto a las investigaciones en el tema a tratar.
A25: =_xlfn.XLOOKUP(B25,'Paso 3 Redacción RA'!I$3:I$11,'Paso 3 Redacción RA'!C$3:C$11,,0,1) -> Saberhacer | B25: Diseña estrategias, herramientas y proyectos de inteligencia de negocios para dar soluciones adecuadas y transformadoras a problemas complejos organizacionales, teniendo en cuenta las necesidades y condiciones financieras y económicas del contexto.
A26: =_xlfn.XLOOKUP(B26,'Paso 3 Redacción RA'!I$3:I$11,'Paso 3 Redacción RA'!C$3:C$11,,0,1) -> Saberser | B26: Establece los elementos o factores que contribuyen a la generación de valor y a la transformación digital de las organizaciones para incorporarlos en el diseño de proyectos de inteligencia de negocios que impacten la gestión organizacional, de acuerdo con las condiciones de estas y el contexto en el que se encuentra.
A27: =_xlfn.XLOOKUP(B27,'Paso 3 Redacción RA'!I$3:I$11,'Paso 3 Redacción RA'!C$3:C$11,,0,1) -> Saber | B27: Evalúa información de las organizaciones, a partir del análisis de datos y la aplicación de metodologías de la inteligencia de negocios para determinar los proyectos y programas que se pueden diseñar e implementar en las organizaciones, de acuerdo con las necesidades que estas presentan.
A28: =_xlfn.XLOOKUP(B28,'Paso 3 Redacción RA'!I$3:I$11,'Paso 3 Redacción RA'!C$3:C$11,,0,1) -> Saber | B28: Reconoce los conceptos, técnicas y metodologías usadas en el desarrollo de proyectos de inteligencia de negocios para determinar los elementos y factores que se requieren en la formulación de soluciones tecnológicas que atiendan las necesidades del sector industrial y de las organizaciones. | C28: 2 | D28: Implementación de Soluciones de Alta Tecnología en Inteligencia de Negocios | E28: Analiza las estrategias de implementación de soluciones de inteligencia de negocios, de acuerdo con las características tecnológicas y perspectivas de crecimiento de una organización, para proyectar las necesidades futuras de la empresa, con respecto al manejo de los datos y el funcionamiento del mismo. | F28: TP | H28: X | I28: 2 | J28: =12*I28 -> 24 | K28: =36*I28 -> 72 | L28: =SUM(J28:K30) -> 96 | M28: 1. Gobierno de la información, sistemas y metodologías en BI 2. Manejo de recursos tecnológicos para IB 3. Modelado de la bodega de datos 4. Consideraciones de calidad | N28: Trabajo directo: Encuentros sincrónicos, mensajería interna, foros generales, anuncios. Trabajo independiente: Lecturas Fundamentales y complementarias Anuncios Foros Actividades de refuerzo y recursos del modulo Revisión de bases de datos lecturas en revistas indexadas. | O28: Evaluación Formativa: Preguntas intercaladas durante los encuentros sincrónicos y los foros. Sugerencias y recomendaciones dadas en los anuncios y en los diferentes tipos de comunicación con los estudiantes. Evaluación Sumativa: Entrega Proyecto I Entrega Proyecto II Entrega Final y Sustentación | P28: Informar: a través de los anuncios, mensajera o foros sobre las bases de datos para el desarrollo de las investigaciones necesarias para los casos de estudio propuestos por los estudiantes. Formar: con el análisis de los documentos presentados a los largo del módulo, se analizan las respuesta de los estudiantes y a partir de ello se realizan las anotaciones sobre las necesidades del caso expuesto para contribuir a la mejora del proyecto propuesto. Prevenir: a través de foros de participación en los que los estudiantes pueden exponer sus dudas. Ayudar a tomar de tomar decisiones: con respecto a las investigaciones en el tema a tratar.
A29: =_xlfn.XLOOKUP(B29,'Paso 3 Redacción RA'!I$3:I$11,'Paso 3 Redacción RA'!C$3:C$11,,0,1) -> Saberhacer | B29: Diseña estrategias, herramientas y proyectos de inteligencia de negocios para dar soluciones adecuadas y transformadoras a problemas complejos organizacionales, teniendo en cuenta las necesidades y condiciones financieras y económicas del contexto.
A30: =_xlfn.XLOOKUP(B30,'Paso 3 Redacción RA'!I$3:I$11,'Paso 3 Redacción RA'!C$3:C$11,,0,1) -> Saber | B30: Evalúa información de las organizaciones, a partir del análisis de datos y la aplicación de metodologías de la inteligencia de negocios para determinar los proyectos y programas que se pueden diseñar e implementar en las organizaciones, de acuerdo con las necesidades que estas presentan.
A31: =_xlfn.XLOOKUP(B31,'Paso 3 Redacción RA'!I$3:I$11,'Paso 3 Redacción RA'!C$3:C$11,,0,1) -> Saber | B31: Reconoce los conceptos, técnicas y metodologías usadas en el desarrollo de proyectos de inteligencia de negocios para determinar los elementos y factores que se requieren en la formulación de soluciones tecnológicas que atiendan las necesidades del sector industrial y de las organizaciones. | C31: 2 | D31: Modelos Tecnológicos en BI | E31: Interpreta la información externa de carácter estratégico de las organizaciones para proyectar alternativas de solución orientadas a la toma de decisiones, en un ambiente dinámico y competitivo. | F31: TP | H31: X | I31: 2 | J31: =12*I31 -> 24 | K31: =36*I31 -> 72 | L31: =SUM(J31:K34) -> 96 | M31: 1. Introducción a la estrategia empresarial 2. Modelos de análisis estratégicos y competitivo. 3. Análisis competitivo y de cliente: capacidad funcional y de recursos 4. Técnicas de análisis de contexto y análisis con técnicas evolutivas | N31: Trabajo directo: Encuentros sincrónicos, mensajería interna, foros generales, anuncios. Trabajo independiente: Lecturas Fundamentales y complementarias Anuncios Foros Actividades de refuerzo y recursos del modulo Revisión de bases de datos lecturas en revistas indexadas. | O31: Evaluación Formativa: Preguntas intercaladas durante los encuentros sincrónicos y los foros. Sugerencias y recomendaciones dadas en los anuncios y en los diferentes tipos de comunicación con los estudiantes. Evaluación Sumativa: Entrega Proyecto I Entrega Proyecto II Entrega Final y Sustentación | P31: Informar: a través de los anuncios, mensajera o foros sobre las bases de datos para el desarrollo de las investigaciones necesarias para los casos de estudio propuestos por los estudiantes. Formar: con el análisis de los documentos presentados a los largo del módulo, se analizan las respuesta de los estudiantes y a partir de ello se realizan las anotaciones sobre las necesidades del caso expuesto para contribuir a la mejora del proyecto propuesto. Prevenir: a través de foros de participación en los que los estudiantes pueden exponer sus dudas. Ayudar a tomar de tomar decisiones: con respecto a las investigaciones en el tema a tratar.
A32: =_xlfn.XLOOKUP(B32,'Paso 3 Redacción RA'!I$3:I$11,'Paso 3 Redacción RA'!C$3:C$11,,0,1) -> Saberhacer | B32: Diseña estrategias, herramientas y proyectos de inteligencia de negocios para dar soluciones adecuadas y transformadoras a problemas complejos organizacionales, teniendo en cuenta las necesidades y condiciones financieras y económicas del contexto.
A33: =_xlfn.XLOOKUP(B33,'Paso 3 Redacción RA'!I$3:I$11,'Paso 3 Redacción RA'!C$3:C$11,,0,1) -> Saberser | B33: Establece los elementos o factores que contribuyen a la generación de valor y a la transformación digital de las organizaciones para incorporarlos en el diseño de proyectos de inteligencia de negocios que impacten la gestión organizacional, de acuerdo con las condiciones de estas y el contexto en el que se encuentra.
A34: =_xlfn.XLOOKUP(B34,'Paso 3 Redacción RA'!I$3:I$11,'Paso 3 Redacción RA'!C$3:C$11,,0,1) -> Saber | B34: Evalúa información de las organizaciones, a partir del análisis de datos y la aplicación de metodologías de la inteligencia de negocios para determinar los proyectos y programas que se pueden diseñar e implementar en las organizaciones, de acuerdo con las necesidades que estas presentan.
