Workbook
Name ActitudinalBAK: 'Taxonomias para RA'!$AC$3:$AG$3
Name Bloom: 'Taxonomias para RA'!$G$3:$I$3
Name Circutos: 'Paso 2 Redacción competen'!$F$4
Name CognitivoBAK: 'Taxonomias para RA'!$S$3:$X$3
Name CompetenciaEspecifica1: 'Paso 2 Redacción competen'!$F$4
Name ComponentesCompetencias: #REF!
Name ComponentesCompetencias: 'Paso1 Analisis perfil egreso'!$E$2:$G$2
Name Creditos: #REF!,#REF!,#REF!,#REF!,#REF!,#REF!,#REF!,#REF!,#REF!
Name FACULTADES: #REF!
Name ProcedimentalBAK: 'Taxonomias para RA'!$Y$3:$AB$3
Name RA: 'Paso 5 Estrategias micro'!$B$10
Name RA: #REF!
Name resultadoaprendizaje: #REF!
Name resultadoaprendizaje: #REF!
Name Saber: 'Paso1 Analisis perfil egreso'!$E$3:$E$9
Name SaberHacer: 'Paso1 Analisis perfil egreso'!$F$3:$F$9
Name SaberSer: 'Paso1 Analisis perfil egreso'!$G$3:$G$9
Name TIC: 'Paso 2 Redacción competen'!$F$9

Sheet Paso1 Analisis perfil egreso
A1: [Escribir el nombre del programa] | B1: [Escribir la modalidad: presencial o virtual] | C1: [Escribir el perfil profesional del egresado.] | D1: [Escribir el perfil ocupacional del egresado.] | E1: Componentes fundamentales aplicables a la solución de problemas en la vida profesional [Listar, según lo escrito en el perfil profesional, qué debe saber el egresado en las categorías de Saber -conocimientos, hechos, teorías-, Saber hacer -técnicas, procedimientos, metodologías-, y Saber ser -valores, condiciones, etc.] | H1: Componentes fundamentales de la ocupación laboral del profesional [Listar, según lo escrito en el perfil ocupacional, en qué áreas, qué tareas potenciales y en qué poblaciones o contextos podrá laborar el profesional.] | K1: Diferencial (valor agregado) del profesional [Listar, según lo escrito en los perfiles, los elementos que son diferenciales y generan un valor agregado al egresado.]
A2: Programa | B2: Modalidad | C2: Perfil profesional | D2: Perfil ocupacional | E2: Saber | F2: SaberHacer | G2: SaberSer | H2: Áreas profesionales | I2: Tareas profesionales | J2: Poblaciones actuación | K2: Valor agregado
A3: Derecho | B3: Virtual | C3: El egresado del programa de Derecho del Politécnico Grancolombiano actúa con perspectiva crítica, analítica, argumentativa e interdisciplinar en cada una de las áreas del ejercicio profesional del abogado; es competitivo, eficiente, tiene habilidades para la negociación, la conciliación y la resolución de conflictos; apropia la responsabilidad social y desarrolla sus conocimientos con ética profesional. Cuenta con capacidad para comprender, abordar y dar soluciones jurídicas a los desafíos de la sociedad y de las organizaciones tanto públicas como privadas, desempeñándose en cargos de dirección y gestión, brindando asesoría y consultoría o ejerciendo funciones de investigación en materia jurídica a nivel nacional e internacional. | D3: El abogado Grancolombiano está capacitado para actuar con criterio ético, competitividad y eficiencia dentro de múltiples ámbitos del ejercicio profesional, desempeñándose en campos de asesoría y consultoría jurídica y organizacional a nivel público y privado; cargos de dirección y gestión de organizaciones empresariales; funciones de investigación en materia socio jurídica y empresarial. Igualmente, podrá actuar como profesional al servicio de la administración de justicia; de instituciones o empresas del sector público y privado; como abogado independiente en cualquier área del Derecho; con orientación hacia la solución alternativa de conflictos; y como docente en áreas del Derecho con particular énfasis por el desarrollo empresarial. | E3: Derecho privado | F3: aplicar los derechos y obligaciones que surgen de relaciones jurídicas entre los particulares, así como buscar su cumplimiento o declaración en escenarios judiciales | G3: de acuerdo con los diferentes instrumentos internacionales, constitucionales, legales y reglamentarios que comprende el derecho civil en escenarios de consulta y litigio | H3: Asesor jurídico en entidades públicas o privadas / Consultor legal corporativo / Oficial de cumplimiento legal y normativo / Consultor en contratación estatal, derecho laboral o tributario / Abogado litigante en áreas civil, penal, laboral, administrativa y comercial / Defensor público / Fiscal o Procurador (previo cumplimiento de requisitos del sistema judicial) / Representante legal en procesos judiciales y extrajudiciales / Coordinador o jefe de asuntos jurídicos / Gerente jurídico en organizaciones empresariales / Director de departamentos legales o unidades normativas / Líder de cumplimiento legal y regulatorio / Funcionario judicial / Servidor público en personerías, defensorías del pueblo, procuradurías y juzgados / Abogado en organismos de control, tribunales o entidades gubernamentales / Asesor legislativo en cuerpos normativos o comisiones / Conciliador extrajudicial en derecho / Mediador o negociador jurídico / Árbitro en procesos civiles y comerciales / Coordinador de proyectos de investigación en derecho, política o ciencias sociales / Analista de política pública y normativa / Docente universitario en áreas del derecho / Abogado en organizaciones internacionales (derechos humanos, comercio, cooperación) / Consultor en proyectos jurídicos internacionales o transnacionales / Defensor de derechos ante cortes internacionales o redes de cooperación. | I3: Elaborar conceptos jurídicos sobre normativas aplicables a casos específicos. / Revisar, redactar y negociar contratos civiles, comerciales y laborales. / Brindar asesoría jurídica a empresas en temas societarios, tributarios o laborales. / Interpretar normas y jurisprudencia para proponer soluciones legales. / Diseñar estrategias legales preventivas para organizaciones públicas y privadas. / Representar clientes en procesos judiciales ante tribunales civiles, penales, laborales y administrativos. / Elaborar demandas, contestaciones, recursos y demás piezas procesales. / Comparecer en audiencias públicas y privadas en calidad de apoderado judicial. / Asesorar jurídicamente a víctimas o imputados en procesos penales. / Ejecutar estrategias de defensa técnica en litigios civiles o comerciales. / Coordinar equipos legales internos en organizaciones empresariales. / Supervisar el cumplimiento normativo de las operaciones jurídicas de la entidad. / Diseñar y aplicar políticas jurídicas internas, manuales y procedimientos legales. / Evaluar riesgos jurídicos en la toma de decisiones estratégicas de la organización. / Representar jurídicamente a empresas ante autoridades administrativas o judiciales. / Apoyar en la elaboración de providencias, autos o sentencias como auxiliar jurídico. / Actuar como secretario de despacho en juzgados o tribunales. / Tramitar expedientes judiciales y dar soporte técnico a jueces o magistrados. / Asesorar jurídicamente a entidades estatales o de control. / Participar en procesos de vigilancia de derechos humanos desde defensorías y personerías. / Participar como conciliador extrajudicial en centros de conciliación. / Redactar acuerdos de conciliación legalmente válidos. / Actuar como facilitador en procesos de negociación privada o institucional. / Diseñar estrategias jurídicas para prevenir y resolver conflictos sin litigio. / Asesorar a partes interesadas en procedimientos de mediación o arbitraje. / Formular problemas jurídicos y estructurar proyectos de investigación. / Analizar fuentes doctrinales, jurisprudenciales y normativas. / Participar en actividades académicas como foros, talleres y simulaciones jurídicas. / Analizar y aplicar normas del derecho internacional público y privado. / Asesorar en materia de derechos humanos, comercio internacional y cooperación jurídica. / Participar en redacción de informes para organismos internacionales. / Apoyar misiones jurídicas internacionales o transnacionales. / Actuar como enlace legal en proyectos binacionales o multilaterales. | J3: Ciudadanos en general que requieren defensa, asesoría o representación legal. / Víctimas o imputados en procesos penales. / Individuos en situaciones de conflicto civil, familiar, laboral o administrativo. / Personas en procesos de conciliación o mediación. / Micro, pequeñas, medianas y grandes empresas. / Organizaciones con actividades comerciales, industriales, tecnológicas o del sector servicios. / Fundaciones y asociaciones sin ánimo de lucro. / Entidades financieras y corporaciones multinacionales. / Alcaldías, gobernaciones y entidades descentralizadas. / Entidades del orden nacional (ministerios, superintendencias, agencias estatales). / Órganos de control (Procuraduría, Contraloría, Defensoría del Pueblo). / Juzgados, tribunales y fiscalías. / Población en situación de pobreza o exclusión social. / Víctimas del conflicto armado interno. / Comunidades étnicas (pueblos indígenas, comunidades afrodescendientes, raizales y ROM). / Personas privadas de la libertad o en procesos de resocialización. / Mujeres víctimas de violencia y personas con discapacidad. / Menores en situación de riesgo o vulneración de derechos. / Sujetos de procesos de adopción, custodia, alimentos o responsabilidad parental. / Víctimas o victimarios en procesos penales de responsabilidad penal juvenil. / Sindicatos, cooperativas, movimientos sociales y colectivos ciudadanos. / Agrupaciones de defensa de derechos humanos o del medio ambiente. / Representaciones legales de barrios, veredas o comunidades rurales. / Asociaciones de víctimas o líderes comunitarios. / Migrantes, refugiados o solicitantes de asilo. / Personas y empresas vinculadas a relaciones jurídicas internacionales. / Instituciones extranjeras que requieren asesoría legal en Colombia. / Población atendida en misiones humanitarias o jurídicas transnacionales. | K3: El programa de Derecho del Politécnico Grancolombiano se distingue por integrar, de forma consistente a lo largo del currículo, contenidos orientados al derecho empresarial, lo que permite a los estudiantes interpretar el entorno organizacional y abordar sus retos jurídicos con criterio normativo y sentido práctico. Esta orientación específica diferencia al programa al incluir temáticas como sociedades, consumo, competencia y derecho corporativo. La estructura curricular incorpora la práctica jurídica desde los consultorios y fomenta una mirada crítica sobre el papel del derecho en la actividad empresarial y su impacto social. Este enfoque brinda al egresado una ventaja formativa en sectores que demandan asesoría jurídica con perspectiva organizacional, donde convergen normatividad, economía y responsabilidad social.
E4: Derecho comercial | F4: asesorar en la generación, modificación o extinción de obligaciones, así como para elaborar contratos de cualquier tipología | G4: de acuerdo con la normatividad colombiana y los estándares internacionales vigentes en planeación, control y administración empresarial
E5: Derecho público | F5: identificar los diferentes instrumentos constitucionales, legales y reglamentarios que comprenden las relaciones con intervención del Estado | G5: de acuerdo con el marco universal de principios y valores propios del Estado Social de Derecho y de la Democracia Participativa, desde una perspectiva social, económica, política y humanista, dentro del contexto nacional e internacional
E6: Derecho penal | F6: asumir y resolver asuntos en pro de la defensa, la acusación o el juzgamiento de conductas punibles, así como la aplicación en cada caso en concreto de los fundamentos del derecho procesal penal | G6: de conformidad con los principios rectores de la actividad penal, como la buena fe, la duda, la presunción de inocencia, y en general la Constitución Política, los fundamentos del Derecho y sus fuentes
E7: Negociación y resolución de conflictos | F7: hacer uso de los diferentes métodos alternativos de solución de conflictos auto y hetero compositivos | G7: de acuerdo con las posibilidades que la ley ofrece, que permiten racionalizar e interpretar los desencuentros que se presentan en las relaciones familiares, sociales, políticas y laborales, así como la toma de conciencia de la existencia y del manejo adecuado de los conflictos
E8: Relaciones de producción desde el ámbito interdisciplinar, según el entorno en el que se desenvuelven los individuos en las organizaciones, empresas o instituciones | F8: comprender los modelos económicos, políticos, laborales y sociales, así como las problemáticas que existen o emergen de estas relaciones | G8: teniendo en cuenta el ordenamiento jurídico colombiano y las políticas económicas
E9: Fenómenos contemporáneos | F9: reconocer sus afectaciones o contribuciones en el marco de las ciudadanías globales y de una sociedad responsable y sostenible | G9: desde una perspectiva global, soportada en datos, con una mirada ética y crítica

Sheet Paso 2 Redacción competen
A1: Elementos para redactar las competencias que desarrollará el programa
A2: [Enumerar las competencias que se van a declarar.] | B2: [A partir de la celda B2 dar clic sobre el ícono de lista desplegable y elegir el verbo que considere adecuado.] | C2: [A partir de la celda C2 dar clic sobre la lista desplegable y elegir el saber extraído del perfil de egreso.] | D2: [Escribir para qué se abordará el saber elegido. Se sugiere apoyarse en el saber hacer.] | E2: [Escribir la condición describiendo los referentes, parámetros, principios, requerimientos o retos que se necesitan para alcanzar las características del perfil en el contexto donde el egresado se desenvolverá.] | F2: [Articular los componentes. Iniciar con el verbo, continuar con el objeto conceptual, luego la finalidad y condición de contexto o referencia; estos últimos no requieren un orden particular.] | G2: [Escribir el tipo de competencia del perfil: Específica (si es del bloque Disciplinar para pregrado o de los componentes para el caso de posgrado) o Genérica (si aplica bloque institucional pregrado)]
A3: No. | B3: Verbo competencia | C3: Objeto conceptual | D3: Finalidad | E3: Condición de contexto o referencia | F3: Redacción competencia | G3: Tipo de competencia
A4: 1 | B4: Dominar | C4: Derecho privado | D4: aplicar los derechos y obligaciones que surgen de relaciones jurídicas entre los particulares, así como buscar su cumplimiento o declaración en escenarios judiciales | E4: de acuerdo con los diferentes instrumentos internacionales, constitucionales, legales y reglamentarios que comprende el derecho civil en escenarios de consulta y litigio | F4: Dominar el derecho privado, para aplicar los derechos y obligaciones que surgen de relaciones jurídicas entre los particulares, así como buscar su cumplimiento o declaración en escenarios judiciales, de acuerdo con los diferentes instrumentos internacionales, constitucionales, legales y reglamentarios que comprende el derecho civil en escenarios de consulta y litigio. | G4: Específica
A5: 2 | B5: Dominar | C5: Derecho comercial | D5: asesorar en la generación, modificación o extinción de obligaciones, así como para elaborar contratos de cualquier tipología | E5: de acuerdo con la normatividad colombiana y los estándares internacionales vigentes en planeación, control y administración empresarial | F5: Dominar el derecho comercial, para asesorar en la generación, modificación o extinción de obligaciones, así como para elaborar contratos de cualquier tipología, de acuerdo con al normatividad colombiana y los estándares internacionales vigentes en planeación, control y administración empresarial. | G5: Específica
A6: 3 | B6: Conocer | C6: Derecho público | D6: identificar los diferentes instrumentos constitucionales, legales y reglamentarios que comprenden las relaciones con intervención del Estado | E6: de acuerdo con el marco universal de principios y valores propios del Estado Social de Derecho y de la Democracia Participativa, desde una perspectiva social, económica, política y humanista, dentro del contexto nacional e internacional | F6: Conocer el derecho público, para identificar los diferentes instrumentos constitucionales, legales y reglamentarios que comprenden las relaciones con intervención del Estado, de acuerdo con el marco universal de principios y valores propios del Estado Social de Derecho y de la Democracia Participativa, desde una perspectiva social, económica, política y humanista, dentro del contexto nacional e internacional. | G6: Específica
A7: 4 | B7: Aplicar | C7: Derecho penal | D7: asumir y resolver asuntos en pro de la defensa, la acusación o el juzgamiento de conductas punibles, así como la aplicación en cada caso en concreto de los fundamentos del derecho procesal penal | E7: de conformidad con los principios rectores de la actividad penal, como la buena fe, la duda, la presunción de inocencia, y en general la Constitución Política, los fundamentos del Derecho y sus fuentes | F7: Aplicar el derecho penal, para asumir y resolver asuntos en pro de la defensa, la acusación o el juzgamiento de conductas punibles, así como la aplicación en cada caso en concreto de los fundamentos del derecho procesal penal, de conformidad con los principios rectores de la actividad penal, como la buena fe, la duda, la presunción de inocencia, y en general la Constitución Política, los fundamentos del Derecho y sus fuentes. | G7: Específica
A8: 5 | B8: Aplicar | C8: Negociación y resolución de conflictos | D8: hacer uso de los diferentes métodos alternativos de solución de conflictos auto y hetero compositivos | E8: de acuerdo con las posibilidades que la ley ofrece, que permiten racionalizar e interpretar los desencuentros que se presentan en las relaciones familiares, sociales, políticas y laborales, así como la toma de conciencia de la existencia y del manejo adecuado de los conflictos | F8: Aplicar las habilidades de negociación y resolución de conflictos para hacer uso de los diferentes métodos alternativos de solución de conflictos auto y hetero compositivos, de acuerdo con las posibilidades que la ley ofrece, que permiten racionalizar e interpretar los desencuentros que se presentan en las relaciones familiares, sociales, políticas y laborales, así como la toma de conciencia de la existencia y del manejo adecuado de los conflictos. | G8: Específica
A9: 6 | B9: Conocer | C9: Relaciones de producción desde el ámbito interdisciplinar, según el entorno en el que se desenvuelven los individuos en las organizaciones, empresas o instituciones | D9: comprender los modelos económicos, políticos, laborales y sociales, así como las problemáticas que existen o emergen de estas relaciones | E9: teniendo en cuenta el ordenamiento jurídico colombiano y las políticas económicas | F9: Conocer los aspectos asociados a las relaciones de producción desde el ámbito interdisciplinar, según el entorno en el que se desenvuelven los individuos en las organizaciones, empresas o instituciones, para comprender los modelos económicos, políticos, laborales y sociales, así como las problemáticas que existen o emergen de estas relaciones, teniendo en cuenta el ordenamiento jurídico colombiano y las políticas económicas. | G9: Específica
A10: 7 | B10: Analizar | C10: Fenómenos contemporáneos | D10: reconocer sus afectaciones o contribuciones en el marco de las ciudadanías globales y de una sociedad responsable y sostenible. | E10: desde una perspectiva global, soportada en datos, con una mirada ética y crítica | F10: Analizar los fenómenos contemporáneos desde una perspectiva glocal, soportada en datos, con una mirada ética y crítica, para reconocer sus afectaciones o contribuciones en el marco de las ciudadanías globales y de una sociedad responsable y sostenible. | G10: Genérica

Sheet Paso 3 Redacción RA
A1: [A partir de la celda A2 dar clic en la lista desplegable y seleccionar la competencia redactada en el paso 2.] | B1: [Enumerar los resultados de aprendizaje que se van a declarar.] | C1: [A partir de la celda C2, dar clic en la lista desplegable y elegir el tipo de dominio a tratar en el resultado de aprendizaje.] | D1: [A partir de la cela D2, dar clic en la lista desplegable y elegir el saber correspondiente al dominio.] | E1: [A partir de la celda E2, dar clic en la lista desplegable y elegir la taxonomía que se considere adecuada, solo se elige una para todos los saberes.] | F1: [A partir de la celda F2, dar clic en la lista desplegable y elegir el dominio que se considera adecuado.] | G1: [A partir de la celda G2, dar clic en la lista desplegable y elegir el nivel del dominio que se considera adecuado.] | H1: [A partir de la celda H2, dar clic en la lista desplegable y elegir el verbo que se considera adecuado.] | I1: [Iniciar con el verbo elegido (columna H), en infinitivo, luego el objeto sobre el cual recae la acción (columna D) y finalmente la condición de contexto (académico, disciplinar, social u otro).]
A2: Competencia por desarrollar | B2: Número de resultado | C2: TipoSaber | D2: SaberAsociado | E2: Taxonomía | F2: Dominio Asociado | G2: Nivel Dominio | H2: Verbo RA | I2: Resultados Aprendizaje
A3: Dominar el derecho privado, para aplicar los derechos y obligaciones que surgen de relaciones jurídicas entre los particulares, así como buscar su cumplimiento o declaración en escenarios judiciales, de acuerdo con los diferentes instrumentos internacionales, constitucionales, legales y reglamentarios que comprende el derecho civil en escenarios de consulta y litigio. | B3: 1 | C3: Saber | D3: Derecho privado | E3: Bloom | F3: CognitivoB | G3: AnálisisB | H3: Reconocer | I3: Reconoce los fundamentos del derecho penal, comercial, público, laboral y privado para determinar el procedimiento a seguir en la resolución de conflictos o de actos jurídicos, observando los principios rectores de cada actividad y atendiendo a la legislación y normatividad vigente, que permitan generar acciones positivas y acordes a las necesidades de los individuos o las organizaciones, según sea el caso.
A4: Dominar el derecho privado, para aplicar los derechos y obligaciones que surgen de relaciones jurídicas entre los particulares, así como buscar su cumplimiento o declaración en escenarios judiciales, de acuerdo con los diferentes instrumentos internacionales, constitucionales, legales y reglamentarios que comprende el derecho civil en escenarios de consulta y litigio. | B4: 3 | C4: SaberHacer | D4: aplicar los derechos y obligaciones que surgen de relaciones jurídicas entre los particulares, así como buscar su cumplimiento o declaración en escenarios judiciales | E4: Bloom | F4: ProcedimentalB | G4: AplicaciónB | H4: Aplicar | I4: Aplica el derecho privado, atendiendo la legislación y normatividad vigente, para dar solución a casos concretos.
A5: Dominar el derecho privado, para aplicar los derechos y obligaciones que surgen de relaciones jurídicas entre los particulares, así como buscar su cumplimiento o declaración en escenarios judiciales, de acuerdo con los diferentes instrumentos internacionales, constitucionales, legales y reglamentarios que comprende el derecho civil en escenarios de consulta y litigio. | B5: 9 | C5: SaberSer | D5: de acuerdo con los diferentes instrumentos internacionales, constitucionales, legales y reglamentarios que comprende el derecho civil en escenarios de consulta y litigio | E5: Bloom | F5: ActitudinalB | G5: AnálisisB | H5: Reconocer | I5: Reconoce los principios éticos del derecho para implementarlos en su conducta y ejercicio profesional, atendiendo a los casos que llegan a su conocimiento en escenarios nacionales e internacionales.
A6: Dominar el derecho comercial, para asesorar en la generación, modificación o extinción de obligaciones, así como para elaborar contratos de cualquier tipología, de acuerdo con al normatividad colombiana y los estándares internacionales vigentes en planeación, control y administración empresarial. | B6: 1 | C6: Saber | D6: Derecho comercial | E6: Bloom | F6: CognitivoB | G6: AnálisisB | H6: Reconocer | I6: Reconoce los fundamentos del derecho penal, comercial, público, laboral y privado para determinar el procedimiento a seguir en la resolución de conflictos o de actos jurídicos, observando los principios rectores de cada actividad y atendiendo a la legislación y normatividad vigente, que permitan generar acciones positivas y acordes a las necesidades de los individuos o las organizaciones, según sea el caso.
A7: Dominar el derecho comercial, para asesorar en la generación, modificación o extinción de obligaciones, así como para elaborar contratos de cualquier tipología, de acuerdo con al normatividad colombiana y los estándares internacionales vigentes en planeación, control y administración empresarial. | B7: 4 | C7: SaberHacer | D7: asesorar en la generación, modificación o extinción de obligaciones, así como para elaborar contratos de cualquier tipología | E7: Bloom | F7: ProcedimentalB | G7: AplicaciónB | H7: Aplicar | I7: Aplica el régimen de las obligaciones y los contratos comerciales de cualquier tipología, nacional e internacional, atendiendo a las necesidades que se derivan de las relaciones comerciales entorno a su nacimiento, modificación y extinción, para adelantar los procesos jurídicos que correspondan al caso.
A8: Dominar el derecho comercial, para asesorar en la generación, modificación o extinción de obligaciones, así como para elaborar contratos de cualquier tipología, de acuerdo con al normatividad colombiana y los estándares internacionales vigentes en planeación, control y administración empresarial. | B8: 9 | C8: SaberSer | D8: de acuerdo con la normatividad colombiana y los estándares internacionales vigentes en planeación, control y administración empresarial | E8: Bloom | F8: ActitudinalB | G8: AnálisisB | H8: Reconocer | I8: Reconoce los principios éticos del derecho para implementarlos en su conducta y ejercicio profesional, atendiendo a los casos que llegan a su conocimiento en escenarios nacionales e internacionales.
A9: Conocer el derecho público, para identificar los diferentes instrumentos constitucionales, legales y reglamentarios que comprenden las relaciones con intervención del Estado, de acuerdo con el marco universal de principios y valores propios del Estado Social de Derecho y de la Democracia Participativa, desde una perspectiva social, económica, política y humanista, dentro del contexto nacional e internacional. | B9: 2 | C9: Saber | D9: Derecho público | E9: Bloom | F9: CognitivoB | G9: ComprensiónB | H9: Identificar | I9: Identifica los elementos característicos de la negociación y resolución de conflictos para caracterizar la información y argumentación requerida en los procesos de acuerdos, transacciones o laudos arbitrales que den por terminados los conflictos puestos a su conocimiento.
A10: Conocer el derecho público, para identificar los diferentes instrumentos constitucionales, legales y reglamentarios que comprenden las relaciones con intervención del Estado, de acuerdo con el marco universal de principios y valores propios del Estado Social de Derecho y de la Democracia Participativa, desde una perspectiva social, económica, política y humanista, dentro del contexto nacional e internacional. | B10: 5 | C10: SaberHacer | D10: identificar los diferentes instrumentos constitucionales, legales y reglamentarios que comprenden las relaciones con intervención del Estado | E10: Bloom | F10: ProcedimentalB | G10: AplicaciónB | H10: Aplicar | I10: Aplica las acciones administrativas y judiciales procedentes del derecho público para proyectar procesos jurídicos que garanticen el reconocimiento y la protección de los derechos de las personas.
A11: Conocer el derecho público, para identificar los diferentes instrumentos constitucionales, legales y reglamentarios que comprenden las relaciones con intervención del Estado, de acuerdo con el marco universal de principios y valores propios del Estado Social de Derecho y de la Democracia Participativa, desde una perspectiva social, económica, política y humanista, dentro del contexto nacional e internacional. | B11: 9 | C11: SaberSer | D11: de acuerdo con el marco universal de principios y valores propios del Estado Social de Derecho y de la Democracia Participativa, desde una perspectiva social, económica, política y humanista, dentro del contexto nacional e internacional | E11: Bloom | F11: ActitudinalB | G11: AnálisisB | H11: Reconocer | I11: Reconoce los principios éticos del derecho para implementarlos en su conducta y ejercicio profesional, atendiendo a los casos que llegan a su conocimiento en escenarios nacionales e internacionales.
A12: Aplicar el derecho penal, para asumir y resolver asuntos en pro de la defensa, la acusación o el juzgamiento de conductas punibles, así como la aplicación en cada caso en concreto de los fundamentos del derecho procesal penal, de conformidad con los principios rectores de la actividad penal, como la buena fe, la duda, la presunción de inocencia, y en general la Constitución Política, los fundamentos del Derecho y sus fuentes. | B12: 1 | C12: Saber | D12: Derecho penal | E12: Bloom | F12: CognitivoB | G12: AnálisisB | H12: Reconocer | I12: Reconoce los fundamentos del derecho penal, comercial, público, laboral y privado para determinar el procedimiento a seguir en la resolución de conflictos o de actos jurídicos, observando los principios rectores de cada actividad y atendiendo a la legislación y normatividad vigente, que permitan generar acciones positivas y acordes a las necesidades de los individuos o las organizaciones, según sea el caso.
A13: Aplicar el derecho penal, para asumir y resolver asuntos en pro de la defensa, la acusación o el juzgamiento de conductas punibles, así como la aplicación en cada caso en concreto de los fundamentos del derecho procesal penal, de conformidad con los principios rectores de la actividad penal, como la buena fe, la duda, la presunción de inocencia, y en general la Constitución Política, los fundamentos del Derecho y sus fuentes. | B13: 6 | C13: SaberHacer | D13: asumir y resolver asuntos en pro de la defensa, la acusación o el juzgamiento de conductas punibles, así como la aplicación en cada caso en concreto de los fundamentos del derecho procesal penal | E13: Bloom | F13: ProcedimentalB | G13: AplicaciónB | H13: Aplicar | I13: Aplica el derecho penal en el procedimiento y la acción procedente en atención al tipo penal identificado para adelantar los procesos jurídicos que correspondan al caso.
A14: Aplicar el derecho penal, para asumir y resolver asuntos en pro de la defensa, la acusación o el juzgamiento de conductas punibles, así como la aplicación en cada caso en concreto de los fundamentos del derecho procesal penal, de conformidad con los principios rectores de la actividad penal, como la buena fe, la duda, la presunción de inocencia, y en general la Constitución Política, los fundamentos del Derecho y sus fuentes. | B14: 9 | C14: SaberSer | D14: de conformidad con los principios rectores de la actividad penal, como la buena fe, la duda, la presunción de inocencia, y en general la Constitución Política, los fundamentos del Derecho y sus fuentes | E14: Bloom | F14: ActitudinalB | G14: AnálisisB | H14: Reconocer | I14: Reconoce los principios éticos del derecho para implementarlos en su conducta y ejercicio profesional, atendiendo a los casos que llegan a su conocimiento en escenarios nacionales e internacionales.
... A21: Analizar los fenómenos contemporáneos desde una perspectiva glocal, soportada en datos, con una mirada ética y crítica, para reconocer sus afectaciones o contribuciones en el marco de las ciudadanías globales y de una sociedad responsable y sostenible. | B21: 2 | C21: Saber | D21: Fenómenos contemporáneos | E21: Bloom | F21: CognitivoB | G21: ComprensiónB | H21: Identificar | I21: Identifica fenómenos contemporáneos y su relación con la profesión, para determinar sus impactos e influencia en la sociedad, de forma responsable y crítica.

Sheet Paso 3 Redacción RA - Backup 
A1: [A partir de la celda A2 dar clic en la lista desplegable y seleccionar la competencia redactada en el paso 2.] | B1: [Enumerar los resultados de aprendizaje que se van a declarar.] | C1: [A partir de la celda C2, dar clic en la lista desplegable y elegir el tipo de dominio a tratar en el resultado de aprendizaje.] | D1: [A partir de la cela D2, dar clic en la lista desplegable y elegir el saber correspondiente al dominio.] | E1: [A partir de la celda E2, dar clic en la lista desplegable y elegir la taxonomía que se considere adecuada, solo se elige una para todos los saberes.] | F1: [A partir de la celda F2, dar clic en la lista desplegable y elegir el dominio que se considera adecuado.] | G1: [A partir de la celda G2, dar clic en la lista desplegable y elegir el nivel del dominio que se considera adecuado.] | H1: [A partir de la celda H2, dar clic en la lista desplegable y elegir el verbo que se considera adecuado.] | I1: [Iniciar con el verbo elegido (columna H), en infinitivo, luego el objeto sobre el cual recae la acción (columna D) y finalmente la condición de contexto (académico, disciplinar, social u otro).]
A2: Competencia por desarrollar | B2: Número de resultado | C2: TipoSaber | D2: SaberAsociado | E2: Taxonomía | F2: Dominio Asociado | G2: Nivel Dominio | H2: Verbo RA | I2: Resultados Aprendizaje
A3: Dominar los elementos de teoría de circuitos y transmisión de información para diseñar, implementar o administrar la infraestructura eléctrica y los dispositivos electrónicos que dan soporte a los sistemas de telecomunicaciones alineado con prácticas basadas en estándares del sector y la normatividad vigente, teniendo en cuenta las condiciones, restricciones y requerimientos técnicos del entorno. | B3: 1 | C3: Saber | D3: los elementos de teoría de circuitos y transmisión de información | E3: BAK | F3: CognitivoBAK | G3: ComprensiónBAK | H3: Identificar | I3: Identifica los elementos de teoría de circuitos, de transmisión de información, de seguridad de la información, de redes de comunicaciones, de sistemas de cómputo, de estandares y marcos de referencia que hacen parte de la gestión de proyectos como del desarrollo de actividades relacionadas a las infraestructuras de TIC, para explicar soluciones de diseño, administración o implementación a problemáticas del sector, desde un abordaje teórico-práctico, a través de herramientas de simulación, análisis de casos prácticos y uso de equipos de laboratorio.
A4: Dominar los elementos de teoría de circuitos y transmisión de información para diseñar, implementar o administrar la infraestructura eléctrica y los dispositivos electrónicos que dan soporte a los sistemas de telecomunicaciones alineado con prácticas basadas en estándares del sector y la normatividad vigente, teniendo en cuenta las condiciones, restricciones y requerimientos técnicos del entorno. | B4: 4 | C4: SaberHacer | D4: para diseñar, implementar o administrar la infraestructura eléctrica y los dispositivos electrónicos que dan soporte a los sistemas de telecomunicaciones | E4: BAK | F4: ProcedimentalBAK | G4: ManipulaciónBAK | H4: Aplicar | I4: Aplica los elementos de teoría de circuitos, de transmisión de información, de seguridad de la información, de redes de comunicaciones, de sistemas de cómputo, de estandares tecnológicos y marcos de referencia que hacen parte de la gestión de proyectos como del desarrollo de actividades relacionadas a las infraestructuras de TIC, para construir propuestas de diseño, implementación o administración de infraestructura eléctrica, dispositivos electrónicos, servicios de comunicaciones en nube o en sitio, sistemas de telecomunicaciones, a través de herramientas de simulación, análisis de casos prácticos y uso de equipos de laboratorio.
A5: Dominar los elementos de teoría de circuitos y transmisión de información para diseñar, implementar o administrar la infraestructura eléctrica y los dispositivos electrónicos que dan soporte a los sistemas de telecomunicaciones alineado con prácticas basadas en estándares del sector y la normatividad vigente, teniendo en cuenta las condiciones, restricciones y requerimientos técnicos del entorno. | B5: 7 | C5: SaberSer | D5: alineado con prácticas basadas en estándares del sector y la normatividad vigente, teniendo en cuenta las condiciones, restricciones y requerimientos técnicos del entorno. | E5: BAK | F5: ActitudinalBAK | G5: ValorarBAK | H5: Emplear | I5: Emplea las buenas prácticas de teoría de circuitos y transmisión, y de seguridad de la información, redes y sistemas de cómputo basadas en estándares del sector y la normatividad vigente, teniendo en cuenta las condiciones, restricciones y requerimientos técnicos de un proyecto, para formular soluciones en infraestructuras TIC o del área de las telecomunicaciones.
A6: Dominar los elementos de seguridad de la información, redes de comunicaciones y sistemas de cómputo que hacen parte de infraestructuras TIC para diseñar, implementar o administrar infraestructuras y servicios de comunicaciones en sitio o en nube alineado con prácticas basadas en estándares del sector y la normatividad vigente, teniendo en cuenta las condiciones, restricciones y requerimientos técnicos del entorno. | B6: 1 | C6: Saber | D6: los elementos de seguridad de la información, redes de comunicaciones y sistemas de cómputo que hacen parte de infraestructuras TIC | E6: BAK | F6: CognitivoBAK | G6: ComprensiónBAK | H6: Identificar | I6: Identifica los elementos de teoría de circuitos, de transmisión de información, de seguridad de la información, de redes de comunicaciones, de sistemas de cómputo, de estandares y marcos de referencia que hacen parte de la gestión de proyectos como del desarrollo de actividades relacionadas a las infraestructuras de TIC, para evaluar soluciones a problemáticas del sector, desde un abordaje teórico-práctico, a través de herramientas de simulación, análisis de casos prácticos y uso de equipos de laboratorio.
A7: Dominar los elementos de seguridad de la información, redes de comunicaciones y sistemas de cómputo que hacen parte de infraestructuras TIC para diseñar, implementar o administrar infraestructuras y servicios de comunicaciones en sitio o en nube alineado con prácticas basadas en estándares del sector y la normatividad vigente, teniendo en cuenta las condiciones, restricciones y requerimientos técnicos del entorno. | B7: 5 | C7: SaberHacer | D7: para diseñar, implementar o administrar infraestructuras y servicios de comunicaciones en sitio o en nube | E7: BAK | F7: ProcedimentalBAK | G7: ManipulaciónBAK | H7: Aplicar | I7: Aplica los elementos de teoría de circuitos, de transmisión de información, de seguridad de la información, de redes de comunicaciones, de sistemas de cómputo, de estandares tecnológicos y marcos de referencia que hacen parte de la gestión de proyectos como del desarrollo de actividades relacionadas a las infraestructuras de TIC, para construir propuestas de diseño, implementación o administración de infraestructura eléctrica, dispositivos electrónicos, servicios de comunicaciones en nube o en sitio, sistemas de telecomunicaciones, a través de herramientas de simulación, análisis de casos prácticos y uso de equipos de laboratorio.
A8: Dominar los elementos de seguridad de la información, redes de comunicaciones y sistemas de cómputo que hacen parte de infraestructuras TIC para diseñar, implementar o administrar infraestructuras y servicios de comunicaciones en sitio o en nube alineado con prácticas basadas en estándares del sector y la normatividad vigente, teniendo en cuenta las condiciones, restricciones y requerimientos técnicos del entorno. | B8: 7 | C8: SaberSer | D8: alineado con prácticas basadas en estándares del sector y la normatividad vigente, teniendo en cuenta las condiciones, restricciones y requerimientos técnicos del entorno. | E8: BAK | F8: ActitudinalBAK | G8: ValorarBAK | H8: Emplear | I8: Emplea las buenas prácticas de teoría de circuitos y transmisión, y de seguridad de la información, redes y sistemas de cómputo basadas en estándares del sector y la normatividad vigente, teniendo en cuenta las condiciones, restricciones y requerimientos técnicos de un proyecto, para formular soluciones en infraestructuras TIC o del área de las telecomunicaciones.
A9: Conocer los estándares y marcos de referencia asociados tanto a la gestión de proyectos como al desarrollo de actividades relacionadas a las tecnologías de la información para diseñar, implementar o administrar soluciones del área de las telecomunicaciones, la seguridad de la información y la infraestructura TIC manteniendo una postura socialmente responsable, autónoma, teniendo en cuenta las condiciones, restricciones y requerimientos técnicos del entorno. | B9: 2 | C9: Saber | D9: los estándares y marcos de referencia asociados tanto a la gestión de proyectos como al desarrollo de actividades relacionadas a las tecnologías de la información | E9: BAK | F9: CognitivoBAK | G9: ComprensiónBAK | H9: Identificar | I9: Identifica los elementos de teoría de circuitos, de transmisión de información, de seguridad de la información, de redes de comunicaciones, de sistemas de cómputo, de estandares y marcos de referencia que hacen parte de la gestión de proyectos como del desarrollo de actividades relacionadas a las infraestructuras de TIC, para evaluar soluciones a problemáticas del sector, desde un abordaje teórico-práctico, a través de herramientas de simulación, análisis de casos prácticos y uso de equipos de laboratorio.
A10: Conocer los estándares y marcos de referencia asociados tanto a la gestión de proyectos como al desarrollo de actividades relacionadas a las tecnologías de la información para diseñar, implementar o administrar soluciones del área de las telecomunicaciones, la seguridad de la información y la infraestructura TIC manteniendo una postura socialmente responsable, autónoma, teniendo en cuenta las condiciones, restricciones y requerimientos técnicos del entorno. | B10: 6 | C10: SaberHacer | D10: para diseñar, implementar o administrar soluciones del área de las telecomunicaciones, la seguridad de la información y la infraestructura TIC | E10: BAK | F10: ProcedimentalBAK | G10: ManipulaciónBAK | H10: Aplicar | I10: Aplica los elementos de teoría de circuitos, de transmisión de información, de seguridad de la información, de redes de comunicaciones, de sistemas de cómputo, de estandares tecnológicos y marcos de referencia que hacen parte de la gestión de proyectos como del desarrollo de actividades relacionadas a las infraestructuras de TIC, para construir propuestas de diseño, implementación o administración de infraestructura eléctrica, dispositivos electrónicos, servicios de comunicaciones en nube o en sitio, sistemas de telecomunicaciones, a través de herramientas de simulación, análisis de casos prácticos y uso de equipos de laboratorio.
A11: Conocer los estándares y marcos de referencia asociados tanto a la gestión de proyectos como al desarrollo de actividades relacionadas a las tecnologías de la información para diseñar, implementar o administrar soluciones del área de las telecomunicaciones, la seguridad de la información y la infraestructura TIC manteniendo una postura socialmente responsable, autónoma, teniendo en cuenta las condiciones, restricciones y requerimientos técnicos del entorno. | B11: 7 | C11: SaberSer | D11: manteniendo una postura socialmente responsable, autónoma, teniendo en cuenta las condiciones, restricciones y requerimientos técnicos del entorno. | E11: BAK | F11: ActitudinalBAK | G11: ValorarBAK | H11: Emplear | I11: Emplea las buenas prácticas de teoría de circuitos y transmisión, y de seguridad de la información, redes y sistemas de cómputo basadas en estándares del sector y la normatividad vigente, teniendo en cuenta las condiciones, restricciones y requerimientos técnicos de un proyecto, para formular soluciones en infraestructuras TIC o del área de las telecomunicaciones.
A12: Analizar los fenómenos contemporáneos desde una perspectiva glocal, soportada en datos, con una mirada ética y crítica, para reconocer sus afectaciones o contribuciones en el marco de las ciudadanías globales y de una sociedad responsable y sostenible. | B12: 3 | C12: Saber | D12: Fenómenos contemporáneos | E12: Bloom | F12: CognitivoB | G12: ComprensiónB | H12: Identificar | I12: Identifica fenómenos contemporáneos y su relación con la profesión, para determinar sus impactos e influencia en la sociedad, de forma responsable y crítica.

Sheet Paso 4 Estrategias mesocurricu
A1: [A partir de la celda A3 despliegue el(los) resultado(s) de aprendizaje y elegir aquel (aquellos) al(a los) que se contribuye desde la estrategia.] | B1: [Escribir el nombre de la estrategia a desarrollar. Participación de los estudiantes en cursos, talleres, seminarios, conferencias, pruebas estandarizadas, investigaciones, actividades o experiencias, cuerpos académicos, redes, comunidades, la elaboración de textos y materiales, así como las publicaciones, entre otros.] | C1: [Describir la(s) estrategia(s) definidas por el programa.] | D1: [Escribir los indicadores de impacto de la estrategia. Se sugieren indicadores como: Valora el nivel de contribución de la estrategia a los resultados de aprendizaje; Número de estudiantes que participan en la estrategia; Número de veces que se realiza la estrategia, entre otros.] | E1: [Escribir las acciones de retroalimentación que usará el programa para comunicar a los estudiantes sobre el alcance de sus resultados de aprendizaje.] | F1: [Escribir, para cada indicador con qué instrumento se recogerá información para evidenciar el (los) impacto (s) declarados. Encuesta, lista de asistencia, informe, entre otros.]
A2: Resultado de aprendizaje | B2: Estrategia del programa | C2: Descripción | D2: Indicador de Impacto de la Estrategia | E2: Acciones de retroalimentación para los estudiantes | F2: Instrumentos de medición
A3: Reconoce los fundamentos del derecho penal, comercial, público, laboral y privado para determinar el procedimiento a seguir en la resolución de conflictos o de actos jurídicos, observando los principios rectores de cada actividad y atendiendo a la legislación y normatividad vigente, que permitan generar acciones positivas y acordes a las necesidades de los individuos o las organizaciones, según sea el caso. | B3: Seminario Internacional | C3: Los estudiantes con un avance en su plan de estudios superior al 70% podrán optar por un seminario internacional en el que al finalizar entregaran un artículo científico que se sustentará ante jurado, demostrando la identificación de un problema jurídico y la solución del mismo en uso de las diferentes fuentes del derecho. | D3: Valoración de la contribución de la estrategia a los resultados de aprendizaje del programa en una escala de Likert. | E3: Informar y formar sobre los temas de tendencia de manera que se contribuya al desarrollo formativo de los estudiantes. | F3: Encuesta.
A4: Aplica el derecho privado, atendiendo la legislación y normatividad vigente, para dar solución a casos concretos. | D4: Número de estudiantes que participan de la estrategia. | F4: Listados de participación.
A5: Reconoce los principios éticos del derecho para implementarlos en su conducta y ejercicio profesional, atendiendo a los casos que llegan a su conocimiento en escenarios nacionales e internacionales. | D5: Número de veces que se desarrolla el seminario. | F5: Reporte.
A6: Aplica el régimen de las obligaciones y los contratos comerciales de cualquier tipología, nacional e internacional, atendiendo a las necesidades que se derivan de las relaciones comerciales entorno a su nacimiento, modificación y extinción, para adelantar los procesos jurídicos que correspondan al caso.
A7: Identifica los elementos característicos de la negociación y resolución de conflictos para caracterizar la información y argumentación requerida en los procesos de acuerdos, transacciones o laudos arbitrales que den por terminados los conflictos puestos a su conocimiento.
A8: Aplica las acciones administrativas y judiciales procedentes del derecho público para proyectar procesos jurídicos que garanticen el reconocimiento y la protección de los derechos de las personas.
A9: Aplica el derecho penal en el procedimiento y la acción procedente en atención al tipo penal identificado para adelantar los procesos jurídicos que correspondan al caso.
A10: Aplica habilidades de negociación y resolución de conflictos para atender las necesidades de los ciudadanos y la consolidación de acuerdos que den por termino los conflictos puestos a su conocimiento.
A11: Aplica los diferentes regímenes laborales para proyectar soluciones, en el marco jurídico, a las controversias que se originan de estas relaciones.
A12: Reconoce los fundamentos del derecho penal, comercial, público, laboral y privado para determinar el procedimiento a seguir en la resolución de conflictos o de actos jurídicos, observando los principios rectores de cada actividad y atendiendo a la legislación y normatividad vigente, que permitan generar acciones positivas y acordes a las necesidades de los individuos o las organizaciones, según sea el caso. | B12: Preparatorios (prueba estandarizada) | C12: Los estudiantes que hayan culminado su plan de estudios y no tengan un promedio igual o superior a 4,3 en el acumulado de la carrera, deberán presentar los exámenes preparatorios que miden la suficiencia de conocimientos en cada especialidad del derecho, esto mediante la preparación y posterior sustentación de un caso con base en las diferentes fuentes del derecho. | D12: Número de estudiantes que participan de la estrategia. | E12: Informar y formar a los estudiantes en la preparación y sustentación de un caso jurídico, evaluando su suficiencia disciplinar y acompañando su proceso de cierre académico. | F12: Listados de participación.
A13: Aplica el derecho privado, atendiendo la legislación y normatividad vigente, para dar solución a casos concretos. | D13: Número de veces que se desarrolla la estrategia en un periodo de tiempo determinado por el programa. | F13: Reporte.
A14: Reconoce los principios éticos del derecho para implementarlos en su conducta y ejercicio profesional, atendiendo a los casos que llegan a su conocimiento en escenarios nacionales e internacionales. | D14: Valoración de la contribución de la estrategia a los resultados de aprendizaje del programa en una escala de Likert. | F14: Encuesta.
A15: Aplica el régimen de las obligaciones y los contratos comerciales de cualquier tipología, nacional e internacional, atendiendo a las necesidades que se derivan de las relaciones comerciales entorno a su nacimiento, modificación y extinción, para adelantar los procesos jurídicos que correspondan al caso.
A16: Identifica los elementos característicos de la negociación y resolución de conflictos para caracterizar la información y argumentación requerida en los procesos de acuerdos, transacciones o laudos arbitrales que den por terminados los conflictos puestos a su conocimiento.
A17: Aplica las acciones administrativas y judiciales procedentes del derecho público para proyectar procesos jurídicos que garanticen el reconocimiento y la protección de los derechos de las personas.
A18: Aplica el derecho penal en el procedimiento y la acción procedente en atención al tipo penal identificado para adelantar los procesos jurídicos que correspondan al caso.
A19: Aplica habilidades de negociación y resolución de conflictos para atender las necesidades de los ciudadanos y la consolidación de acuerdos que den por termino los conflictos puestos a su conocimiento.
A20: Aplica los diferentes regímenes laborales para proyectar soluciones, en el marco jurídico, a las controversias que se originan de estas relaciones.
A21: Reconoce los fundamentos del derecho penal, comercial, público, laboral y privado para determinar el procedimiento a seguir en la resolución de conflictos o de actos jurídicos, observando los principios rectores de cada actividad y atendiendo a la legislación y normatividad vigente, que permitan generar acciones positivas y acordes a las necesidades de los individuos o las organizaciones, según sea el caso. | B21: Clases espejo nacional e internacional | C21: Tanto profesores como estudiantes participan en clases activamente, en una o doble vía, con grupos de otras universidades nacionales e internacionales, con la finalidad de reforzar sus conocimientos en derecho sustancial de las diferentes disciplinas y conocer los postulados internacionales en mismo sentido. | D21: Número de estudiantes que participan de la estrategia. | E21: Informar y formar sobre los temas abordados en las clases de manera que se contribuya al desarrollo formativo de los estudiantes. | F21: Listados de participación.
A22: Aplica el derecho privado, atendiendo la legislación y normatividad vigente, para dar solución a casos concretos. | D22: Número de veces que se desarrolla la estrategia en un periodo de tiempo determinado por el programa. | F22: Reporte.
A23: Reconoce los principios éticos del derecho para implementarlos en su conducta y ejercicio profesional, atendiendo a los casos que llegan a su conocimiento en escenarios nacionales e internacionales. | D23: Valora la contribución de la estrategia a los resultados de aprendizaje del programa en una escala de Likert. | F23: Encuesta.
A24: Aplica el régimen de las obligaciones y los contratos comerciales de cualquier tipología, nacional e internacional, atendiendo a las necesidades que se derivan de las relaciones comerciales entorno a su nacimiento, modificación y extinción, para adelantar los procesos jurídicos que correspondan al caso.
A25: Identifica los elementos característicos de la negociación y resolución de conflictos para caracterizar la información y argumentación requerida en los procesos de acuerdos, transacciones o laudos arbitrales que den por terminados los conflictos puestos a su conocimiento.
A26: Aplica las acciones administrativas y judiciales procedentes del derecho público para proyectar procesos jurídicos que garanticen el reconocimiento y la protección de los derechos de las personas.
A27: Aplica el derecho penal en el procedimiento y la acción procedente en atención al tipo penal identificado para adelantar los procesos jurídicos que correspondan al caso.
A28: Aplica habilidades de negociación y resolución de conflictos para atender las necesidades de los ciudadanos y la consolidación de acuerdos que den por termino los conflictos puestos a su conocimiento.
A29: Aplica los diferentes regímenes laborales para proyectar soluciones, en el marco jurídico, a las controversias que se originan de estas relaciones.
A30: Reconoce los fundamentos del derecho penal, comercial, público, laboral y privado para determinar el procedimiento a seguir en la resolución de conflictos o de actos jurídicos, observando los principios rectores de cada actividad y atendiendo a la legislación y normatividad vigente, que permitan generar acciones positivas y acordes a las necesidades de los individuos o las organizaciones, según sea el caso. | B30: Divulgación de los trabajos desarrollados en las opciones de grado | C30: Publicación de los trabajos en el Repositorio de Alejandría. | D30: Número de trabajos publicados en los periodos de tiempo que establezca el programa. | E30: Informar y formar sobre los temas abordados en los trabajos como medio de apropiación social del conocimiento. | F30: Reporte.
A31: Aplica el derecho privado, atendiendo la legislación y normatividad vigente, para dar solución a casos concretos. | D31: Número de estudiantes que participan de la estrategia. | F31: Listados de participación.
A32: Reconoce los principios éticos del derecho para implementarlos en su conducta y ejercicio profesional, atendiendo a los casos que llegan a su conocimiento en escenarios nacionales e internacionales.
A33: Aplica el régimen de las obligaciones y los contratos comerciales de cualquier tipología, nacional e internacional, atendiendo a las necesidades que se derivan de las relaciones comerciales entorno a su nacimiento, modificación y extinción, para adelantar los procesos jurídicos que correspondan al caso.
A34: Identifica los elementos característicos de la negociación y resolución de conflictos para caracterizar la información y argumentación requerida en los procesos de acuerdos, transacciones o laudos arbitrales que den por terminados los conflictos puestos a su conocimiento.
A35: Aplica las acciones administrativas y judiciales procedentes del derecho público para proyectar procesos jurídicos que garanticen el reconocimiento y la protección de los derechos de las personas.
A36: Aplica el derecho penal en el procedimiento y la acción procedente en atención al tipo penal identificado para adelantar los procesos jurídicos que correspondan al caso.
A37: Aplica habilidades de negociación y resolución de conflictos para atender las necesidades de los ciudadanos y la consolidación de acuerdos que den por termino los conflictos puestos a su conocimiento.
A38: Aplica los diferentes regímenes laborales para proyectar soluciones, en el marco jurídico, a las controversias que se originan de estas relaciones.
A39: Reconoce los fundamentos del derecho penal, comercial, público, laboral y privado para determinar el procedimiento a seguir en la resolución de conflictos o de actos jurídicos, observando los principios rectores de cada actividad y atendiendo a la legislación y normatividad vigente, que permitan generar acciones positivas y acordes a las necesidades de los individuos o las organizaciones, según sea el caso. | B39: Curso de preparación para el Saber Pro | C39: Los estudiantes al finalizar su plan de estudios, para optar por el grado de abogados, deben presentar un examen de Estado que evalúa sus conocimientos generales y específicos, para esto, desde el programa se genera un MOOCS de preparación para el examen de Estado, con acompañamiento de tutor en el desarrollo del mismo. | D39: Número de estudiantes que participan de la estrategia. | E39: Formar, prevenir y ayudar a tomar decisiones para el desarrollo formativo de los estudiantes. | F39: Listados de participación.
A40: Aplica el derecho privado, atendiendo la legislación y normatividad vigente, para dar solución a casos concretos. | D40: Número de veces que se desarrolla la estrategia en un periodo de tiempo determinado por el programa. | F40: Reporte.
...

Sheet Paso 5 Estrategias micro
